Workbook

Sheet Summary
A1: Inventory aged 181+ days vs Prime Day deals
A2: Ages: Amazon age snapshot 2026-10-03 (via the Ecotero LTSF engine). Deals: Jospeh_Allocation_Planner.xlsx. Next aged-inventory charge 2026-10-15; a removal submitted by 2026-10-14 avoids it. US figures in USD, CA in CAD. Charges are the engine's projections and match Amazon's own estimates (ratio 1.00).
A4: Market | B4: Product | C4: Aged SKUs | D4: Aged units 181+ | E4: Units 271d+ | F4: Oct-15 charge (est.) | G4: PD committed units (aged SKUs) | H4: Aged units left after PD | I4: SKUs: deal covers all aged | J4: SKUs: deal covers part | K4: SKUs: left out of PD | L4: SKUs: product not in PD
A5: US | B5: Bamboo Sheets 4 Piece | C5: =COUNTIFS('Aged SKUs vs PD'!$A$2:$A$212,$A5,'Aged SKUs vs PD'!$B$2:$B$212,$B5) -> 16 | D5: =SUMIFS('Aged SKUs vs PD'!$E$2:$E$212,'Aged SKUs vs PD'!$A$2:$A$212,$A5,'Aged SKUs vs PD'!$B$2:$B$212,$B5) -> 897 | E5: =SUMIFS('Aged SKUs vs PD'!$N$2:$N$212,'Aged SKUs vs PD'!$A$2:$A$212,$A5,'Aged SKUs vs PD'!$B$2:$B$212,$B5) -> 548 | F5: =SUMIFS('Aged SKUs vs PD'!$O$2:$O$212,'Aged SKUs vs PD'!$A$2:$A$212,$A5,'Aged SKUs vs PD'!$B$2:$B$212,$B5) -> 917.87 | G5: =SUMIFS('Aged SKUs vs PD'!$T$2:$T$212,'Aged SKUs vs PD'!$A$2:$A$212,$A5,'Aged SKUs vs PD'!$B$2:$B$212,$B5) -> 228 | H5: =SUMIFS('Aged SKUs vs PD'!$U$2:$U$212,'Aged SKUs vs PD'!$A$2:$A$212,$A5,'Aged SKUs vs PD'!$B$2:$B$212,$B5) -> 673 | I5: =COUNTIFS('Aged SKUs vs PD'!$A$2:$A$212,$A5,'Aged SKUs vs PD'!$B$2:$B$212,$B5,'Aged SKUs vs PD'!$R$2:$R$212,"In PD – deal covers all aged units") -> 1 | J5: =COUNTIFS('Aged SKUs vs PD'!$A$2:$A$212,$A5,'Aged SKUs vs PD'!$B$2:$B$212,$B5,'Aged SKUs vs PD'!$R$2:$R$212,"In PD – deal covers part of the aged units") -> 14 | K5: =COUNTIFS('Aged SKUs vs PD'!$A$2:$A$212,$A5,'Aged SKUs vs PD'!$B$2:$B$212,$B5,'Aged SKUs vs PD'!$R$2:$R$212,"Left out of PD") -> 1 | L5: =COUNTIFS('Aged SKUs vs PD'!$A$2:$A$212,$A5,'Aged SKUs vs PD'!$B$2:$B$212,$B5,'Aged SKUs vs PD'!$R$2:$R$212,"Not in any PD deal sheet") -> 0
A6: US | B6: Bamboo Sheets 6 Piece | C6: =COUNTIFS('Aged SKUs vs PD'!$A$2:$A$212,$A6,'Aged SKUs vs PD'!$B$2:$B$212,$B6) -> 18 | D6: =SUMIFS('Aged SKUs vs PD'!$E$2:$E$212,'Aged SKUs vs PD'!$A$2:$A$212,$A6,'Aged SKUs vs PD'!$B$2:$B$212,$B6) -> 1614 | E6: =SUMIFS('Aged SKUs vs PD'!$N$2:$N$212,'Aged SKUs vs PD'!$A$2:$A$212,$A6,'Aged SKUs vs PD'!$B$2:$B$212,$B6) -> 1294 | F6: =SUMIFS('Aged SKUs vs PD'!$O$2:$O$212,'Aged SKUs vs PD'!$A$2:$A$212,$A6,'Aged SKUs vs PD'!$B$2:$B$212,$B6) -> 2517.19 | G6: =SUMIFS('Aged SKUs vs PD'!$T$2:$T$212,'Aged SKUs vs PD'!$A$2:$A$212,$A6,'Aged SKUs vs PD'!$B$2:$B$212,$B6) -> 257 | H6: =SUMIFS('Aged SKUs vs PD'!$U$2:$U$212,'Aged SKUs vs PD'!$A$2:$A$212,$A6,'Aged SKUs vs PD'!$B$2:$B$212,$B6) -> 1371 | I6: =COUNTIFS('Aged SKUs vs PD'!$A$2:$A$212,$A6,'Aged SKUs vs PD'!$B$2:$B$212,$B6,'Aged SKUs vs PD'!$R$2:$R$212,"In PD – deal covers all aged units") -> 2 | J6: =COUNTIFS('Aged SKUs vs PD'!$A$2:$A$212,$A6,'Aged SKUs vs PD'!$B$2:$B$212,$B6,'Aged SKUs vs PD'!$R$2:$R$212,"In PD – deal covers part of the aged units") -> 14 | K6: =COUNTIFS('Aged SKUs vs PD'!$A$2:$A$212,$A6,'Aged SKUs vs PD'!$B$2:$B$212,$B6,'Aged SKUs vs PD'!$R$2:$R$212,"Left out of PD") -> 2 | L6: =COUNTIFS('Aged SKUs vs PD'!$A$2:$A$212,$A6,'Aged SKUs vs PD'!$B$2:$B$212,$B6,'Aged SKUs vs PD'!$R$2:$R$212,"Not in any PD deal sheet") -> 0
A7: US | B7: Satin Sheets 4 Piece | C7: =COUNTIFS('Aged SKUs vs PD'!$A$2:$A$212,$A7,'Aged SKUs vs PD'!$B$2:$B$212,$B7) -> 42 | D7: =SUMIFS('Aged SKUs vs PD'!$E$2:$E$212,'Aged SKUs vs PD'!$A$2:$A$212,$A7,'Aged SKUs vs PD'!$B$2:$B$212,$B7) -> 2919 | E7: =SUMIFS('Aged SKUs vs PD'!$N$2:$N$212,'Aged SKUs vs PD'!$A$2:$A$212,$A7,'Aged SKUs vs PD'!$B$2:$B$212,$B7) -> 672 | F7: =SUMIFS('Aged SKUs vs PD'!$O$2:$O$212,'Aged SKUs vs PD'!$A$2:$A$212,$A7,'Aged SKUs vs PD'!$B$2:$B$212,$B7) -> 1494.26 | G7: =SUMIFS('Aged SKUs vs PD'!$T$2:$T$212,'Aged SKUs vs PD'!$A$2:$A$212,$A7,'Aged SKUs vs PD'!$B$2:$B$212,$B7) -> 590 | H7: =SUMIFS('Aged SKUs vs PD'!$U$2:$U$212,'Aged SKUs vs PD'!$A$2:$A$212,$A7,'Aged SKUs vs PD'!$B$2:$B$212,$B7) -> 2399 | I7: =COUNTIFS('Aged SKUs vs PD'!$A$2:$A$212,$A7,'Aged SKUs vs PD'!$B$2:$B$212,$B7,'Aged SKUs vs PD'!$R$2:$R$212,"In PD – deal covers all aged units") -> 7 | J7: =COUNTIFS('Aged SKUs vs PD'!$A$2:$A$212,$A7,'Aged SKUs vs PD'!$B$2:$B$212,$B7,'Aged SKUs vs PD'!$R$2:$R$212,"In PD – deal covers part of the aged units") -> 27 | K7: =COUNTIFS('Aged SKUs vs PD'!$A$2:$A$212,$A7,'Aged SKUs vs PD'!$B$2:$B$212,$B7,'Aged SKUs vs PD'!$R$2:$R$212,"Left out of PD") -> 8 | L7: =COUNTIFS('Aged SKUs vs PD'!$A$2:$A$212,$A7,'Aged SKUs vs PD'!$B$2:$B$212,$B7,'Aged SKUs vs PD'!$R$2:$R$212,"Not in any PD deal sheet") -> 0
A8: US | B8: Satin Sheets 6 Piece | C8: =COUNTIFS('Aged SKUs vs PD'!$A$2:$A$212,$A8,'Aged SKUs vs PD'!$B$2:$B$212,$B8) -> 46 | D8: =SUMIFS('Aged SKUs vs PD'!$E$2:$E$212,'Aged SKUs vs PD'!$A$2:$A$212,$A8,'Aged SKUs vs PD'!$B$2:$B$212,$B8) -> 1062 | E8: =SUMIFS('Aged SKUs vs PD'!$N$2:$N$212,'Aged SKUs vs PD'!$A$2:$A$212,$A8,'Aged SKUs vs PD'!$B$2:$B$212,$B8) -> 821 | F8: =SUMIFS('Aged SKUs vs PD'!$O$2:$O$212,'Aged SKUs vs PD'!$A$2:$A$212,$A8,'Aged SKUs vs PD'!$B$2:$B$212,$B8) -> 1164.75 | G8: =SUMIFS('Aged SKUs vs PD'!$T$2:$T$212,'Aged SKUs vs PD'!$A$2:$A$212,$A8,'Aged SKUs vs PD'!$B$2:$B$212,$B8) -> 0 | H8: =SUMIFS('Aged SKUs vs PD'!$U$2:$U$212,'Aged SKUs vs PD'!$A$2:$A$212,$A8,'Aged SKUs vs PD'!$B$2:$B$212,$B8) -> 1062 | I8: =COUNTIFS('Aged SKUs vs PD'!$A$2:$A$212,$A8,'Aged SKUs vs PD'!$B$2:$B$212,$B8,'Aged SKUs vs PD'!$R$2:$R$212,"In PD – deal covers all aged units") -> 0 | J8: =COUNTIFS('Aged SKUs vs PD'!$A$2:$A$212,$A8,'Aged SKUs vs PD'!$B$2:$B$212,$B8,'Aged SKUs vs PD'!$R$2:$R$212,"In PD – deal covers part of the aged units") -> 0 | K8: =COUNTIFS('Aged SKUs vs PD'!$A$2:$A$212,$A8,'Aged SKUs vs PD'!$B$2:$B$212,$B8,'Aged SKUs vs PD'!$R$2:$R$212,"Left out of PD") -> 0 | L8: =COUNTIFS('Aged SKUs vs PD'!$A$2:$A$212,$A8,'Aged SKUs vs PD'!$B$2:$B$212,$B8,'Aged SKUs vs PD'!$R$2:$R$212,"Not in any PD deal sheet") -> 46
A9: US | B9: Silk Pillowcase | C9: =COUNTIFS('Aged SKUs vs PD'!$A$2:$A$212,$A9,'Aged SKUs vs PD'!$B$2:$B$212,$B9) -> 12 | D9: =SUMIFS('Aged SKUs vs PD'!$E$2:$E$212,'Aged SKUs vs PD'!$A$2:$A$212,$A9,'Aged SKUs vs PD'!$B$2:$B$212,$B9) -> 1963 | E9: =SUMIFS('Aged SKUs vs PD'!$N$2:$N$212,'Aged SKUs vs PD'!$A$2:$A$212,$A9,'Aged SKUs vs PD'!$B$2:$B$212,$B9) -> 1780 | F9: =SUMIFS('Aged SKUs vs PD'!$O$2:$O$212,'Aged SKUs vs PD'!$A$2:$A$212,$A9,'Aged SKUs vs PD'!$B$2:$B$212,$B9) -> 411.65 | G9: =SUMIFS('Aged SKUs vs PD'!$T$2:$T$212,'Aged SKUs vs PD'!$A$2:$A$212,$A9,'Aged SKUs vs PD'!$B$2:$B$212,$B9) -> 110 | H9: =SUMIFS('Aged SKUs vs PD'!$U$2:$U$212,'Aged SKUs vs PD'!$A$2:$A$212,$A9,'Aged SKUs vs PD'!$B$2:$B$212,$B9) -> 1853 | I9: =COUNTIFS('Aged SKUs vs PD'!$A$2:$A$212,$A9,'Aged SKUs vs PD'!$B$2:$B$212,$B9,'Aged SKUs vs PD'!$R$2:$R$212,"In PD – deal covers all aged units") -> 0 | J9: =COUNTIFS('Aged SKUs vs PD'!$A$2:$A$212,$A9,'Aged SKUs vs PD'!$B$2:$B$212,$B9,'Aged SKUs vs PD'!$R$2:$R$212,"In PD – deal covers part of the aged units") -> 11 | K9: =COUNTIFS('Aged SKUs vs PD'!$A$2:$A$212,$A9,'Aged SKUs vs PD'!$B$2:$B$212,$B9,'Aged SKUs vs PD'!$R$2:$R$212,"Left out of PD") -> 1 | L9: =COUNTIFS('Aged SKUs vs PD'!$A$2:$A$212,$A9,'Aged SKUs vs PD'!$B$2:$B$212,$B9,'Aged SKUs vs PD'!$R$2:$R$212,"Not in any PD deal sheet") -> 0
A10: CA | B10: Bamboo Sheets 4 Piece | C10: =COUNTIFS('Aged SKUs vs PD'!$A$2:$A$212,$A10,'Aged SKUs vs PD'!$B$2:$B$212,$B10) -> 13 | D10: =SUMIFS('Aged SKUs vs PD'!$E$2:$E$212,'Aged SKUs vs PD'!$A$2:$A$212,$A10,'Aged SKUs vs PD'!$B$2:$B$212,$B10) -> 111 | E10: =SUMIFS('Aged SKUs vs PD'!$N$2:$N$212,'Aged SKUs vs PD'!$A$2:$A$212,$A10,'Aged SKUs vs PD'!$B$2:$B$212,$B10) -> 92 | F10: =SUMIFS('Aged SKUs vs PD'!$O$2:$O$212,'Aged SKUs vs PD'!$A$2:$A$212,$A10,'Aged SKUs vs PD'!$B$2:$B$212,$B10) -> 226.29 | G10: =SUMIFS('Aged SKUs vs PD'!$T$2:$T$212,'Aged SKUs vs PD'!$A$2:$A$212,$A10,'Aged SKUs vs PD'!$B$2:$B$212,$B10) -> 61 | H10: =SUMIFS('Aged SKUs vs PD'!$U$2:$U$212,'Aged SKUs vs PD'!$A$2:$A$212,$A10,'Aged SKUs vs PD'!$B$2:$B$212,$B10) -> 68 | I10: =COUNTIFS('Aged SKUs vs PD'!$A$2:$A$212,$A10,'Aged SKUs vs PD'!$B$2:$B$212,$B10,'Aged SKUs vs PD'!$R$2:$R$212,"In PD – deal covers all aged units") -> 3 | J10: =COUNTIFS('Aged SKUs vs PD'!$A$2:$A$212,$A10,'Aged SKUs vs PD'!$B$2:$B$212,$B10,'Aged SKUs vs PD'!$R$2:$R$212,"In PD – deal covers part of the aged units") -> 4 | K10: =COUNTIFS('Aged SKUs vs PD'!$A$2:$A$212,$A10,'Aged SKUs vs PD'!$B$2:$B$212,$B10,'Aged SKUs vs PD'!$R$2:$R$212,"Left out of PD") -> 6 | L10: =COUNTIFS('Aged SKUs vs PD'!$A$2:$A$212,$A10,'Aged SKUs vs PD'!$B$2:$B$212,$B10,'Aged SKUs vs PD'!$R$2:$R$212,"Not in any PD deal sheet") -> 0
A11: CA | B11: Bamboo Sheets 6 Piece | C11: =COUNTIFS('Aged SKUs vs PD'!$A$2:$A$212,$A11,'Aged SKUs vs PD'!$B$2:$B$212,$B11) -> 11 | D11: =SUMIFS('Aged SKUs vs PD'!$E$2:$E$212,'Aged SKUs vs PD'!$A$2:$A$212,$A11,'Aged SKUs vs PD'!$B$2:$B$212,$B11) -> 88 | E11: =SUMIFS('Aged SKUs vs PD'!$N$2:$N$212,'Aged SKUs vs PD'!$A$2:$A$212,$A11,'Aged SKUs vs PD'!$B$2:$B$212,$B11) -> 80 | F11: =SUMIFS('Aged SKUs vs PD'!$O$2:$O$212,'Aged SKUs vs PD'!$A$2:$A$212,$A11,'Aged SKUs vs PD'!$B$2:$B$212,$B11) -> 191.11 | G11: =SUMIFS('Aged SKUs vs PD'!$T$2:$T$212,'Aged SKUs vs PD'!$A$2:$A$212,$A11,'Aged SKUs vs PD'!$B$2:$B$212,$B11) -> 27 | H11: =SUMIFS('Aged SKUs vs PD'!$U$2:$U$212,'Aged SKUs vs PD'!$A$2:$A$212,$A11,'Aged SKUs vs PD'!$B$2:$B$212,$B11) -> 68 | I11: =COUNTIFS('Aged SKUs vs PD'!$A$2:$A$212,$A11,'Aged SKUs vs PD'!$B$2:$B$212,$B11,'Aged SKUs vs PD'!$R$2:$R$212,"In PD – deal covers all aged units") -> 2 | J11: =COUNTIFS('Aged SKUs vs PD'!$A$2:$A$212,$A11,'Aged SKUs vs PD'!$B$2:$B$212,$B11,'Aged SKUs vs PD'!$R$2:$R$212,"In PD – deal covers part of the aged units") -> 3 | K11: =COUNTIFS('Aged SKUs vs PD'!$A$2:$A$212,$A11,'Aged SKUs vs PD'!$B$2:$B$212,$B11,'Aged SKUs vs PD'!$R$2:$R$212,"Left out of PD") -> 6 | L11: =COUNTIFS('Aged SKUs vs PD'!$A$2:$A$212,$A11,'Aged SKUs vs PD'!$B$2:$B$212,$B11,'Aged SKUs vs PD'!$R$2:$R$212,"Not in any PD deal sheet") -> 0
A12: CA | B12: Satin Sheets 4 Piece | C12: =COUNTIFS('Aged SKUs vs PD'!$A$2:$A$212,$A12,'Aged SKUs vs PD'!$B$2:$B$212,$B12) -> 21 | D12: =SUMIFS('Aged SKUs vs PD'!$E$2:$E$212,'Aged SKUs vs PD'!$A$2:$A$212,$A12,'Aged SKUs vs PD'!$B$2:$B$212,$B12) -> 117 | E12: =SUMIFS('Aged SKUs vs PD'!$N$2:$N$212,'Aged SKUs vs PD'!$A$2:$A$212,$A12,'Aged SKUs vs PD'!$B$2:$B$212,$B12) -> 77 | F12: =SUMIFS('Aged SKUs vs PD'!$O$2:$O$212,'Aged SKUs vs PD'!$A$2:$A$212,$A12,'Aged SKUs vs PD'!$B$2:$B$212,$B12) -> 116.35 | G12: =SUMIFS('Aged SKUs vs PD'!$T$2:$T$212,'Aged SKUs vs PD'!$A$2:$A$212,$A12,'Aged SKUs vs PD'!$B$2:$B$212,$B12) -> 10 | H12: =SUMIFS('Aged SKUs vs PD'!$U$2:$U$212,'Aged SKUs vs PD'!$A$2:$A$212,$A12,'Aged SKUs vs PD'!$B$2:$B$212,$B12) -> 113 | I12: =COUNTIFS('Aged SKUs vs PD'!$A$2:$A$212,$A12,'Aged SKUs vs PD'!$B$2:$B$212,$B12,'Aged SKUs vs PD'!$R$2:$R$212,"In PD – deal covers all aged units") -> 2 | J12: =COUNTIFS('Aged SKUs vs PD'!$A$2:$A$212,$A12,'Aged SKUs vs PD'!$B$2:$B$212,$B12,'Aged SKUs vs PD'!$R$2:$R$212,"In PD – deal covers part of the aged units") -> 0 | K12: =COUNTIFS('Aged SKUs vs PD'!$A$2:$A$212,$A12,'Aged SKUs vs PD'!$B$2:$B$212,$B12,'Aged SKUs vs PD'!$R$2:$R$212,"Left out of PD") -> 19 | L12: =COUNTIFS('Aged SKUs vs PD'!$A$2:$A$212,$A12,'Aged SKUs vs PD'!$B$2:$B$212,$B12,'Aged SKUs vs PD'!$R$2:$R$212,"Not in any PD deal sheet") -> 0
A13: CA | B13: Satin Sheets 6 Piece | C13: =COUNTIFS('Aged SKUs vs PD'!$A$2:$A$212,$A13,'Aged SKUs vs PD'!$B$2:$B$212,$B13) -> 32 | D13: =SUMIFS('Aged SKUs vs PD'!$E$2:$E$212,'Aged SKUs vs PD'!$A$2:$A$212,$A13,'Aged SKUs vs PD'!$B$2:$B$212,$B13) -> 231 | E13: =SUMIFS('Aged SKUs vs PD'!$N$2:$N$212,'Aged SKUs vs PD'!$A$2:$A$212,$A13,'Aged SKUs vs PD'!$B$2:$B$212,$B13) -> 170 | F13: =SUMIFS('Aged SKUs vs PD'!$O$2:$O$212,'Aged SKUs vs PD'!$A$2:$A$212,$A13,'Aged SKUs vs PD'!$B$2:$B$212,$B13) -> 234.05 | G13: =SUMIFS('Aged SKUs vs PD'!$T$2:$T$212,'Aged SKUs vs PD'!$A$2:$A$212,$A13,'Aged SKUs vs PD'!$B$2:$B$212,$B13) -> 50 | H13: =SUMIFS('Aged SKUs vs PD'!$U$2:$U$212,'Aged SKUs vs PD'!$A$2:$A$212,$A13,'Aged SKUs vs PD'!$B$2:$B$212,$B13) -> 182 | I13: =COUNTIFS('Aged SKUs vs PD'!$A$2:$A$212,$A13,'Aged SKUs vs PD'!$B$2:$B$212,$B13,'Aged SKUs vs PD'!$R$2:$R$212,"In PD – deal covers all aged units") -> 2 | J13: =COUNTIFS('Aged SKUs vs PD'!$A$2:$A$212,$A13,'Aged SKUs vs PD'!$B$2:$B$212,$B13,'Aged SKUs vs PD'!$R$2:$R$212,"In PD – deal covers part of the aged units") -> 8 | K13: =COUNTIFS('Aged SKUs vs PD'!$A$2:$A$212,$A13,'Aged SKUs vs PD'!$B$2:$B$212,$B13,'Aged SKUs vs PD'!$R$2:$R$212,"Left out of PD") -> 22 | L13: =COUNTIFS('Aged SKUs vs PD'!$A$2:$A$212,$A13,'Aged SKUs vs PD'!$B$2:$B$212,$B13,'Aged SKUs vs PD'!$R$2:$R$212,"Not in any PD deal sheet") -> 0
A14: US | B14: Total US | C14: =C5+C6+C7+C8+C9 -> 134 | D14: =D5+D6+D7+D8+D9 -> 8455 | E14: =E5+E6+E7+E8+E9 -> 5115 | F14: =F5+F6+F7+F8+F9 -> 6505.72 | G14: =G5+G6+G7+G8+G9 -> 1185 | H14: =H5+H6+H7+H8+H9 -> 7358 | I14: =I5+I6+I7+I8+I9 -> 10 | J14: =J5+J6+J7+J8+J9 -> 66 | ... L14: =L5+L6+L7+L8+L9 -> 46
A15: CA | B15: Total CA | C15: =C10+C11+C12+C13 -> 77 | D15: =D10+D11+D12+D13 -> 547 | E15: =E10+E11+E12+E13 -> 419 | F15: =F10+F11+F12+F13 -> 767.8 | G15: =G10+G11+G12+G13 -> 148 | H15: =H10+H11+H12+H13 -> 431 | I15: =I10+I11+I12+I13 -> 9 | J15: =J10+J11+J12+J13 -> 15 | ... L15: =L10+L11+L12+L13 -> 0
A18: All products holding 181+ day stock (Ecotero LTSF portfolio, age snapshot 2026-10-03)
A19: Brand | B19: Product | C19: Lifecycle | D19: US aged units | E19: US monthly charge (USD) | F19: CA aged units | G19: CA monthly charge (CAD) | H19: In PD deal sheet?
A20: Decolure | B20: Bamboo Sheets 6 Piece | C20: Re-Launch | D20: 1614 | E20: 2517.2 | F20: 88 | G20: 191.09 | H20: Yes (US + CA)
A21: Sleephoria | B21: Satin Sheets 4 Piece | C21: Maintenance | D21: 2228 | E21: 2340.23 | F21: 86 | G21: 173.77 | H21: No
A22: Decolure | B22: Linen Curtains | C22: Liquidation | D22: 1206 | E22: 1840.55 | F22: 2 | G22: 2.37 | H22: No
A23: Sleephoria | B23: Bamboo Sheets 6 Piece | C23: Re-Launch | D23: 948 | E23: 1751.48 | F23: 0 | G23: 0 | H23: No
A24: Decolure | B24: Satin Sheets 4 Piece | C24: Maintenance | D24: 2919 | E24: 1494.27 | F24: 117 | G24: 116.36 | H24: Yes (US + CA)
A25: Decolure | B25: Satin Sheets 6 Piece | C25: Maintenance | D25: 1062 | E25: 1164.75 | F25: 231 | G25: 234.06 | H25: CA only
A26: Decolure | B26: Satin Fitted Sheet | C26: Maintenance | D26: 1324 | E26: 941.95 | F26: 82 | G26: 52.19 | H26: No
A27: Decolure | B27: Bamboo Sheets 4 Piece | C27: Re-Launch | D27: 897 | E27: 917.88 | F27: 111 | G27: 226.31 | H27: Yes (US + CA)
A28: Decolure | B28: Cooling Sheets 4 Piece | C28: Re-Launch | D28: 584 | E28: 698.08 | F28: 0 | G28: 0 | H28: No
A29: Decolure | B29: Hanging Closet Organizer | C29: Liquidation | D29: 179 | E29: 604.54 | F29: 0 | G29: 0 | H29: No
A30: Decolure | B30: Silk Pillowcase | C30: Re-Launch | D30: 1963 | E30: 411.64 | F30: 0 | G30: 0 | H30: Yes (US)
A31: Sleephoria | B31: Quilt Set | C31: Liquidation | D31: 65 | E31: 285.92 | F31: 0 | G31: 0 | H31: No
... A42: Sleephoria | B42: Cooling Pillowcases | C42: Re-Launch | D42: 4 | E42: 1.21 | F42: 0 | G42: 0 | H42: No
B43: Total | D43: =SUM(D20:D42) -> 16424 | E43: =SUM(E20:E42) -> 16152.78 | F43: =SUM(F20:F42) -> 718 | G43: =SUM(G20:G42) -> 998.49
A44: Blue figures are typed in from the ltsf_portfolio read on 2026-10-06. The Liquidation lifecycle tag marks a product as terminal.

Sheet Aged SKUs vs PD
A1: Market | B1: Product | C1: SKU | D1: ASIN | E1: Aged units 181+ | F1: 181-210d | G1: 211-240d | H1: 241-270d | I1: 271-300d | J1: 301-330d | K1: 331-365d | L1: 366-455d | M1: 456+d | N1: Units 271d+ | O1: Oct-15 aged charge (est., local ccy) | P1: Sales / week | Q1: Months to clear | R1: PD deal status | S1: Deals (sheet: status, units @ price) | T1: PD committed units | U1: Aged units left after PD | V1: Lowest deal price | W1: LTSF floor price | X1: Fulfillable today | Y1: Planner note | Z1: Watch
A2: US | B2: Bamboo Sheets 4 Piece | C2: BAMBOO-FULL-LIGHTOLIVE | D2: B0BZPZPGDC | E2: 105 | F2: 1 | G2: 1 | H2: 0 | I2: 0 | J2: 0 | K2: 60 | L2: 3 | M2: 40 | N2: =SUM(I2:M2) -> 103 | O2: 165.64 | P2: 3.25 | Q2: 7.54 | R2: In PD – deal covers part of the aged units | S2: PED US: include 10u @ 51.99 | T2: 10 | U2: =MAX(E2-T2,0) -> 95 | V2: 51.99 | W2: 26.7 | X2: 105 | Z2: 20+ units at 271d+ (high-rate brackets) still left after PD
A3: US | B3: Bamboo Sheets 4 Piece | C3: BAMBOO-FULL-PURPLE | D3: B0BZPY4PXY | E3: 74 | F3: 0 | G3: 0 | H3: 0 | I3: 0 | J3: 1 | K3: 73 | L3: 0 | M3: 0 | N3: =SUM(I3:M3) -> 74 | O3: 122.28 | P3: 4.25 | Q3: 4.06 | R3: In PD – deal covers part of the aged units | S3: PED US: include 10u @ 51.99 | T3: 10 | U3: =MAX(E3-T3,0) -> 64 | V3: 51.99 | W3: 23.47 | X3: 78 | Z3: 20+ units at 271d+ (high-rate brackets) still left after PD
A4: US | B4: Bamboo Sheets 4 Piece | C4: BAMBOO-TWIN-BURGUNDY-NEW | D4: B0CRHX3LKM | E4: 122 | F4: 1 | G4: 12 | H4: 48 | I4: 0 | J4: 2 | K4: 12 | L4: 47 | M4: 0 | N4: =SUM(I4:M4) -> 61 | O4: 110.33 | P4: 2.25 | Q4: 12.66 | R4: In PD – deal covers part of the aged units | S4: PED US: include 10u @ 43.99 | T4: 10 | U4: =MAX(E4-T4,0) -> 112 | V4: 43.99 | W4: 27.79 | X4: 129 | Z4: 20+ units at 271d+ (high-rate brackets) still left after PD
A5: US | B5: Bamboo Sheets 4 Piece | C5: BAMBOO-CALIFKING-LIGHT PINK | D5: B0CLKD23ZH | E5: 58 | F5: 0 | G5: 0 | H5: 0 | I5: 58 | J5: 0 | K5: 0 | L5: 0 | M5: 0 | N5: =SUM(I5:M5) -> 58 | O5: 90.78 | P5: 0.5 | Q5: 27.1 | R5: In PD – deal covers part of the aged units | S5: PED US: include 10u @ 63.99 | T5: 10 | U5: =MAX(E5-T5,0) -> 48 | V5: 63.99 | W5: 47.47 | X5: 46 | Z5: 20+ units at 271d+ (high-rate brackets) still left after PD
A6: US | B6: Bamboo Sheets 4 Piece | C6: BAMBOO-FULL-SAGE GREEN | D6: B0CLKFLJMZ | E6: 60 | F6: 0 | G6: 1 | H6: 2 | I6: 1 | J6: 2 | K6: 54 | L6: 0 | M6: 0 | N6: =SUM(I6:M6) -> 57 | O6: 85.58 | P6: 7.25 | Q6: 1.93 | R6: In PD – deal covers part of the aged units | S6: PED US: include 10u @ 51.99 | T6: 10 | U6: =MAX(E6-T6,0) -> 50 | V6: 51.99 | W6: 20.91 | X6: 57 | Z6: 20+ units at 271d+ (high-rate brackets) still left after PD
A7: US | B7: Bamboo Sheets 4 Piece | C7: BAMBOO-FULL-OLIVE | D7: B08KQJTP39 | E7: 57 | F7: 0 | G7: 6 | H7: 24 | I7: 0 | J7: 1 | K7: 0 | L7: 26 | M7: 0 | N7: =SUM(I7:M7) -> 27 | O7: 53.32 | P7: 9.5 | Q7: 1.4 | R7: In PD – deal covers part of the aged units | S7: PED US: include 16u @ 51.34 | T7: 16 | U7: =MAX(E7-T7,0) -> 41 | V7: 51.34 | W7: 20.99 | X7: 73 | Z7: 20+ units at 271d+ (high-rate brackets) still left after PD
A8: US | B8: Bamboo Sheets 4 Piece | C8: BAMBOO-TWIN-CREME | D8: B08KQKS54Q | E8: 42 | F8: 0 | G8: 0 | H8: 0 | I8: 0 | J8: 1 | K8: 0 | L8: 41 | M8: 0 | N8: =SUM(I8:M8) -> 42 | O8: 50.27 | P8: 1 | Q8: 9.79 | R8: In PD – deal covers part of the aged units | S8: PED US: include 10u @ 43.99 | T8: 10 | U8: =MAX(E8-T8,0) -> 32 | V8: 43.99 | W8: 24.01 | X8: 44 | Z8: 20+ units at 271d+ (high-rate brackets) still left after PD
A9: US | B9: Bamboo Sheets 4 Piece | C9: BAMBOO-TWIN-MIDGREY | D9: B0BZQ21K22 | E9: 43 | F9: 1 | G9: 0 | H9: 1 | I9: 1 | J9: 1 | K9: 39 | L9: 0 | M9: 0 | N9: =SUM(I9:M9) -> 41 | O9: 48.84 | P9: 1 | Q9: 10.02 | R9: In PD – deal covers part of the aged units | S9: PED US: include 10u @ 43.99 | T9: 10 | U9: =MAX(E9-T9,0) -> 33 | V9: 43.99 | W9: 24.96 | X9: 67 | Z9: 20+ units at 271d+ (high-rate brackets) still left after PD
A10: US | B10: Bamboo Sheets 4 Piece | C10: BAMBOO-QUEEN-OLIVE | D10: B08KQJRSW6 | E10: 32 | F10: 1 | G10: 1 | H10: 3 | I10: 10 | J10: 11 | K10: 6 | L10: 0 | M10: 0 | N10: =SUM(I10:M10) -> 27 | O10: 42.27 | P10: 18.25 | Q10: 0.41 | R10: In PD – deal covers all aged units | S10: PED US: include 36u @ 59.99 | T10: 36 | U10: =MAX(E10-T10,0) -> 0 | V10: 59.99 | W10: 22.38 | X10: 305
A11: US | B11: Bamboo Sheets 4 Piece | C11: BAMBOO-KING-LIGHTBLUE | D11: B08KQL6HKG | E11: 82 | F11: 3 | G11: 3 | H11: 76 | I11: 0 | J11: 0 | K11: 0 | L11: 0 | M11: 0 | N11: =SUM(I11:M11) -> 0 | O11: 31.51 | P11: 18 | Q11: 1.06 | R11: In PD – deal covers part of the aged units | S11: PED US: include 36u @ 63.99 | T11: 36 | U11: =MAX(E11-T11,0) -> 46 | V11: 63.99 | W11: 23.05 | X11: 390
A12: US | B12: Bamboo Sheets 4 Piece | C12: BAMBOO-KING-OLIVE | D12: B08KQLK2HK | E12: 72 | F12: 2 | G12: 44 | H12: 26 | I12: 0 | J12: 0 | K12: 0 | L12: 0 | M12: 0 | N12: =SUM(I12:M12) -> 0 | O12: 27.61 | P12: 15.25 | Q12: 1.1 | R12: In PD – deal covers part of the aged units | S12: PED US: include 30u @ 63.19 | T12: 30 | U12: =MAX(E12-T12,0) -> 42 | V12: 63.19 | W12: 23.27 | X12: 278
A13: US | B13: Bamboo Sheets 4 Piece | C13: BAMBOO-TWIN-LIGHTBLUE | D13: B08KQJGSW2 | E13: 30 | F13: 0 | G13: 0 | H13: 2 | I13: 2 | J13: 1 | K13: 25 | L13: 0 | M13: 0 | N13: =SUM(I13:M13) -> 28 | O13: 27.27 | P13: 3.5 | Q13: 2 | R13: In PD – deal covers part of the aged units | S13: PED US: include 10u @ 43.99 | T13: 10 | U13: =MAX(E13-T13,0) -> 20 | V13: 43.99 | W13: 18.19 | X13: 36 | Z13: 20+ units at 271d+ (high-rate brackets) still left after PD
A14: US | B14: Bamboo Sheets 4 Piece | C14: BAMBOO-TWIN-LIGHTOLIVE | D14: B0BZQ3XM7P | E14: 13 | F14: 0 | G14: 0 | H14: 0 | I14: 0 | J14: 0 | K14: 1 | L14: 0 | M14: 12 | N14: =SUM(I14:M14) -> 13 | O14: 20.2 | P14: 1 | Q14: 3.03 | R14: In PD – deal covers part of the aged units | S14: PED US: include 10u @ 43.99 | T14: 10 | U14: =MAX(E14-T14,0) -> 3 | V14: 43.99 | W14: 20.58 | X14: 17
A15: US | B15: Bamboo Sheets 4 Piece | C15: BAMBOO-TWIN-SAGE GREEN | D15: B0CLKBT95K | E15: 19 | F15: 3 | G15: 0 | H15: 1 | I15: 0 | J15: 0 | K15: 15 | L15: 0 | M15: 0 | N15: =SUM(I15:M15) -> 15 | O15: 18.28 | P15: 3.25 | Q15: 1.36 | R15: Left out of PD | S15: PED US: leave out | T15: 0 | U15: =MAX(E15-T15,0) -> 19 | W15: 18.56 | X15: 24 | Y15: under 10 units after keeping 30 days of cover (24 fulfillable, 0.6/day) | Z15: Left out to keep 30d cover — but this stock is already aged
A16: US | B16: Bamboo Sheets 4 Piece | C16: BAMBOO-TWIN-LIGHTGREY | D16: B08KQK8Z1J | E16: 40 | F16: 0 | G16: 1 | H16: 37 | I16: 2 | J16: 0 | K16: 0 | L16: 0 | M16: 0 | N16: =SUM(I16:M16) -> 2 | O16: 12.29 | P16: 1.75 | Q16: 5.33 | R16: In PD – deal covers part of the aged units | S16: PED US: include 10u @ 43.99 | T16: 10 | U16: =MAX(E16-T16,0) -> 30 | V16: 43.99 | W16: 19.58 | X16: 44
A17: US | B17: Bamboo Sheets 4 Piece | C17: BAMBOO-TWIN-OLIVE | D17: B08KQKKVSX | E17: 48 | F17: 0 | G17: 12 | H17: 36 | I17: 0 | J17: 0 | K17: 0 | L17: 0 | M17: 0 | N17: =SUM(I17:M17) -> 0 | O17: 11.4 | P17: 2.25 | Q17: 4.98 | R17: In PD – deal covers part of the aged units | S17: PED US: include 10u @ 43.99 | T17: 10 | U17: =MAX(E17-T17,0) -> 38 | V17: 43.99 | W17: 18.91 | X17: 48
A18: US | B18: Bamboo Sheets 6 Piece | C18: BAMBOO-FULL-OLIVE-6PCS | D18: B0CQ33ZGQ4 | E18: 255 | F18: 0 | G18: 6 | H18: 0 | I18: 145 | J18: 1 | K18: 12 | L18: 19 | M18: 72 | N18: =SUM(I18:M18) -> 249 | O18: 570.4 | P18: 3 | Q18: 19.83 | R18: In PD – deal covers part of the aged units | S18: PED US: include 10u @ 55.99 | T18: 10 | U18: =MAX(E18-T18,0) -> 245 | V18: 55.99 | W18: 47.5 | X18: 257 | Z18: 20+ units at 271d+ (high-rate brackets) still left after PD
A19: US | B19: Bamboo Sheets 6 Piece | C19: BAMBOO-FULL-CREME-6PCS | D19: B0CQ2ZVD96 | E19: 246 | F19: 3 | G19: 2 | H19: 2 | I19: 206 | J19: 2 | K19: 31 | L19: 0 | M19: 0 | N19: =SUM(I19:M19) -> 239 | O19: 438.87 | P19: 6 | Q19: 9.57 | R19: In PD – deal covers part of the aged units | S19: PED US: include 19u @ 52.49 | T19: 19 | U19: =MAX(E19-T19,0) -> 227 | V19: 52.49 | W19: 30.65 | X19: 262 | Z19: 20+ units at 271d+ (high-rate brackets) still left after PD
A20: US | B20: Bamboo Sheets 6 Piece | C20: BAMBOO-QUEEN-OLIVE-6PCS | D20: B0CQ32B24Y | E20: 263 | F20: 1 | G20: 2 | H20: 3 | I20: 10 | J20: 6 | K20: 189 | L20: 52 | M20: 0 | N20: =SUM(I20:M20) -> 257 | O20: 434.94 | P20: 21.75 | Q20: 2.82 | R20: In PD – deal covers part of the aged units | S20: PED US: include 48u @ 59.99 | T20: 48 | U20: =MAX(E20-T20,0) -> 215 | V20: 59.99 | W20: 25.2 | X20: 475 | Z20: 20+ units at 271d+ (high-rate brackets) still left after PD
A21: US | B21: Bamboo Sheets 6 Piece | C21: BAMBOO-QUEEN-LIGHTOLIVE-6PCS | D21: B0CQ312HKC | E21: 125 | F21: 0 | G21: 0 | H21: 3 | I21: 0 | J21: 0 | K21: 18 | L21: 104 | M21: 0 | N21: =SUM(I21:M21) -> 122 | O21: 266.46 | P21: 3.75 | Q21: 7.78 | R21: In PD – deal covers part of the aged units | S21: PED US: include 10u @ 63.19 | T21: 10 | U21: =MAX(E21-T21,0) -> 115 | V21: 63.19 | W21: 32.5 | X21: 127 | Z21: 20+ units at 271d+ (high-rate brackets) still left after PD
A22: US | B22: Bamboo Sheets 6 Piece | C22: BAMBOO-QUEEN-LIGHTGREY-6PCS | D22: B0CQ33K3TL | E22: 190 | F22: 9 | G22: 6 | H22: 68 | I22: 107 | J22: 0 | K22: 0 | L22: 0 | M22: 0 | N22: =SUM(I22:M22) -> 107 | O22: 204.45 | P22: 14.5 | Q22: 3.06 | R22: In PD – deal covers part of the aged units | S22: PED US: include 31u @ 59.99 | T22: 31 | U22: =MAX(E22-T22,0) -> 159 | V22: 59.99 | W22: 24.24 | X22: 179 | Z22: 20+ units at 271d+ (high-rate brackets) still left after PD
A23: US | B23: Bamboo Sheets 6 Piece | C23: BAMBOO-FULL-LIGHTOLIVE-6PCS | D23: B0CQ2YBSK2 | E23: 74 | F23: 0 | G23: 6 | H23: 0 | I23: 0 | J23: 0 | K23: 18 | L23: 42 | M23: 8 | N23: =SUM(I23:M23) -> 68 | O23: 122.53 | P23: 2 | Q23: 8.63 | R23: In PD – deal covers part of the aged units | S23: PED US: include 10u @ 55.99 | T23: 10 | U23: =MAX(E23-T23,0) -> 64 | V23: 55.99 | W23: 29.27 | X23: 83 | Z23: 20+ units at 271d+ (high-rate brackets) still left after PD
A24: US | B24: Bamboo Sheets 6 Piece | C24: BAMBOO-FULL-SAGE GREEN-6PCS | D24: B0CQ322XC6 | E24: 64 | F24: 6 | G24: 1 | H24: 0 | I24: 57 | J24: 0 | K24: 0 | L24: 0 | M24: 0 | N24: =SUM(I24:M24) -> 57 | O24: 76.33 | P24: 0.25 | Q24: 59.81 | R24: In PD – deal covers part of the aged units | S24: PED US: include 10u @ 59.99 | T24: 10 | U24: =MAX(E24-T24,0) -> 54 | V24: 59.99 | W24: 41.57 | X24: 97 | Z24: 20+ units at 271d+ (high-rate brackets) still left after PD
A25: US | B25: Bamboo Sheets 6 Piece | C25: BAMBOO-FULL-LIGHTBLUE-6PCS | D25: B0CQ32JNVG | E25: 47 | F25: 0 | G25: 2 | H25: 0 | I25: 45 | J25: 0 | K25: 0 | L25: 0 | M25: 0 | N25: =SUM(I25:M25) -> 45 | O25: 72.89 | P25: 1 | Q25: 10.96 | R25: Left out of PD | S25: PED US: leave out | T25: 0 | U25: =MAX(E25-T25,0) -> 47 | W25: 31.32 | X25: 51 | Y25: not in the deal on the board (Amazon: rating below PED minimum) | Z25: 20+ units at 271d+ (high-rate brackets) still left after PD
A26: US | B26: Bamboo Sheets 6 Piece | C26: BAMBOO-KING-PURPLE-6PCS | D26: B0CQ328N9Z | E26: 37 | F26: 3 | G26: 2 | H26: 0 | I26: 32 | J26: 0 | K26: 0 | L26: 0 | M26: 0 | N26: =SUM(I26:M26) -> 32 | O26: 68.46 | P26: 11.25 | Q26: 0.77 | R26: In PD – deal covers part of the aged units | S26: PED US: include 23u @ 67.99 | T26: 23 | U26: =MAX(E26-T26,0) -> 14 | V26: 67.99 | W26: 24.99 | X26: 39 | Y26: top-seller exception: runs to the board projection; 8 days of cover after the event
A27: US | B27: Bamboo Sheets 6 Piece | C27: BAMBOO-KING-LIGHT PINK-6PCS | D27: B0CQ3437ZF | E27: 130 | F27: 0 | G27: 6 | H27: 124 | I27: 0 | J27: 0 | K27: 0 | L27: 0 | M27: 0 | N27: =SUM(I27:M27) -> 0 | O27: 62.92 | P27: 7.5 | Q27: 4.04 | R27: In PD – deal covers part of the aged units | S27: PED US: include 15u @ 67.99 | T27: 15 | U27: =MAX(E27-T27,0) -> 115 | V27: 67.99 | W27: 26.84 | X27: 263
A28: US | B28: Bamboo Sheets 6 Piece | C28: BAMBOO-FULL-LIGHTGREY-6PCS | D28: B0CQ32VM8N | E28: 33 | F28: 0 | G28: 0 | H28: 2 | I28: 1 | J28: 0 | K28: 30 | L28: 0 | M28: 0 | N28: =SUM(I28:M28) -> 31 | O28: 60.36 | P28: 0 | R28: Left out of PD | S28: PED US: leave out | T28: 0 | U28: =MAX(E28-T28,0) -> 33 | X28: 44 | Y28: not in the deal on the board (Amazon: rating below PED minimum) | Z28: 20+ units at 271d+ (high-rate brackets) still left after PD
A29: US | B29: Bamboo Sheets 6 Piece | C29: BAMBOO-QUEEN-SAGE GREEN-6PCS | D29: B0CQ3CDRTN | E29: 43 | F29: 3 | G29: 5 | H29: 11 | I29: 4 | J29: 20 | K29: 0 | L29: 0 | M29: 0 | N29: =SUM(I29:M29) -> 24 | O29: 41.59 | P29: 10.5 | Q29: 0.96 | R29: In PD – deal covers part of the aged units | S29: PED US: include 21u @ 59.99 | T29: 21 | U29: =MAX(E29-T29,0) -> 22 | V29: 59.99 | W29: 23.69 | X29: 119 | Z29: 20+ units at 271d+ (high-rate brackets) still left after PD
A30: US | B30: Bamboo Sheets 6 Piece | C30: BAMBOO-TWIN-LIGHTOLIVE-6PCS | D30: B0CQ2YWCB3 | E30: 31 | F30: 1 | G30: 0 | H30: 0 | I30: 0 | J30: 0 | K30: 1 | L30: 29 | M30: 0 | N30: =SUM(I30:M30) -> 30 | O30: 38.1 | P30: 0.75 | Q30: 9.66 | R30: In PD – deal covers part of the aged units | S30: PED US: include 10u @ 47.99 | T30: 10 | U30: =MAX(E30-T30,0) -> 21 | V30: 47.99 | W30: 25.39 | X30: 35 | Z30: 20+ units at 271d+ (high-rate brackets) still left after PD
A31: US | B31: Bamboo Sheets 6 Piece | C31: BAMBOO-FULL-PURPLE-6PCS | D31: B0CQ31X3X5 | E31: 21 | F31: 0 | G31: 0 | H31: 7 | I31: 1 | J31: 0 | K31: 0 | L31: 13 | M31: 0 | N31: =SUM(I31:M31) -> 14 | O31: 30.09 | P31: 1.75 | Q31: 2.8 | R31: In PD – deal covers part of the aged units | S31: PED US: include 10u @ 55.99 | T31: 10 | U31: =MAX(E31-T31,0) -> 11 | V31: 55.99 | W31: 23.63 | X31: 24
A32: US | B32: Bamboo Sheets 6 Piece | C32: BAMBOO-TWIN-MIDGREY-6PCS | D32: B0CQ31XF3H | E32: 15 | F32: 0 | G32: 1 | H32: 0 | I32: 14 | J32: 0 | K32: 0 | L32: 0 | M32: 0 | N32: =SUM(I32:M32) -> 14 | O32: 14.16 | P32: 1.25 | Q32: 2.8 | R32: In PD – deal covers part of the aged units | S32: PED US: include 10u @ 44.39 | T32: 10 | U32: =MAX(E32-T32,0) -> 5 | V32: 44.39 | W32: 20.37 | X32: 29
A33: US | B33: Bamboo Sheets 6 Piece | C33: BAMBOO-TWIN-SAGE GREEN-6PCS | D33: B0CQ2YZ364 | E33: 34 | F33: 3 | G33: 3 | H33: 28 | I33: 0 | J33: 0 | K33: 0 | L33: 0 | M33: 0 | N33: =SUM(I33:M33) -> 0 | O33: 8.67 | P33: 2.25 | Q33: 3.53 | R33: In PD – deal covers part of the aged units | S33: PED US: include 10u @ 47.99 | T33: 10 | U33: =MAX(E33-T33,0) -> 24 | V33: 47.99 | W33: 19.78 | X33: 52
A34: US | B34: Bamboo Sheets 6 Piece | C34: BAMBOO-TWIN-OLIVE-6PCS | D34: B0CQ2ZVMJJ | E34: 5 | F34: 0 | G34: 0 | H34: 0 | I34: 2 | J34: 0 | K34: 1 | L34: 2 | M34: 0 | N34: =SUM(I34:M34) -> 5 | O34: 5.65 | P34: 3 | Q34: 0.39 | R34: In PD – deal covers all aged units | S34: PED US: include 10u @ 47.99 | T34: 10 | U34: =MAX(E34-T34,0) -> 0 | V34: 47.99 | W34: 18.92 | X34: 33
A35: US | B35: Bamboo Sheets 6 Piece | C35: BAMBOO-TWIN-NAVYBLUE-6PCS | D35: B0CQ31N5Q5 | E35: 1 | F35: 0 | G35: 0 | H35: 1 | I35: 0 | J35: 0 | K35: 0 | L35: 0 | M35: 0 | N35: =SUM(I35:M35) -> 0 | O35: 0.32 | P35: 1.25 | Q35: 0.19 | R35: In PD – deal covers all aged units | S35: PED US: include 10u @ 47.99 | T35: 10 | U35: =MAX(E35-T35,0) -> 0 | V35: 47.99 | W35: 18.91 | X35: 25
A36: US | B36: Satin Sheets 4 Piece | C36: SATIN-QUEEN-GREY | D36: B0839LQK8K | E36: 1100 | F36: 36 | G36: 227 | H36: 837 | I36: 0 | J36: 0 | K36: 0 | L36: 0 | M36: 0 | N36: =SUM(I36:M36) -> 0 | O36: 372.27 | P36: 34 | Q36: 7.55 | R36: In PD – deal covers part of the aged units | S36: PED US: include 18u @ 23.96; S4 LD US: include 23u @ 23.96 | T36: 41 | U36: =MAX(E36-T36,0) -> 1059 | V36: 23.96 | W36: 16.43 | X36: 1107
A37: US | B37: Satin Sheets 4 Piece | C37: SATIN-4PCS-QUEEN-STONE-GREY | D37: B0DD4JMGXN | E37: 499 | F37: 1 | G37: 35 | H37: 452 | I37: 2 | J37: 9 | K37: 0 | L37: 0 | M37: 0 | N37: =SUM(I37:M37) -> 11 | O37: 205.41 | P37: 17.25 | Q37: 6.75 | R37: Left out of PD | S37: PED US: leave out; S4 LD US: leave out | T37: 0 | U37: =MAX(E37-T37,0) -> 499 | W37: 16.52 | X37: 814 | Y37: not in the deal on the board (PED needs 29% off: loses $0.31 a unit after ads)
A38: US | B38: Satin Sheets 4 Piece | C38: SATIN-SEA-TEAL-TWIN | D38: B0BG21MMW9 | E38: 75 | F38: 0 | G38: 1 | H38: 1 | I38: 30 | J38: 0 | K38: 0 | L38: 0 | M38: 43 | N38: =SUM(I38:M38) -> 73 | O38: 99.12 | P38: 2 | Q38: 8.75 | R38: In PD – deal covers part of the aged units | S38: PED US: leave out; S4 LD US: include 10u @ 19.91 | T38: 10 | U38: =MAX(E38-T38,0) -> 65 | V38: 19.91 | W38: 17.31 | X38: 129 | Y38: Oct 5: Amazon needs 37% off, under break-even ($18.00) | Z38: 20+ units at 271d+ (high-rate brackets) still left after PD
A39: US | B39: Satin Sheets 4 Piece | C39: SATIN-4PC-FULL-DARK GREEN | D39: B0CQRX2Z2G | E39: 84 | F39: 0 | G39: 1 | H39: 30 | I39: 19 | J39: 0 | K39: 34 | L39: 0 | M39: 0 | N39: =SUM(I39:M39) -> 53 | O39: 83.48 | P39: 3.25 | Q39: 6.03 | R39: In PD – deal covers part of the aged units | S39: PED US: include 10u @ 23.96; S4 LD US: include 10u @ 23.96 | T39: 20 | U39: =MAX(E39-T39,0) -> 64 | V39: 23.96 | W39: 15.94 | X39: 92 | Z39: 20+ units at 271d+ (high-rate brackets) still left after PD
A40: US | B40: Satin Sheets 4 Piece | C40: SATIN-4PCS-FULL-ROSEWOOD | D40: B0DBQVFTZS | E40: 48 | F40: 0 | G40: 1 | H40: 0 | I40: 2 | J40: 0 | K40: 45 | L40: 0 | M40: 0 | N40: =SUM(I40:M40) -> 47 | O40: 70.79 | P40: 7.5 | Q40: 1.49 | R40: In PD – deal covers part of the aged units | S40: PED US: leave out; S4 LD US: include 10u @ 23.96 | T40: 10 | U40: =MAX(E40-T40,0) -> 38 | V40: 23.96 | W40: 13.44 | X40: 125 | Y40: loses $0.17 a unit after ads (not a top seller) | Z40: 20+ units at 271d+ (high-rate brackets) still left after PD
...
