Workbook

Sheet Summary
A1: Prime Day - Day 1 (Oct 6, 2026): hero vs non-hero ad spend
A2: Answers Erik's question on non-hero spend. Hero = White (Bamboo) / Black (Satin). Spend by variation from Sellerboard per-SKU SP spend; LTSF from Ecotero campaign data.
B4: FX: 1 CAD = USD | C4: 0.72 | D4: Input. Rate used on Joseph's live board (fxCad). Sellerboard reports CA spend converted to USD.
A6: US (USD)
A7: Product | B7: SP spend | C7: Hero spend | D7: Hero % | E7: Non-hero spend | F7: LTSF campaigns (this product only) | G7: LTSF campaigns shared across products (full amount) | H7: Non-hero outside LTSF - low | I7: Non-hero outside LTSF - high | J7: Hero % excluding LTSF
A8: Bamboo 4pc | B8: =SUMIFS(US_SKU_Spend!$F:$F,US_SKU_Spend!$A:$A,$A8) -> 1880.85 | C8: =SUMIFS(US_SKU_Spend!$F:$F,US_SKU_Spend!$A:$A,$A8,US_SKU_Spend!$E:$E,"Yes") -> 983.13 | D8: =IFERROR(C8/B8,0) -> 0.52270516 | E8: =B8-C8 -> 897.72 | F8: =SUMIFS(US_Campaigns!$O:$O,US_Campaigns!$A:$A,$A8,US_Campaigns!$D:$D,"LTSF / Clearance",US_Campaigns!$I:$I,"No") -> 541.12 | G8: =SUMIFS(US_Campaigns!$O:$O,US_Campaigns!$A:$A,$A8,US_Campaigns!$D:$D,"LTSF / Clearance",US_Campaigns!$I:$I,"Yes") -> 59.65 | H8: =MAX(E8-F8-G8,0) -> 296.95 | I8: =MAX(E8-F8,0) -> 356.6 | J8: =IFERROR(C8/(B8-F8),0) -> 0.73382697
A9: Bamboo 6pc | B9: =SUMIFS(US_SKU_Spend!$F:$F,US_SKU_Spend!$A:$A,$A9) -> 1496.44 | C9: =SUMIFS(US_SKU_Spend!$F:$F,US_SKU_Spend!$A:$A,$A9,US_SKU_Spend!$E:$E,"Yes") -> 894.8 | D9: =IFERROR(C9/B9,0) -> 0.59795247 | E9: =B9-C9 -> 601.64 | F9: =SUMIFS(US_Campaigns!$O:$O,US_Campaigns!$A:$A,$A9,US_Campaigns!$D:$D,"LTSF / Clearance",US_Campaigns!$I:$I,"No") -> 322.82 | G9: =SUMIFS(US_Campaigns!$O:$O,US_Campaigns!$A:$A,$A9,US_Campaigns!$D:$D,"LTSF / Clearance",US_Campaigns!$I:$I,"Yes") -> 59.65 | H9: =MAX(E9-F9-G9,0) -> 219.17 | I9: =MAX(E9-F9,0) -> 278.82 | J9: =IFERROR(C9/(B9-F9),0) -> 0.76242736
A10: Satin 4pc | B10: =SUMIFS(US_SKU_Spend!$F:$F,US_SKU_Spend!$A:$A,$A10) -> 899.35 | C10: =SUMIFS(US_SKU_Spend!$F:$F,US_SKU_Spend!$A:$A,$A10,US_SKU_Spend!$E:$E,"Yes") -> 472.37 | D10: =IFERROR(C10/B10,0) -> 0.52523489 | E10: =B10-C10 -> 426.98 | F10: =SUMIFS(US_Campaigns!$O:$O,US_Campaigns!$A:$A,$A10,US_Campaigns!$D:$D,"LTSF / Clearance",US_Campaigns!$I:$I,"No") -> 206.93 | G10: =SUMIFS(US_Campaigns!$O:$O,US_Campaigns!$A:$A,$A10,US_Campaigns!$D:$D,"LTSF / Clearance",US_Campaigns!$I:$I,"Yes") -> 7.96 | H10: =MAX(E10-F10-G10,0) -> 212.09 | I10: =MAX(E10-F10,0) -> 220.05 | J10: =IFERROR(C10/(B10-F10),0) -> 0.68220155
A11: Total | B11: =SUM(B8:B10) -> 4276.64 | C11: =SUM(C8:C10) -> 2350.3 | D11: =IFERROR(C11/B11,0) -> 0.54956695 | E11: =SUM(E8:E10) -> 1926.34 | F11: =SUM(F8:F10) -> 1070.87 | G11: =SUMIFS(US_Campaigns!$O:$O,US_Campaigns!$D:$D,"LTSF / Clearance",US_Campaigns!$I:$I,"Yes",US_Campaigns!$K:$K,"Yes") -> 59.65 | H11: =MAX(E11-F11-G11,0) -> 795.82 | I11: =MAX(E11-F11,0) -> 855.47 | J11: =IFERROR(C11/(B11-F11-G11),0) -> 0.74704716
A12: Total row counts each shared LTSF campaign once. "Low" assumes all shared LTSF spend landed on this product; "high" assumes none did.
A14: Canada (CAD)
A15: Product | B15: SP spend | C15: Hero spend | D15: Hero % | E15: Non-hero spend | F15: LTSF campaigns (this product only) | G15: LTSF campaigns shared across products (full amount) | H15: Non-hero outside LTSF - low | I15: Non-hero outside LTSF - high | J15: Hero % excluding LTSF
A16: Bamboo 4pc | B16: =SUMIFS(CA_SKU_Spend!$F:$F,CA_SKU_Spend!$A:$A,$A16)/$C$4 -> 910.90278 | C16: =SUMIFS(CA_SKU_Spend!$F:$F,CA_SKU_Spend!$A:$A,$A16,CA_SKU_Spend!$E:$E,"Yes")/$C$4 -> 16.277778 | D16: =IFERROR(C16/B16,0) -> 0.01786994 | E16: =B16-C16 -> 894.625 | F16: =SUMIFS(CA_Campaigns!$O:$O,CA_Campaigns!$A:$A,$A16,CA_Campaigns!$D:$D,"LTSF / Clearance",CA_Campaigns!$I:$I,"No") -> 336.5 | G16: =SUMIFS(CA_Campaigns!$O:$O,CA_Campaigns!$A:$A,$A16,CA_Campaigns!$D:$D,"LTSF / Clearance",CA_Campaigns!$I:$I,"Yes") -> 123.09 | H16: =MAX(E16-F16-G16,0) -> 435.035 | I16: =MAX(E16-F16,0) -> 558.125 | J16: =IFERROR(C16/(B16-F16),0) -> 0.028338613
A17: Bamboo 6pc | B17: =SUMIFS(CA_SKU_Spend!$F:$F,CA_SKU_Spend!$A:$A,$A17)/$C$4 -> 553.20833 | C17: =SUMIFS(CA_SKU_Spend!$F:$F,CA_SKU_Spend!$A:$A,$A17,CA_SKU_Spend!$E:$E,"Yes")/$C$4 -> 316.30556 | D17: =IFERROR(C17/B17,0) -> 0.57176571 | E17: =B17-C17 -> 236.90278 | F17: =SUMIFS(CA_Campaigns!$O:$O,CA_Campaigns!$A:$A,$A17,CA_Campaigns!$D:$D,"LTSF / Clearance",CA_Campaigns!$I:$I,"No") -> 83.09 | G17: =SUMIFS(CA_Campaigns!$O:$O,CA_Campaigns!$A:$A,$A17,CA_Campaigns!$D:$D,"LTSF / Clearance",CA_Campaigns!$I:$I,"Yes") -> 0 | H17: =MAX(E17-F17-G17,0) -> 153.81278 | I17: =MAX(E17-F17,0) -> 153.81278 | J17: =IFERROR(C17/(B17-F17),0) -> 0.67282115
A18: Satin 4pc | B18: =SUMIFS(CA_SKU_Spend!$F:$F,CA_SKU_Spend!$A:$A,$A18)/$C$4 -> 378.33333 | C18: =SUMIFS(CA_SKU_Spend!$F:$F,CA_SKU_Spend!$A:$A,$A18,CA_SKU_Spend!$E:$E,"Yes")/$C$4 -> 59.375 | D18: =IFERROR(C18/B18,0) -> 0.15693833 | E18: =B18-C18 -> 318.95833 | F18: =SUMIFS(CA_Campaigns!$O:$O,CA_Campaigns!$A:$A,$A18,CA_Campaigns!$D:$D,"LTSF / Clearance",CA_Campaigns!$I:$I,"No") -> 5.11 | G18: =SUMIFS(CA_Campaigns!$O:$O,CA_Campaigns!$A:$A,$A18,CA_Campaigns!$D:$D,"LTSF / Clearance",CA_Campaigns!$I:$I,"Yes") -> 228.43 | H18: =MAX(E18-F18-G18,0) -> 85.418333 | I18: =MAX(E18-F18,0) -> 313.84833 | J18: =IFERROR(C18/(B18-F18),0) -> 0.15908705
A19: Satin 6pc | B19: =SUMIFS(CA_SKU_Spend!$F:$F,CA_SKU_Spend!$A:$A,$A19)/$C$4 -> 260.48611 | C19: =SUMIFS(CA_SKU_Spend!$F:$F,CA_SKU_Spend!$A:$A,$A19,CA_SKU_Spend!$E:$E,"Yes")/$C$4 -> 105.68056 | D19: =IFERROR(C19/B19,0) -> 0.40570515 | E19: =B19-C19 -> 154.80556 | F19: =SUMIFS(CA_Campaigns!$O:$O,CA_Campaigns!$A:$A,$A19,CA_Campaigns!$D:$D,"LTSF / Clearance",CA_Campaigns!$I:$I,"No") -> 49.57 | G19: =SUMIFS(CA_Campaigns!$O:$O,CA_Campaigns!$A:$A,$A19,CA_Campaigns!$D:$D,"LTSF / Clearance",CA_Campaigns!$I:$I,"Yes") -> 228.43 | H19: =MAX(E19-F19-G19,0) -> 0 | I19: =MAX(E19-F19,0) -> 105.23556 | J19: =IFERROR(C19/(B19-F19),0) -> 0.50105492
A20: Total | B20: =SUM(B16:B19) -> 2102.9306 | C20: =SUM(C16:C19) -> 497.63889 | D20: =IFERROR(C20/B20,0) -> 0.23664067 | E20: =SUM(E16:E19) -> 1605.2917 | F20: =SUM(F16:F19) -> 474.27 | G20: =SUMIFS(CA_Campaigns!$O:$O,CA_Campaigns!$D:$D,"LTSF / Clearance",CA_Campaigns!$I:$I,"Yes",CA_Campaigns!$K:$K,"Yes") -> 228.43 | H20: =MAX(E20-F20-G20,0) -> 902.59167 | I20: =MAX(E20-F20,0) -> 1131.0217 | J20: =IFERROR(C20/(B20-F20-G20),0) -> 0.35539782
A21: Total row counts each shared LTSF campaign once. "Low" assumes all shared LTSF spend landed on this product; "high" assumes none did.
A23: Spend by campaign category (each campaign counted once)
A24: Category | B24: US spend (USD) | C24: US share | D24: CA spend (CAD) | E24: CA share
A25: Ranking | B25: =SUMIFS(US_Campaigns!$O:$O,US_Campaigns!$D:$D,$A25,US_Campaigns!$K:$K,"Yes") -> 1549.4 | C25: =IFERROR(B25/B$33,0) -> 0.35724826 | D25: =SUMIFS(CA_Campaigns!$O:$O,CA_Campaigns!$D:$D,$A25,CA_Campaigns!$K:$K,"Yes") -> 726.72 | E25: =IFERROR(D25/D$33,0) -> 0.32998978
A26: Conversion | B26: =SUMIFS(US_Campaigns!$O:$O,US_Campaigns!$D:$D,$A26,US_Campaigns!$K:$K,"Yes") -> 25.75 | C26: =IFERROR(B26/B$33,0) -> 0.0059372291 | D26: =SUMIFS(CA_Campaigns!$O:$O,CA_Campaigns!$D:$D,$A26,CA_Campaigns!$K:$K,"Yes") -> 123.88 | E26: =IFERROR(D26/D$33,0) -> 0.056251561
A27: Defensive / Brand | B27: =SUMIFS(US_Campaigns!$O:$O,US_Campaigns!$D:$D,$A27,US_Campaigns!$K:$K,"Yes") -> 227.66 | C27: =IFERROR(B27/B$33,0) -> 0.052492022 | D27: =SUMIFS(CA_Campaigns!$O:$O,CA_Campaigns!$D:$D,$A27,CA_Campaigns!$K:$K,"Yes") -> 161.06 | E27: =IFERROR(D27/D$33,0) -> 0.073134294
A28: Discovery (keyword) | B28: =SUMIFS(US_Campaigns!$O:$O,US_Campaigns!$D:$D,$A28,US_Campaigns!$K:$K,"Yes") -> 134.57 | C28: =IFERROR(B28/B$33,0) -> 0.031028074 | D28: =SUMIFS(CA_Campaigns!$O:$O,CA_Campaigns!$D:$D,$A28,CA_Campaigns!$K:$K,"Yes") -> 183.03 | E28: =IFERROR(D28/D$33,0) -> 0.083110455
A29: Auto (multi-colour, Amazon picks ad) | B29: =SUMIFS(US_Campaigns!$O:$O,US_Campaigns!$D:$D,$A29,US_Campaigns!$K:$K,"Yes") -> 795.73 | C29: =IFERROR(B29/B$33,0) -> 0.18347306 | D29: =SUMIFS(CA_Campaigns!$O:$O,CA_Campaigns!$D:$D,$A29,CA_Campaigns!$K:$K,"Yes") -> 268.13 | E29: =IFERROR(D29/D$33,0) -> 0.12175275
A30: Product targeting | B30: =SUMIFS(US_Campaigns!$O:$O,US_Campaigns!$D:$D,$A30,US_Campaigns!$K:$K,"Yes") -> 454.85 | C30: =IFERROR(B30/B$33,0) -> 0.10487568 | D30: =SUMIFS(CA_Campaigns!$O:$O,CA_Campaigns!$D:$D,$A30,CA_Campaigns!$K:$K,"Yes") -> 36.73 | E30: =IFERROR(D30/D$33,0) -> 0.016678397
A31: LTSF / Clearance | B31: =SUMIFS(US_Campaigns!$O:$O,US_Campaigns!$D:$D,$A31,US_Campaigns!$K:$K,"Yes") -> 1130.52 | C31: =IFERROR(B31/B$33,0) -> 0.26066626 | D31: =SUMIFS(CA_Campaigns!$O:$O,CA_Campaigns!$D:$D,$A31,CA_Campaigns!$K:$K,"Yes") -> 702.7 | E31: =IFERROR(D31/D$33,0) -> 0.31908276
A32: Other | B32: =SUMIFS(US_Campaigns!$O:$O,US_Campaigns!$D:$D,$A32,US_Campaigns!$K:$K,"Yes") -> 18.56 | C32: =IFERROR(B32/B$33,0) -> 0.0042794164 | D32: =SUMIFS(CA_Campaigns!$O:$O,CA_Campaigns!$D:$D,$A32,CA_Campaigns!$K:$K,"Yes") -> 0 | E32: =IFERROR(D32/D$33,0) -> 0
A33: Total | B33: =SUM(B25:B32) -> 4337.04 | C33: =SUM(C25:C32) -> 1 | D33: =SUM(D25:D32) -> 2202.25 | E33: =SUM(E25:E32) -> 1
A34: Campaign totals include spend on other products a shared campaign carries, so this total is slightly above the product SP spend above.
A36: Key findings
A37: 1. US: LTSF clearance is about $1,130 of the $1,926 non-hero spend. Excluding it, the hero takes about 75%, leaving roughly $795 (about 19% of spend) on other colours.
A38: 2. Largest non-LTSF leak: discovery autos carrying several colours, where Amazon picks the ad. DBS4 "Auto...FULL-GREY" spent $333.83 at a $3.97 CPC, 52.8% ACoS, 167% of budget, est. -$154 (Sellerboard). DBS6 "Auto...QUEEN-WHITE-6PCS" spent $93.08 at $4.65 CPC, 146% ACoS.
A39: 3. Planned size variants: King satin keywords run on King Grey (~$85 across king exacts) and Twin bamboo keywords on Twin Burgundy/Navy (~$58 on $5-budget exacts paying $5-10 a click). Worth testing against Erik's CTR-first rule.
A40: 4. Canada: Bamboo 4pc puts ~2% of spend on White and Satin 4pc ~16% on Black because ranking/defensive campaigns are built on Taupe, Olive and Queen Grey. Needs a decision on CA preferred colours.
A41: 5. Build issue: "DBS4-SP-BROAD-(PD-LTSF)" advertises Satin 4pc SKUs (e.g. SATIN-4PC-KING-GREY), not Bamboo 4pc. See Issues_To_Check.
A42: 6. Day 2 context: Joseph's system paused 42 non-hero ads under the hero colour rule and cut placement modifiers on autos on Oct 7, which addresses part of the auto leak.

Sheet US_SKU_Spend
A1: US - Day 1 (Oct 6, 2026) Sponsored Products spend by advertised SKU
A2: Source: Sellerboard (Ecotero account) per-SKU ad spend, USD. Hero = White (Bamboo) / Black (Satin).
A4: Product | B4: SKU | C4: Size | D4: Colour | E4: Hero colour? | F4: SP spend (USD) | G4: SB / SBV spend (USD) | H4: Total ad spend (USD) | I4: % of product SP spend | J4: Units sold (all channels) | K4: Note
A5: Bamboo 4pc | B5: BAMBOO-KING-WHITE | C5: King | D5: White | E5: Yes | F5: 811.22 | G5: 22.18 | H5: =F5+G5 -> 833.4 | I5: =IFERROR(F5/SUMIFS($F:$F,$A:$A,A5),0) -> 0.431305 | J5: 42
A6: Bamboo 4pc | B6: BAMBOO-QUEEN-WHITE | C6: Queen | D6: White | E6: Yes | F6: 142.39 | G6: 3.01 | H6: =F6+G6 -> 145.4 | I6: =IFERROR(F6/SUMIFS($F:$F,$A:$A,A6),0) -> 0.075705133 | J6: 27
A7: Bamboo 4pc | B7: BAMBOO-FULL-OLIVE | C7: Full | D7: Olive | E7: No | F7: 99.72 | G7: 0.62 | H7: =F7+G7 -> 100.34 | I7: =IFERROR(F7/SUMIFS($F:$F,$A:$A,A7),0) -> 0.053018582 | J7: 5 | K7: PD-LTSF auto + older LTSF campaigns
A8: Bamboo 4pc | B8: BAMBOO-TWIN-LIGHTGREY | C8: Twin | D8: Lightgrey | E8: No | F8: 85.44 | G8: 0 | H8: =F8+G8 -> 85.44 | I8: =IFERROR(F8/SUMIFS($F:$F,$A:$A,A8),0) -> 0.04542627 | J8: 2 | K8: PD-LTSF auto + LTSF clearance broad only
A9: Bamboo 4pc | B9: BAMBOO-QUEEN-MIDGREY | C9: Queen | D9: Midgrey | E9: No | F9: 78.62 | G9: 0 | H9: =F9+G9 -> 78.62 | I9: =IFERROR(F9/SUMIFS($F:$F,$A:$A,A9),0) -> 0.04180025 | J9: 14 | K9: 100% from DBS4 "Auto...FULL-GREY" discovery auto (multi-colour)
A10: Bamboo 4pc | B10: BAMBOO-TWIN-BURGUNDY-NEW | C10: Twin | D10: Burgundy | E10: No | F10: 72.78 | G10: 0 | H10: =F10+G10 -> 72.78 | I10: =IFERROR(F10/SUMIFS($F:$F,$A:$A,A10),0) -> 0.038695271 | J10: 0 | K10: Twin ranking exacts are built on Twin Burgundy
A11: Bamboo 4pc | B11: BAMBOO-FULL-PURPLE | C11: Full | D11: Purple | E11: No | F11: 69.9 | G11: 0 | H11: =F11+G11 -> 69.9 | I11: =IFERROR(F11/SUMIFS($F:$F,$A:$A,A11),0) -> 0.037164048 | J11: 2
A12: Bamboo 4pc | B12: BAMBOO-TWIN-NAVYBLUE | C12: Twin | D12: Navyblue | E12: No | F12: 62.82 | G12: 0 | H12: =F12+G12 -> 62.82 | I12: =IFERROR(F12/SUMIFS($F:$F,$A:$A,A12),0) -> 0.033399793 | J12: 1 | K12: Carried in Twin ranking exacts (Burgundy-named) and autos
A13: Bamboo 4pc | B13: BAMBOO-KING-LIGHTBLUE | C13: King | D13: Lightblue | E13: No | F13: 57.91 | G13: 0 | H13: =F13+G13 -> 57.91 | I13: =IFERROR(F13/SUMIFS($F:$F,$A:$A,A13),0) -> 0.030789271 | J13: 11
A14: Bamboo 4pc | B14: BAMBOO-QUEEN-LIGHTBLUE | C14: Queen | D14: Lightblue | E14: No | F14: 49.47 | G14: 0 | H14: =F14+G14 -> 49.47 | I14: =IFERROR(F14/SUMIFS($F:$F,$A:$A,A14),0) -> 0.026301938 | J14: 10
A15: Bamboo 4pc | B15: BAMBOO-QUEEN-OLIVE | C15: Queen | D15: Olive | E15: No | F15: 49.42 | G15: 16.76 | H15: =F15+G15 -> 66.18 | I15: =IFERROR(F15/SUMIFS($F:$F,$A:$A,A15),0) -> 0.026275354 | J15: 15
A16: Bamboo 4pc | B16: BAMBOO-KING-BURGUNDY-NEW | C16: King | D16: Burgundy | E16: No | F16: 48.98 | G16: 0 | H16: =F16+G16 -> 48.98 | I16: =IFERROR(F16/SUMIFS($F:$F,$A:$A,A16),0) -> 0.026041417 | J16: 15
A17: Bamboo 4pc | B17: BAMBOO-TWIN-OLIVE | C17: Twin | D17: Olive | E17: No | F17: 44.95 | G17: 0 | H17: =F17+G17 -> 44.95 | I17: =IFERROR(F17/SUMIFS($F:$F,$A:$A,A17),0) -> 0.023898769 | J17: 1
A18: Bamboo 4pc | B18: BAMBOO-FULL-SAGE GREEN | C18: Full | D18: Sage Green | E18: No | F18: 30.99 | G18: 0 | H18: =F18+G18 -> 30.99 | I18: =IFERROR(F18/SUMIFS($F:$F,$A:$A,A18),0) -> 0.016476593 | J18: 2
A19: Bamboo 4pc | B19: BAMBOO-TWIN-WHITE | C19: Twin | D19: White | E19: Yes | F19: 29.52 | G19: 0 | H19: =F19+G19 -> 29.52 | I19: =IFERROR(F19/SUMIFS($F:$F,$A:$A,A19),0) -> 0.015695032 | J19: 18
A20: Bamboo 4pc | B20: BAMBOO-FULL-LIGHTOLIVE | C20: Full | D20: Lightolive | E20: No | F20: 20.84 | G20: 0 | H20: =F20+G20 -> 20.84 | I20: =IFERROR(F20/SUMIFS($F:$F,$A:$A,A20),0) -> 0.011080097 | J20: 1
A21: Bamboo 4pc | B21: BAMBOO-KING-OLIVE | C21: King | D21: Olive | E21: No | F21: 18.45 | G21: 2.56 | H21: =F21+G21 -> 21.01 | I21: =IFERROR(F21/SUMIFS($F:$F,$A:$A,A21),0) -> 0.0098093947 | J21: 14
A22: Bamboo 4pc | B22: BAMBOO-TWIN-PURPLE | C22: Twin | D22: Purple | E22: No | F22: 17.15 | G22: 0 | H22: =F22+G22 -> 17.15 | I22: =IFERROR(F22/SUMIFS($F:$F,$A:$A,A22),0) -> 0.0091182178 | J22: 2
A23: Bamboo 4pc | B23: BAMBOO-TWIN-LIGHTBLUE | C23: Twin | D23: Lightblue | E23: No | F23: 15.59 | G23: 0 | H23: =F23+G23 -> 15.59 | I23: =IFERROR(F23/SUMIFS($F:$F,$A:$A,A23),0) -> 0.0082888056 | J23: 7
A24: Bamboo 4pc | B24: BAMBOO-CALIFKING-LIGHT PINK | C24: Califking | D24: Light Pink | E24: No | F24: 14.42 | G24: 0 | H24: =F24+G24 -> 14.42 | I24: =IFERROR(F24/SUMIFS($F:$F,$A:$A,A24),0) -> 0.0076667464 | J24: 2
... A37: Bamboo 6pc | B37: BAMBOO-KING-WHITE-6PCS | C37: King | D37: White | E37: Yes | F37: 770.42 | G37: 0.53 | H37: =F37+G37 -> 770.95 | I37: =IFERROR(F37/SUMIFS($F:$F,$A:$A,A37),0) -> 0.51483521 | J37: 50
A38: Bamboo 6pc | B38: BAMBOO-QUEEN-OLIVE-6PCS | C38: Queen | D38: Olive | E38: No | F38: 244.49 | G38: 0 | H38: =F38+G38 -> 244.49 | I38: =IFERROR(F38/SUMIFS($F:$F,$A:$A,A38),0) -> 0.16338109 | J38: 7 | K38: PD-LTSF auto + DBS6 Queen White autos/exact also carry it
A39: Bamboo 6pc | B39: BAMBOO-QUEEN-WHITE-6PCS | C39: Queen | D39: White | E39: Yes | F39: 118.69 | G39: 0.3 | H39: =F39+G39 -> 118.99 | I39: =IFERROR(F39/SUMIFS($F:$F,$A:$A,A39),0) -> 0.079314907 | J39: 30
A40: Bamboo 6pc | B40: BAMBOO-KING-LIGHT PINK-6PCS | C40: King | D40: Light Pink | E40: No | F40: 75.08 | G40: 0 | H40: =F40+G40 -> 75.08 | I40: =IFERROR(F40/SUMIFS($F:$F,$A:$A,A40),0) -> 0.050172409 | J40: 3
A41: Bamboo 6pc | B41: BAMBOO-QUEEN-LIGHTGREY-6PCS | C41: Queen | D41: Lightgrey | E41: No | F41: 65.07 | G41: 0 | H41: =F41+G41 -> 65.07 | I41: =IFERROR(F41/SUMIFS($F:$F,$A:$A,A41),0) -> 0.0434832 | J41: 10
A42: Bamboo 6pc | B42: BAMBOO-FULL-OLIVE-6PCS | C42: Full | D42: Olive | E42: No | F42: 36.84 | G42: 0 | H42: =F42+G42 -> 36.84 | I42: =IFERROR(F42/SUMIFS($F:$F,$A:$A,A42),0) -> 0.024618428 | J42: 1
A43: Bamboo 6pc | B43: BAMBOO-KING-PURPLE-6PCS | C43: King | D43: Purple | E43: No | F43: 35.67 | G43: 0 | H43: =F43+G43 -> 35.67 | I43: =IFERROR(F43/SUMIFS($F:$F,$A:$A,A43),0) -> 0.023836572 | J43: 15
A44: Bamboo 6pc | B44: BAMBOO-QUEEN-LIGHTOLIVE-6PCS | C44: Queen | D44: Lightolive | E44: No | F44: 22.76 | G44: 0 | H44: =F44+G44 -> 22.76 | I44: =IFERROR(F44/SUMIFS($F:$F,$A:$A,A44),0) -> 0.01520943 | J44: 1
A45: Bamboo 6pc | B45: BAMBOO-TWIN-OLIVE-6PCS | C45: Twin | D45: Olive | E45: No | F45: 20.2 | G45: 0 | H45: =F45+G45 -> 20.2 | I45: =IFERROR(F45/SUMIFS($F:$F,$A:$A,A45),0) -> 0.013498704 | J45: 0
A46: Bamboo 6pc | B46: BAMBOO-QUEEN-SAGE GREEN-6PCS | C46: Queen | D46: Sage Green | E46: No | F46: 17.2 | G46: 0 | H46: =F46+G46 -> 17.2 | I46: =IFERROR(F46/SUMIFS($F:$F,$A:$A,A46),0) -> 0.011493946 | J46: 15
A47: Bamboo 6pc | B47: BAMBOO-FULL-PURPLE-6PCS | C47: Full | D47: Purple | E47: No | F47: 13.52 | G47: 0 | H47: =F47+G47 -> 13.52 | I47: =IFERROR(F47/SUMIFS($F:$F,$A:$A,A47),0) -> 0.0090347759 | J47: 0
A48: Bamboo 6pc | B48: BAMBOO-QUEEN-LIGHTBLUE-6PCS | C48: Queen | D48: Lightblue | E48: No | F48: 13.19 | G48: 0 | H48: =F48+G48 -> 13.19 | I48: =IFERROR(F48/SUMIFS($F:$F,$A:$A,A48),0) -> 0.0088142525 | J48: 7
A49: Bamboo 6pc | B49: BAMBOO-TWIN-SAGE GREEN-6PCS | C49: Twin | D49: Sage Green | E49: No | F49: 8.24 | G49: 0 | H49: =F49+G49 -> 8.24 | I49: =IFERROR(F49/SUMIFS($F:$F,$A:$A,A49),0) -> 0.0055064019 | J49: 0
A50: Bamboo 6pc | B50: BAMBOO-KING-SAGE GREEN-6PCS | C50: King | D50: Sage Green | E50: No | F50: 7.76 | G50: 0 | H50: =F50+G50 -> 7.76 | I50: =IFERROR(F50/SUMIFS($F:$F,$A:$A,A50),0) -> 0.0051856406 | J50: 7
... A60: Satin 4pc | B60: SATIN-QUEEN-BLACK | C60: Queen | D60: Black | E60: Yes | F60: 362.32 | G60: 23.1 | H60: =F60+G60 -> 385.42 | I60: =IFERROR(F60/SUMIFS($F:$F,$A:$A,A60),0) -> 0.40286874 | J60: 60
A61: Satin 4pc | B61: SATIN-4PC-KING-GREY | C61: King | D61: Grey | E61: No | F61: 126.2 | G61: 0 | H61: =F61+G61 -> 126.2 | I61: =IFERROR(F61/SUMIFS($F:$F,$A:$A,A61),0) -> 0.14032357 | J61: 10 | K61: King keywords run on King Grey by design (ranking/test exacts) - also carried by DBS4 PD-LTSF broad
A62: Satin 4pc | B62: SATIN-FULL-BLACK | C62: Full | D62: Black | E62: Yes | F62: 72.82 | G62: 83.73 | H62: =F62+G62 -> 156.55 | I62: =IFERROR(F62/SUMIFS($F:$F,$A:$A,A62),0) -> 0.080969589 | J62: 16
...

Sheet CA_SKU_Spend
A1: CA - Day 1 (Oct 6, 2026) Sponsored Products spend by advertised SKU
A2: Source: Sellerboard (Ecotero account) per-SKU ad spend, converted by Sellerboard to USD; CAD column uses the FX rate on the Summary tab. Hero = White (Bamboo) / Black (Satin).
A4: Product | B4: SKU | C4: Size | D4: Colour | E4: Hero colour? | F4: SP spend (USD) | G4: SP spend (CAD) | H4: SB / SBV spend (USD) | I4: Total ad spend (USD) | J4: % of product SP spend | K4: Units sold (all channels) | L4: Note
A5: Bamboo 4pc | B5: BAMBOO-KING-TAUPE | C5: King | D5: Taupe | E5: No | F5: 155.43 | G5: =F5/Summary!$C$4 -> 215.875 | H5: 0 | I5: =F5+H5 -> 155.43 | J5: =IFERROR(F5/SUMIFS($F:$F,$A:$A,A5),0) -> 0.23699017 | K5: 4
A6: Bamboo 4pc | B6: BAMBOO-FULL-OLIVE | C6: Full | D6: Olive | E6: No | F6: 131.17 | G6: =F6/Summary!$C$4 -> 182.18056 | H6: 0 | I6: =F6+H6 -> 131.17 | J6: =IFERROR(F6/SUMIFS($F:$F,$A:$A,A6),0) -> 0.2 | K6: 3
A7: Bamboo 4pc | B7: BAMBOO-QUEEN-OLIVE | C7: Queen | D7: Olive | E7: No | F7: 108.2 | G7: =F7/Summary!$C$4 -> 150.27778 | H7: 0 | I7: =F7+H7 -> 108.2 | J7: =IFERROR(F7/SUMIFS($F:$F,$A:$A,A7),0) -> 0.16497675 | K7: 9
A8: Bamboo 4pc | B8: BAMBOO-QUEEN-TAUPE | C8: Queen | D8: Taupe | E8: No | F8: 50.78 | G8: =F8/Summary!$C$4 -> 70.527778 | H8: 0 | I8: =F8+H8 -> 50.78 | J8: =IFERROR(F8/SUMIFS($F:$F,$A:$A,A8),0) -> 0.077426241 | K8: 9
A9: Bamboo 4pc | B9: BAMBOO-FULL-LIGHTOLIVE | C9: Full | D9: Lightolive | E9: No | F9: 47.55 | G9: =F9/Summary!$C$4 -> 66.041667 | H9: 0 | I9: =F9+H9 -> 47.55 | J9: =IFERROR(F9/SUMIFS($F:$F,$A:$A,A9),0) -> 0.072501334 | K9: 1
A10: Bamboo 4pc | B10: BAMBOO-CALIFKING-CREME | C10: Califking | D10: Creme | E10: No | F10: 28.38 | G10: =F10/Summary!$C$4 -> 39.416667 | H10: 17.18 | I10: =F10+H10 -> 45.56 | J10: =IFERROR(F10/SUMIFS($F:$F,$A:$A,A10),0) -> 0.04327209 | K10: 1
A11: Bamboo 4pc | B11: BAMBOO-KING-LIGHTBLUE | C11: King | D11: Lightblue | E11: No | F11: 16.42 | G11: =F11/Summary!$C$4 -> 22.805556 | H11: 0 | I11: =F11+H11 -> 16.42 | J11: =IFERROR(F11/SUMIFS($F:$F,$A:$A,A11),0) -> 0.025036213 | K11: 9
A12: Bamboo 4pc | B12: BAMBOO-QUEEN-MIDGREY | C12: Queen | D12: Midgrey | E12: No | F12: 15.4 | G12: =F12/Summary!$C$4 -> 21.388889 | H12: 0 | I12: =F12+H12 -> 15.4 | J12: =IFERROR(F12/SUMIFS($F:$F,$A:$A,A12),0) -> 0.023480979 | K12: 7
A13: Bamboo 4pc | B13: BAMBOO-FULL-PURPLE | C13: Full | D13: Purple | E13: No | F13: 9.32 | G13: =F13/Summary!$C$4 -> 12.944444 | H13: 0 | I13: =F13+H13 -> 9.32 | J13: =IFERROR(F13/SUMIFS($F:$F,$A:$A,A13),0) -> 0.014210566 | K13: 2
A14: Bamboo 4pc | B14: BAMBOO-QUEEN-LIGHTBLUE | C14: Queen | D14: Lightblue | E14: No | F14: 8.99 | G14: =F14/Summary!$C$4 -> 12.486111 | H14: 0 | I14: =F14+H14 -> 8.99 | J14: =IFERROR(F14/SUMIFS($F:$F,$A:$A,A14),0) -> 0.013707403 | K14: 6
A15: Bamboo 4pc | B15: BAMBOO-CALIFKING-MIDGREY | C15: Califking | D15: Midgrey | E15: No | F15: 8.25 | G15: =F15/Summary!$C$4 -> 11.458333 | H15: 0 | I15: =F15+H15 -> 8.25 | J15: =IFERROR(F15/SUMIFS($F:$F,$A:$A,A15),0) -> 0.012579096 | K15: 0
A16: Bamboo 4pc | B16: BAMBOO-CALIFKING-LIGHTGREY | C16: Califking | D16: Lightgrey | E16: No | F16: 7.77 | G16: =F16/Summary!$C$4 -> 10.791667 | H16: 0 | I16: =F16+H16 -> 7.77 | J16: =IFERROR(F16/SUMIFS($F:$F,$A:$A,A16),0) -> 0.011847221 | K16: 1
... A103: Satin 6pc | B103: SATIN-GOLD-QUEEN-6PCS | C103: Queen | D103: Gold | E103: No | F103: 1.07 | G103: =F103/Summary!$C$4 -> 1.4861111 | H103: 0 | I103: =F103+H103 -> 1.07 | J103: =IFERROR(F103/SUMIFS($F:$F,$A:$A,A103),0) -> 0.0057051453 | K103: 0

Sheet US_Campaigns
A1: US - Day 1 (Oct 6, 2026) campaigns advertising each deal product
A2: Source: Ecotero Command Center PPC campaigns (campaign totals, USD). A campaign that advertises several products is listed under each one ("Shared" = Yes); use "Count once" to total without double counting. "SKU in campaign name" is what the name says - names do not always match the ads actually running.
A4: Product | B4: Campaign ID | C4: Campaign name | D4: Category | E4: Match type | F4: Objective | G4: SKU in campaign name | H4: Name colour = hero? | I4: Shared across products? | J4: Also advertises | K4: Count once | L4: Impressions | M4: Clicks | N4: CTR | O4: Spend (USD) | P4: CPC (USD) | Q4: Orders | R4: Sales (USD) | S4: ACoS | T4: CVR
A5: Bamboo 4pc | B5: 55487419943563 | C5: DBS4-SP-AUTO-(PD-LTSF)-Aged Deal SKUs | D5: LTSF / Clearance | E5: Auto | I5: No | K5: Yes | L5: 42507 | M5: 377 | N5: =IFERROR(M5/L5,0) -> 0.0088691274 | O5: 501.26 | P5: =IFERROR(O5/M5,0) -> 1.3296021 | Q5: 21 | R5: 1364.14 | S5: =IFERROR(O5/R5,0) -> 0.36745495 | T5: =IFERROR(Q5/M5,0) -> 0.055702918
A6: Bamboo 4pc | B6: 310976801193815 | C6: DBS4-SP-Auto-(AUTO)-Auto-(Discovery)-DO-BAMBOO-FULL-GREY | D6: Auto (multi-colour, Amazon picks ad) | E6: Auto | F6: Discovery | G6: BAMBOO-FULL-GREY | H6: No | I6: Yes | J6: Bamboo 6pc | K6: Yes | L6: 17347 | M6: 90 | N6: =IFERROR(M6/L6,0) -> 0.005188217 | O6: 337.28 | P6: =IFERROR(O6/M6,0) -> 3.7475556 | Q6: 11 | R6: 701.04 | S6: =IFERROR(O6/R6,0) -> 0.48111377 | T6: =IFERROR(Q6/M6,0) -> 0.12222222
A7: Bamboo 4pc | B7: 305062484006669 | C7: DBS4-SP-Auto-(AUTO)-Auto-(Discovery)-DO-BAMBOO-KING-WHITE | D7: Auto (multi-colour, Amazon picks ad) | E7: Auto | F7: Discovery | G7: BAMBOO-KING-WHITE | H7: Yes | I7: No | K7: Yes | L7: 15071 | M7: 64 | N7: =IFERROR(M7/L7,0) -> 0.0042465663 | O7: 303.01 | P7: =IFERROR(O7/M7,0) -> 4.7345312 | Q7: 13 | R7: 972.3 | S7: =IFERROR(O7/R7,0) -> 0.3116425 | T7: =IFERROR(Q7/M7,0) -> 0.203125
A8: Bamboo 4pc | B8: 389142860904839 | C8: DBS4-SP-Decolure Bamboo Sheets-(LSV)-Broad-(Defensive)-DO-BAMBOO-KING-WHITE | D8: Defensive / Brand | E8: Broad | F8: Defensive | G8: BAMBOO-KING-WHITE | H8: Yes | I8: No | K8: Yes | L8: 11995 | M8: 69 | N8: =IFERROR(M8/L8,0) -> 0.0057523968 | O8: 202.39 | P8: =IFERROR(O8/M8,0) -> 2.9331884 | Q8: 14 | R8: 943.56 | S8: =IFERROR(O8/R8,0) -> 0.21449616 | T8: =IFERROR(Q8/M8,0) -> 0.20289855
A9: Bamboo 4pc | B9: 291577934636516 | C9: DBS4-SP-Cooling Bamboo Sheets-[Bamboo|Cooling]-(MSV)-Exact-(Ranking)-DO-BAMBOO-KING-WHITE | D9: Ranking | E9: Exact | F9: Ranking | G9: BAMBOO-KING-WHITE | H9: Yes | I9: No | K9: Yes | L9: 164 | M9: 11 | N9: =IFERROR(M9/L9,0) -> 0.067073171 | O9: 71.6 | P9: =IFERROR(O9/M9,0) -> 6.5090909 | Q9: 2 | R9: 135.53 | S9: =IFERROR(O9/R9,0) -> 0.52829632 | T9: =IFERROR(Q9/M9,0) -> 0.18181818
A10: Bamboo 4pc | B10: 526089960409455 | C10: DBS4-SP-B08KQHRDDG-(PAT)-Targeting-(Conversion)-DO-BAMBOO-KING-WHITE | D10: Product targeting | E10: Product Targeting | F10: Conversions | G10: BAMBOO-KING-WHITE | H10: Yes | I10: No | K10: Yes | L10: 1821 | M10: 32 | N10: =IFERROR(M10/L10,0) -> 0.017572762 | O10: 62.68 | P10: =IFERROR(O10/M10,0) -> 1.95875 | Q10: 6 | R10: 410.34 | S10: =IFERROR(O10/R10,0) -> 0.15275138 | T10: =IFERROR(Q10/M10,0) -> 0.1875
A11: Bamboo 4pc | B11: 217202192519686 | C11: DBS4-SP-bamboo sheets queen size-[Bamboo|Queen]-(HSV)-Broad-(DISC)-DO-BAMBOO-QUEEN-WHITE | D11: Discovery (keyword) | E11: Broad | F11: Discovery | G11: BAMBOO-QUEEN-WHITE | H11: Yes | I11: No | K11: Yes | L11: 4102 | M11: 12 | N11: =IFERROR(M11/L11,0) -> 0.0029254022 | O11: 51.63 | P11: =IFERROR(O11/M11,0) -> 4.3025 | Q11: 3 | R11: 196.37 | S11: =IFERROR(O11/R11,0) -> 0.26292203 | T11: =IFERROR(Q11/M11,0) -> 0.25
A12: Bamboo 4pc | B12: 26875799662688 | C12: DBS4-SP-Conquest-(PAT)-Targeting-(Conquesting)-FIX-BAMBOO-QUEEN-WHITE-TEST | D12: Product targeting | E12: Product Targeting | G12: BAMBOO-QUEEN-WHITE-TEST | H12: Yes | I12: No | K12: Yes | L12: 6173 | M12: 22 | N12: =IFERROR(M12/L12,0) -> 0.0035639073 | O12: 47.74 | P12: =IFERROR(O12/M12,0) -> 2.17 | Q12: 0 | R12: 0 | S12: =IFERROR(O12/R12,0) -> 0 | T12: =IFERROR(Q12/M12,0) -> 0
A13: Bamboo 4pc | B13: 379276084224195 | C13: Decolure_SP_Exact_PAT_Defensive | D13: Product targeting | E13: Product Targeting | F13: Defensive | I13: Yes | J13: Bamboo 6pc, Satin 4pc | K13: Yes | L13: 10572 | M13: 64 | N13: =IFERROR(M13/L13,0) -> 0.0060537268 | O13: 47.6 | P13: =IFERROR(O13/M13,0) -> 0.74375 | Q13: 10 | R13: 453.42 | S13: =IFERROR(O13/R13,0) -> 0.10497993 | T13: =IFERROR(Q13/M13,0) -> 0.15625
A14: Bamboo 4pc | B14: 435654690515168 | C14: DBS4-SP-Bamboo Sheets Queen-[Bamboo|Queen]-(MSV)-Exact-(Ranking)-DO-BAMBOO-QUEEN-WHITE | D14: Ranking | E14: Exact | F14: Ranking | G14: BAMBOO-QUEEN-WHITE | H14: Yes | I14: No | K14: Yes | L14: 1141 | M14: 11 | N14: =IFERROR(M14/L14,0) -> 0.0096406661 | O14: 39.09 | P14: =IFERROR(O14/M14,0) -> 3.5536364 | Q14: 5 | R14: 396.49 | S14: =IFERROR(O14/R14,0) -> 0.098590128 | T14: =IFERROR(Q14/M14,0) -> 0.45454545
A15: Bamboo 4pc | B15: 457513225586449 | C15: DECOLURE - Bamboo 4Pcs- LTSF Campaign | D15: LTSF / Clearance | E15: Auto | F15: Liquidation | I15: Yes | J15: Bamboo 6pc | K15: Yes | L15: 2304 | M15: 16 | N15: =IFERROR(M15/L15,0) -> 0.0069444444 | O15: 38.42 | P15: =IFERROR(O15/M15,0) -> 2.40125 | Q15: 0 | R15: 0 | S15: =IFERROR(O15/R15,0) -> 0 | T15: =IFERROR(Q15/M15,0) -> 0
A16: Bamboo 4pc | B16: 225300380920122 | C16: DBS4-SP-Bamboo Sheets Cooling-[Bamboo|Cooling]-(MSV)-Exact-(Ranking)-DO-BAMBOO-KING-WHITE | D16: Ranking | E16: Exact | F16: Ranking | G16: BAMBOO-KING-WHITE | H16: Yes | I16: No | K16: Yes | L16: 47 | M16: 3 | N16: =IFERROR(M16/L16,0) -> 0.063829787 | O16: 25.23 | P16: =IFERROR(O16/M16,0) -> 8.41 | Q16: 0 | R16: 0 | S16: =IFERROR(O16/R16,0) -> 0 | T16: =IFERROR(Q16/M16,0) -> 0
A17: Bamboo 4pc | B17: 1477422308688 | C17: DBS4-SP-king size sheets set bamboo cooling-[Bamboo|Cooling]-(LSV)-Exact-(Ranking)-FIX-BAMBOO-KING-WHITE | D17: Ranking | E17: Exact | F17: Ranking | G17: BAMBOO-KING-WHITE | H17: Yes | I17: No | K17: Yes | L17: 815 | M17: 3 | N17: =IFERROR(M17/L17,0) -> 0.0036809816 | O17: 24.28 | P17: =IFERROR(O17/M17,0) -> 8.0933333 | Q17: 2 | R17: 135.98 | S17: =IFERROR(O17/R17,0) -> 0.17855567 | T17: =IFERROR(Q17/M17,0) -> 0.66666667
A18: Bamboo 4pc | B18: 39362978301776 | C18: DBS6-SP-LTSF-ALL-Broad-(Clearance)-DO-AGED-ALL | D18: LTSF / Clearance | E18: Broad | F18: Liquidation | G18: AGED-ALL | H18: No | I18: No | K18: Yes | L18: 2758 | M18: 23 | N18: =IFERROR(M18/L18,0) -> 0.0083393764 | O18: 24.22 | P18: =IFERROR(O18/M18,0) -> 1.0530435 | Q18: 1 | R18: 79.99 | S18: =IFERROR(O18/R18,0) -> 0.30278785 | T18: =IFERROR(Q18/M18,0) -> 0.043478261
A19: Bamboo 4pc | B19: 476122833243587 | C19: DBS4-SP-B07MZ4GKZH-(PAT)-Targeting-(Conversion)-DO-BAMBOO-KING-WHITE | D19: Product targeting | E19: Product Targeting | F19: Conversions | G19: BAMBOO-KING-WHITE | H19: Yes | I19: No | K19: Yes | L19: 2562 | M19: 11 | N19: =IFERROR(M19/L19,0) -> 0.0042935207 | O19: 21.92 | P19: =IFERROR(O19/M19,0) -> 1.9927273 | Q19: 1 | R19: 62.39 | S19: =IFERROR(O19/R19,0) -> 0.35133836 | T19: =IFERROR(Q19/M19,0) -> 0.090909091
A20: Bamboo 4pc | B20: 169190618188277 | C20: DBS4-SP-bamboo cool sheets-[Bamboo|Cooling]-(LSV)-Exact-(Ranking)-FIX-BAMBOO-KING-WHITE-TAIL-3 | D20: Ranking | E20: Exact | F20: Ranking | G20: BAMBOO-KING-WHITE-TAIL-3 | H20: Yes | I20: No | K20: Yes | L20: 137 | M20: 3 | N20: =IFERROR(M20/L20,0) -> 0.02189781 | O20: 17.3 | P20: =IFERROR(O20/M20,0) -> 5.7666667 | Q20: 0 | R20: 0 | S20: =IFERROR(O20/R20,0) -> 0 | T20: =IFERROR(Q20/M20,0) -> 0
A21: Bamboo 4pc | B21: 6072077389058 | C21: DBS4-SP-Cooling King Bed Sheets-[Cooling|King]-(LSV)-Exact-(Ranking)-DO-BAMBOO-KING-WHITE | D21: Ranking | E21: Exact | F21: Ranking | G21: BAMBOO-KING-WHITE | H21: Yes | I21: No | K21: Yes | L21: 169 | M21: 3 | N21: =IFERROR(M21/L21,0) -> 0.017751479 | O21: 15.91 | P21: =IFERROR(O21/M21,0) -> 5.3033333 | Q21: 1 | R21: 84.99 | S21: =IFERROR(O21/R21,0) -> 0.18719849 | T21: =IFERROR(Q21/M21,0) -> 0.33333333
A22: Bamboo 4pc | B22: 308189422883149 | C22: DBS4-SP-Bamboo Cooling Sheets King Size-[Bamboo|Cooling]-(LSV)-Exact-(Ranking)-DO-BAMBOO-KING-WHITE | D22: Ranking | E22: Exact | F22: Ranking | G22: BAMBOO-KING-WHITE | H22: Yes | I22: No | K22: Yes | L22: 242 | M22: 24 | N22: =IFERROR(M22/L22,0) -> 0.099173554 | O22: 15.73 | P22: =IFERROR(O22/M22,0) -> 0.65541667 | Q22: 0 | R22: 0 | S22: =IFERROR(O22/R22,0) -> 0 | T22: =IFERROR(Q22/M22,0) -> 0
A23: Bamboo 4pc | B23: 81668335931852 | C23: DBS6-SP-LTSF-TWIN-Phrase-(Clearance)-DO-AGED-TWIN | D23: LTSF / Clearance | E23: Phrase | F23: Liquidation | G23: AGED-TWIN | H23: No | I23: No | K23: Yes | L23: 2253 | M23: 7 | N23: =IFERROR(M23/L23,0) -> 0.0031069685 | O23: 15.64 | P23: =IFERROR(O23/M23,0) -> 2.2342857 | Q23: 0 | R23: 0 | S23: =IFERROR(O23/R23,0) -> 0 | T23: =IFERROR(Q23/M23,0) -> 0
A24: Bamboo 4pc | B24: 332114561773037 | C24: DBS4-SP-100 Bamboo-(VLSV)-Broad-(Discovery)-DO-BAMBOO-QUEEN-WHITE | D24: Discovery (keyword) | E24: Broad | F24: Discovery | G24: BAMBOO-QUEEN-WHITE | H24: Yes | I24: No | K24: Yes | L24: 1950 | M24: 12 | N24: =IFERROR(M24/L24,0) -> 0.0061538462 | O24: 14.71 | P24: =IFERROR(O24/M24,0) -> 1.2258333 | Q24: 1 | R24: 63.99 | S24: =IFERROR(O24/R24,0) -> 0.22987967 | T24: =IFERROR(Q24/M24,0) -> 0.083333333
A25: Bamboo 4pc | B25: 468904898254533 | C25: DBS4-SP-Sheets Full Size Bed Bamboo-(VLSV)-Exact-(Ranking)-DO-BAMBOO-FULL-WHITE | D25: Ranking | E25: Exact | F25: Ranking | G25: BAMBOO-FULL-WHITE | H25: Yes | I25: No | K25: Yes | L25: 877 | M25: 3 | N25: =IFERROR(M25/L25,0) -> 0.0034207526 | O25: 14.02 | P25: =IFERROR(O25/M25,0) -> 4.6733333 | Q25: 1 | R25: 55.29 | S25: =IFERROR(O25/R25,0) -> 0.25357207 | T25: =IFERROR(Q25/M25,0) -> 0.33333333
A26: Bamboo 4pc | B26: 173753122670008 | C26: DBS4-SP-Bamboo Sheets Twin-(MSV)-Exact-(Ranking)-DO-BAMBOO-TWIN-WHITE | D26: Ranking | E26: Exact | F26: Ranking | G26: BAMBOO-TWIN-WHITE | H26: Yes | I26: No | K26: Yes | L26: 61 | M26: 3 | N26: =IFERROR(M26/L26,0) -> 0.049180328 | O26: 13.53 | P26: =IFERROR(O26/M26,0) -> 4.51 | Q26: 3 | R26: 154.17 | S26: =IFERROR(O26/R26,0) -> 0.087760265 | T26: =IFERROR(Q26/M26,0) -> 1
A27: Bamboo 4pc | B27: 254494086894356 | C27: DBS4-SP-Twin Bamboo Bed Sheets-[Bamboo|Twin]-(HSV)-Exact-(Ranking)-DO-BAMBOO-TWIN-BURGUNDY-NEW | D27: Ranking | E27: Exact | F27: Ranking | G27: BAMBOO-TWIN-BURGUNDY-NEW | H27: No | I27: No | K27: Yes | L27: 107 | M27: 2 | N27: =IFERROR(M27/L27,0) -> 0.018691589 | O27: 13.35 | P27: =IFERROR(O27/M27,0) -> 6.675 | Q27: 1 | R27: 46.19 | S27: =IFERROR(O27/R27,0) -> 0.2890236 | T27: =IFERROR(Q27/M27,0) -> 0.5
A28: Bamboo 4pc | B28: 562907116323646 | C28: DECOLURE - B4 - QUEEN OLIVE - PRIME CAMPAIGN 2 (LTSF) | D28: LTSF / Clearance | E28: Auto | F28: Liquidation | I28: Yes | J28: Bamboo 6pc | K28: Yes | L28: 4665 | M28: 17 | N28: =IFERROR(M28/L28,0) -> 0.0036441586 | O28: 13.27 | P28: =IFERROR(O28/M28,0) -> 0.78058824 | Q28: 0 | R28: 0 | S28: =IFERROR(O28/R28,0) -> 0 | T28: =IFERROR(Q28/M28,0) -> 0
A29: Bamboo 4pc | B29: 510977750871435 | C29: DBS4-SP-B07YKCZHGK-(PAT)-Targeting-(Conversion)-DO-BAMBOO-KING-CREME | D29: Product targeting | E29: Product Targeting | F29: Conversions | G29: BAMBOO-KING-CREME | H29: No | I29: No | K29: Yes | L29: 502 | M29: 6 | N29: =IFERROR(M29/L29,0) -> 0.011952191 | O29: 11.82 | P29: =IFERROR(O29/M29,0) -> 1.97 | Q29: 0 | R29: 0 | S29: =IFERROR(O29/R29,0) -> 0 | T29: =IFERROR(Q29/M29,0) -> 0
A30: Bamboo 4pc | B30: 133572104497162 | C30: DBS4-SP-Decolure Bamboo Sheets-(LSV)-Exact-(Defensive)-DO-BAMBOO-KING-WHITE | D30: Defensive / Brand | E30: Exact | F30: Defensive | G30: BAMBOO-KING-WHITE | H30: Yes | I30: No | K30: Yes | L30: 599 | M30: 7 | N30: =IFERROR(M30/L30,0) -> 0.011686144 | O30: 10.28 | P30: =IFERROR(O30/M30,0) -> 1.4685714 | Q30: 1 | R30: 67.99 | S30: =IFERROR(O30/R30,0) -> 0.15119871 | T30: =IFERROR(Q30/M30,0) -> 0.14285714
A31: Bamboo 4pc | B31: 165736265830033 | C31: DBS4-SP-Bamboo Twin Sheets Set-[Bamboo|Twin]-(MSV)-Exact-(Ranking)-DO-BAMBOO-TWIN-BURGUNDY-NEW | D31: Ranking | E31: Exact | F31: Ranking | G31: BAMBOO-TWIN-BURGUNDY-NEW | H31: No | I31: No | K31: Yes | L31: 14 | M31: 1 | N31: =IFERROR(M31/L31,0) -> 0.071428571 | O31: 10.12 | P31: =IFERROR(O31/M31,0) -> 10.12 | Q31: 0 | R31: 0 | S31: =IFERROR(O31/R31,0) -> 0 | T31: =IFERROR(Q31/M31,0) -> 0
A32: Bamboo 4pc | B32: 120999019617631 | C32: DBS4-SP-Cooling Sheets Bamboo-[Bamboo|Cooling]-(MSV)-Exact-(Ranking)-DO-BAMBOO-KING-WHITE | D32: Ranking | E32: Exact | F32: Ranking | G32: BAMBOO-KING-WHITE | H32: Yes | I32: No | K32: Yes | L32: 30 | M32: 1 | N32: =IFERROR(M32/L32,0) -> 0.033333333 | O32: 9.55 | P32: =IFERROR(O32/M32,0) -> 9.55 | Q32: 0 | R32: 0 | S32: =IFERROR(O32/R32,0) -> 0 | T32: =IFERROR(Q32/M32,0) -> 0
A33: Bamboo 4pc | B33: 25448313713632 | C33: DBS4-SP-Twin Sheets Set Bamboo-[Bamboo|Twin]-(MSV)-Exact-(Ranking)-DO-BAMBOO-TWIN-BURGUNDY-NEW | D33: Ranking | E33: Exact | F33: Ranking | G33: BAMBOO-TWIN-BURGUNDY-NEW | H33: No | I33: No | K33: Yes | L33: 60 | M33: 2 | N33: =IFERROR(M33/L33,0) -> 0.033333333 | O33: 9.55 | P33: =IFERROR(O33/M33,0) -> 4.775 | Q33: 0 | R33: 0 | S33: =IFERROR(O33/R33,0) -> 0 | T33: =IFERROR(Q33/M33,0) -> 0
A34: Bamboo 4pc | B34: 208669798220852 | C34: DBS4-SP-bamboo cooling sheets queen size bed set deep pockets-[Bamboo|Cooling]-(LSV)-Exact-(Ranking)-FIX-BAMBOO-QUEEN-WHITE | D34: Ranking | E34: Exact | F34: Ranking | G34: BAMBOO-QUEEN-WHITE | H34: Yes | I34: No | K34: Yes | L34: 44 | M34: 2 | N34: =IFERROR(M34/L34,0) -> 0.045454545 | O34: 8.64 | P34: =IFERROR(O34/M34,0) -> 4.32 | Q34: 0 | R34: 0 | S34: =IFERROR(O34/R34,0) -> 0 | T34: =IFERROR(Q34/M34,0) -> 0
A35: Bamboo 4pc | B35: 456564870715953 | C35: DBS4-SP-Twin Sheets Bamboo-[Bamboo|Twin]-(LSV)-Exact-(Ranking)-DO-BAMBOO-TWIN-BURGUNDY-NEW | D35: Ranking | E35: Exact | F35: Ranking | G35: BAMBOO-TWIN-BURGUNDY-NEW | H35: No | I35: No | K35: Yes | L35: 48 | M35: 1 | N35: =IFERROR(M35/L35,0) -> 0.020833333 | O35: 8.3 | P35: =IFERROR(O35/M35,0) -> 8.3 | Q35: 0 | R35: 0 | S35: =IFERROR(O35/R35,0) -> 0 | T35: =IFERROR(Q35/M35,0) -> 0
A36: Bamboo 4pc | B36: 428094781835473 | C36: DCS-SP-Auto/LTSF-Def-Multi LTSF SKUs | D36: LTSF / Clearance | E36: Auto | F36: Liquidation | I36: Yes | J36: Bamboo 6pc, Satin 4pc | K36: Yes | L36: 2736 | M36: 18 | N36: =IFERROR(M36/L36,0) -> 0.0065789474 | O36: 7.96 | P36: =IFERROR(O36/M36,0) -> 0.44222222 | Q36: 2 | R36: 61.9 | S36: =IFERROR(O36/R36,0) -> 0.12859451 | T36: =IFERROR(Q36/M36,0) -> 0.11111111
A37: Bamboo 4pc | B37: 462304093247311 | C37: DBS4-SP-Twin Bamboo Sheets-[Bamboo|Twin]-(LSV)-Exact-(Ranking)-DO-BAMBOO-TWIN-BURGUNDY-NEW | D37: Ranking | E37: Exact | F37: Ranking | G37: BAMBOO-TWIN-BURGUNDY-NEW | H37: No | I37: No | K37: Yes | L37: 40 | M37: 1 | N37: =IFERROR(M37/L37,0) -> 0.025 | O37: 7.69 | P37: =IFERROR(O37/M37,0) -> 7.69 | Q37: 0 | R37: 0 | S37: =IFERROR(O37/R37,0) -> 0 | T37: =IFERROR(Q37/M37,0) -> 0
A38: Bamboo 4pc | B38: 99023725891341 | C38: DBS4-SP-Bamboo Sheets Twin Size-[Bamboo|Twin]-(MSV)-Exact-(Ranking)-DO-BAMBOO-TWIN-BURGUNDY-NEW | D38: Ranking | E38: Exact | F38: Ranking | G38: BAMBOO-TWIN-BURGUNDY-NEW | H38: No | I38: No | K38: Yes | L38: 9 | M38: 1 | N38: =IFERROR(M38/L38,0) -> 0.11111111 | O38: 7.13 | P38: =IFERROR(O38/M38,0) -> 7.13 | Q38: 0 | R38: 0 | S38: =IFERROR(O38/R38,0) -> 0 | T38: =IFERROR(Q38/M38,0) -> 0
A39: Bamboo 4pc | B39: 382575122533704 | C39: DBS4-SP-Purple Bamboo Sheets-(VLSV)-Exact-(Ranking)-DO-BAMBOO-QUEEN-PURPLE | D39: Ranking | E39: Exact | F39: Ranking | G39: BAMBOO-QUEEN-PURPLE | H39: No | I39: No | K39: Yes | L39: 878 | M39: 5 | N39: =IFERROR(M39/L39,0) -> 0.0056947608 | O39: 6.82 | P39: =IFERROR(O39/M39,0) -> 1.364 | Q39: 0 | R39: 0 | S39: =IFERROR(O39/R39,0) -> 0 | T39: =IFERROR(Q39/M39,0) -> 0
A40: Bamboo 4pc | B40: 554499949808410 | C40: DBS4-SP-Deep Pocket King Sheet Set-(HSV)-Exact-(Ranking)-DO-BAMBOO-KING-WHITE | D40: Ranking | E40: Exact | F40: Ranking | G40: BAMBOO-KING-WHITE | H40: Yes | I40: No | K40: Yes | L40: 326 | M40: 3 | N40: =IFERROR(M40/L40,0) -> 0.009202454 | O40: 6.57 | P40: =IFERROR(O40/M40,0) -> 2.19 | Q40: 0 | R40: 0 | S40: =IFERROR(O40/R40,0) -> 0 | T40: =IFERROR(Q40/M40,0) -> 0
A41: Bamboo 4pc | B41: 345754272659953 | C41: BAMBOO-KING-LIGHTGREY-6PCS_SP_Exact_PAT_Defensive | D41: Product targeting | E41: Product Targeting | F41: Defensive | G41: BAMBOO-KING-LIGHTGREY-6PCS | H41: No | I41: Yes | J41: Bamboo 6pc, Satin 4pc | K41: Yes | L41: 249 | M41: 6 | N41: =IFERROR(M41/L41,0) -> 0.024096386 | O41: 6.43 | P41: =IFERROR(O41/M41,0) -> 1.0716667 | Q41: 1 | R41: 67.99 | S41: =IFERROR(O41/R41,0) -> 0.094572731 | T41: =IFERROR(Q41/M41,0) -> 0.16666667
...

Sheet CA_Campaigns
A1: CA - Day 1 (Oct 6, 2026) campaigns advertising each deal product
A2: Source: Ecotero Command Center PPC campaigns (campaign totals, CAD). A campaign that advertises several products is listed under each one ("Shared" = Yes); use "Count once" to total without double counting. "SKU in campaign name" is what the name says - names do not always match the ads actually running.
A4: Product | B4: Campaign ID | C4: Campaign name | D4: Category | E4: Match type | F4: Objective | G4: SKU in campaign name | H4: Name colour = hero? | I4: Shared across products? | J4: Also advertises | K4: Count once | L4: Impressions | M4: Clicks | N4: CTR | O4: Spend (CAD) | P4: CPC (CAD) | Q4: Orders | R4: Sales (CAD) | S4: ACoS | T4: CVR
A5: Bamboo 4pc | B5: 58846483429019 | C5: DBS4-CA-SP-AUTO-(PD-LTSF)-Aged Deal SKUs | D5: LTSF / Clearance | E5: Auto | I5: No | K5: Yes | L5: 59055 | M5: 216 | N5: =IFERROR(M5/L5,0) -> 0.0036576073 | O5: 250.51 | P5: =IFERROR(O5/M5,0) -> 1.1597685 | Q5: 19 | R5: 1596.71 | S5: =IFERROR(O5/R5,0) -> 0.15689136 | T5: =IFERROR(Q5/M5,0) -> 0.087962963
A6: Bamboo 4pc | B6: 67523305673170 | C6: DBS4-CA-SP-Auto-(AUTO)-Auto-(Discovery)-DO-BAMBOO-FULL-BLACK | D6: Auto (multi-colour, Amazon picks ad) | E6: Auto | F6: Discovery | G6: BAMBOO-FULL-BLACK | H6: No | I6: No | K6: Yes | L6: 135024 | M6: 145 | N6: =IFERROR(M6/L6,0) -> 0.0010738832 | O6: 150.16 | P6: =IFERROR(O6/M6,0) -> 1.0355862 | Q6: 10 | R6: 897.13 | S6: =IFERROR(O6/R6,0) -> 0.16737819 | T6: =IFERROR(Q6/M6,0) -> 0.068965517
A7: Bamboo 4pc | B7: 556882202453641 | C7: DECOLURE - All SKU - Prime Campaign - High LTSF Charge | D7: LTSF / Clearance | E7: Auto | F7: Liquidation | I7: Yes | J7: Satin 4pc, Satin 6pc | K7: Yes | L7: 61980 | M7: 123 | N7: =IFERROR(M7/L7,0) -> 0.0019845111 | O7: 123.09 | P7: =IFERROR(O7/M7,0) -> 1.0007317 | Q7: 5 | R7: 303.79 | S7: =IFERROR(O7/R7,0) -> 0.40518121 | T7: =IFERROR(Q7/M7,0) -> 0.040650407
A8: Bamboo 4pc | B8: 722305506558 | C8: DBS4-CA-SP-BROAD-(PD-LTSF) | D8: LTSF / Clearance | E8: Broad | I8: No | K8: Yes | L8: 5629 | M8: 61 | N8: =IFERROR(M8/L8,0) -> 0.010836738 | O8: 77.97 | P8: =IFERROR(O8/M8,0) -> 1.2781967 | Q8: 5 | R8: 464.95 | S8: =IFERROR(O8/R8,0) -> 0.16769545 | T8: =IFERROR(Q8/M8,0) -> 0.081967213
A9: Bamboo 4pc | B9: 519336685394450 | C9: BAMBOO-QUEEN-TAUPE SP EX - TT - 8124 bamboo sheets ZB | D9: Ranking | E9: Exact | F9: Ranking | G9: BAMBOO-QUEEN-TAUPE | H9: No | I9: No | K9: Yes | L9: 6970 | M9: 41 | N9: =IFERROR(M9/L9,0) -> 0.0058823529 | O9: 68.1 | P9: =IFERROR(O9/M9,0) -> 1.6609756 | Q9: 6 | R9: 507.94 | S9: =IFERROR(O9/R9,0) -> 0.13407095 | T9: =IFERROR(Q9/M9,0) -> 0.14634146
A10: Bamboo 4pc | B10: 184314823645958 | C10: DBS4-CA-SP-Decolure Bamboo Sheets-(VLSV)-Exact-(Defensive)-DO-BAMBOO-KING-TAUPE | D10: Defensive / Brand | E10: Exact | F10: Defensive | G10: BAMBOO-KING-TAUPE | H10: No | I10: No | K10: Yes | L10: 3752 | M10: 30 | N10: =IFERROR(M10/L10,0) -> 0.0079957356 | O10: 62 | P10: =IFERROR(O10/M10,0) -> 2.0666667 | Q10: 8 | R10: 676.67 | S10: =IFERROR(O10/R10,0) -> 0.091625164 | T10: =IFERROR(Q10/M10,0) -> 0.26666667
A11: Bamboo 4pc | B11: 420811336431276 | C11: Bamboo 4 Pcs B08KQJMZ8Q - bamboo sheets queen size | D11: Ranking | E11: Exact | F11: Ranking | I11: No | K11: Yes | L11: 2626 | M11: 13 | N11: =IFERROR(M11/L11,0) -> 0.004950495 | O11: 44.82 | P11: =IFERROR(O11/M11,0) -> 3.4476923 | Q11: 1 | R11: 79.99 | S11: =IFERROR(O11/R11,0) -> 0.56032004 | T11: =IFERROR(Q11/M11,0) -> 0.076923077
A12: Bamboo 4pc | B12: 451730563061312 | C12: DBS4-CA-SP-Bamboo Sheets King-[Bamboo|King]-(MSV)-Exact-(Ranking)-DO-BAMBOO-KING-TAUPE | D12: Ranking | E12: Exact | F12: Ranking | G12: BAMBOO-KING-TAUPE | H12: No | I12: No | K12: Yes | L12: 517 | M12: 8 | N12: =IFERROR(M12/L12,0) -> 0.015473888 | O12: 40.73 | P12: =IFERROR(O12/M12,0) -> 5.09125 | Q12: 0 | R12: 0 | S12: =IFERROR(O12/R12,0) -> 0 | T12: =IFERROR(Q12/M12,0) -> 0
A13: Bamboo 4pc | B13: 398348552892938 | C13: BAMBOO-QUEEN-OLIVE SP BR 04102024 Decolure-Branded KW ZB | D13: Defensive / Brand | E13: Broad | F13: Defensive | G13: BAMBOO-QUEEN-OLIVE | H13: No | I13: No | K13: Yes | L13: 1717 | M13: 30 | N13: =IFERROR(M13/L13,0) -> 0.017472335 | O13: 30.47 | P13: =IFERROR(O13/M13,0) -> 1.0156667 | Q13: 0 | R13: 0 | S13: =IFERROR(O13/R13,0) -> 0 | T13: =IFERROR(Q13/M13,0) -> 0
A14: Bamboo 4pc | B14: 376141856045333 | C14: DBS4-CA-SP-Organic Bamboo Sheets-[Bamboo]-(VLSV)-Exact-(Ranking)-DO-BAMBOO-KING-TAUPE | D14: Ranking | E14: Exact | F14: Ranking | G14: BAMBOO-KING-TAUPE | H14: No | I14: No | K14: Yes | L14: 1857 | M14: 10 | N14: =IFERROR(M14/L14,0) -> 0.0053850296 | O14: 28.6 | P14: =IFERROR(O14/M14,0) -> 2.86 | Q14: 2 | R14: 165.73 | S14: =IFERROR(O14/R14,0) -> 0.17256984 | T14: =IFERROR(Q14/M14,0) -> 0.2
A15: Bamboo 4pc | B15: 386318421864974 | C15: DBS4-CA-SP-B08KQJ61T7-(PAT)-Targeting-(Ranking)-DO-BAMBOO-QUEEN-OLIVE | D15: Product targeting | E15: Product Targeting | F15: Ranking | G15: BAMBOO-QUEEN-OLIVE | H15: No | I15: No | K15: Yes | L15: 4656 | M15: 8 | N15: =IFERROR(M15/L15,0) -> 0.0017182131 | O15: 18.28 | P15: =IFERROR(O15/M15,0) -> 2.285 | Q15: 2 | R15: 187.98 | S15: =IFERROR(O15/R15,0) -> 0.097244388 | T15: =IFERROR(Q15/M15,0) -> 0.25
A16: Bamboo 4pc | B16: 559320196626290 | C16: DBS4-CA-SP-Bamboo Queen Sheets-[Bamboo|Queen]-(VLSV)-Exact-(Ranking)-DO-BAMBOO-QUEEN-TAUPE | D16: Ranking | E16: Exact | F16: Ranking | G16: BAMBOO-QUEEN-TAUPE | H16: No | I16: No | K16: Yes | L16: 288 | M16: 8 | N16: =IFERROR(M16/L16,0) -> 0.027777778 | O16: 17.89 | P16: =IFERROR(O16/M16,0) -> 2.23625 | Q16: 4 | R16: 360.71 | S16: =IFERROR(O16/R16,0) -> 0.049596629 | T16: =IFERROR(Q16/M16,0) -> 0.5
A17: Bamboo 4pc | B17: 33369664492843 | C17: BAMBOO-QUEEN-OLIVE SP Exact 092822 High Rel 2 JP | D17: Ranking | E17: Exact | F17: Ranking | G17: BAMBOO-QUEEN-OLIVE | H17: No | I17: No | K17: Yes | L17: 379 | M17: 3 | N17: =IFERROR(M17/L17,0) -> 0.0079155673 | O17: 4.88 | P17: =IFERROR(O17/M17,0) -> 1.6266667 | Q17: 0 | R17: 0 | S17: =IFERROR(O17/R17,0) -> 0 | T17: =IFERROR(Q17/M17,0) -> 0
A18: Bamboo 4pc | B18: 375066673206911 | C18: Bamboo Sheets 4 Pcs B08KQHRDDG - bamboo king size bed sheets | D18: Ranking | E18: Exact | F18: Ranking | I18: No | K18: Yes | L18: 370 | M18: 2 | N18: =IFERROR(M18/L18,0) -> 0.0054054054 | O18: 3.82 | P18: =IFERROR(O18/M18,0) -> 1.91 | Q18: 0 | R18: 0 | S18: =IFERROR(O18/R18,0) -> 0 | T18: =IFERROR(Q18/M18,0) -> 0
A19: Bamboo 4pc | B19: 231651601426405 | C19: DEAL CAMPAIGN B4-BROAD | D19: Discovery (keyword) | E19: Broad | F19: Discovery | I19: No | K19: Yes | L19: 11298 | M19: 13 | N19: =IFERROR(M19/L19,0) -> 0.0011506461 | O19: 3.68 | P19: =IFERROR(O19/M19,0) -> 0.28307692 | Q19: 2 | R19: 179.98 | S19: =IFERROR(O19/R19,0) -> 0.020446716 | T19: =IFERROR(Q19/M19,0) -> 0.15384615
A20: Bamboo 4pc | B20: 521448945097660 | C20: DBS4-CA-SP-B07X8FPWJH-(PAT)-Targeting-(Conversion)-DO-BAMBOO-QUEEN-OLIVE | D20: Product targeting | E20: Product Targeting | F20: Conversions | G20: BAMBOO-QUEEN-OLIVE | H20: No | I20: No | K20: Yes | L20: 109 | M20: 2 | N20: =IFERROR(M20/L20,0) -> 0.018348624 | O20: 3.61 | P20: =IFERROR(O20/M20,0) -> 1.805 | Q20: 0 | R20: 0 | S20: =IFERROR(O20/R20,0) -> 0 | T20: =IFERROR(Q20/M20,0) -> 0
A21: Bamboo 4pc | B21: 380485763019154 | C21: DBS4-CA-SP-King Size Bed Sheets Cooling-[Cooling|King]-(VLSV)-Exact-(Ranking)-DO-BAMBOO-KING-TAUPE | D21: Ranking | E21: Exact | F21: Ranking | G21: BAMBOO-KING-TAUPE | H21: No | I21: No | K21: Yes | L21: 2150 | M21: 2 | N21: =IFERROR(M21/L21,0) -> 0.00093023256 | O21: 3.6 | P21: =IFERROR(O21/M21,0) -> 1.8 | Q21: 0 | R21: 0 | S21: =IFERROR(O21/R21,0) -> 0 | T21: =IFERROR(Q21/M21,0) -> 0
A22: Bamboo 4pc | B22: 459704733500591 | C22: Decolure_Automatic_B4_CA_LTSF_1 | D22: LTSF / Clearance | E22: Auto | F22: Liquidation | I22: No | K22: Yes | L22: 1619 | M22: 8 | N22: =IFERROR(M22/L22,0) -> 0.0049413218 | O22: 3.38 | P22: =IFERROR(O22/M22,0) -> 0.4225 | Q22: 0 | R22: 0 | S22: =IFERROR(O22/R22,0) -> 0 | T22: =IFERROR(Q22/M22,0) -> 0
A23: Bamboo 4pc | B23: 427699350598315 | C23: DECOLURE - Bamboo 4 PCS - B08KQHRDDG - double bed sheets bamboo - Exact | D23: Ranking | E23: Exact | F23: Ranking | I23: No | K23: Yes | L23: 45 | M23: 2 | N23: =IFERROR(M23/L23,0) -> 0.044444444 | O23: 3.28 | P23: =IFERROR(O23/M23,0) -> 1.64 | Q23: 0 | R23: 0 | S23: =IFERROR(O23/R23,0) -> 0 | T23: =IFERROR(Q23/M23,0) -> 0
A24: Bamboo 4pc | B24: 440404381964351 | C24: BAMBOO-QUEEN-TAUPE SP EX - TT - 8124 queen sheets bamboo ZB | D24: Ranking | E24: Exact | F24: Ranking | G24: BAMBOO-QUEEN-TAUPE | H24: No | I24: No | K24: Yes | L24: 65 | M24: 1 | N24: =IFERROR(M24/L24,0) -> 0.015384615 | O24: 3.18 | P24: =IFERROR(O24/M24,0) -> 3.18 | Q24: 0 | R24: 0 | S24: =IFERROR(O24/R24,0) -> 0 | T24: =IFERROR(Q24/M24,0) -> 0
A25: Bamboo 4pc | B25: 47529222479606 | C25: DBS4-CA-SP-Queen Bed Sheets Bamboo Cooling-(VLSV)-Exact-(Ranking)-DO-BAMBOO-QUEEN-WHITE | D25: Ranking | E25: Exact | F25: Ranking | G25: BAMBOO-QUEEN-WHITE | H25: Yes | I25: No | K25: Yes | L25: 45 | M25: 2 | N25: =IFERROR(M25/L25,0) -> 0.044444444 | O25: 3.07 | P25: =IFERROR(O25/M25,0) -> 1.535 | Q25: 0 | R25: 0 | S25: =IFERROR(O25/R25,0) -> 0 | T25: =IFERROR(Q25/M25,0) -> 0
A26: Bamboo 4pc | B26: 191172769063677 | C26: DBS4-CA-SP-Bamboo King Size Sheets-[Bamboo|King]-(VLSV)-Exact-(Ranking)-DO-BAMBOO-KING-TAUPE | D26: Ranking | E26: Exact | F26: Ranking | G26: BAMBOO-KING-TAUPE | H26: No | I26: No | K26: Yes | L26: 75 | M26: 2 | N26: =IFERROR(M26/L26,0) -> 0.026666667 | O26: 3.01 | P26: =IFERROR(O26/M26,0) -> 1.505 | Q26: 1 | R26: 99.99 | S26: =IFERROR(O26/R26,0) -> 0.03010301 | T26: =IFERROR(Q26/M26,0) -> 0.5
A27: Bamboo 4pc | B27: 562624252747320 | C27: Decolure_Automatic_B4_CA_LTSF_3 | D27: LTSF / Clearance | E27: Auto | F27: Liquidation | I27: No | K27: Yes | L27: 2208 | M27: 6 | N27: =IFERROR(M27/L27,0) -> 0.0027173913 | O27: 2.66 | P27: =IFERROR(O27/M27,0) -> 0.44333333 | Q27: 1 | R27: 79.99 | S27: =IFERROR(O27/R27,0) -> 0.033254157 | T27: =IFERROR(Q27/M27,0) -> 0.16666667
A28: Bamboo 4pc | B28: 530352029264453 | C28: DBS4-CA-SP-Bamboo Viscose Sheets Queen-[Bamboo|Queen]-(VLSV)-Exact-(Ranking)-DO-BAMBOO-QUEEN-OLIVE | D28: Ranking | E28: Exact | F28: Ranking | G28: BAMBOO-QUEEN-OLIVE | H28: No | I28: No | K28: Yes | L28: 561 | M28: 2 | N28: =IFERROR(M28/L28,0) -> 0.0035650624 | O28: 2.39 | P28: =IFERROR(O28/M28,0) -> 1.195 | Q28: 0 | R28: 0 | S28: =IFERROR(O28/R28,0) -> 0 | T28: =IFERROR(Q28/M28,0) -> 0
A29: Bamboo 4pc | B29: 367014870111009 | C29: Decolure-SP_Exact_PAT_B0D69WR3MW_CA_Bamboo Queen 4 & 6 | D29: Product targeting | E29: Product Targeting | F29: Conquesting | I29: Yes | J29: Bamboo 6pc | K29: Yes | L29: 55 | M29: 1 | N29: =IFERROR(M29/L29,0) -> 0.018181818 | O29: 2.23 | P29: =IFERROR(O29/M29,0) -> 2.23 | Q29: 0 | R29: 0 | S29: =IFERROR(O29/R29,0) -> 0 | T29: =IFERROR(Q29/M29,0) -> 0
A30: Bamboo 4pc | B30: 467706449994759 | C30: Bamboo Sheets 4 Pcs B08KQHRDDG - king sheets bamboo | D30: Ranking | E30: Exact | F30: Ranking | I30: No | K30: Yes | L30: 367 | M30: 1 | N30: =IFERROR(M30/L30,0) -> 0.0027247956 | O30: 1.91 | P30: =IFERROR(O30/M30,0) -> 1.91 | Q30: 0 | R30: 0 | S30: =IFERROR(O30/R30,0) -> 0 | T30: =IFERROR(Q30/M30,0) -> 0
A31: Bamboo 4pc | B31: 251787466967113 | C31: BAMBOO-QUEEN-OLIVE SP Exact 020823 3 JP | D31: Ranking | E31: Exact | F31: Ranking | G31: BAMBOO-QUEEN-OLIVE | H31: No | I31: No | K31: Yes | L31: 24 | M31: 1 | N31: =IFERROR(M31/L31,0) -> 0.041666667 | O31: 1.91 | P31: =IFERROR(O31/M31,0) -> 1.91 | Q31: 0 | R31: 0 | S31: =IFERROR(O31/R31,0) -> 0 | T31: =IFERROR(Q31/M31,0) -> 0
A32: Bamboo 4pc | B32: 132147199158670 | C32: BAMBOO-QUEEN-OLIVE SP Exact 022323 STR 12 JP | D32: Ranking | E32: Exact | F32: Ranking | G32: BAMBOO-QUEEN-OLIVE | H32: No | I32: No | K32: Yes | L32: 69 | M32: 1 | N32: =IFERROR(M32/L32,0) -> 0.014492754 | O32: 1.84 | P32: =IFERROR(O32/M32,0) -> 1.84 | Q32: 0 | R32: 0 | S32: =IFERROR(O32/R32,0) -> 0 | T32: =IFERROR(Q32/M32,0) -> 0
A33: Bamboo 4pc | B33: 555946226950410 | C33: DBS4-CA-SP-Sheets King-(VLSV)-Exact-(Ranking)-DO-BAMBOO-KING-TAUPE | D33: Ranking | E33: Exact | F33: Ranking | G33: BAMBOO-KING-TAUPE | H33: No | I33: No | K33: Yes | L33: 1621 | M33: 1 | N33: =IFERROR(M33/L33,0) -> 0.00061690315 | O33: 1.73 | P33: =IFERROR(O33/M33,0) -> 1.73 | Q33: 1 | R33: 99.99 | S33: =IFERROR(O33/R33,0) -> 0.01730173 | T33: =IFERROR(Q33/M33,0) -> 1
A34: Bamboo 4pc | B34: 532495245231724 | C34: DBS4-CA-SP-King Bed Sheets Cooling-[Cooling|King]-(VLSV)-Exact-(Conversion)-DO-BAMBOO-KING-WHITE | D34: Conversion | E34: Exact | F34: Conversions | G34: BAMBOO-KING-WHITE | H34: Yes | I34: No | K34: Yes | L34: 164 | M34: 1 | N34: =IFERROR(M34/L34,0) -> 0.006097561 | O34: 1.54 | P34: =IFERROR(O34/M34,0) -> 1.54 | Q34: 0 | R34: 0 | S34: =IFERROR(O34/R34,0) -> 0 | T34: =IFERROR(Q34/M34,0) -> 0
A35: Bamboo 4pc | B35: 296656623571415 | C35: DBS4-CA-SP-Bamboo Full Sheets-[Bamboo|Full]-(VLSV)-Exact-(Ranking)-DO-BAMBOO-FULL-OLIVE | D35: Ranking | E35: Exact | F35: Ranking | G35: BAMBOO-FULL-OLIVE | H35: No | I35: No | K35: Yes | L35: 41 | M35: 1 | N35: =IFERROR(M35/L35,0) -> 0.024390244 | O35: 1.45 | P35: =IFERROR(O35/M35,0) -> 1.45 | Q35: 0 | R35: 0 | S35: =IFERROR(O35/R35,0) -> 0 | T35: =IFERROR(Q35/M35,0) -> 0
A36: Bamboo 4pc | B36: 401335870451730 | C36: BAMBOO-QUEEN-OLIVE SP EXACT 1424 5 MA | D36: Ranking | E36: Exact | F36: Ranking | G36: BAMBOO-QUEEN-OLIVE | H36: No | I36: No | K36: Yes | L36: 9 | M36: 1 | N36: =IFERROR(M36/L36,0) -> 0.11111111 | O36: 1.41 | P36: =IFERROR(O36/M36,0) -> 1.41 | Q36: 0 | R36: 0 | S36: =IFERROR(O36/R36,0) -> 0 | T36: =IFERROR(Q36/M36,0) -> 0
A37: Bamboo 4pc | B37: 481721008407608 | C37: Bamboo 4 Pcs B08KQJMZ8Q - drap bambou queen | D37: Ranking | E37: Exact | F37: Ranking | I37: No | K37: Yes | L37: 267 | M37: 1 | N37: =IFERROR(M37/L37,0) -> 0.0037453184 | O37: 1.37 | P37: =IFERROR(O37/M37,0) -> 1.37 | Q37: 0 | R37: 0 | S37: =IFERROR(O37/R37,0) -> 0 | T37: =IFERROR(Q37/M37,0) -> 0
A38: Bamboo 4pc | B38: 184371477344401 | C38: Bamboo Sheets 4 Pcs - B08KQJ3M9N - bed sheets king size - Exact | D38: Ranking | E38: Exact | F38: Ranking | I38: No | K38: Yes | L38: 23 | M38: 3 | N38: =IFERROR(M38/L38,0) -> 0.13043478 | O38: 1.36 | P38: =IFERROR(O38/M38,0) -> 0.45333333 | Q38: 0 | R38: 0 | S38: =IFERROR(O38/R38,0) -> 0 | T38: =IFERROR(Q38/M38,0) -> 0
A39: Bamboo 4pc | B39: 416805838954672 | C39: DBS4-CA-SP-King Bamboo Sheets-[Bamboo|King]-(VLSV)-Exact-(Ranking)-DO-BAMBOO-KING-TAUPE | D39: Ranking | E39: Exact | F39: Ranking | G39: BAMBOO-KING-TAUPE | H39: No | I39: No | K39: Yes | L39: 207 | M39: 1 | N39: =IFERROR(M39/L39,0) -> 0.0048309179 | O39: 1.3 | P39: =IFERROR(O39/M39,0) -> 1.3 | Q39: 0 | R39: 0 | S39: =IFERROR(O39/R39,0) -> 0 | T39: =IFERROR(Q39/M39,0) -> 0
A40: Bamboo 4pc | B40: 394924617015340 | C40: Decolure_Automatic_B4_CA_LTSF_2 | D40: LTSF / Clearance | E40: Auto | F40: Liquidation | I40: No | K40: Yes | L40: 656 | M40: 3 | N40: =IFERROR(M40/L40,0) -> 0.0045731707 | O40: 1.21 | P40: =IFERROR(O40/M40,0) -> 0.40333333 | Q40: 0 | R40: 0 | S40: =IFERROR(O40/R40,0) -> 0 | T40: =IFERROR(Q40/M40,0) -> 0
A41: Bamboo 4pc | B41: 84609523123133 | C41: DBS4-CA-SP-california king bamboo sheets-[Bamboo|California King]-(VLSV)-Broad-(DISC)-DO-BAMBOO-CALIFKING-WHITE | D41: Discovery (keyword) | E41: Broad | G41: BAMBOO-CALIFKING-WHITE | H41: Yes | I41: No | K41: Yes | L41: 37 | M41: 1 | N41: =IFERROR(M41/L41,0) -> 0.027027027 | O41: 1.09 | P41: =IFERROR(O41/M41,0) -> 1.09 | Q41: 1 | R41: 79.99 | S41: =IFERROR(O41/R41,0) -> 0.013626703 | T41: =IFERROR(Q41/M41,0) -> 1
...

Sheet NonHero_Drivers
A1: US - which campaigns carry the biggest non-hero SKUs (Day 1)
A2: Source: Sellerboard PPC, campaigns filtered by SKU text (substring search, so a 4pc search also matches the 6pc SKU of the same colour). Spend shown is the campaign total, not the SKU's share.
A4: Non-hero SKU | B4: SKU SP spend (USD) | C4: Campaign carrying it | D4: Campaign type | E4: Campaign spend (USD) | F4: CPC | G4: ACoS | H4: Comment
A5: BAMBOO-QUEEN-MIDGREY | B5: 78.62 | C5: DBS4-SP-Auto-(AUTO)-Auto-(Discovery)-DO-BAMBOO-FULL-GREY | D5: Auto (multi-colour) | E5: 333.83 | F5: 3.97 | G5: 0.5277 | H5: Only campaign carrying this SKU. 167% of $200 budget used, est. -$153.72.
A6: BAMBOO-QUEEN-OLIVE-6PCS | B6: 244.49 | C6: DBS6-SP-AUTO-(PD-LTSF)-Aged Deal SKUs | D6: LTSF / Clearance | E6: 252.66 | F6: 1.33 | G6: 0.1781 | H6: Intended (aged stock).
C7: DBS6-SP-Auto-(AUTO)-Auto-(Discovery)-DO-BAMBOO-QUEEN-WHITE-6PCS | D7: Auto (multi-colour) | E7: 93.08 | F7: 4.65 | G7: 1.4603 | H7: Named Queen White but also carries Olive. 1 order, est. -$73.32.
C8: DBS6-SP-Viscose Bamboo Sheets-[Bamboo]-(LSV)-Exact-(Ranking)-DO-BAMBOO-QUEEN-WHITE-6PCS | D8: Ranking | E8: 79.08 | F8: 3.3 | G8: 0.413 | H8: Ranking exact named Queen White but carries Olive too.
C9: DBS6-SP-Auto-(AUTO)-Auto-(Discovery)-DO-BAMBOO-QUEEN-WHITE-6PCS-2 | D9: Auto (multi-colour) | E9: 6.65 | F9: 1.11 | G9: 0
C10: DBS6-SP-olive green bamboo sheets-[Bamboo]-(LSV)-Exact-(Ranking)-FIX-BAMBOO-QUEEN-OLIVE-6PCS-TAIL-4 | D10: Ranking (colour keyword) | E10: 6.52 | F10: 3.26 | G10: 0.0493 | H10: Colour keyword - Olive is correct here.
A11: BAMBOO-FULL-OLIVE | B11: 99.72 | C11: DBS4-SP-AUTO-(PD-LTSF)-Aged Deal SKUs | D11: LTSF / Clearance | E11: 501.26 | F11: 1.33 | G11: 0.352 | H11: Intended (aged stock).
C12: DBS6-SP-AUTO-(PD-LTSF)-Aged Deal SKUs | D12: LTSF / Clearance | E12: 252.66 | F12: 1.33 | G12: 0.1781 | H12: Match is the 6pc Full Olive.
C13: DBS6-SP-BROAD-(PD-LTSF) | D13: LTSF / Clearance | E13: 70.16 | F13: 1.4 | G13: 0.3625
C14: DECOLURE - Bamboo 4Pcs- LTSF Campaign | D14: LTSF / Clearance | E14: 37.87 | F14: 2.52 | G14: 0 | H14: 0 orders.
C15: DBS4-SP-Sheets Full Size Bed Bamboo-(VLSV)-Exact-(Ranking)-DO-BAMBOO-FULL-WHITE | D15: Ranking | E15: 8.03 | F15: 4.02 | G15: 0.1452 | H15: Named Full White but carries Full Olive.
A16: BAMBOO-TWIN-LIGHTGREY | B16: 85.44 | C16: DBS4-SP-AUTO-(PD-LTSF)-Aged Deal SKUs | D16: LTSF / Clearance | E16: 501.26 | F16: 1.33 | G16: 0.352 | H16: Intended (aged stock).
C17: DBS6-SP-LTSF-ALL-Broad-(Clearance)-DO-AGED-ALL | D17: LTSF / Clearance | E17: 15.9 | F17: 1.06 | G17: 0.1988
A18: BAMBOO-FULL-PURPLE | B18: 69.9 | C18: DBS4-SP-AUTO-(PD-LTSF)-Aged Deal SKUs | D18: LTSF / Clearance | E18: 501.26 | F18: 1.33 | G18: 0.352
C19: DBS6-SP-AUTO-(PD-LTSF)-Aged Deal SKUs | D19: LTSF / Clearance | E19: 252.66 | F19: 1.33 | G19: 0.1781
C20: Decolure_SP_Exact_PAT_Defensive | D20: Product targeting (defensive) | E20: 34.47 | F20: 0.78 | G20: 0.0826
C21: DECOLURE - B4 - QUEEN OLIVE - PRIME CAMPAIGN 2 (LTSF) | D21: LTSF / Clearance | E21: 8.53 | F21: 0.85 | G21: 0 | H21: 0 orders.
C22: DBS4-SP-Purple Bamboo Sheets-(VLSV)-Exact-(Ranking)-DO-BAMBOO-QUEEN-PURPLE | D22: Ranking (colour keyword) | E22: 5.74 | F22: 1.44 | G22: 0 | H22: Colour keyword.
A23: BAMBOO-TWIN-NAVYBLUE | B23: 62.82 | C23: DBS4-SP-Auto-(AUTO)-Auto-(Discovery)-DO-BAMBOO-FULL-GREY | D23: Auto (multi-colour) | E23: 333.83 | F23: 3.97 | G23: 0.5277 | H23: Same loss-making auto.
C24: DBS6-SP-AUTO-(PD-LTSF)-Aged Deal SKUs | D24: LTSF / Clearance | E24: 252.66 | F24: 1.33 | G24: 0.1781
C25: DBS4-SP-Twin Bamboo Bed Sheets-[Bamboo|Twin]-(HSV)-Exact-(Ranking)-DO-BAMBOO-TWIN-BURGUNDY-NEW | D25: Ranking | E25: 13.35 | F25: 6.68 | G25: 0.289 | H25: $5 budget, 267% used.
C26: DBS4-SP-Bamboo Twin Sheets Set-[Bamboo|Twin]-(MSV)-Exact-(Ranking)-DO-BAMBOO-TWIN-BURGUNDY-NEW | D26: Ranking | E26: 10.12 | F26: 10.12 | G26: 0 | H26: $5 budget, 202% used, 0 orders.
C27: DBS4-SP-Twin Sheets Set Bamboo-[Bamboo|Twin]-(MSV)-Exact-(Ranking)-DO-BAMBOO-TWIN-BURGUNDY-NEW | D27: Ranking | E27: 9.55 | F27: 4.78 | G27: 0 | H27: $5 budget, 191% used, 0 orders.
C28: DBS4-SP-Bamboo Sheets Twin Size-[Bamboo|Twin]-(MSV)-Exact-(Ranking)-DO-BAMBOO-TWIN-BURGUNDY-NEW | D28: Ranking | E28: 7.13 | F28: 7.13 | G28: 0 | H28: $5 budget, 143% used, 0 orders.
A29: SATIN-4PC-KING-GREY | B29: 126.2 | C29: DBS4-SP-BROAD-(PD-LTSF) | D29: LTSF / Clearance | E29: 151.25 | F29: 1.21 | G29: 0.3427 | H29: BAMBOO-named LTSF broad carrying Satin SKUs. Est. -$203.80.
C30: DSS4-SP-King Size Silk Sheets-[Silk|King]-(LSV)-Exact-(Ranking)-DO-SATIN-4PC-KING-GREY | D30: Ranking | E30: 27.7 | F30: 3.96 | G30: 0.8159 | H30: 121% of budget.
C31: DSS4-SP-Satin Sheets King Size-[Satin|King]-(LSV)-Exact-(Ranking)-DO-SATIN-4PC-KING-GREY | D31: Ranking | E31: 24.72 | F31: 2.47 | G31: 0.3641
C32: DSS4-SP-king size satin sheets set-[Satin|King]-(LSV)-Exact-(Conversion)-DO-SATIN-4PC-KING-GREY-TEST | D32: Conversion | E32: 8.78 | F32: 2.2 | G32: 0.1293
C33: DSS4-SP-King Sheets Silk-[Silk|King]-(LSV)-Exact-(Ranking)-DO-SATIN-4PC-KING-GREY | D33: Ranking | E33: 7.81 | F33: 1.95 | G33: 0
C34: 7 more King Grey exacts (Sateen/Satin/Silk king terms) | D34: Ranking / Conversion | E34: 20.73 | H34: Small campaigns, $0.83-$5.20 each.

