Workbook
Name Products_US: Lists!$A$1:$A$28
Name Products_CA: Lists!$B$1:$B$7
Name Brands: Lists!$C$1:$C$246
Name Tiers: Lists!$D$1:$D$5
Name Families: Lists!$E$1:$E$6
Name Types: Lists!$F$1:$F$6

Sheet README
A1: BFCM 2026 Competitor Research
A2: Owner: Shayan Rana · Prepared for: Erik Fisher & Joseph Fisher · Backup: Zarlish · Final for Thu Oct 15, 2026 · Data as of Oct 13-15, 2026
A4: How to use it
A5: 1. US Dashboard and CA Dashboard - pick a product in the yellow cell (brand, tier and family narrow the competitors). Our product panel, stock tiles, competitor tiles and the competitor gallery update. 'Open the product tab' jumps to the full analysis.
A6: 2. Product Index - every product in both marketplaces with its image, variations and BFCM 2025 result; click a tab name to open it.
A7: 3. BFCM Stock - every variation: stock at Amazon, inbound, sales a day, units needed to Nov 30, run-out date with and without inbound, and status. Filter by product or status.
A8: 4. Product tabs - US tabs (blue) then CA tabs (orange), 33 in all. Each has: 1 Our product (plan, assumed deal prices, stock outlook, deal pricing notes) · 2 Our variations · 3 Our BFCM 2025 result · 4 Competitor landscape.
A9: 5. Data Check - the as-of date, coverage and verification result of every data set; Data Gaps - what is still missing.
A11: Key rules
A12: Our price = the latest catalog price read (US Oct 13, CA Oct 14); a variation without one shows no price.
A13: Assumed BFCM 2026 deal price, until final prices are set: 15% off today's price on Nov 19-26 and 20% off on Nov 27-30 (Black Friday to Cyber Monday). Amazon sets the reference price the day before the deal and can use a lower reference, which would lower the deal price.
A14: BFCM 2026 stock: demand at today's pace to Nov 18, then x the product's BFCM 2025 lift for Nov 19-30 (the account's lift where the product's own is missing or unreliable, labelled ASSUMED). Inbound has no arrival date, so each variation shows its run-out date with and without inbound.
... A17: Estimated weekly units and sales bands for competitors are estimates - use them to rank competitors, not as exact sales.

Sheet US Dashboard
B1: BFCM 2026 Tracker · Amazon.com (US) | AA1: All | AB1: All | AC1: All | AD1: All | AE1: All
B2: Pick a product in the yellow cell. Competitor type (Direct = same product and material as ours), brand, tier and family narrow the competitor list. Everything below updates instantly. | AA2: DC B4 | AB2: 100% Blackout Shield | AC2: Aspirational | AD2: Bamboo | AE2: Direct
B3: Owner: Shayan Rana · Prepared for: Erik Fisher & Joseph Fisher · Data as of Oct 13-15, 2026 | AA3: DC B6 | AB3: ACCURATEX | AC3: Beatable | AD3: Satin | AE3: Alternative material
B4: Product | C4: DC B4 | D4: ▼ pick from the list | E4: =IF($C$4="All","",IFERROR(_xlfn.IMAGE(IFERROR(INDEX(Lookup!$A$2:$Y$34,MATCH("US|"&$C$4,Lookup!$A$2:$A$34,0),5),"")),"IMAGE COMING SOON")) | F4: Our product | G4: =IF($C$4="All","All products",IFERROR(INDEX(Lookup!$A$2:$Y$34,MATCH("US|"&$C$4,Lookup!$A$2:$A$34,0),4),"")) | L4: STOCK AT AMAZON | N4: INBOUND | P4: UNITS NEEDED TO NOV 30 | R4: VARIATIONS SHORT / OUT OF STOCK | AA4: SL B6 | AB4: Adubor | AC4: Poor | AD4: Silk | AE4: Material not verified
B5: Brand | C5: All | D5: ▼ pick from the list | F5: Brand · parent ASIN | G5: =IF($C$4="All","",IFERROR(INDEX(Lookup!$A$2:$Y$34,MATCH("US|"&$C$4,Lookup!$A$2:$A$34,0),6),"")&" · "&IFERROR(INDEX(Lookup!$A$2:$Y$34,MATCH("US|"&$C$4,Lookup!$A$2:$A$34,0),7),"")) | L5: =IF($C$4="All","",IFERROR(INDEX(Lookup!$A$2:$Y$34,MATCH("US|"&$C$4,Lookup!$A$2:$A$34,0),16),"")) | N5: =IF($C$4="All","",IFERROR(INDEX(Lookup!$A$2:$Y$34,MATCH("US|"&$C$4,Lookup!$A$2:$A$34,0),17),"")) | P5: =IF($C$4="All","",IFERROR(INDEX(Lookup!$A$2:$Y$34,MATCH("US|"&$C$4,Lookup!$A$2:$A$34,0),18),"")) | R5: =IF($C$4="All","",IFERROR(INDEX(Lookup!$A$2:$Y$34,MATCH("US|"&$C$4,Lookup!$A$2:$A$34,0),22),"")&" / "&IFERROR(INDEX(Lookup!$A$2:$Y$34,MATCH("US|"&$C$4,Lookup!$A$2:$A$34,0),23),"")) | AA5: SL B4 | AB5: AiAngu | AC5: Untiered | AD5: Cooling | AE5: Different product type
B6: Tier | C6: All | D6: ▼ pick from the list | F6: Our price (best child) | G6: =IF($C$4="All","",IFERROR(INDEX(Lookup!$A$2:$Y$34,MATCH("US|"&$C$4,Lookup!$A$2:$A$34,0),10),"")) | AA6: DC Bamboo Fitted | AB6: akkialla | AD6: Other | AE6: Not classified
B7: Family | C7: All | D7: ▼ pick from the list | F7: Units, last 28 days | G7: =IF($C$4="All","",IFERROR(INDEX(Lookup!$A$2:$Y$34,MATCH("US|"&$C$4,Lookup!$A$2:$A$34,0),11),"")) | L7: COMPETITORS SHOWN | N7: MEDIAN COMPETITOR PRICE | P7: PRICED BELOW US | R7: AVG BFCM 2025 DISCOUNT | AA7: SL Bamboo Pillowcase | AB7: ALASKA BEAR
B8: Competitor type | C8: All | D8: ▼ pick from the list | F8: BFCM 2026 plan | G8: =IF($C$4="All","",IFERROR(INDEX(Lookup!$A$2:$Y$34,MATCH("US|"&$C$4,Lookup!$A$2:$A$34,0),13),"")) | L8: =COUNTIF(Data!$A$2:$A$745,TRUE) | N8: {=IFERROR(MEDIAN(IF((Data!$A$2:$A$745=TRUE)*ISNUMBER(Data!$N$2:$N$745),Data!$N$2:$N$745)),"")} | P8: =COUNTIFS(Data!$A$2:$A$745,TRUE,Data!$R$2:$R$745,"<0") | R8: =IFERROR(AVERAGEIFS(Data!$AD$2:$AD$745,Data!$A$2:$A$745,TRUE),"") | AA8: DC S4 | AB8: Amazon Basics
B9: → CA Dashboard | F9: Assumed deal price (15% / 20%) | G9: =IF(OR($C$4="All",IFERROR(INDEX(Lookup!$A$2:$Y$34,MATCH("US|"&$C$4,Lookup!$A$2:$A$34,0),14),"")=""),"No deal planned",TEXT(IFERROR(INDEX(Lookup!$A$2:$Y$34,MATCH("US|"&$C$4,Lookup!$A$2:$A$34,0),14),""),"$0.00")&" (Nov 19-26) · "&TEXT(IFERROR(INDEX(Lookup!$A$2:$Y$34,MATCH("US|"&$C$4,Lookup!$A$2:$A$34,0),15),""),"$0.00")&" (Nov 27-30)") | AA9: DC S6 | AB9: Andency
B10: → BFCM Stock | F10: BFCM 2025 sales lift | G10: =IF($C$4="All","",IFERROR(INDEX(Lookup!$A$2:$Y$34,MATCH("US|"&$C$4,Lookup!$A$2:$A$34,0),12),"")) | AA10: SSS4 | AB10: Anibedding
F11: Open the product tab: | G11: =IF($C$4="All","",HYPERLINK("#'"&IFERROR(INDEX(Lookup!$A$2:$Y$34,MATCH("US|"&$C$4,Lookup!$A$2:$A$34,0),3),"")&"'!A1",IFERROR(INDEX(Lookup!$A$2:$Y$34,MATCH("US|"&$C$4,Lookup!$A$2:$A$34,0),3),""))) | AA11: SL Satin 6pc | AB11: Artrello
AA12: DC Satin Fitted | AB12: ATreebay
B13: COMPETITORS (first 80 matches, in tier then weekly-units order) | AA13: DC Silk Pillowcase | AB13: Avolare
B14: # | C14: Image | D14: Brand · Tier | E14: Title | F14: Competitor type | G14: Size · colour | H14: Price | I14: List Price | J14: List % over | K14: vs our price | L14: BSR | M14: Wk units | N14: Rating | O14: Reviews | P14: Variations | Q14: BFCM 2025 discount | R14: ASIN | AA14: SL Mask Contoured | AB14: Back Bay Audio
B15: =IF(1<=COUNTIF(Data!$A$2:$A$745,TRUE),1,"") | C15: =IF(B15="","",IFERROR(_xlfn.IMAGE(IFERROR(IF(INDEX(Data!$J$2:$J$745,MATCH(1,Data!$B$2:$B$745,0))="","",INDEX(Data!$J$2:$J$745,MATCH(1,Data!$B$2:$B$745,0))),"")),"IMAGE COMING SOON")) | D15: =IF(B15="","",IFERROR(IF(INDEX(Data!$G$2:$G$745,MATCH(1,Data!$B$2:$B$745,0))="","",INDEX(Data!$G$2:$G$745,MATCH(1,Data!$B$2:$B$745,0))),"")&CHAR(10)&IFERROR(IF(INDEX(Data!$H$2:$H$745,MATCH(1,Data!$B$2:$B$745,0))="","",INDEX(Data!$H$2:$H$745,MATCH(1,Data!$B$2:$B$745,0))),"")) | E15: =IF(B15="","",IFERROR(IF(INDEX(Data!$I$2:$I$745,MATCH(1,Data!$B$2:$B$745,0))="","",INDEX(Data!$I$2:$I$745,MATCH(1,Data!$B$2:$B$745,0))),"")) | F15: =IF(B15="","",IFERROR(IF(INDEX(Data!$AJ$2:$AJ$745,MATCH(1,Data!$B$2:$B$745,0))="","",INDEX(Data!$AJ$2:$AJ$745,MATCH(1,Data!$B$2:$B$745,0))),"")) | G15: =IF(B15="","",TRIM(IFERROR(IF(INDEX(Data!$AF$2:$AF$745,MATCH(1,Data!$B$2:$B$745,0))="","",INDEX(Data!$AF$2:$AF$745,MATCH(1,Data!$B$2:$B$745,0))),"")&" "&IFERROR(IF(INDEX(Data!$AG$2:$AG$745,MATCH(1,Data!$B$2:$B$745,0))="","",INDEX(Data!$AG$2:$AG$745,MATCH(1,Data!$B$2:$B$745,0))),""))) | H15: =IF(B15="","",IFERROR(IF(INDEX(Data!$N$2:$N$745,MATCH(1,Data!$B$2:$B$745,0))="","",INDEX(Data!$N$2:$N$745,MATCH(1,Data!$B$2:$B$745,0))),"")) | I15: =IF(B15="","",IFERROR(IF(INDEX(Data!$O$2:$O$745,MATCH(1,Data!$B$2:$B$745,0))="","",INDEX(Data!$O$2:$O$745,MATCH(1,Data!$B$2:$B$745,0))),"")) | J15: =IF(B15="","",IFERROR(IF(INDEX(Data!$P$2:$P$745,MATCH(1,Data!$B$2:$B$745,0))="","",INDEX(Data!$P$2:$P$745,MATCH(1,Data!$B$2:$B$745,0))),"")) | K15: =IF(B15="","",IFERROR(IF(INDEX(Data!$R$2:$R$745,MATCH(1,Data!$B$2:$B$745,0))="","",INDEX(Data!$R$2:$R$745,MATCH(1,Data!$B$2:$B$745,0))),"")) | L15: =IF(B15="","",IFERROR(IF(INDEX(Data!$S$2:$S$745,MATCH(1,Data!$B$2:$B$745,0))="","",INDEX(Data!$S$2:$S$745,MATCH(1,Data!$B$2:$B$745,0))),"")) | M15: =IF(B15="","",IFERROR(IF(INDEX(Data!$T$2:$T$745,MATCH(1,Data!$B$2:$B$745,0))="","",INDEX(Data!$T$2:$T$745,MATCH(1,Data!$B$2:$B$745,0))),"")) | N15: =IF(B15="","",IFERROR(IF(INDEX(Data!$U$2:$U$745,MATCH(1,Data!$B$2:$B$745,0))="","",INDEX(Data!$U$2:$U$745,MATCH(1,Data!$B$2:$B$745,0))),"")) | O15: =IF(B15="","",IFERROR(IF(INDEX(Data!$V$2:$V$745,MATCH(1,Data!$B$2:$B$745,0))="","",INDEX(Data!$V$2:$V$745,MATCH(1,Data!$B$2:$B$745,0))),"")) | P15: =IF(B15="","",IFERROR(IF(INDEX(Data!$M$2:$M$745,MATCH(1,Data!$B$2:$B$745,0))="","",INDEX(Data!$M$2:$M$745,MATCH(1,Data!$B$2:$B$745,0))),"")) | Q15: =IF(B15="","",IFERROR(IF(INDEX(Data!$AD$2:$AD$745,MATCH(1,Data!$B$2:$B$745,0))="","",INDEX(Data!$AD$2:$AD$745,MATCH(1,Data!$B$2:$B$745,0))),"")) | R15: =IF(B15="","",IFERROR(IF(INDEX(Data!$L$2:$L$745,MATCH(1,Data!$B$2:$B$745,0))="","",INDEX(Data!$L$2:$L$745,MATCH(1,Data!$B$2:$B$745,0))),"")) | AA15: SL Mask Velcro | AB15: Bambaw
B16: =IF(2<=COUNTIF(Data!$A$2:$A$745,TRUE),2,"") | C16: =IF(B16="","",IFERROR(_xlfn.IMAGE(IFERROR(IF(INDEX(Data!$J$2:$J$745,MATCH(2,Data!$B$2:$B$745,0))="","",INDEX(Data!$J$2:$J$745,MATCH(2,Data!$B$2:$B$745,0))),"")),"IMAGE COMING SOON")) | D16: =IF(B16="","",IFERROR(IF(INDEX(Data!$G$2:$G$745,MATCH(2,Data!$B$2:$B$745,0))="","",INDEX(Data!$G$2:$G$745,MATCH(2,Data!$B$2:$B$745,0))),"")&CHAR(10)&IFERROR(IF(INDEX(Data!$H$2:$H$745,MATCH(2,Data!$B$2:$B$745,0))="","",INDEX(Data!$H$2:$H$745,MATCH(2,Data!$B$2:$B$745,0))),"")) | E16: =IF(B16="","",IFERROR(IF(INDEX(Data!$I$2:$I$745,MATCH(2,Data!$B$2:$B$745,0))="","",INDEX(Data!$I$2:$I$745,MATCH(2,Data!$B$2:$B$745,0))),"")) | F16: =IF(B16="","",IFERROR(IF(INDEX(Data!$AJ$2:$AJ$745,MATCH(2,Data!$B$2:$B$745,0))="","",INDEX(Data!$AJ$2:$AJ$745,MATCH(2,Data!$B$2:$B$745,0))),"")) | G16: =IF(B16="","",TRIM(IFERROR(IF(INDEX(Data!$AF$2:$AF$745,MATCH(2,Data!$B$2:$B$745,0))="","",INDEX(Data!$AF$2:$AF$745,MATCH(2,Data!$B$2:$B$745,0))),"")&" "&IFERROR(IF(INDEX(Data!$AG$2:$AG$745,MATCH(2,Data!$B$2:$B$745,0))="","",INDEX(Data!$AG$2:$AG$745,MATCH(2,Data!$B$2:$B$745,0))),""))) | H16: =IF(B16="","",IFERROR(IF(INDEX(Data!$N$2:$N$745,MATCH(2,Data!$B$2:$B$745,0))="","",INDEX(Data!$N$2:$N$745,MATCH(2,Data!$B$2:$B$745,0))),"")) | I16: =IF(B16="","",IFERROR(IF(INDEX(Data!$O$2:$O$745,MATCH(2,Data!$B$2:$B$745,0))="","",INDEX(Data!$O$2:$O$745,MATCH(2,Data!$B$2:$B$745,0))),"")) | J16: =IF(B16="","",IFERROR(IF(INDEX(Data!$P$2:$P$745,MATCH(2,Data!$B$2:$B$745,0))="","",INDEX(Data!$P$2:$P$745,MATCH(2,Data!$B$2:$B$745,0))),"")) | K16: =IF(B16="","",IFERROR(IF(INDEX(Data!$R$2:$R$745,MATCH(2,Data!$B$2:$B$745,0))="","",INDEX(Data!$R$2:$R$745,MATCH(2,Data!$B$2:$B$745,0))),"")) | L16: =IF(B16="","",IFERROR(IF(INDEX(Data!$S$2:$S$745,MATCH(2,Data!$B$2:$B$745,0))="","",INDEX(Data!$S$2:$S$745,MATCH(2,Data!$B$2:$B$745,0))),"")) | M16: =IF(B16="","",IFERROR(IF(INDEX(Data!$T$2:$T$745,MATCH(2,Data!$B$2:$B$745,0))="","",INDEX(Data!$T$2:$T$745,MATCH(2,Data!$B$2:$B$745,0))),"")) | N16: =IF(B16="","",IFERROR(IF(INDEX(Data!$U$2:$U$745,MATCH(2,Data!$B$2:$B$745,0))="","",INDEX(Data!$U$2:$U$745,MATCH(2,Data!$B$2:$B$745,0))),"")) | O16: =IF(B16="","",IFERROR(IF(INDEX(Data!$V$2:$V$745,MATCH(2,Data!$B$2:$B$745,0))="","",INDEX(Data!$V$2:$V$745,MATCH(2,Data!$B$2:$B$745,0))),"")) | P16: =IF(B16="","",IFERROR(IF(INDEX(Data!$M$2:$M$745,MATCH(2,Data!$B$2:$B$745,0))="","",INDEX(Data!$M$2:$M$745,MATCH(2,Data!$B$2:$B$745,0))),"")) | Q16: =IF(B16="","",IFERROR(IF(INDEX(Data!$AD$2:$AD$745,MATCH(2,Data!$B$2:$B$745,0))="","",INDEX(Data!$AD$2:$AD$745,MATCH(2,Data!$B$2:$B$745,0))),"")) | R16: =IF(B16="","",IFERROR(IF(INDEX(Data!$L$2:$L$745,MATCH(2,Data!$B$2:$B$745,0))="","",INDEX(Data!$L$2:$L$745,MATCH(2,Data!$B$2:$B$745,0))),"")) | AA16: DC Cooling 4pc | AB16: Bamboo Bay
B17: =IF(3<=COUNTIF(Data!$A$2:$A$745,TRUE),3,"") | C17: =IF(B17="","",IFERROR(_xlfn.IMAGE(IFERROR(IF(INDEX(Data!$J$2:$J$745,MATCH(3,Data!$B$2:$B$745,0))="","",INDEX(Data!$J$2:$J$745,MATCH(3,Data!$B$2:$B$745,0))),"")),"IMAGE COMING SOON")) | D17: =IF(B17="","",IFERROR(IF(INDEX(Data!$G$2:$G$745,MATCH(3,Data!$B$2:$B$745,0))="","",INDEX(Data!$G$2:$G$745,MATCH(3,Data!$B$2:$B$745,0))),"")&CHAR(10)&IFERROR(IF(INDEX(Data!$H$2:$H$745,MATCH(3,Data!$B$2:$B$745,0))="","",INDEX(Data!$H$2:$H$745,MATCH(3,Data!$B$2:$B$745,0))),"")) | E17: =IF(B17="","",IFERROR(IF(INDEX(Data!$I$2:$I$745,MATCH(3,Data!$B$2:$B$745,0))="","",INDEX(Data!$I$2:$I$745,MATCH(3,Data!$B$2:$B$745,0))),"")) | F17: =IF(B17="","",IFERROR(IF(INDEX(Data!$AJ$2:$AJ$745,MATCH(3,Data!$B$2:$B$745,0))="","",INDEX(Data!$AJ$2:$AJ$745,MATCH(3,Data!$B$2:$B$745,0))),"")) | G17: =IF(B17="","",TRIM(IFERROR(IF(INDEX(Data!$AF$2:$AF$745,MATCH(3,Data!$B$2:$B$745,0))="","",INDEX(Data!$AF$2:$AF$745,MATCH(3,Data!$B$2:$B$745,0))),"")&" "&IFERROR(IF(INDEX(Data!$AG$2:$AG$745,MATCH(3,Data!$B$2:$B$745,0))="","",INDEX(Data!$AG$2:$AG$745,MATCH(3,Data!$B$2:$B$745,0))),""))) | H17: =IF(B17="","",IFERROR(IF(INDEX(Data!$N$2:$N$745,MATCH(3,Data!$B$2:$B$745,0))="","",INDEX(Data!$N$2:$N$745,MATCH(3,Data!$B$2:$B$745,0))),"")) | I17: =IF(B17="","",IFERROR(IF(INDEX(Data!$O$2:$O$745,MATCH(3,Data!$B$2:$B$745,0))="","",INDEX(Data!$O$2:$O$745,MATCH(3,Data!$B$2:$B$745,0))),"")) | J17: =IF(B17="","",IFERROR(IF(INDEX(Data!$P$2:$P$745,MATCH(3,Data!$B$2:$B$745,0))="","",INDEX(Data!$P$2:$P$745,MATCH(3,Data!$B$2:$B$745,0))),"")) | K17: =IF(B17="","",IFERROR(IF(INDEX(Data!$R$2:$R$745,MATCH(3,Data!$B$2:$B$745,0))="","",INDEX(Data!$R$2:$R$745,MATCH(3,Data!$B$2:$B$745,0))),"")) | L17: =IF(B17="","",IFERROR(IF(INDEX(Data!$S$2:$S$745,MATCH(3,Data!$B$2:$B$745,0))="","",INDEX(Data!$S$2:$S$745,MATCH(3,Data!$B$2:$B$745,0))),"")) | M17: =IF(B17="","",IFERROR(IF(INDEX(Data!$T$2:$T$745,MATCH(3,Data!$B$2:$B$745,0))="","",INDEX(Data!$T$2:$T$745,MATCH(3,Data!$B$2:$B$745,0))),"")) | N17: =IF(B17="","",IFERROR(IF(INDEX(Data!$U$2:$U$745,MATCH(3,Data!$B$2:$B$745,0))="","",INDEX(Data!$U$2:$U$745,MATCH(3,Data!$B$2:$B$745,0))),"")) | O17: =IF(B17="","",IFERROR(IF(INDEX(Data!$V$2:$V$745,MATCH(3,Data!$B$2:$B$745,0))="","",INDEX(Data!$V$2:$V$745,MATCH(3,Data!$B$2:$B$745,0))),"")) | P17: =IF(B17="","",IFERROR(IF(INDEX(Data!$M$2:$M$745,MATCH(3,Data!$B$2:$B$745,0))="","",INDEX(Data!$M$2:$M$745,MATCH(3,Data!$B$2:$B$745,0))),"")) | Q17: =IF(B17="","",IFERROR(IF(INDEX(Data!$AD$2:$AD$745,MATCH(3,Data!$B$2:$B$745,0))="","",INDEX(Data!$AD$2:$AD$745,MATCH(3,Data!$B$2:$B$745,0))),"")) | R17: =IF(B17="","",IFERROR(IF(INDEX(Data!$L$2:$L$745,MATCH(3,Data!$B$2:$B$745,0))="","",INDEX(Data!$L$2:$L$745,MATCH(3,Data!$B$2:$B$745,0))),"")) | AA17: SL Cooling 4pc | AB17: BAMPURE
B18: =IF(4<=COUNTIF(Data!$A$2:$A$745,TRUE),4,"") | C18: =IF(B18="","",IFERROR(_xlfn.IMAGE(IFERROR(IF(INDEX(Data!$J$2:$J$745,MATCH(4,Data!$B$2:$B$745,0))="","",INDEX(Data!$J$2:$J$745,MATCH(4,Data!$B$2:$B$745,0))),"")),"IMAGE COMING SOON")) | D18: =IF(B18="","",IFERROR(IF(INDEX(Data!$G$2:$G$745,MATCH(4,Data!$B$2:$B$745,0))="","",INDEX(Data!$G$2:$G$745,MATCH(4,Data!$B$2:$B$745,0))),"")&CHAR(10)&IFERROR(IF(INDEX(Data!$H$2:$H$745,MATCH(4,Data!$B$2:$B$745,0))="","",INDEX(Data!$H$2:$H$745,MATCH(4,Data!$B$2:$B$745,0))),"")) | E18: =IF(B18="","",IFERROR(IF(INDEX(Data!$I$2:$I$745,MATCH(4,Data!$B$2:$B$745,0))="","",INDEX(Data!$I$2:$I$745,MATCH(4,Data!$B$2:$B$745,0))),"")) | F18: =IF(B18="","",IFERROR(IF(INDEX(Data!$AJ$2:$AJ$745,MATCH(4,Data!$B$2:$B$745,0))="","",INDEX(Data!$AJ$2:$AJ$745,MATCH(4,Data!$B$2:$B$745,0))),"")) | G18: =IF(B18="","",TRIM(IFERROR(IF(INDEX(Data!$AF$2:$AF$745,MATCH(4,Data!$B$2:$B$745,0))="","",INDEX(Data!$AF$2:$AF$745,MATCH(4,Data!$B$2:$B$745,0))),"")&" "&IFERROR(IF(INDEX(Data!$AG$2:$AG$745,MATCH(4,Data!$B$2:$B$745,0))="","",INDEX(Data!$AG$2:$AG$745,MATCH(4,Data!$B$2:$B$745,0))),""))) | H18: =IF(B18="","",IFERROR(IF(INDEX(Data!$N$2:$N$745,MATCH(4,Data!$B$2:$B$745,0))="","",INDEX(Data!$N$2:$N$745,MATCH(4,Data!$B$2:$B$745,0))),"")) | I18: =IF(B18="","",IFERROR(IF(INDEX(Data!$O$2:$O$745,MATCH(4,Data!$B$2:$B$745,0))="","",INDEX(Data!$O$2:$O$745,MATCH(4,Data!$B$2:$B$745,0))),"")) | J18: =IF(B18="","",IFERROR(IF(INDEX(Data!$P$2:$P$745,MATCH(4,Data!$B$2:$B$745,0))="","",INDEX(Data!$P$2:$P$745,MATCH(4,Data!$B$2:$B$745,0))),"")) | K18: =IF(B18="","",IFERROR(IF(INDEX(Data!$R$2:$R$745,MATCH(4,Data!$B$2:$B$745,0))="","",INDEX(Data!$R$2:$R$745,MATCH(4,Data!$B$2:$B$745,0))),"")) | L18: =IF(B18="","",IFERROR(IF(INDEX(Data!$S$2:$S$745,MATCH(4,Data!$B$2:$B$745,0))="","",INDEX(Data!$S$2:$S$745,MATCH(4,Data!$B$2:$B$745,0))),"")) | M18: =IF(B18="","",IFERROR(IF(INDEX(Data!$T$2:$T$745,MATCH(4,Data!$B$2:$B$745,0))="","",INDEX(Data!$T$2:$T$745,MATCH(4,Data!$B$2:$B$745,0))),"")) | N18: =IF(B18="","",IFERROR(IF(INDEX(Data!$U$2:$U$745,MATCH(4,Data!$B$2:$B$745,0))="","",INDEX(Data!$U$2:$U$745,MATCH(4,Data!$B$2:$B$745,0))),"")) | O18: =IF(B18="","",IFERROR(IF(INDEX(Data!$V$2:$V$745,MATCH(4,Data!$B$2:$B$745,0))="","",INDEX(Data!$V$2:$V$745,MATCH(4,Data!$B$2:$B$745,0))),"")) | P18: =IF(B18="","",IFERROR(IF(INDEX(Data!$M$2:$M$745,MATCH(4,Data!$B$2:$B$745,0))="","",INDEX(Data!$M$2:$M$745,MATCH(4,Data!$B$2:$B$745,0))),"")) | Q18: =IF(B18="","",IFERROR(IF(INDEX(Data!$AD$2:$AD$745,MATCH(4,Data!$B$2:$B$745,0))="","",INDEX(Data!$AD$2:$AD$745,MATCH(4,Data!$B$2:$B$745,0))),"")) | R18: =IF(B18="","",IFERROR(IF(INDEX(Data!$L$2:$L$745,MATCH(4,Data!$B$2:$B$745,0))="","",INDEX(Data!$L$2:$L$745,MATCH(4,Data!$B$2:$B$745,0))),"")) | AA18: SL Cooling 6pc | AB18: Bamtek
B19: =IF(5<=COUNTIF(Data!$A$2:$A$745,TRUE),5,"") | C19: =IF(B19="","",IFERROR(_xlfn.IMAGE(IFERROR(IF(INDEX(Data!$J$2:$J$745,MATCH(5,Data!$B$2:$B$745,0))="","",INDEX(Data!$J$2:$J$745,MATCH(5,Data!$B$2:$B$745,0))),"")),"IMAGE COMING SOON")) | D19: =IF(B19="","",IFERROR(IF(INDEX(Data!$G$2:$G$745,MATCH(5,Data!$B$2:$B$745,0))="","",INDEX(Data!$G$2:$G$745,MATCH(5,Data!$B$2:$B$745,0))),"")&CHAR(10)&IFERROR(IF(INDEX(Data!$H$2:$H$745,MATCH(5,Data!$B$2:$B$745,0))="","",INDEX(Data!$H$2:$H$745,MATCH(5,Data!$B$2:$B$745,0))),"")) | E19: =IF(B19="","",IFERROR(IF(INDEX(Data!$I$2:$I$745,MATCH(5,Data!$B$2:$B$745,0))="","",INDEX(Data!$I$2:$I$745,MATCH(5,Data!$B$2:$B$745,0))),"")) | F19: =IF(B19="","",IFERROR(IF(INDEX(Data!$AJ$2:$AJ$745,MATCH(5,Data!$B$2:$B$745,0))="","",INDEX(Data!$AJ$2:$AJ$745,MATCH(5,Data!$B$2:$B$745,0))),"")) | G19: =IF(B19="","",TRIM(IFERROR(IF(INDEX(Data!$AF$2:$AF$745,MATCH(5,Data!$B$2:$B$745,0))="","",INDEX(Data!$AF$2:$AF$745,MATCH(5,Data!$B$2:$B$745,0))),"")&" "&IFERROR(IF(INDEX(Data!$AG$2:$AG$745,MATCH(5,Data!$B$2:$B$745,0))="","",INDEX(Data!$AG$2:$AG$745,MATCH(5,Data!$B$2:$B$745,0))),""))) | H19: =IF(B19="","",IFERROR(IF(INDEX(Data!$N$2:$N$745,MATCH(5,Data!$B$2:$B$745,0))="","",INDEX(Data!$N$2:$N$745,MATCH(5,Data!$B$2:$B$745,0))),"")) | I19: =IF(B19="","",IFERROR(IF(INDEX(Data!$O$2:$O$745,MATCH(5,Data!$B$2:$B$745,0))="","",INDEX(Data!$O$2:$O$745,MATCH(5,Data!$B$2:$B$745,0))),"")) | J19: =IF(B19="","",IFERROR(IF(INDEX(Data!$P$2:$P$745,MATCH(5,Data!$B$2:$B$745,0))="","",INDEX(Data!$P$2:$P$745,MATCH(5,Data!$B$2:$B$745,0))),"")) | K19: =IF(B19="","",IFERROR(IF(INDEX(Data!$R$2:$R$745,MATCH(5,Data!$B$2:$B$745,0))="","",INDEX(Data!$R$2:$R$745,MATCH(5,Data!$B$2:$B$745,0))),"")) | L19: =IF(B19="","",IFERROR(IF(INDEX(Data!$S$2:$S$745,MATCH(5,Data!$B$2:$B$745,0))="","",INDEX(Data!$S$2:$S$745,MATCH(5,Data!$B$2:$B$745,0))),"")) | M19: =IF(B19="","",IFERROR(IF(INDEX(Data!$T$2:$T$745,MATCH(5,Data!$B$2:$B$745,0))="","",INDEX(Data!$T$2:$T$745,MATCH(5,Data!$B$2:$B$745,0))),"")) | N19: =IF(B19="","",IFERROR(IF(INDEX(Data!$U$2:$U$745,MATCH(5,Data!$B$2:$B$745,0))="","",INDEX(Data!$U$2:$U$745,MATCH(5,Data!$B$2:$B$745,0))),"")) | O19: =IF(B19="","",IFERROR(IF(INDEX(Data!$V$2:$V$745,MATCH(5,Data!$B$2:$B$745,0))="","",INDEX(Data!$V$2:$V$745,MATCH(5,Data!$B$2:$B$745,0))),"")) | P19: =IF(B19="","",IFERROR(IF(INDEX(Data!$M$2:$M$745,MATCH(5,Data!$B$2:$B$745,0))="","",INDEX(Data!$M$2:$M$745,MATCH(5,Data!$B$2:$B$745,0))),"")) | Q19: =IF(B19="","",IFERROR(IF(INDEX(Data!$AD$2:$AD$745,MATCH(5,Data!$B$2:$B$745,0))="","",INDEX(Data!$AD$2:$AD$745,MATCH(5,Data!$B$2:$B$745,0))),"")) | R19: =IF(B19="","",IFERROR(IF(INDEX(Data!$L$2:$L$745,MATCH(5,Data!$B$2:$B$745,0))="","",INDEX(Data!$L$2:$L$745,MATCH(5,Data!$B$2:$B$745,0))),"")) | AA19: CL Cooling Sheets | AB19: Bare Home
B20: =IF(6<=COUNTIF(Data!$A$2:$A$745,TRUE),6,"") | C20: =IF(B20="","",IFERROR(_xlfn.IMAGE(IFERROR(IF(INDEX(Data!$J$2:$J$745,MATCH(6,Data!$B$2:$B$745,0))="","",INDEX(Data!$J$2:$J$745,MATCH(6,Data!$B$2:$B$745,0))),"")),"IMAGE COMING SOON")) | D20: =IF(B20="","",IFERROR(IF(INDEX(Data!$G$2:$G$745,MATCH(6,Data!$B$2:$B$745,0))="","",INDEX(Data!$G$2:$G$745,MATCH(6,Data!$B$2:$B$745,0))),"")&CHAR(10)&IFERROR(IF(INDEX(Data!$H$2:$H$745,MATCH(6,Data!$B$2:$B$745,0))="","",INDEX(Data!$H$2:$H$745,MATCH(6,Data!$B$2:$B$745,0))),"")) | E20: =IF(B20="","",IFERROR(IF(INDEX(Data!$I$2:$I$745,MATCH(6,Data!$B$2:$B$745,0))="","",INDEX(Data!$I$2:$I$745,MATCH(6,Data!$B$2:$B$745,0))),"")) | F20: =IF(B20="","",IFERROR(IF(INDEX(Data!$AJ$2:$AJ$745,MATCH(6,Data!$B$2:$B$745,0))="","",INDEX(Data!$AJ$2:$AJ$745,MATCH(6,Data!$B$2:$B$745,0))),"")) | G20: =IF(B20="","",TRIM(IFERROR(IF(INDEX(Data!$AF$2:$AF$745,MATCH(6,Data!$B$2:$B$745,0))="","",INDEX(Data!$AF$2:$AF$745,MATCH(6,Data!$B$2:$B$745,0))),"")&" "&IFERROR(IF(INDEX(Data!$AG$2:$AG$745,MATCH(6,Data!$B$2:$B$745,0))="","",INDEX(Data!$AG$2:$AG$745,MATCH(6,Data!$B$2:$B$745,0))),""))) | H20: =IF(B20="","",IFERROR(IF(INDEX(Data!$N$2:$N$745,MATCH(6,Data!$B$2:$B$745,0))="","",INDEX(Data!$N$2:$N$745,MATCH(6,Data!$B$2:$B$745,0))),"")) | I20: =IF(B20="","",IFERROR(IF(INDEX(Data!$O$2:$O$745,MATCH(6,Data!$B$2:$B$745,0))="","",INDEX(Data!$O$2:$O$745,MATCH(6,Data!$B$2:$B$745,0))),"")) | J20: =IF(B20="","",IFERROR(IF(INDEX(Data!$P$2:$P$745,MATCH(6,Data!$B$2:$B$745,0))="","",INDEX(Data!$P$2:$P$745,MATCH(6,Data!$B$2:$B$745,0))),"")) | K20: =IF(B20="","",IFERROR(IF(INDEX(Data!$R$2:$R$745,MATCH(6,Data!$B$2:$B$745,0))="","",INDEX(Data!$R$2:$R$745,MATCH(6,Data!$B$2:$B$745,0))),"")) | L20: =IF(B20="","",IFERROR(IF(INDEX(Data!$S$2:$S$745,MATCH(6,Data!$B$2:$B$745,0))="","",INDEX(Data!$S$2:$S$745,MATCH(6,Data!$B$2:$B$745,0))),"")) | M20: =IF(B20="","",IFERROR(IF(INDEX(Data!$T$2:$T$745,MATCH(6,Data!$B$2:$B$745,0))="","",INDEX(Data!$T$2:$T$745,MATCH(6,Data!$B$2:$B$745,0))),"")) | N20: =IF(B20="","",IFERROR(IF(INDEX(Data!$U$2:$U$745,MATCH(6,Data!$B$2:$B$745,0))="","",INDEX(Data!$U$2:$U$745,MATCH(6,Data!$B$2:$B$745,0))),"")) | O20: =IF(B20="","",IFERROR(IF(INDEX(Data!$V$2:$V$745,MATCH(6,Data!$B$2:$B$745,0))="","",INDEX(Data!$V$2:$V$745,MATCH(6,Data!$B$2:$B$745,0))),"")) | P20: =IF(B20="","",IFERROR(IF(INDEX(Data!$M$2:$M$745,MATCH(6,Data!$B$2:$B$745,0))="","",INDEX(Data!$M$2:$M$745,MATCH(6,Data!$B$2:$B$745,0))),"")) | Q20: =IF(B20="","",IFERROR(IF(INDEX(Data!$AD$2:$AD$745,MATCH(6,Data!$B$2:$B$745,0))="","",INDEX(Data!$AD$2:$AD$745,MATCH(6,Data!$B$2:$B$745,0))),"")) | R20: =IF(B20="","",IFERROR(IF(INDEX(Data!$L$2:$L$745,MATCH(6,Data!$B$2:$B$745,0))="","",INDEX(Data!$L$2:$L$745,MATCH(6,Data!$B$2:$B$745,0))),"")) | AA20: CL Pillowcases | AB20: BC BELLA COTERIE
B21: =IF(7<=COUNTIF(Data!$A$2:$A$745,TRUE),7,"") | C21: =IF(B21="","",IFERROR(_xlfn.IMAGE(IFERROR(IF(INDEX(Data!$J$2:$J$745,MATCH(7,Data!$B$2:$B$745,0))="","",INDEX(Data!$J$2:$J$745,MATCH(7,Data!$B$2:$B$745,0))),"")),"IMAGE COMING SOON")) | D21: =IF(B21="","",IFERROR(IF(INDEX(Data!$G$2:$G$745,MATCH(7,Data!$B$2:$B$745,0))="","",INDEX(Data!$G$2:$G$745,MATCH(7,Data!$B$2:$B$745,0))),"")&CHAR(10)&IFERROR(IF(INDEX(Data!$H$2:$H$745,MATCH(7,Data!$B$2:$B$745,0))="","",INDEX(Data!$H$2:$H$745,MATCH(7,Data!$B$2:$B$745,0))),"")) | E21: =IF(B21="","",IFERROR(IF(INDEX(Data!$I$2:$I$745,MATCH(7,Data!$B$2:$B$745,0))="","",INDEX(Data!$I$2:$I$745,MATCH(7,Data!$B$2:$B$745,0))),"")) | F21: =IF(B21="","",IFERROR(IF(INDEX(Data!$AJ$2:$AJ$745,MATCH(7,Data!$B$2:$B$745,0))="","",INDEX(Data!$AJ$2:$AJ$745,MATCH(7,Data!$B$2:$B$745,0))),"")) | G21: =IF(B21="","",TRIM(IFERROR(IF(INDEX(Data!$AF$2:$AF$745,MATCH(7,Data!$B$2:$B$745,0))="","",INDEX(Data!$AF$2:$AF$745,MATCH(7,Data!$B$2:$B$745,0))),"")&" "&IFERROR(IF(INDEX(Data!$AG$2:$AG$745,MATCH(7,Data!$B$2:$B$745,0))="","",INDEX(Data!$AG$2:$AG$745,MATCH(7,Data!$B$2:$B$745,0))),""))) | H21: =IF(B21="","",IFERROR(IF(INDEX(Data!$N$2:$N$745,MATCH(7,Data!$B$2:$B$745,0))="","",INDEX(Data!$N$2:$N$745,MATCH(7,Data!$B$2:$B$745,0))),"")) | I21: =IF(B21="","",IFERROR(IF(INDEX(Data!$O$2:$O$745,MATCH(7,Data!$B$2:$B$745,0))="","",INDEX(Data!$O$2:$O$745,MATCH(7,Data!$B$2:$B$745,0))),"")) | J21: =IF(B21="","",IFERROR(IF(INDEX(Data!$P$2:$P$745,MATCH(7,Data!$B$2:$B$745,0))="","",INDEX(Data!$P$2:$P$745,MATCH(7,Data!$B$2:$B$745,0))),"")) | K21: =IF(B21="","",IFERROR(IF(INDEX(Data!$R$2:$R$745,MATCH(7,Data!$B$2:$B$745,0))="","",INDEX(Data!$R$2:$R$745,MATCH(7,Data!$B$2:$B$745,0))),"")) | L21: =IF(B21="","",IFERROR(IF(INDEX(Data!$S$2:$S$745,MATCH(7,Data!$B$2:$B$745,0))="","",INDEX(Data!$S$2:$S$745,MATCH(7,Data!$B$2:$B$745,0))),"")) | M21: =IF(B21="","",IFERROR(IF(INDEX(Data!$T$2:$T$745,MATCH(7,Data!$B$2:$B$745,0))="","",INDEX(Data!$T$2:$T$745,MATCH(7,Data!$B$2:$B$745,0))),"")) | N21: =IF(B21="","",IFERROR(IF(INDEX(Data!$U$2:$U$745,MATCH(7,Data!$B$2:$B$745,0))="","",INDEX(Data!$U$2:$U$745,MATCH(7,Data!$B$2:$B$745,0))),"")) | O21: =IF(B21="","",IFERROR(IF(INDEX(Data!$V$2:$V$745,MATCH(7,Data!$B$2:$B$745,0))="","",INDEX(Data!$V$2:$V$745,MATCH(7,Data!$B$2:$B$745,0))),"")) | P21: =IF(B21="","",IFERROR(IF(INDEX(Data!$M$2:$M$745,MATCH(7,Data!$B$2:$B$745,0))="","",INDEX(Data!$M$2:$M$745,MATCH(7,Data!$B$2:$B$745,0))),"")) | Q21: =IF(B21="","",IFERROR(IF(INDEX(Data!$AD$2:$AD$745,MATCH(7,Data!$B$2:$B$745,0))="","",INDEX(Data!$AD$2:$AD$745,MATCH(7,Data!$B$2:$B$745,0))),"")) | R21: =IF(B21="","",IFERROR(IF(INDEX(Data!$L$2:$L$745,MATCH(7,Data!$B$2:$B$745,0))="","",INDEX(Data!$L$2:$L$745,MATCH(7,Data!$B$2:$B$745,0))),"")) | AA21: SL Cooling Pillowcase | AB21: Beatrice Home Fashions
B22: =IF(8<=COUNTIF(Data!$A$2:$A$745,TRUE),8,"") | C22: =IF(B22="","",IFERROR(_xlfn.IMAGE(IFERROR(IF(INDEX(Data!$J$2:$J$745,MATCH(8,Data!$B$2:$B$745,0))="","",INDEX(Data!$J$2:$J$745,MATCH(8,Data!$B$2:$B$745,0))),"")),"IMAGE COMING SOON")) | D22: =IF(B22="","",IFERROR(IF(INDEX(Data!$G$2:$G$745,MATCH(8,Data!$B$2:$B$745,0))="","",INDEX(Data!$G$2:$G$745,MATCH(8,Data!$B$2:$B$745,0))),"")&CHAR(10)&IFERROR(IF(INDEX(Data!$H$2:$H$745,MATCH(8,Data!$B$2:$B$745,0))="","",INDEX(Data!$H$2:$H$745,MATCH(8,Data!$B$2:$B$745,0))),"")) | E22: =IF(B22="","",IFERROR(IF(INDEX(Data!$I$2:$I$745,MATCH(8,Data!$B$2:$B$745,0))="","",INDEX(Data!$I$2:$I$745,MATCH(8,Data!$B$2:$B$745,0))),"")) | F22: =IF(B22="","",IFERROR(IF(INDEX(Data!$AJ$2:$AJ$745,MATCH(8,Data!$B$2:$B$745,0))="","",INDEX(Data!$AJ$2:$AJ$745,MATCH(8,Data!$B$2:$B$745,0))),"")) | G22: =IF(B22="","",TRIM(IFERROR(IF(INDEX(Data!$AF$2:$AF$745,MATCH(8,Data!$B$2:$B$745,0))="","",INDEX(Data!$AF$2:$AF$745,MATCH(8,Data!$B$2:$B$745,0))),"")&" "&IFERROR(IF(INDEX(Data!$AG$2:$AG$745,MATCH(8,Data!$B$2:$B$745,0))="","",INDEX(Data!$AG$2:$AG$745,MATCH(8,Data!$B$2:$B$745,0))),""))) | H22: =IF(B22="","",IFERROR(IF(INDEX(Data!$N$2:$N$745,MATCH(8,Data!$B$2:$B$745,0))="","",INDEX(Data!$N$2:$N$745,MATCH(8,Data!$B$2:$B$745,0))),"")) | I22: =IF(B22="","",IFERROR(IF(INDEX(Data!$O$2:$O$745,MATCH(8,Data!$B$2:$B$745,0))="","",INDEX(Data!$O$2:$O$745,MATCH(8,Data!$B$2:$B$745,0))),"")) | J22: =IF(B22="","",IFERROR(IF(INDEX(Data!$P$2:$P$745,MATCH(8,Data!$B$2:$B$745,0))="","",INDEX(Data!$P$2:$P$745,MATCH(8,Data!$B$2:$B$745,0))),"")) | K22: =IF(B22="","",IFERROR(IF(INDEX(Data!$R$2:$R$745,MATCH(8,Data!$B$2:$B$745,0))="","",INDEX(Data!$R$2:$R$745,MATCH(8,Data!$B$2:$B$745,0))),"")) | L22: =IF(B22="","",IFERROR(IF(INDEX(Data!$S$2:$S$745,MATCH(8,Data!$B$2:$B$745,0))="","",INDEX(Data!$S$2:$S$745,MATCH(8,Data!$B$2:$B$745,0))),"")) | M22: =IF(B22="","",IFERROR(IF(INDEX(Data!$T$2:$T$745,MATCH(8,Data!$B$2:$B$745,0))="","",INDEX(Data!$T$2:$T$745,MATCH(8,Data!$B$2:$B$745,0))),"")) | N22: =IF(B22="","",IFERROR(IF(INDEX(Data!$U$2:$U$745,MATCH(8,Data!$B$2:$B$745,0))="","",INDEX(Data!$U$2:$U$745,MATCH(8,Data!$B$2:$B$745,0))),"")) | O22: =IF(B22="","",IFERROR(IF(INDEX(Data!$V$2:$V$745,MATCH(8,Data!$B$2:$B$745,0))="","",INDEX(Data!$V$2:$V$745,MATCH(8,Data!$B$2:$B$745,0))),"")) | P22: =IF(B22="","",IFERROR(IF(INDEX(Data!$M$2:$M$745,MATCH(8,Data!$B$2:$B$745,0))="","",INDEX(Data!$M$2:$M$745,MATCH(8,Data!$B$2:$B$745,0))),"")) | Q22: =IF(B22="","",IFERROR(IF(INDEX(Data!$AD$2:$AD$745,MATCH(8,Data!$B$2:$B$745,0))="","",INDEX(Data!$AD$2:$AD$745,MATCH(8,Data!$B$2:$B$745,0))),"")) | R22: =IF(B22="","",IFERROR(IF(INDEX(Data!$L$2:$L$745,MATCH(8,Data!$B$2:$B$745,0))="","",INDEX(Data!$L$2:$L$745,MATCH(8,Data!$B$2:$B$745,0))),"")) | AA22: SL Cooling Comforter | AB22: BEDELITE
B23: =IF(9<=COUNTIF(Data!$A$2:$A$745,TRUE),9,"") | C23: =IF(B23="","",IFERROR(_xlfn.IMAGE(IFERROR(IF(INDEX(Data!$J$2:$J$745,MATCH(9,Data!$B$2:$B$745,0))="","",INDEX(Data!$J$2:$J$745,MATCH(9,Data!$B$2:$B$745,0))),"")),"IMAGE COMING SOON")) | D23: =IF(B23="","",IFERROR(IF(INDEX(Data!$G$2:$G$745,MATCH(9,Data!$B$2:$B$745,0))="","",INDEX(Data!$G$2:$G$745,MATCH(9,Data!$B$2:$B$745,0))),"")&CHAR(10)&IFERROR(IF(INDEX(Data!$H$2:$H$745,MATCH(9,Data!$B$2:$B$745,0))="","",INDEX(Data!$H$2:$H$745,MATCH(9,Data!$B$2:$B$745,0))),"")) | E23: =IF(B23="","",IFERROR(IF(INDEX(Data!$I$2:$I$745,MATCH(9,Data!$B$2:$B$745,0))="","",INDEX(Data!$I$2:$I$745,MATCH(9,Data!$B$2:$B$745,0))),"")) | F23: =IF(B23="","",IFERROR(IF(INDEX(Data!$AJ$2:$AJ$745,MATCH(9,Data!$B$2:$B$745,0))="","",INDEX(Data!$AJ$2:$AJ$745,MATCH(9,Data!$B$2:$B$745,0))),"")) | G23: =IF(B23="","",TRIM(IFERROR(IF(INDEX(Data!$AF$2:$AF$745,MATCH(9,Data!$B$2:$B$745,0))="","",INDEX(Data!$AF$2:$AF$745,MATCH(9,Data!$B$2:$B$745,0))),"")&" "&IFERROR(IF(INDEX(Data!$AG$2:$AG$745,MATCH(9,Data!$B$2:$B$745,0))="","",INDEX(Data!$AG$2:$AG$745,MATCH(9,Data!$B$2:$B$745,0))),""))) | H23: =IF(B23="","",IFERROR(IF(INDEX(Data!$N$2:$N$745,MATCH(9,Data!$B$2:$B$745,0))="","",INDEX(Data!$N$2:$N$745,MATCH(9,Data!$B$2:$B$745,0))),"")) | I23: =IF(B23="","",IFERROR(IF(INDEX(Data!$O$2:$O$745,MATCH(9,Data!$B$2:$B$745,0))="","",INDEX(Data!$O$2:$O$745,MATCH(9,Data!$B$2:$B$745,0))),"")) | J23: =IF(B23="","",IFERROR(IF(INDEX(Data!$P$2:$P$745,MATCH(9,Data!$B$2:$B$745,0))="","",INDEX(Data!$P$2:$P$745,MATCH(9,Data!$B$2:$B$745,0))),"")) | K23: =IF(B23="","",IFERROR(IF(INDEX(Data!$R$2:$R$745,MATCH(9,Data!$B$2:$B$745,0))="","",INDEX(Data!$R$2:$R$745,MATCH(9,Data!$B$2:$B$745,0))),"")) | L23: =IF(B23="","",IFERROR(IF(INDEX(Data!$S$2:$S$745,MATCH(9,Data!$B$2:$B$745,0))="","",INDEX(Data!$S$2:$S$745,MATCH(9,Data!$B$2:$B$745,0))),"")) | M23: =IF(B23="","",IFERROR(IF(INDEX(Data!$T$2:$T$745,MATCH(9,Data!$B$2:$B$745,0))="","",INDEX(Data!$T$2:$T$745,MATCH(9,Data!$B$2:$B$745,0))),"")) | N23: =IF(B23="","",IFERROR(IF(INDEX(Data!$U$2:$U$745,MATCH(9,Data!$B$2:$B$745,0))="","",INDEX(Data!$U$2:$U$745,MATCH(9,Data!$B$2:$B$745,0))),"")) | O23: =IF(B23="","",IFERROR(IF(INDEX(Data!$V$2:$V$745,MATCH(9,Data!$B$2:$B$745,0))="","",INDEX(Data!$V$2:$V$745,MATCH(9,Data!$B$2:$B$745,0))),"")) | P23: =IF(B23="","",IFERROR(IF(INDEX(Data!$M$2:$M$745,MATCH(9,Data!$B$2:$B$745,0))="","",INDEX(Data!$M$2:$M$745,MATCH(9,Data!$B$2:$B$745,0))),"")) | Q23: =IF(B23="","",IFERROR(IF(INDEX(Data!$AD$2:$AD$745,MATCH(9,Data!$B$2:$B$745,0))="","",INDEX(Data!$AD$2:$AD$745,MATCH(9,Data!$B$2:$B$745,0))),"")) | R23: =IF(B23="","",IFERROR(IF(INDEX(Data!$L$2:$L$745,MATCH(9,Data!$B$2:$B$745,0))="","",INDEX(Data!$L$2:$L$745,MATCH(9,Data!$B$2:$B$745,0))),"")) | AA23: SL Cooling Fitted | AB23: Bedlifes
B24: =IF(10<=COUNTIF(Data!$A$2:$A$745,TRUE),10,"") | C24: =IF(B24="","",IFERROR(_xlfn.IMAGE(IFERROR(IF(INDEX(Data!$J$2:$J$745,MATCH(10,Data!$B$2:$B$745,0))="","",INDEX(Data!$J$2:$J$745,MATCH(10,Data!$B$2:$B$745,0))),"")),"IMAGE COMING SOON")) | D24: =IF(B24="","",IFERROR(IF(INDEX(Data!$G$2:$G$745,MATCH(10,Data!$B$2:$B$745,0))="","",INDEX(Data!$G$2:$G$745,MATCH(10,Data!$B$2:$B$745,0))),"")&CHAR(10)&IFERROR(IF(INDEX(Data!$H$2:$H$745,MATCH(10,Data!$B$2:$B$745,0))="","",INDEX(Data!$H$2:$H$745,MATCH(10,Data!$B$2:$B$745,0))),"")) | E24: =IF(B24="","",IFERROR(IF(INDEX(Data!$I$2:$I$745,MATCH(10,Data!$B$2:$B$745,0))="","",INDEX(Data!$I$2:$I$745,MATCH(10,Data!$B$2:$B$745,0))),"")) | F24: =IF(B24="","",IFERROR(IF(INDEX(Data!$AJ$2:$AJ$745,MATCH(10,Data!$B$2:$B$745,0))="","",INDEX(Data!$AJ$2:$AJ$745,MATCH(10,Data!$B$2:$B$745,0))),"")) | G24: =IF(B24="","",TRIM(IFERROR(IF(INDEX(Data!$AF$2:$AF$745,MATCH(10,Data!$B$2:$B$745,0))="","",INDEX(Data!$AF$2:$AF$745,MATCH(10,Data!$B$2:$B$745,0))),"")&" "&IFERROR(IF(INDEX(Data!$AG$2:$AG$745,MATCH(10,Data!$B$2:$B$745,0))="","",INDEX(Data!$AG$2:$AG$745,MATCH(10,Data!$B$2:$B$745,0))),""))) | H24: =IF(B24="","",IFERROR(IF(INDEX(Data!$N$2:$N$745,MATCH(10,Data!$B$2:$B$745,0))="","",INDEX(Data!$N$2:$N$745,MATCH(10,Data!$B$2:$B$745,0))),"")) | I24: =IF(B24="","",IFERROR(IF(INDEX(Data!$O$2:$O$745,MATCH(10,Data!$B$2:$B$745,0))="","",INDEX(Data!$O$2:$O$745,MATCH(10,Data!$B$2:$B$745,0))),"")) | J24: =IF(B24="","",IFERROR(IF(INDEX(Data!$P$2:$P$745,MATCH(10,Data!$B$2:$B$745,0))="","",INDEX(Data!$P$2:$P$745,MATCH(10,Data!$B$2:$B$745,0))),"")) | K24: =IF(B24="","",IFERROR(IF(INDEX(Data!$R$2:$R$745,MATCH(10,Data!$B$2:$B$745,0))="","",INDEX(Data!$R$2:$R$745,MATCH(10,Data!$B$2:$B$745,0))),"")) | L24: =IF(B24="","",IFERROR(IF(INDEX(Data!$S$2:$S$745,MATCH(10,Data!$B$2:$B$745,0))="","",INDEX(Data!$S$2:$S$745,MATCH(10,Data!$B$2:$B$745,0))),"")) | M24: =IF(B24="","",IFERROR(IF(INDEX(Data!$T$2:$T$745,MATCH(10,Data!$B$2:$B$745,0))="","",INDEX(Data!$T$2:$T$745,MATCH(10,Data!$B$2:$B$745,0))),"")) | N24: =IF(B24="","",IFERROR(IF(INDEX(Data!$U$2:$U$745,MATCH(10,Data!$B$2:$B$745,0))="","",INDEX(Data!$U$2:$U$745,MATCH(10,Data!$B$2:$B$745,0))),"")) | O24: =IF(B24="","",IFERROR(IF(INDEX(Data!$V$2:$V$745,MATCH(10,Data!$B$2:$B$745,0))="","",INDEX(Data!$V$2:$V$745,MATCH(10,Data!$B$2:$B$745,0))),"")) | P24: =IF(B24="","",IFERROR(IF(INDEX(Data!$M$2:$M$745,MATCH(10,Data!$B$2:$B$745,0))="","",INDEX(Data!$M$2:$M$745,MATCH(10,Data!$B$2:$B$745,0))),"")) | Q24: =IF(B24="","",IFERROR(IF(INDEX(Data!$AD$2:$AD$745,MATCH(10,Data!$B$2:$B$745,0))="","",INDEX(Data!$AD$2:$AD$745,MATCH(10,Data!$B$2:$B$745,0))),"")) | R24: =IF(B24="","",IFERROR(IF(INDEX(Data!$L$2:$L$745,MATCH(10,Data!$B$2:$B$745,0))="","",INDEX(Data!$L$2:$L$745,MATCH(10,Data!$B$2:$B$745,0))),"")) | AA24: SL Quilt Set | AB24: bedsmile
B25: =IF(11<=COUNTIF(Data!$A$2:$A$745,TRUE),11,"") | C25: =IF(B25="","",IFERROR(_xlfn.IMAGE(IFERROR(IF(INDEX(Data!$J$2:$J$745,MATCH(11,Data!$B$2:$B$745,0))="","",INDEX(Data!$J$2:$J$745,MATCH(11,Data!$B$2:$B$745,0))),"")),"IMAGE COMING SOON")) | D25: =IF(B25="","",IFERROR(IF(INDEX(Data!$G$2:$G$745,MATCH(11,Data!$B$2:$B$745,0))="","",INDEX(Data!$G$2:$G$745,MATCH(11,Data!$B$2:$B$745,0))),"")&CHAR(10)&IFERROR(IF(INDEX(Data!$H$2:$H$745,MATCH(11,Data!$B$2:$B$745,0))="","",INDEX(Data!$H$2:$H$745,MATCH(11,Data!$B$2:$B$745,0))),"")) | E25: =IF(B25="","",IFERROR(IF(INDEX(Data!$I$2:$I$745,MATCH(11,Data!$B$2:$B$745,0))="","",INDEX(Data!$I$2:$I$745,MATCH(11,Data!$B$2:$B$745,0))),"")) | F25: =IF(B25="","",IFERROR(IF(INDEX(Data!$AJ$2:$AJ$745,MATCH(11,Data!$B$2:$B$745,0))="","",INDEX(Data!$AJ$2:$AJ$745,MATCH(11,Data!$B$2:$B$745,0))),"")) | G25: =IF(B25="","",TRIM(IFERROR(IF(INDEX(Data!$AF$2:$AF$745,MATCH(11,Data!$B$2:$B$745,0))="","",INDEX(Data!$AF$2:$AF$745,MATCH(11,Data!$B$2:$B$745,0))),"")&" "&IFERROR(IF(INDEX(Data!$AG$2:$AG$745,MATCH(11,Data!$B$2:$B$745,0))="","",INDEX(Data!$AG$2:$AG$745,MATCH(11,Data!$B$2:$B$745,0))),""))) | H25: =IF(B25="","",IFERROR(IF(INDEX(Data!$N$2:$N$745,MATCH(11,Data!$B$2:$B$745,0))="","",INDEX(Data!$N$2:$N$745,MATCH(11,Data!$B$2:$B$745,0))),"")) | I25: =IF(B25="","",IFERROR(IF(INDEX(Data!$O$2:$O$745,MATCH(11,Data!$B$2:$B$745,0))="","",INDEX(Data!$O$2:$O$745,MATCH(11,Data!$B$2:$B$745,0))),"")) | J25: =IF(B25="","",IFERROR(IF(INDEX(Data!$P$2:$P$745,MATCH(11,Data!$B$2:$B$745,0))="","",INDEX(Data!$P$2:$P$745,MATCH(11,Data!$B$2:$B$745,0))),"")) | K25: =IF(B25="","",IFERROR(IF(INDEX(Data!$R$2:$R$745,MATCH(11,Data!$B$2:$B$745,0))="","",INDEX(Data!$R$2:$R$745,MATCH(11,Data!$B$2:$B$745,0))),"")) | L25: =IF(B25="","",IFERROR(IF(INDEX(Data!$S$2:$S$745,MATCH(11,Data!$B$2:$B$745,0))="","",INDEX(Data!$S$2:$S$745,MATCH(11,Data!$B$2:$B$745,0))),"")) | M25: =IF(B25="","",IFERROR(IF(INDEX(Data!$T$2:$T$745,MATCH(11,Data!$B$2:$B$745,0))="","",INDEX(Data!$T$2:$T$745,MATCH(11,Data!$B$2:$B$745,0))),"")) | N25: =IF(B25="","",IFERROR(IF(INDEX(Data!$U$2:$U$745,MATCH(11,Data!$B$2:$B$745,0))="","",INDEX(Data!$U$2:$U$745,MATCH(11,Data!$B$2:$B$745,0))),"")) | O25: =IF(B25="","",IFERROR(IF(INDEX(Data!$V$2:$V$745,MATCH(11,Data!$B$2:$B$745,0))="","",INDEX(Data!$V$2:$V$745,MATCH(11,Data!$B$2:$B$745,0))),"")) | P25: =IF(B25="","",IFERROR(IF(INDEX(Data!$M$2:$M$745,MATCH(11,Data!$B$2:$B$745,0))="","",INDEX(Data!$M$2:$M$745,MATCH(11,Data!$B$2:$B$745,0))),"")) | Q25: =IF(B25="","",IFERROR(IF(INDEX(Data!$AD$2:$AD$745,MATCH(11,Data!$B$2:$B$745,0))="","",INDEX(Data!$AD$2:$AD$745,MATCH(11,Data!$B$2:$B$745,0))),"")) | R25: =IF(B25="","",IFERROR(IF(INDEX(Data!$L$2:$L$745,MATCH(11,Data!$B$2:$B$745,0))="","",INDEX(Data!$L$2:$L$745,MATCH(11,Data!$B$2:$B$745,0))),"")) | AA25: DC Linen Curtains | AB25: Bedsure
B26: =IF(12<=COUNTIF(Data!$A$2:$A$745,TRUE),12,"") | C26: =IF(B26="","",IFERROR(_xlfn.IMAGE(IFERROR(IF(INDEX(Data!$J$2:$J$745,MATCH(12,Data!$B$2:$B$745,0))="","",INDEX(Data!$J$2:$J$745,MATCH(12,Data!$B$2:$B$745,0))),"")),"IMAGE COMING SOON")) | D26: =IF(B26="","",IFERROR(IF(INDEX(Data!$G$2:$G$745,MATCH(12,Data!$B$2:$B$745,0))="","",INDEX(Data!$G$2:$G$745,MATCH(12,Data!$B$2:$B$745,0))),"")&CHAR(10)&IFERROR(IF(INDEX(Data!$H$2:$H$745,MATCH(12,Data!$B$2:$B$745,0))="","",INDEX(Data!$H$2:$H$745,MATCH(12,Data!$B$2:$B$745,0))),"")) | E26: =IF(B26="","",IFERROR(IF(INDEX(Data!$I$2:$I$745,MATCH(12,Data!$B$2:$B$745,0))="","",INDEX(Data!$I$2:$I$745,MATCH(12,Data!$B$2:$B$745,0))),"")) | F26: =IF(B26="","",IFERROR(IF(INDEX(Data!$AJ$2:$AJ$745,MATCH(12,Data!$B$2:$B$745,0))="","",INDEX(Data!$AJ$2:$AJ$745,MATCH(12,Data!$B$2:$B$745,0))),"")) | G26: =IF(B26="","",TRIM(IFERROR(IF(INDEX(Data!$AF$2:$AF$745,MATCH(12,Data!$B$2:$B$745,0))="","",INDEX(Data!$AF$2:$AF$745,MATCH(12,Data!$B$2:$B$745,0))),"")&" "&IFERROR(IF(INDEX(Data!$AG$2:$AG$745,MATCH(12,Data!$B$2:$B$745,0))="","",INDEX(Data!$AG$2:$AG$745,MATCH(12,Data!$B$2:$B$745,0))),""))) | H26: =IF(B26="","",IFERROR(IF(INDEX(Data!$N$2:$N$745,MATCH(12,Data!$B$2:$B$745,0))="","",INDEX(Data!$N$2:$N$745,MATCH(12,Data!$B$2:$B$745,0))),"")) | I26: =IF(B26="","",IFERROR(IF(INDEX(Data!$O$2:$O$745,MATCH(12,Data!$B$2:$B$745,0))="","",INDEX(Data!$O$2:$O$745,MATCH(12,Data!$B$2:$B$745,0))),"")) | J26: =IF(B26="","",IFERROR(IF(INDEX(Data!$P$2:$P$745,MATCH(12,Data!$B$2:$B$745,0))="","",INDEX(Data!$P$2:$P$745,MATCH(12,Data!$B$2:$B$745,0))),"")) | K26: =IF(B26="","",IFERROR(IF(INDEX(Data!$R$2:$R$745,MATCH(12,Data!$B$2:$B$745,0))="","",INDEX(Data!$R$2:$R$745,MATCH(12,Data!$B$2:$B$745,0))),"")) | L26: =IF(B26="","",IFERROR(IF(INDEX(Data!$S$2:$S$745,MATCH(12,Data!$B$2:$B$745,0))="","",INDEX(Data!$S$2:$S$745,MATCH(12,Data!$B$2:$B$745,0))),"")) | M26: =IF(B26="","",IFERROR(IF(INDEX(Data!$T$2:$T$745,MATCH(12,Data!$B$2:$B$745,0))="","",INDEX(Data!$T$2:$T$745,MATCH(12,Data!$B$2:$B$745,0))),"")) | N26: =IF(B26="","",IFERROR(IF(INDEX(Data!$U$2:$U$745,MATCH(12,Data!$B$2:$B$745,0))="","",INDEX(Data!$U$2:$U$745,MATCH(12,Data!$B$2:$B$745,0))),"")) | O26: =IF(B26="","",IFERROR(IF(INDEX(Data!$V$2:$V$745,MATCH(12,Data!$B$2:$B$745,0))="","",INDEX(Data!$V$2:$V$745,MATCH(12,Data!$B$2:$B$745,0))),"")) | P26: =IF(B26="","",IFERROR(IF(INDEX(Data!$M$2:$M$745,MATCH(12,Data!$B$2:$B$745,0))="","",INDEX(Data!$M$2:$M$745,MATCH(12,Data!$B$2:$B$745,0))),"")) | Q26: =IF(B26="","",IFERROR(IF(INDEX(Data!$AD$2:$AD$745,MATCH(12,Data!$B$2:$B$745,0))="","",INDEX(Data!$AD$2:$AD$745,MATCH(12,Data!$B$2:$B$745,0))),"")) | R26: =IF(B26="","",IFERROR(IF(INDEX(Data!$L$2:$L$745,MATCH(12,Data!$B$2:$B$745,0))="","",INDEX(Data!$L$2:$L$745,MATCH(12,Data!$B$2:$B$745,0))),"")) | AA26: DC Beach Towel | AB26: Bedtter
B27: =IF(13<=COUNTIF(Data!$A$2:$A$745,TRUE),13,"") | C27: =IF(B27="","",IFERROR(_xlfn.IMAGE(IFERROR(IF(INDEX(Data!$J$2:$J$745,MATCH(13,Data!$B$2:$B$745,0))="","",INDEX(Data!$J$2:$J$745,MATCH(13,Data!$B$2:$B$745,0))),"")),"IMAGE COMING SOON")) | D27: =IF(B27="","",IFERROR(IF(INDEX(Data!$G$2:$G$745,MATCH(13,Data!$B$2:$B$745,0))="","",INDEX(Data!$G$2:$G$745,MATCH(13,Data!$B$2:$B$745,0))),"")&CHAR(10)&IFERROR(IF(INDEX(Data!$H$2:$H$745,MATCH(13,Data!$B$2:$B$745,0))="","",INDEX(Data!$H$2:$H$745,MATCH(13,Data!$B$2:$B$745,0))),"")) | E27: =IF(B27="","",IFERROR(IF(INDEX(Data!$I$2:$I$745,MATCH(13,Data!$B$2:$B$745,0))="","",INDEX(Data!$I$2:$I$745,MATCH(13,Data!$B$2:$B$745,0))),"")) | F27: =IF(B27="","",IFERROR(IF(INDEX(Data!$AJ$2:$AJ$745,MATCH(13,Data!$B$2:$B$745,0))="","",INDEX(Data!$AJ$2:$AJ$745,MATCH(13,Data!$B$2:$B$745,0))),"")) | G27: =IF(B27="","",TRIM(IFERROR(IF(INDEX(Data!$AF$2:$AF$745,MATCH(13,Data!$B$2:$B$745,0))="","",INDEX(Data!$AF$2:$AF$745,MATCH(13,Data!$B$2:$B$745,0))),"")&" "&IFERROR(IF(INDEX(Data!$AG$2:$AG$745,MATCH(13,Data!$B$2:$B$745,0))="","",INDEX(Data!$AG$2:$AG$745,MATCH(13,Data!$B$2:$B$745,0))),""))) | H27: =IF(B27="","",IFERROR(IF(INDEX(Data!$N$2:$N$745,MATCH(13,Data!$B$2:$B$745,0))="","",INDEX(Data!$N$2:$N$745,MATCH(13,Data!$B$2:$B$745,0))),"")) | I27: =IF(B27="","",IFERROR(IF(INDEX(Data!$O$2:$O$745,MATCH(13,Data!$B$2:$B$745,0))="","",INDEX(Data!$O$2:$O$745,MATCH(13,Data!$B$2:$B$745,0))),"")) | J27: =IF(B27="","",IFERROR(IF(INDEX(Data!$P$2:$P$745,MATCH(13,Data!$B$2:$B$745,0))="","",INDEX(Data!$P$2:$P$745,MATCH(13,Data!$B$2:$B$745,0))),"")) | K27: =IF(B27="","",IFERROR(IF(INDEX(Data!$R$2:$R$745,MATCH(13,Data!$B$2:$B$745,0))="","",INDEX(Data!$R$2:$R$745,MATCH(13,Data!$B$2:$B$745,0))),"")) | L27: =IF(B27="","",IFERROR(IF(INDEX(Data!$S$2:$S$745,MATCH(13,Data!$B$2:$B$745,0))="","",INDEX(Data!$S$2:$S$745,MATCH(13,Data!$B$2:$B$745,0))),"")) | M27: =IF(B27="","",IFERROR(IF(INDEX(Data!$T$2:$T$745,MATCH(13,Data!$B$2:$B$745,0))="","",INDEX(Data!$T$2:$T$745,MATCH(13,Data!$B$2:$B$745,0))),"")) | N27: =IF(B27="","",IFERROR(IF(INDEX(Data!$U$2:$U$745,MATCH(13,Data!$B$2:$B$745,0))="","",INDEX(Data!$U$2:$U$745,MATCH(13,Data!$B$2:$B$745,0))),"")) | O27: =IF(B27="","",IFERROR(IF(INDEX(Data!$V$2:$V$745,MATCH(13,Data!$B$2:$B$745,0))="","",INDEX(Data!$V$2:$V$745,MATCH(13,Data!$B$2:$B$745,0))),"")) | P27: =IF(B27="","",IFERROR(IF(INDEX(Data!$M$2:$M$745,MATCH(13,Data!$B$2:$B$745,0))="","",INDEX(Data!$M$2:$M$745,MATCH(13,Data!$B$2:$B$745,0))),"")) | Q27: =IF(B27="","",IFERROR(IF(INDEX(Data!$AD$2:$AD$745,MATCH(13,Data!$B$2:$B$745,0))="","",INDEX(Data!$AD$2:$AD$745,MATCH(13,Data!$B$2:$B$745,0))),"")) | R27: =IF(B27="","",IFERROR(IF(INDEX(Data!$L$2:$L$745,MATCH(13,Data!$B$2:$B$745,0))="","",INDEX(Data!$L$2:$L$745,MATCH(13,Data!$B$2:$B$745,0))),"")) | AA27: DC Welcome Sign | AB27: BGment
B28: =IF(14<=COUNTIF(Data!$A$2:$A$745,TRUE),14,"") | C28: =IF(B28="","",IFERROR(_xlfn.IMAGE(IFERROR(IF(INDEX(Data!$J$2:$J$745,MATCH(14,Data!$B$2:$B$745,0))="","",INDEX(Data!$J$2:$J$745,MATCH(14,Data!$B$2:$B$745,0))),"")),"IMAGE COMING SOON")) | D28: =IF(B28="","",IFERROR(IF(INDEX(Data!$G$2:$G$745,MATCH(14,Data!$B$2:$B$745,0))="","",INDEX(Data!$G$2:$G$745,MATCH(14,Data!$B$2:$B$745,0))),"")&CHAR(10)&IFERROR(IF(INDEX(Data!$H$2:$H$745,MATCH(14,Data!$B$2:$B$745,0))="","",INDEX(Data!$H$2:$H$745,MATCH(14,Data!$B$2:$B$745,0))),"")) | E28: =IF(B28="","",IFERROR(IF(INDEX(Data!$I$2:$I$745,MATCH(14,Data!$B$2:$B$745,0))="","",INDEX(Data!$I$2:$I$745,MATCH(14,Data!$B$2:$B$745,0))),"")) | F28: =IF(B28="","",IFERROR(IF(INDEX(Data!$AJ$2:$AJ$745,MATCH(14,Data!$B$2:$B$745,0))="","",INDEX(Data!$AJ$2:$AJ$745,MATCH(14,Data!$B$2:$B$745,0))),"")) | G28: =IF(B28="","",TRIM(IFERROR(IF(INDEX(Data!$AF$2:$AF$745,MATCH(14,Data!$B$2:$B$745,0))="","",INDEX(Data!$AF$2:$AF$745,MATCH(14,Data!$B$2:$B$745,0))),"")&" "&IFERROR(IF(INDEX(Data!$AG$2:$AG$745,MATCH(14,Data!$B$2:$B$745,0))="","",INDEX(Data!$AG$2:$AG$745,MATCH(14,Data!$B$2:$B$745,0))),""))) | H28: =IF(B28="","",IFERROR(IF(INDEX(Data!$N$2:$N$745,MATCH(14,Data!$B$2:$B$745,0))="","",INDEX(Data!$N$2:$N$745,MATCH(14,Data!$B$2:$B$745,0))),"")) | I28: =IF(B28="","",IFERROR(IF(INDEX(Data!$O$2:$O$745,MATCH(14,Data!$B$2:$B$745,0))="","",INDEX(Data!$O$2:$O$745,MATCH(14,Data!$B$2:$B$745,0))),"")) | J28: =IF(B28="","",IFERROR(IF(INDEX(Data!$P$2:$P$745,MATCH(14,Data!$B$2:$B$745,0))="","",INDEX(Data!$P$2:$P$745,MATCH(14,Data!$B$2:$B$745,0))),"")) | K28: =IF(B28="","",IFERROR(IF(INDEX(Data!$R$2:$R$745,MATCH(14,Data!$B$2:$B$745,0))="","",INDEX(Data!$R$2:$R$745,MATCH(14,Data!$B$2:$B$745,0))),"")) | L28: =IF(B28="","",IFERROR(IF(INDEX(Data!$S$2:$S$745,MATCH(14,Data!$B$2:$B$745,0))="","",INDEX(Data!$S$2:$S$745,MATCH(14,Data!$B$2:$B$745,0))),"")) | M28: =IF(B28="","",IFERROR(IF(INDEX(Data!$T$2:$T$745,MATCH(14,Data!$B$2:$B$745,0))="","",INDEX(Data!$T$2:$T$745,MATCH(14,Data!$B$2:$B$745,0))),"")) | N28: =IF(B28="","",IFERROR(IF(INDEX(Data!$U$2:$U$745,MATCH(14,Data!$B$2:$B$745,0))="","",INDEX(Data!$U$2:$U$745,MATCH(14,Data!$B$2:$B$745,0))),"")) | O28: =IF(B28="","",IFERROR(IF(INDEX(Data!$V$2:$V$745,MATCH(14,Data!$B$2:$B$745,0))="","",INDEX(Data!$V$2:$V$745,MATCH(14,Data!$B$2:$B$745,0))),"")) | P28: =IF(B28="","",IFERROR(IF(INDEX(Data!$M$2:$M$745,MATCH(14,Data!$B$2:$B$745,0))="","",INDEX(Data!$M$2:$M$745,MATCH(14,Data!$B$2:$B$745,0))),"")) | Q28: =IF(B28="","",IFERROR(IF(INDEX(Data!$AD$2:$AD$745,MATCH(14,Data!$B$2:$B$745,0))="","",INDEX(Data!$AD$2:$AD$745,MATCH(14,Data!$B$2:$B$745,0))),"")) | R28: =IF(B28="","",IFERROR(IF(INDEX(Data!$L$2:$L$745,MATCH(14,Data!$B$2:$B$745,0))="","",INDEX(Data!$L$2:$L$745,MATCH(14,Data!$B$2:$B$745,0))),"")) | AA28: DC Chair Cover | AB28: BIETYONE
B29: =IF(15<=COUNTIF(Data!$A$2:$A$745,TRUE),15,"") | C29: =IF(B29="","",IFERROR(_xlfn.IMAGE(IFERROR(IF(INDEX(Data!$J$2:$J$745,MATCH(15,Data!$B$2:$B$745,0))="","",INDEX(Data!$J$2:$J$745,MATCH(15,Data!$B$2:$B$745,0))),"")),"IMAGE COMING SOON")) | D29: =IF(B29="","",IFERROR(IF(INDEX(Data!$G$2:$G$745,MATCH(15,Data!$B$2:$B$745,0))="","",INDEX(Data!$G$2:$G$745,MATCH(15,Data!$B$2:$B$745,0))),"")&CHAR(10)&IFERROR(IF(INDEX(Data!$H$2:$H$745,MATCH(15,Data!$B$2:$B$745,0))="","",INDEX(Data!$H$2:$H$745,MATCH(15,Data!$B$2:$B$745,0))),"")) | E29: =IF(B29="","",IFERROR(IF(INDEX(Data!$I$2:$I$745,MATCH(15,Data!$B$2:$B$745,0))="","",INDEX(Data!$I$2:$I$745,MATCH(15,Data!$B$2:$B$745,0))),"")) | F29: =IF(B29="","",IFERROR(IF(INDEX(Data!$AJ$2:$AJ$745,MATCH(15,Data!$B$2:$B$745,0))="","",INDEX(Data!$AJ$2:$AJ$745,MATCH(15,Data!$B$2:$B$745,0))),"")) | G29: =IF(B29="","",TRIM(IFERROR(IF(INDEX(Data!$AF$2:$AF$745,MATCH(15,Data!$B$2:$B$745,0))="","",INDEX(Data!$AF$2:$AF$745,MATCH(15,Data!$B$2:$B$745,0))),"")&" "&IFERROR(IF(INDEX(Data!$AG$2:$AG$745,MATCH(15,Data!$B$2:$B$745,0))="","",INDEX(Data!$AG$2:$AG$745,MATCH(15,Data!$B$2:$B$745,0))),""))) | H29: =IF(B29="","",IFERROR(IF(INDEX(Data!$N$2:$N$745,MATCH(15,Data!$B$2:$B$745,0))="","",INDEX(Data!$N$2:$N$745,MATCH(15,Data!$B$2:$B$745,0))),"")) | I29: =IF(B29="","",IFERROR(IF(INDEX(Data!$O$2:$O$745,MATCH(15,Data!$B$2:$B$745,0))="","",INDEX(Data!$O$2:$O$745,MATCH(15,Data!$B$2:$B$745,0))),"")) | J29: =IF(B29="","",IFERROR(IF(INDEX(Data!$P$2:$P$745,MATCH(15,Data!$B$2:$B$745,0))="","",INDEX(Data!$P$2:$P$745,MATCH(15,Data!$B$2:$B$745,0))),"")) | K29: =IF(B29="","",IFERROR(IF(INDEX(Data!$R$2:$R$745,MATCH(15,Data!$B$2:$B$745,0))="","",INDEX(Data!$R$2:$R$745,MATCH(15,Data!$B$2:$B$745,0))),"")) | L29: =IF(B29="","",IFERROR(IF(INDEX(Data!$S$2:$S$745,MATCH(15,Data!$B$2:$B$745,0))="","",INDEX(Data!$S$2:$S$745,MATCH(15,Data!$B$2:$B$745,0))),"")) | M29: =IF(B29="","",IFERROR(IF(INDEX(Data!$T$2:$T$745,MATCH(15,Data!$B$2:$B$745,0))="","",INDEX(Data!$T$2:$T$745,MATCH(15,Data!$B$2:$B$745,0))),"")) | N29: =IF(B29="","",IFERROR(IF(INDEX(Data!$U$2:$U$745,MATCH(15,Data!$B$2:$B$745,0))="","",INDEX(Data!$U$2:$U$745,MATCH(15,Data!$B$2:$B$745,0))),"")) | O29: =IF(B29="","",IFERROR(IF(INDEX(Data!$V$2:$V$745,MATCH(15,Data!$B$2:$B$745,0))="","",INDEX(Data!$V$2:$V$745,MATCH(15,Data!$B$2:$B$745,0))),"")) | P29: =IF(B29="","",IFERROR(IF(INDEX(Data!$M$2:$M$745,MATCH(15,Data!$B$2:$B$745,0))="","",INDEX(Data!$M$2:$M$745,MATCH(15,Data!$B$2:$B$745,0))),"")) | Q29: =IF(B29="","",IFERROR(IF(INDEX(Data!$AD$2:$AD$745,MATCH(15,Data!$B$2:$B$745,0))="","",INDEX(Data!$AD$2:$AD$745,MATCH(15,Data!$B$2:$B$745,0))),"")) | R29: =IF(B29="","",IFERROR(IF(INDEX(Data!$L$2:$L$745,MATCH(15,Data!$B$2:$B$745,0))="","",INDEX(Data!$L$2:$L$745,MATCH(15,Data!$B$2:$B$745,0))),"")) | AB29: BLISSFORD
B30: =IF(16<=COUNTIF(Data!$A$2:$A$745,TRUE),16,"") | C30: =IF(B30="","",IFERROR(_xlfn.IMAGE(IFERROR(IF(INDEX(Data!$J$2:$J$745,MATCH(16,Data!$B$2:$B$745,0))="","",INDEX(Data!$J$2:$J$745,MATCH(16,Data!$B$2:$B$745,0))),"")),"IMAGE COMING SOON")) | D30: =IF(B30="","",IFERROR(IF(INDEX(Data!$G$2:$G$745,MATCH(16,Data!$B$2:$B$745,0))="","",INDEX(Data!$G$2:$G$745,MATCH(16,Data!$B$2:$B$745,0))),"")&CHAR(10)&IFERROR(IF(INDEX(Data!$H$2:$H$745,MATCH(16,Data!$B$2:$B$745,0))="","",INDEX(Data!$H$2:$H$745,MATCH(16,Data!$B$2:$B$745,0))),"")) | E30: =IF(B30="","",IFERROR(IF(INDEX(Data!$I$2:$I$745,MATCH(16,Data!$B$2:$B$745,0))="","",INDEX(Data!$I$2:$I$745,MATCH(16,Data!$B$2:$B$745,0))),"")) | F30: =IF(B30="","",IFERROR(IF(INDEX(Data!$AJ$2:$AJ$745,MATCH(16,Data!$B$2:$B$745,0))="","",INDEX(Data!$AJ$2:$AJ$745,MATCH(16,Data!$B$2:$B$745,0))),"")) | G30: =IF(B30="","",TRIM(IFERROR(IF(INDEX(Data!$AF$2:$AF$745,MATCH(16,Data!$B$2:$B$745,0))="","",INDEX(Data!$AF$2:$AF$745,MATCH(16,Data!$B$2:$B$745,0))),"")&" "&IFERROR(IF(INDEX(Data!$AG$2:$AG$745,MATCH(16,Data!$B$2:$B$745,0))="","",INDEX(Data!$AG$2:$AG$745,MATCH(16,Data!$B$2:$B$745,0))),""))) | H30: =IF(B30="","",IFERROR(IF(INDEX(Data!$N$2:$N$745,MATCH(16,Data!$B$2:$B$745,0))="","",INDEX(Data!$N$2:$N$745,MATCH(16,Data!$B$2:$B$745,0))),"")) | I30: =IF(B30="","",IFERROR(IF(INDEX(Data!$O$2:$O$745,MATCH(16,Data!$B$2:$B$745,0))="","",INDEX(Data!$O$2:$O$745,MATCH(16,Data!$B$2:$B$745,0))),"")) | J30: =IF(B30="","",IFERROR(IF(INDEX(Data!$P$2:$P$745,MATCH(16,Data!$B$2:$B$745,0))="","",INDEX(Data!$P$2:$P$745,MATCH(16,Data!$B$2:$B$745,0))),"")) | K30: =IF(B30="","",IFERROR(IF(INDEX(Data!$R$2:$R$745,MATCH(16,Data!$B$2:$B$745,0))="","",INDEX(Data!$R$2:$R$745,MATCH(16,Data!$B$2:$B$745,0))),"")) | L30: =IF(B30="","",IFERROR(IF(INDEX(Data!$S$2:$S$745,MATCH(16,Data!$B$2:$B$745,0))="","",INDEX(Data!$S$2:$S$745,MATCH(16,Data!$B$2:$B$745,0))),"")) | M30: =IF(B30="","",IFERROR(IF(INDEX(Data!$T$2:$T$745,MATCH(16,Data!$B$2:$B$745,0))="","",INDEX(Data!$T$2:$T$745,MATCH(16,Data!$B$2:$B$745,0))),"")) | N30: =IF(B30="","",IFERROR(IF(INDEX(Data!$U$2:$U$745,MATCH(16,Data!$B$2:$B$745,0))="","",INDEX(Data!$U$2:$U$745,MATCH(16,Data!$B$2:$B$745,0))),"")) | O30: =IF(B30="","",IFERROR(IF(INDEX(Data!$V$2:$V$745,MATCH(16,Data!$B$2:$B$745,0))="","",INDEX(Data!$V$2:$V$745,MATCH(16,Data!$B$2:$B$745,0))),"")) | P30: =IF(B30="","",IFERROR(IF(INDEX(Data!$M$2:$M$745,MATCH(16,Data!$B$2:$B$745,0))="","",INDEX(Data!$M$2:$M$745,MATCH(16,Data!$B$2:$B$745,0))),"")) | Q30: =IF(B30="","",IFERROR(IF(INDEX(Data!$AD$2:$AD$745,MATCH(16,Data!$B$2:$B$745,0))="","",INDEX(Data!$AD$2:$AD$745,MATCH(16,Data!$B$2:$B$745,0))),"")) | R30: =IF(B30="","",IFERROR(IF(INDEX(Data!$L$2:$L$745,MATCH(16,Data!$B$2:$B$745,0))="","",INDEX(Data!$L$2:$L$745,MATCH(16,Data!$B$2:$B$745,0))),"")) | AB30: BLISSY
B31: =IF(17<=COUNTIF(Data!$A$2:$A$745,TRUE),17,"") | C31: =IF(B31="","",IFERROR(_xlfn.IMAGE(IFERROR(IF(INDEX(Data!$J$2:$J$745,MATCH(17,Data!$B$2:$B$745,0))="","",INDEX(Data!$J$2:$J$745,MATCH(17,Data!$B$2:$B$745,0))),"")),"IMAGE COMING SOON")) | D31: =IF(B31="","",IFERROR(IF(INDEX(Data!$G$2:$G$745,MATCH(17,Data!$B$2:$B$745,0))="","",INDEX(Data!$G$2:$G$745,MATCH(17,Data!$B$2:$B$745,0))),"")&CHAR(10)&IFERROR(IF(INDEX(Data!$H$2:$H$745,MATCH(17,Data!$B$2:$B$745,0))="","",INDEX(Data!$H$2:$H$745,MATCH(17,Data!$B$2:$B$745,0))),"")) | E31: =IF(B31="","",IFERROR(IF(INDEX(Data!$I$2:$I$745,MATCH(17,Data!$B$2:$B$745,0))="","",INDEX(Data!$I$2:$I$745,MATCH(17,Data!$B$2:$B$745,0))),"")) | F31: =IF(B31="","",IFERROR(IF(INDEX(Data!$AJ$2:$AJ$745,MATCH(17,Data!$B$2:$B$745,0))="","",INDEX(Data!$AJ$2:$AJ$745,MATCH(17,Data!$B$2:$B$745,0))),"")) | G31: =IF(B31="","",TRIM(IFERROR(IF(INDEX(Data!$AF$2:$AF$745,MATCH(17,Data!$B$2:$B$745,0))="","",INDEX(Data!$AF$2:$AF$745,MATCH(17,Data!$B$2:$B$745,0))),"")&" "&IFERROR(IF(INDEX(Data!$AG$2:$AG$745,MATCH(17,Data!$B$2:$B$745,0))="","",INDEX(Data!$AG$2:$AG$745,MATCH(17,Data!$B$2:$B$745,0))),""))) | H31: =IF(B31="","",IFERROR(IF(INDEX(Data!$N$2:$N$745,MATCH(17,Data!$B$2:$B$745,0))="","",INDEX(Data!$N$2:$N$745,MATCH(17,Data!$B$2:$B$745,0))),"")) | I31: =IF(B31="","",IFERROR(IF(INDEX(Data!$O$2:$O$745,MATCH(17,Data!$B$2:$B$745,0))="","",INDEX(Data!$O$2:$O$745,MATCH(17,Data!$B$2:$B$745,0))),"")) | J31: =IF(B31="","",IFERROR(IF(INDEX(Data!$P$2:$P$745,MATCH(17,Data!$B$2:$B$745,0))="","",INDEX(Data!$P$2:$P$745,MATCH(17,Data!$B$2:$B$745,0))),"")) | K31: =IF(B31="","",IFERROR(IF(INDEX(Data!$R$2:$R$745,MATCH(17,Data!$B$2:$B$745,0))="","",INDEX(Data!$R$2:$R$745,MATCH(17,Data!$B$2:$B$745,0))),"")) | L31: =IF(B31="","",IFERROR(IF(INDEX(Data!$S$2:$S$745,MATCH(17,Data!$B$2:$B$745,0))="","",INDEX(Data!$S$2:$S$745,MATCH(17,Data!$B$2:$B$745,0))),"")) | M31: =IF(B31="","",IFERROR(IF(INDEX(Data!$T$2:$T$745,MATCH(17,Data!$B$2:$B$745,0))="","",INDEX(Data!$T$2:$T$745,MATCH(17,Data!$B$2:$B$745,0))),"")) | N31: =IF(B31="","",IFERROR(IF(INDEX(Data!$U$2:$U$745,MATCH(17,Data!$B$2:$B$745,0))="","",INDEX(Data!$U$2:$U$745,MATCH(17,Data!$B$2:$B$745,0))),"")) | O31: =IF(B31="","",IFERROR(IF(INDEX(Data!$V$2:$V$745,MATCH(17,Data!$B$2:$B$745,0))="","",INDEX(Data!$V$2:$V$745,MATCH(17,Data!$B$2:$B$745,0))),"")) | P31: =IF(B31="","",IFERROR(IF(INDEX(Data!$M$2:$M$745,MATCH(17,Data!$B$2:$B$745,0))="","",INDEX(Data!$M$2:$M$745,MATCH(17,Data!$B$2:$B$745,0))),"")) | Q31: =IF(B31="","",IFERROR(IF(INDEX(Data!$AD$2:$AD$745,MATCH(17,Data!$B$2:$B$745,0))="","",INDEX(Data!$AD$2:$AD$745,MATCH(17,Data!$B$2:$B$745,0))),"")) | R31: =IF(B31="","",IFERROR(IF(INDEX(Data!$L$2:$L$745,MATCH(17,Data!$B$2:$B$745,0))="","",INDEX(Data!$L$2:$L$745,MATCH(17,Data!$B$2:$B$745,0))),"")) | AB31: BLSSNZ
B32: =IF(18<=COUNTIF(Data!$A$2:$A$745,TRUE),18,"") | C32: =IF(B32="","",IFERROR(_xlfn.IMAGE(IFERROR(IF(INDEX(Data!$J$2:$J$745,MATCH(18,Data!$B$2:$B$745,0))="","",INDEX(Data!$J$2:$J$745,MATCH(18,Data!$B$2:$B$745,0))),"")),"IMAGE COMING SOON")) | D32: =IF(B32="","",IFERROR(IF(INDEX(Data!$G$2:$G$745,MATCH(18,Data!$B$2:$B$745,0))="","",INDEX(Data!$G$2:$G$745,MATCH(18,Data!$B$2:$B$745,0))),"")&CHAR(10)&IFERROR(IF(INDEX(Data!$H$2:$H$745,MATCH(18,Data!$B$2:$B$745,0))="","",INDEX(Data!$H$2:$H$745,MATCH(18,Data!$B$2:$B$745,0))),"")) | E32: =IF(B32="","",IFERROR(IF(INDEX(Data!$I$2:$I$745,MATCH(18,Data!$B$2:$B$745,0))="","",INDEX(Data!$I$2:$I$745,MATCH(18,Data!$B$2:$B$745,0))),"")) | F32: =IF(B32="","",IFERROR(IF(INDEX(Data!$AJ$2:$AJ$745,MATCH(18,Data!$B$2:$B$745,0))="","",INDEX(Data!$AJ$2:$AJ$745,MATCH(18,Data!$B$2:$B$745,0))),"")) | G32: =IF(B32="","",TRIM(IFERROR(IF(INDEX(Data!$AF$2:$AF$745,MATCH(18,Data!$B$2:$B$745,0))="","",INDEX(Data!$AF$2:$AF$745,MATCH(18,Data!$B$2:$B$745,0))),"")&" "&IFERROR(IF(INDEX(Data!$AG$2:$AG$745,MATCH(18,Data!$B$2:$B$745,0))="","",INDEX(Data!$AG$2:$AG$745,MATCH(18,Data!$B$2:$B$745,0))),""))) | H32: =IF(B32="","",IFERROR(IF(INDEX(Data!$N$2:$N$745,MATCH(18,Data!$B$2:$B$745,0))="","",INDEX(Data!$N$2:$N$745,MATCH(18,Data!$B$2:$B$745,0))),"")) | I32: =IF(B32="","",IFERROR(IF(INDEX(Data!$O$2:$O$745,MATCH(18,Data!$B$2:$B$745,0))="","",INDEX(Data!$O$2:$O$745,MATCH(18,Data!$B$2:$B$745,0))),"")) | J32: =IF(B32="","",IFERROR(IF(INDEX(Data!$P$2:$P$745,MATCH(18,Data!$B$2:$B$745,0))="","",INDEX(Data!$P$2:$P$745,MATCH(18,Data!$B$2:$B$745,0))),"")) | K32: =IF(B32="","",IFERROR(IF(INDEX(Data!$R$2:$R$745,MATCH(18,Data!$B$2:$B$745,0))="","",INDEX(Data!$R$2:$R$745,MATCH(18,Data!$B$2:$B$745,0))),"")) | L32: =IF(B32="","",IFERROR(IF(INDEX(Data!$S$2:$S$745,MATCH(18,Data!$B$2:$B$745,0))="","",INDEX(Data!$S$2:$S$745,MATCH(18,Data!$B$2:$B$745,0))),"")) | M32: =IF(B32="","",IFERROR(IF(INDEX(Data!$T$2:$T$745,MATCH(18,Data!$B$2:$B$745,0))="","",INDEX(Data!$T$2:$T$745,MATCH(18,Data!$B$2:$B$745,0))),"")) | N32: =IF(B32="","",IFERROR(IF(INDEX(Data!$U$2:$U$745,MATCH(18,Data!$B$2:$B$745,0))="","",INDEX(Data!$U$2:$U$745,MATCH(18,Data!$B$2:$B$745,0))),"")) | O32: =IF(B32="","",IFERROR(IF(INDEX(Data!$V$2:$V$745,MATCH(18,Data!$B$2:$B$745,0))="","",INDEX(Data!$V$2:$V$745,MATCH(18,Data!$B$2:$B$745,0))),"")) | P32: =IF(B32="","",IFERROR(IF(INDEX(Data!$M$2:$M$745,MATCH(18,Data!$B$2:$B$745,0))="","",INDEX(Data!$M$2:$M$745,MATCH(18,Data!$B$2:$B$745,0))),"")) | Q32: =IF(B32="","",IFERROR(IF(INDEX(Data!$AD$2:$AD$745,MATCH(18,Data!$B$2:$B$745,0))="","",INDEX(Data!$AD$2:$AD$745,MATCH(18,Data!$B$2:$B$745,0))),"")) | R32: =IF(B32="","",IFERROR(IF(INDEX(Data!$L$2:$L$745,MATCH(18,Data!$B$2:$B$745,0))="","",INDEX(Data!$L$2:$L$745,MATCH(18,Data!$B$2:$B$745,0))),"")) | AB32: Breescape
B33: =IF(19<=COUNTIF(Data!$A$2:$A$745,TRUE),19,"") | C33: =IF(B33="","",IFERROR(_xlfn.IMAGE(IFERROR(IF(INDEX(Data!$J$2:$J$745,MATCH(19,Data!$B$2:$B$745,0))="","",INDEX(Data!$J$2:$J$745,MATCH(19,Data!$B$2:$B$745,0))),"")),"IMAGE COMING SOON")) | D33: =IF(B33="","",IFERROR(IF(INDEX(Data!$G$2:$G$745,MATCH(19,Data!$B$2:$B$745,0))="","",INDEX(Data!$G$2:$G$745,MATCH(19,Data!$B$2:$B$745,0))),"")&CHAR(10)&IFERROR(IF(INDEX(Data!$H$2:$H$745,MATCH(19,Data!$B$2:$B$745,0))="","",INDEX(Data!$H$2:$H$745,MATCH(19,Data!$B$2:$B$745,0))),"")) | E33: =IF(B33="","",IFERROR(IF(INDEX(Data!$I$2:$I$745,MATCH(19,Data!$B$2:$B$745,0))="","",INDEX(Data!$I$2:$I$745,MATCH(19,Data!$B$2:$B$745,0))),"")) | F33: =IF(B33="","",IFERROR(IF(INDEX(Data!$AJ$2:$AJ$745,MATCH(19,Data!$B$2:$B$745,0))="","",INDEX(Data!$AJ$2:$AJ$745,MATCH(19,Data!$B$2:$B$745,0))),"")) | G33: =IF(B33="","",TRIM(IFERROR(IF(INDEX(Data!$AF$2:$AF$745,MATCH(19,Data!$B$2:$B$745,0))="","",INDEX(Data!$AF$2:$AF$745,MATCH(19,Data!$B$2:$B$745,0))),"")&" "&IFERROR(IF(INDEX(Data!$AG$2:$AG$745,MATCH(19,Data!$B$2:$B$745,0))="","",INDEX(Data!$AG$2:$AG$745,MATCH(19,Data!$B$2:$B$745,0))),""))) | H33: =IF(B33="","",IFERROR(IF(INDEX(Data!$N$2:$N$745,MATCH(19,Data!$B$2:$B$745,0))="","",INDEX(Data!$N$2:$N$745,MATCH(19,Data!$B$2:$B$745,0))),"")) | I33: =IF(B33="","",IFERROR(IF(INDEX(Data!$O$2:$O$745,MATCH(19,Data!$B$2:$B$745,0))="","",INDEX(Data!$O$2:$O$745,MATCH(19,Data!$B$2:$B$745,0))),"")) | J33: =IF(B33="","",IFERROR(IF(INDEX(Data!$P$2:$P$745,MATCH(19,Data!$B$2:$B$745,0))="","",INDEX(Data!$P$2:$P$745,MATCH(19,Data!$B$2:$B$745,0))),"")) | K33: =IF(B33="","",IFERROR(IF(INDEX(Data!$R$2:$R$745,MATCH(19,Data!$B$2:$B$745,0))="","",INDEX(Data!$R$2:$R$745,MATCH(19,Data!$B$2:$B$745,0))),"")) | L33: =IF(B33="","",IFERROR(IF(INDEX(Data!$S$2:$S$745,MATCH(19,Data!$B$2:$B$745,0))="","",INDEX(Data!$S$2:$S$745,MATCH(19,Data!$B$2:$B$745,0))),"")) | M33: =IF(B33="","",IFERROR(IF(INDEX(Data!$T$2:$T$745,MATCH(19,Data!$B$2:$B$745,0))="","",INDEX(Data!$T$2:$T$745,MATCH(19,Data!$B$2:$B$745,0))),"")) | N33: =IF(B33="","",IFERROR(IF(INDEX(Data!$U$2:$U$745,MATCH(19,Data!$B$2:$B$745,0))="","",INDEX(Data!$U$2:$U$745,MATCH(19,Data!$B$2:$B$745,0))),"")) | O33: =IF(B33="","",IFERROR(IF(INDEX(Data!$V$2:$V$745,MATCH(19,Data!$B$2:$B$745,0))="","",INDEX(Data!$V$2:$V$745,MATCH(19,Data!$B$2:$B$745,0))),"")) | P33: =IF(B33="","",IFERROR(IF(INDEX(Data!$M$2:$M$745,MATCH(19,Data!$B$2:$B$745,0))="","",INDEX(Data!$M$2:$M$745,MATCH(19,Data!$B$2:$B$745,0))),"")) | Q33: =IF(B33="","",IFERROR(IF(INDEX(Data!$AD$2:$AD$745,MATCH(19,Data!$B$2:$B$745,0))="","",INDEX(Data!$AD$2:$AD$745,MATCH(19,Data!$B$2:$B$745,0))),"")) | R33: =IF(B33="","",IFERROR(IF(INDEX(Data!$L$2:$L$745,MATCH(19,Data!$B$2:$B$745,0))="","",INDEX(Data!$L$2:$L$745,MATCH(19,Data!$B$2:$B$745,0))),"")) | AB33: Brooklinen
