Workbook

Sheet README
A1: BFCM 2026 Competitor Tracker (v1)
A2: Owner: Shayan Rana · Backup: Zarlish · Due Thu Oct 15, 2026 (ClickUp BFCM-2026 › Competitor BFCM tracker) · Built 2026-10-13 from the Command Center (primary) and Data Dive
A4: What it is for
A5: 1. Lift forecast (Erik Oct 8 / Oct 13): tune our BFCM lift per product on what competitors did, not only our own history - deal type, depth and BSR change last BFCM, and how hard they push at events.
A6: 2. Pricing and STR: where competitors set List Price today, how far over their price, and who already sits below our planned BFCM deal price (plan risk P2 'Competitors undercut on heroes' - report only, no regular-price cut without Joseph).
A7: 3. Event watch: one log for Nov 20 - Dec 1 competitor checks.
A9: Tabs
A10: Dashboard - one row per our product: our profile (SKUs, sizes, colours, price, margin), the competitor set, price position, List Price/STR read, our BFCM 2025 lift, Prime Day 2026 visibility lift (ours vs theirs) and Keepa completion.
A11: Competitors - every mapped competitor for every product (Command Center map), with current price / List Price / BSR / weekly units, listing details (variations, age, ads) from Data Dive, ASINsight traffic, Prime Day 2026 visibility, and the yellow BFCM 2025 + STR columns to fill from Keepa.
A12: Our BFCM 2025 - our own result per product: BFCM week vs the 30 days before and vs December, from the Command Center PPC/TACoS data, plus the deals and events the Command Center logged.
A13: Our Daily 2025 - day-by-day Oct 15 - Dec 15, 2025 per product (ad spend, ad sales, orders) to see the shape of the lift.
A14: Visibility History - Command Center daily placement scores summarised per window, per ASIN (organic and advertising). Competitor history starts Jan-Apr 2026, ours goes back to Oct 2025.
... A29: Our BFCM 2025 total sales are derived from the Command Center: ad spend / TACoS. Marked 'derived' wherever used.

Sheet Key Insights
A1: Family | B1: Our product | C1: Topic | D1: Insight (computed from the data on Oct 13, 2026)
A2: All | B2: Portfolio | C2: Our BFCM 2025 lift | D2: BFCM week 2025 daily total sales vs the 30 days before (derived from ad spend / TACoS): DC B4 4.25x, SL Cooling Comforter 3.39x, DC S6 3.08x, DC S4 2.64x, SSS4 2.59x, DC B6 2.49x, DC Satin Fitted 2.47x, DC Cooling 4pc 1.63x, DC Silk Pillowcase 1.35x, SL B6 1.20x, SL Cooling 4pc 1.14x. Ad spend per day rose DC B4 2.4x, SL Cooling Comforter 1.5x, DC S6 2.3x, DC S4 1.2x, SSS4 2.2x, DC B6 2.1x, DC Satin Fitted 1.7x, DC Cooling 4pc 2.2x, DC Silk Pillowcase 1.4x, SL B6 0.6x, SL Cooling 4pc 0.4x - lift came with heavier spend, so read lift and TACoS together.
A3: All | B3: Portfolio | C3: List Price / STR landscape | D3: 155 of 616 mapped competitor rows (25%) carry a List Price above their price. 30 sit within 12% (the band Joseph's study found Amazon shows), 64 are more than 25% over (usually ignored). Median List Price premium where set: 23%. Whether Amazon actually displays each one still needs the page / STR Panel check (Competitors tab, 'STR showing now?').
A4: All | B4: Portfolio | C4: Prime Day 2026 behaviour | D4: 259 competitor rows (86 brands) have Command Center visibility history over Prime Day 2026. Median organic visibility lift Jun 23-26 vs Jun 1-20: 1.07x. Competitor history does not reach BFCM 2025 (starts Jan-Apr 2026), so Prime Day is the closest in-house event read; BFCM 2025 needs Keepa.
A5: Bamboo | B5: Decolure Bamboo Sheets 4 Piece | C5: Who sells the most | D5: Top 5 of 55 mapped rivals by est weekly units: Love's cabin (Beatable) ~924/wk at $37.99, List Price $44.99 (+18%); Bedsure (Aspirational) ~809/wk at $62.99, List Price $69.99 (+11%); Pure Bamboo (Aspirational) ~809/wk at $109.99, no List Price; Hotel Sheets Direct (Aspirational) ~347/wk at $79.99, no List Price; KRIMANO (Beatable) ~185/wk at $84.99, no List Price. Tracked rivals ~5,455 units/wk; we sell ~453/wk (7.7% of the tracked set).
A6: Bamboo | B6: Decolure Bamboo Sheets 4 Piece | C6: List Price / STR | D6: 15 of 55 rivals carry a List Price above price; 3 inside 12%: Bedsure +11%, AiAngu +7%, Kickoff Home +10%. These are the ones most likely to show a strikethrough at BFCM - check them on the page first.
A7: Bamboo | B7: Decolure Bamboo Sheets 4 Piece | C7: Our BFCM 2025 | D7: BFCM week 2025 total sales 4.25x the prior-30-day daily rate; TACoS 6.3% in BFCM week vs 11.2% before; December ran 1.86x the pre-event rate.
A8: Bamboo | B8: Decolure Bamboo Sheets 4 Piece | C8: Prime Day 2026 visibility | D8: Our best child B08KQHRDDG: organic visibility 0.91x over Prime Day vs the 3 weeks before; mapped rivals' median 1.25x (n=14, rivals with a baseline score of 5+). Rivals gained more event visibility than we did.
A9: Bamboo | B9: Decolure Bamboo Sheets 4 Piece | C9: Price position | D9: 29 of 55 rivals are priced below our same-size (or Queen) price today. Our blended price $80.69, contribution $34.45/unit, break-even ACoS 43%.
A10: Bamboo | B10: Decolure Bamboo Sheets 6 Piece | C10: Who sells the most | D10: Top 5 of 46 mapped rivals by est weekly units: Love's cabin (Beatable) ~924/wk at $37.99, List Price $44.99 (+18%); Bedsure (Aspirational) ~809/wk at $62.99, List Price $69.99 (+11%); Pure Bamboo (Aspirational) ~809/wk at $109.99, no List Price; Hotel Sheets Direct (Aspirational) ~347/wk at $79.99, no List Price; KRIMANO (Beatable) ~185/wk at $84.99, no List Price. Tracked rivals ~4,821 units/wk; we sell ~476/wk (9.0% of the tracked set).
A11: Bamboo | B11: Decolure Bamboo Sheets 6 Piece | C11: List Price / STR | D11: 14 of 46 rivals carry a List Price above price; 3 inside 12%: Bedsure +11%, AiAngu +7%, Kickoff Home +10%. These are the ones most likely to show a strikethrough at BFCM - check them on the page first.
A12: Bamboo | B12: Decolure Bamboo Sheets 6 Piece | C12: Our BFCM 2025 | D12: BFCM week 2025 total sales 2.49x the prior-30-day daily rate; TACoS 6.4% in BFCM week vs 7.4% before; December ran 1.36x the pre-event rate.
... A91: Other | B91: Decolure Waterproof Chair Cover | C91: List Price / STR | D91: 5 of 23 rivals carry a List Price above price; 0 inside 12%. These are the ones most likely to show a strikethrough at BFCM - check them on the page first.
A93: Computed at build time from the Command Center (rosters, prices, List Price, est weekly units, our PPC/TACoS, visibility) and Data Dive. Estimates are estimates; Keepa fills the BFCM 2025 competitor history.

Sheet Dashboard
A1: PRODUCT | E1: OUR PRODUCT - Command Center | N1: COMPETITOR SET + OUR HISTORY (formulas) | AE1: COMPETITOR SET + OUR HISTORY (formulas)
A2: Family | B2: Our product | C2: Prod ID | D2: BFCM role (plan) | E2: Stage | F2: Our parent ASIN | G2: Our SKUs (variations) | H2: Sizes | I2: Colours | J2: Our blended price ($) | K2: Contribution / unit ($) | L2: Break-even ACoS | M2: Our units 28d | N2: Competitors mapped | O2: Aspirational | P2: Beatable | Q2: Poor | R2: Comp median price ($) | S2: Our price vs comp median | T2: Comps priced below us (same size) | U2: Comps with List Price set | V2: of which <=12% over (STR zone) | W2: Comp avg List Price % over | X2: Comp est weekly units (sum) | Y2: Our weekly units (28d/4) | Z2: Our share of tracked units | AA2: Comp median variations (DD) | AB2: Our BFCM 2025 lift (daily sales vs 30d pre) | AC2: Our BFCM 2025 TACoS | AD2: Our PD 2026 organic vis lift | AE2: Comp median PD 2026 organic vis lift | AF2: Keepa rows filled | AG2: Comp avg BFCM 2025 discount | AH2: Comp avg BFCM 2025 BSR lift
A3: Bamboo | B3: Decolure Bamboo Sheets 4 Piece | C3: 59 | D3: Hero: rank and profit | E3: Re-Launch | F3: B0BZQ1G5B8 | G3: 81 | H3: 5 | I3: 16 | J3: 80.694292 | K3: 34.445844 | L3: 0.42686841 | M3: 1813 | N3: =COUNTIF(Competitors!$C$3:$C$618,$C3) -> 55 | O3: =COUNTIFS(Competitors!$C$3:$C$618,$C3,Competitors!$J$3:$J$618,"Aspirational") -> 3 | P3: =COUNTIFS(Competitors!$C$3:$C$618,$C3,Competitors!$J$3:$J$618,"Beatable") -> 24 | Q3: =COUNTIFS(Competitors!$C$3:$C$618,$C3,Competitors!$J$3:$J$618,"Poor") -> 18 | R3: 79.99 | S3: =IF(AND(ISNUMBER(J3),ISNUMBER(R3),R3>0),J3/R3-1,"") -> 0.0088047455 | T3: =COUNTIFS(Competitors!$C$3:$C$618,$C3,Competitors!$Q$3:$Q$618,"<0") -> 29 | U3: =COUNTIFS(Competitors!$C$3:$C$618,$C3,Competitors!$M$3:$M$618,">0") -> 15 | V3: =COUNTIFS(Competitors!$C$3:$C$618,$C3,Competitors!$M$3:$M$618,">0",Competitors!$M$3:$M$618,"<=0.12") -> 3 | W3: =IFERROR(AVERAGEIFS(Competitors!$M$3:$M$618,Competitors!$C$3:$C$618,$C3,Competitors!$M$3:$M$618,">0"),"") -> 0.22158824 | X3: =SUMIF(Competitors!$C$3:$C$618,$C3,Competitors!$T$3:$T$618) -> 5455 | Y3: =IF(ISNUMBER(M3),M3/4,"") -> 453.25 | Z3: =IF(AND(ISNUMBER(Y3),X3>0),Y3/(Y3+X3),"") -> 0.076714763 | AA3: 56 | AB3: =IFERROR(IF(N(INDEX('Our BFCM 2025'!$S:$S,MATCH($C3,'Our BFCM 2025'!$C:$C,0)))=0,"",INDEX('Our BFCM 2025'!$S:$S,MATCH($C3,'Our BFCM 2025'!$C:$C,0))),"") -> 4.2549984 | AC3: =IFERROR(IF(N(INDEX('Our BFCM 2025'!$H:$H,MATCH($C3,'Our BFCM 2025'!$C:$C,0)))=0,"",INDEX('Our BFCM 2025'!$H:$H,MATCH($C3,'Our BFCM 2025'!$C:$C,0))),"") -> 0.062528589 | AD3: 0.90814196 | AE3: 1.2462863 | AF3: =COUNTIFS(Competitors!$C$3:$C$618,$C3,Competitors!$AY$3:$AY$618,"<>") -> 0 | AG3: =IFERROR(AVERAGEIFS(Competitors!$BD$3:$BD$618,Competitors!$C$3:$C$618,$C3),"") | AH3: =IFERROR(AVERAGEIFS(Competitors!$BH$3:$BH$618,Competitors!$C$3:$C$618,$C3),"")
A4: Bamboo | B4: Decolure Bamboo Sheets 6 Piece | C4: 30 | D4: Hero: rank and profit | E4: Re-Launch | F4: B0CQ31D5FM | G4: 86 | H4: 6 | I4: 17 | J4: 89.529424 | K4: 36.930305 | L4: 0.41249349 | M4: 1905 | N4: =COUNTIF(Competitors!$C$3:$C$618,$C4) -> 46 | O4: =COUNTIFS(Competitors!$C$3:$C$618,$C4,Competitors!$J$3:$J$618,"Aspirational") -> 4 | P4: =COUNTIFS(Competitors!$C$3:$C$618,$C4,Competitors!$J$3:$J$618,"Beatable") -> 24 | Q4: =COUNTIFS(Competitors!$C$3:$C$618,$C4,Competitors!$J$3:$J$618,"Poor") -> 18 | R4: 82.485 | S4: =IF(AND(ISNUMBER(J4),ISNUMBER(R4),R4>0),J4/R4-1,"") -> 0.08540248 | T4: =COUNTIFS(Competitors!$C$3:$C$618,$C4,Competitors!$Q$3:$Q$618,"<0") -> 29 | U4: =COUNTIFS(Competitors!$C$3:$C$618,$C4,Competitors!$M$3:$M$618,">0") -> 14 | V4: =COUNTIFS(Competitors!$C$3:$C$618,$C4,Competitors!$M$3:$M$618,">0",Competitors!$M$3:$M$618,"<=0.12") -> 3 | W4: =IFERROR(AVERAGEIFS(Competitors!$M$3:$M$618,Competitors!$C$3:$C$618,$C4,Competitors!$M$3:$M$618,">0"),"") -> 0.21955417 | X4: =SUMIF(Competitors!$C$3:$C$618,$C4,Competitors!$T$3:$T$618) -> 4821 | Y4: =IF(ISNUMBER(M4),M4/4,"") -> 476.25 | Z4: =IF(AND(ISNUMBER(Y4),X4>0),Y4/(Y4+X4),"") -> 0.089905139 | AA4: 52.5 | AB4: =IFERROR(IF(N(INDEX('Our BFCM 2025'!$S:$S,MATCH($C4,'Our BFCM 2025'!$C:$C,0)))=0,"",INDEX('Our BFCM 2025'!$S:$S,MATCH($C4,'Our BFCM 2025'!$C:$C,0))),"") -> 2.4883024 | AC4: =IFERROR(IF(N(INDEX('Our BFCM 2025'!$H:$H,MATCH($C4,'Our BFCM 2025'!$C:$C,0)))=0,"",INDEX('Our BFCM 2025'!$H:$H,MATCH($C4,'Our BFCM 2025'!$C:$C,0))),"") -> 0.064032365 | AD4: 1.4420922 | AE4: 1.2462863 | AF4: =COUNTIFS(Competitors!$C$3:$C$618,$C4,Competitors!$AY$3:$AY$618,"<>") -> 0 | AG4: =IFERROR(AVERAGEIFS(Competitors!$BD$3:$BD$618,Competitors!$C$3:$C$618,$C4),"") | AH4: =IFERROR(AVERAGEIFS(Competitors!$BH$3:$BH$618,Competitors!$C$3:$C$618,$C4),"")
A5: Bamboo | B5: Sleephoria Bamboo Sheets 6 Piece | C5: 32 | D5: Core | E5: Re-Launch | F5: B0DDTY8HFR | G5: 78 | H5: 5 | I5: 16 | J5: 67.067922 | K5: 15.992987 | L5: 0.23845956 | M5: 91 | N5: =COUNTIF(Competitors!$C$3:$C$618,$C5) -> 30 | O5: =COUNTIFS(Competitors!$C$3:$C$618,$C5,Competitors!$J$3:$J$618,"Aspirational") -> 4 | P5: =COUNTIFS(Competitors!$C$3:$C$618,$C5,Competitors!$J$3:$J$618,"Beatable") -> 8 | Q5: =COUNTIFS(Competitors!$C$3:$C$618,$C5,Competitors!$J$3:$J$618,"Poor") -> 18 | R5: 79.99 | S5: =IF(AND(ISNUMBER(J5),ISNUMBER(R5),R5>0),J5/R5-1,"") -> -0.16154617 | T5: =COUNTIFS(Competitors!$C$3:$C$618,$C5,Competitors!$Q$3:$Q$618,"<0") -> 9 | U5: =COUNTIFS(Competitors!$C$3:$C$618,$C5,Competitors!$M$3:$M$618,">0") -> 8 | V5: =COUNTIFS(Competitors!$C$3:$C$618,$C5,Competitors!$M$3:$M$618,">0",Competitors!$M$3:$M$618,"<=0.12") -> 2 | W5: =IFERROR(AVERAGEIFS(Competitors!$M$3:$M$618,Competitors!$C$3:$C$618,$C5,Competitors!$M$3:$M$618,">0"),"") -> 0.23466751 | X5: =SUMIF(Competitors!$C$3:$C$618,$C5,Competitors!$T$3:$T$618) -> 2409 | Y5: =IF(ISNUMBER(M5),M5/4,"") -> 22.75 | Z5: =IF(AND(ISNUMBER(Y5),X5>0),Y5/(Y5+X5),"") -> 0.0093554025 | AA5: 42.5 | AB5: =IFERROR(IF(N(INDEX('Our BFCM 2025'!$S:$S,MATCH($C5,'Our BFCM 2025'!$C:$C,0)))=0,"",INDEX('Our BFCM 2025'!$S:$S,MATCH($C5,'Our BFCM 2025'!$C:$C,0))),"") -> 1.20129 | AC5: =IFERROR(IF(N(INDEX('Our BFCM 2025'!$H:$H,MATCH($C5,'Our BFCM 2025'!$C:$C,0)))=0,"",INDEX('Our BFCM 2025'!$H:$H,MATCH($C5,'Our BFCM 2025'!$C:$C,0))),"") -> 0.18701621 | AD5: 0.19871795 | AE5: 1.3148085 | AF5: =COUNTIFS(Competitors!$C$3:$C$618,$C5,Competitors!$AY$3:$AY$618,"<>") -> 0 | AG5: =IFERROR(AVERAGEIFS(Competitors!$BD$3:$BD$618,Competitors!$C$3:$C$618,$C5),"") | AH5: =IFERROR(AVERAGEIFS(Competitors!$BH$3:$BH$618,Competitors!$C$3:$C$618,$C5),"")
A6: Bamboo | B6: Sleephoria Bamboo Sheets 4 Piece | C6: 36 | D6: Core | E6: Production | F6: B0DDTRVWNR | G6: 84 | H6: 5 | I6: 16 | J6: 54.99 | K6: 15.91 | L6: 0.28932533 | M6: 2 | N6: =COUNTIF(Competitors!$C$3:$C$618,$C6) -> 28 | O6: =COUNTIFS(Competitors!$C$3:$C$618,$C6,Competitors!$J$3:$J$618,"Aspirational") -> 2 | P6: =COUNTIFS(Competitors!$C$3:$C$618,$C6,Competitors!$J$3:$J$618,"Beatable") -> 8 | Q6: =COUNTIFS(Competitors!$C$3:$C$618,$C6,Competitors!$J$3:$J$618,"Poor") -> 18 | R6: 79.99 | S6: =IF(AND(ISNUMBER(J6),ISNUMBER(R6),R6>0),J6/R6-1,"") -> -0.31253907 | T6: =COUNTIFS(Competitors!$C$3:$C$618,$C6,Competitors!$Q$3:$Q$618,"<0") -> 4 | U6: =COUNTIFS(Competitors!$C$3:$C$618,$C6,Competitors!$M$3:$M$618,">0") -> 8 | V6: =COUNTIFS(Competitors!$C$3:$C$618,$C6,Competitors!$M$3:$M$618,">0",Competitors!$M$3:$M$618,"<=0.12") -> 2 | W6: =IFERROR(AVERAGEIFS(Competitors!$M$3:$M$618,Competitors!$C$3:$C$618,$C6,Competitors!$M$3:$M$618,">0"),"") -> 0.23466751 | X6: =SUMIF(Competitors!$C$3:$C$618,$C6,Competitors!$T$3:$T$618) -> 2399 | Y6: =IF(ISNUMBER(M6),M6/4,"") -> 0.5 | Z6: =IF(AND(ISNUMBER(Y6),X6>0),Y6/(Y6+X6),"") -> 0.00020837675 | AA6: 42.5 | AB6: =IFERROR(IF(N(INDEX('Our BFCM 2025'!$S:$S,MATCH($C6,'Our BFCM 2025'!$C:$C,0)))=0,"",INDEX('Our BFCM 2025'!$S:$S,MATCH($C6,'Our BFCM 2025'!$C:$C,0))),"") | AC6: =IFERROR(IF(N(INDEX('Our BFCM 2025'!$H:$H,MATCH($C6,'Our BFCM 2025'!$C:$C,0)))=0,"",INDEX('Our BFCM 2025'!$H:$H,MATCH($C6,'Our BFCM 2025'!$C:$C,0))),"") | AE6: 1.3148085 | AF6: =COUNTIFS(Competitors!$C$3:$C$618,$C6,Competitors!$AY$3:$AY$618,"<>") -> 0 | AG6: =IFERROR(AVERAGEIFS(Competitors!$BD$3:$BD$618,Competitors!$C$3:$C$618,$C6),"") | AH6: =IFERROR(AVERAGEIFS(Competitors!$BH$3:$BH$618,Competitors!$C$3:$C$618,$C6),"")
A7: Bamboo | B7: Decolure Bamboo Fitted Sheet | C7: 73 | D7: Excluded (ranking variations OOS to Dec 3) | E7: Launch | F7: B0FX2T8CG8 | G7: 22 | H7: 2 | I7: 11 | M7: 102 | N7: =COUNTIF(Competitors!$C$3:$C$618,$C7) -> 15 | O7: =COUNTIFS(Competitors!$C$3:$C$618,$C7,Competitors!$J$3:$J$618,"Aspirational") -> 3 | P7: =COUNTIFS(Competitors!$C$3:$C$618,$C7,Competitors!$J$3:$J$618,"Beatable") -> 9 | Q7: =COUNTIFS(Competitors!$C$3:$C$618,$C7,Competitors!$J$3:$J$618,"Poor") -> 1 | R7: 74.99 | S7: =IF(AND(ISNUMBER(J7),ISNUMBER(R7),R7>0),J7/R7-1,"") | T7: =COUNTIFS(Competitors!$C$3:$C$618,$C7,Competitors!$Q$3:$Q$618,"<0") -> 0 | U7: =COUNTIFS(Competitors!$C$3:$C$618,$C7,Competitors!$M$3:$M$618,">0") -> 5 | V7: =COUNTIFS(Competitors!$C$3:$C$618,$C7,Competitors!$M$3:$M$618,">0",Competitors!$M$3:$M$618,"<=0.12") -> 2 | W7: =IFERROR(AVERAGEIFS(Competitors!$M$3:$M$618,Competitors!$C$3:$C$618,$C7,Competitors!$M$3:$M$618,">0"),"") -> 0.2538565 | X7: =SUMIF(Competitors!$C$3:$C$618,$C7,Competitors!$T$3:$T$618) -> 2428 | Y7: =IF(ISNUMBER(M7),M7/4,"") -> 25.5 | Z7: =IF(AND(ISNUMBER(Y7),X7>0),Y7/(Y7+X7),"") -> 0.010393316 | AA7: 104 | AB7: =IFERROR(IF(N(INDEX('Our BFCM 2025'!$S:$S,MATCH($C7,'Our BFCM 2025'!$C:$C,0)))=0,"",INDEX('Our BFCM 2025'!$S:$S,MATCH($C7,'Our BFCM 2025'!$C:$C,0))),"") | AC7: =IFERROR(IF(N(INDEX('Our BFCM 2025'!$H:$H,MATCH($C7,'Our BFCM 2025'!$C:$C,0)))=0,"",INDEX('Our BFCM 2025'!$H:$H,MATCH($C7,'Our BFCM 2025'!$C:$C,0))),"") | AE7: 1.2415672 | AF7: =COUNTIFS(Competitors!$C$3:$C$618,$C7,Competitors!$AY$3:$AY$618,"<>") -> 0 | AG7: =IFERROR(AVERAGEIFS(Competitors!$BD$3:$BD$618,Competitors!$C$3:$C$618,$C7),"") | AH7: =IFERROR(AVERAGEIFS(Competitors!$BH$3:$BH$618,Competitors!$C$3:$C$618,$C7),"")
A8: Bamboo | B8: Sleephoria Bamboo Pillowcases | C8: 40 | D8: Other | E8: Production | F8: B0FX2RDXXR | G8: 54 | H8: 3 | I8: 18 | M8: 0 | N8: =COUNTIF(Competitors!$C$3:$C$618,$C8) -> 6 | O8: =COUNTIFS(Competitors!$C$3:$C$618,$C8,Competitors!$J$3:$J$618,"Aspirational") -> 0 | P8: =COUNTIFS(Competitors!$C$3:$C$618,$C8,Competitors!$J$3:$J$618,"Beatable") -> 0 | Q8: =COUNTIFS(Competitors!$C$3:$C$618,$C8,Competitors!$J$3:$J$618,"Poor") -> 0 | R8: 13.49 | S8: =IF(AND(ISNUMBER(J8),ISNUMBER(R8),R8>0),J8/R8-1,"") | T8: =COUNTIFS(Competitors!$C$3:$C$618,$C8,Competitors!$Q$3:$Q$618,"<0") -> 0 | U8: =COUNTIFS(Competitors!$C$3:$C$618,$C8,Competitors!$M$3:$M$618,">0") -> 2 | V8: =COUNTIFS(Competitors!$C$3:$C$618,$C8,Competitors!$M$3:$M$618,">0",Competitors!$M$3:$M$618,"<=0.12") -> 0 | W8: =IFERROR(AVERAGEIFS(Competitors!$M$3:$M$618,Competitors!$C$3:$C$618,$C8,Competitors!$M$3:$M$618,">0"),"") -> 0.44539162 | X8: =SUMIF(Competitors!$C$3:$C$618,$C8,Competitors!$T$3:$T$618) -> 3217 | Y8: =IF(ISNUMBER(M8),M8/4,"") -> 0 | Z8: =IF(AND(ISNUMBER(Y8),X8>0),Y8/(Y8+X8),"") -> 0 | AA8: 64 | AB8: =IFERROR(IF(N(INDEX('Our BFCM 2025'!$S:$S,MATCH($C8,'Our BFCM 2025'!$C:$C,0)))=0,"",INDEX('Our BFCM 2025'!$S:$S,MATCH($C8,'Our BFCM 2025'!$C:$C,0))),"") | AC8: =IFERROR(IF(N(INDEX('Our BFCM 2025'!$H:$H,MATCH($C8,'Our BFCM 2025'!$C:$C,0)))=0,"",INDEX('Our BFCM 2025'!$H:$H,MATCH($C8,'Our BFCM 2025'!$C:$C,0))),"") | AE8: 1.0414909 | AF8: =COUNTIFS(Competitors!$C$3:$C$618,$C8,Competitors!$AY$3:$AY$618,"<>") -> 0 | AG8: =IFERROR(AVERAGEIFS(Competitors!$BD$3:$BD$618,Competitors!$C$3:$C$618,$C8),"") | AH8: =IFERROR(AVERAGEIFS(Competitors!$BH$3:$BH$618,Competitors!$C$3:$C$618,$C8),"")
A9: Satin | B9: Decolure Satin Sheets 4 Piece | C9: 37 | D9: Clearance with margin | E9: Maintenance | F9: B0CQRY9WLD | G9: 125 | H9: 4 | I9: 29 | J9: 32.03725 | K9: 10.823128 | L9: 0.33782951 | M9: 2627 | N9: =COUNTIF(Competitors!$C$3:$C$618,$C9) -> 26 | O9: =COUNTIFS(Competitors!$C$3:$C$618,$C9,Competitors!$J$3:$J$618,"Aspirational") -> 3 | P9: =COUNTIFS(Competitors!$C$3:$C$618,$C9,Competitors!$J$3:$J$618,"Beatable") -> 13 | Q9: =COUNTIFS(Competitors!$C$3:$C$618,$C9,Competitors!$J$3:$J$618,"Poor") -> 8 | R9: 22.49 | S9: =IF(AND(ISNUMBER(J9),ISNUMBER(R9),R9>0),J9/R9-1,"") -> 0.42451089 | T9: =COUNTIFS(Competitors!$C$3:$C$618,$C9,Competitors!$Q$3:$Q$618,"<0") -> 26 | U9: =COUNTIFS(Competitors!$C$3:$C$618,$C9,Competitors!$M$3:$M$618,">0") -> 3 | V9: =COUNTIFS(Competitors!$C$3:$C$618,$C9,Competitors!$M$3:$M$618,">0",Competitors!$M$3:$M$618,"<=0.12") -> 0 | W9: =IFERROR(AVERAGEIFS(Competitors!$M$3:$M$618,Competitors!$C$3:$C$618,$C9,Competitors!$M$3:$M$618,">0"),"") -> 0.25953488 | X9: =SUMIF(Competitors!$C$3:$C$618,$C9,Competitors!$T$3:$T$618) -> 4991 | Y9: =IF(ISNUMBER(M9),M9/4,"") -> 656.75 | Z9: =IF(AND(ISNUMBER(Y9),X9>0),Y9/(Y9+X9),"") -> 0.11628525 | AA9: 105.5 | AB9: =IFERROR(IF(N(INDEX('Our BFCM 2025'!$S:$S,MATCH($C9,'Our BFCM 2025'!$C:$C,0)))=0,"",INDEX('Our BFCM 2025'!$S:$S,MATCH($C9,'Our BFCM 2025'!$C:$C,0))),"") -> 2.6361338 | AC9: =IFERROR(IF(N(INDEX('Our BFCM 2025'!$H:$H,MATCH($C9,'Our BFCM 2025'!$C:$C,0)))=0,"",INDEX('Our BFCM 2025'!$H:$H,MATCH($C9,'Our BFCM 2025'!$C:$C,0))),"") -> 0.048605254 | AD9: 1.242515 | AE9: 0.98611111 | AF9: =COUNTIFS(Competitors!$C$3:$C$618,$C9,Competitors!$AY$3:$AY$618,"<>") -> 0 | AG9: =IFERROR(AVERAGEIFS(Competitors!$BD$3:$BD$618,Competitors!$C$3:$C$618,$C9),"") | AH9: =IFERROR(AVERAGEIFS(Competitors!$BH$3:$BH$618,Competitors!$C$3:$C$618,$C9),"")
A10: Satin | B10: Decolure Satin Sheets 6 Piece | C10: 31 | D10: Clearance with margin | E10: Maintenance | F10: B0D9QQWYP4 | G10: 111 | H10: 4 | I10: 29 | J10: 32.904322 | K10: 9.0015031 | L10: 0.27356599 | M10: 479 | N10: =COUNTIF(Competitors!$C$3:$C$618,$C10) -> 26 | O10: =COUNTIFS(Competitors!$C$3:$C$618,$C10,Competitors!$J$3:$J$618,"Aspirational") -> 6 | P10: =COUNTIFS(Competitors!$C$3:$C$618,$C10,Competitors!$J$3:$J$618,"Beatable") -> 16 | Q10: =COUNTIFS(Competitors!$C$3:$C$618,$C10,Competitors!$J$3:$J$618,"Poor") -> 2 | R10: 22.49 | S10: =IF(AND(ISNUMBER(J10),ISNUMBER(R10),R10>0),J10/R10-1,"") -> 0.46306454 | T10: =COUNTIFS(Competitors!$C$3:$C$618,$C10,Competitors!$Q$3:$Q$618,"<0") -> 26 | U10: =COUNTIFS(Competitors!$C$3:$C$618,$C10,Competitors!$M$3:$M$618,">0") -> 3 | V10: =COUNTIFS(Competitors!$C$3:$C$618,$C10,Competitors!$M$3:$M$618,">0",Competitors!$M$3:$M$618,"<=0.12") -> 0 | W10: =IFERROR(AVERAGEIFS(Competitors!$M$3:$M$618,Competitors!$C$3:$C$618,$C10,Competitors!$M$3:$M$618,">0"),"") -> 0.25953488 | X10: =SUMIF(Competitors!$C$3:$C$618,$C10,Competitors!$T$3:$T$618) -> 4991 | Y10: =IF(ISNUMBER(M10),M10/4,"") -> 119.75 | Z10: =IF(AND(ISNUMBER(Y10),X10>0),Y10/(Y10+X10),"") -> 0.023431003 | AA10: 105.5 | AB10: =IFERROR(IF(N(INDEX('Our BFCM 2025'!$S:$S,MATCH($C10,'Our BFCM 2025'!$C:$C,0)))=0,"",INDEX('Our BFCM 2025'!$S:$S,MATCH($C10,'Our BFCM 2025'!$C:$C,0))),"") -> 3.084742 | AC10: =IFERROR(IF(N(INDEX('Our BFCM 2025'!$H:$H,MATCH($C10,'Our BFCM 2025'!$C:$C,0)))=0,"",INDEX('Our BFCM 2025'!$H:$H,MATCH($C10,'Our BFCM 2025'!$C:$C,0))),"") -> 0.14844922 | AD10: 1.215748 | AE10: 0.98611111 | AF10: =COUNTIFS(Competitors!$C$3:$C$618,$C10,Competitors!$AY$3:$AY$618,"<>") -> 0 | AG10: =IFERROR(AVERAGEIFS(Competitors!$BD$3:$BD$618,Competitors!$C$3:$C$618,$C10),"") | AH10: =IFERROR(AVERAGEIFS(Competitors!$BH$3:$BH$618,Competitors!$C$3:$C$618,$C10),"")
A11: Satin | B11: Sleephoria Satin Sheets 4 Piece | C11: 39 | D11: Clearance with margin | E11: Maintenance | F11: B0DDR4HJCS | G11: 116 | H11: 4 | I11: 29 | J11: 37.055714 | K11: 13.852086 | L11: 0.3738178 | M11: 700 | N11: =COUNTIF(Competitors!$C$3:$C$618,$C11) -> 29 | O11: =COUNTIFS(Competitors!$C$3:$C$618,$C11,Competitors!$J$3:$J$618,"Aspirational") -> 5 | P11: =COUNTIFS(Competitors!$C$3:$C$618,$C11,Competitors!$J$3:$J$618,"Beatable") -> 8 | Q11: =COUNTIFS(Competitors!$C$3:$C$618,$C11,Competitors!$J$3:$J$618,"Poor") -> 16 | R11: 21.99 | S11: =IF(AND(ISNUMBER(J11),ISNUMBER(R11),R11>0),J11/R11-1,"") -> 0.68511661 | T11: =COUNTIFS(Competitors!$C$3:$C$618,$C11,Competitors!$Q$3:$Q$618,"<0") -> 29 | U11: =COUNTIFS(Competitors!$C$3:$C$618,$C11,Competitors!$M$3:$M$618,">0") -> 4 | V11: =COUNTIFS(Competitors!$C$3:$C$618,$C11,Competitors!$M$3:$M$618,">0",Competitors!$M$3:$M$618,"<=0.12") -> 0 | W11: =IFERROR(AVERAGEIFS(Competitors!$M$3:$M$618,Competitors!$C$3:$C$618,$C11,Competitors!$M$3:$M$618,">0"),"") -> 0.25738583 | X11: =SUMIF(Competitors!$C$3:$C$618,$C11,Competitors!$T$3:$T$618) -> 5309 | Y11: =IF(ISNUMBER(M11),M11/4,"") -> 175 | Z11: =IF(AND(ISNUMBER(Y11),X11>0),Y11/(Y11+X11),"") -> 0.031911014 | AA11: 101.5 | AB11: =IFERROR(IF(N(INDEX('Our BFCM 2025'!$S:$S,MATCH($C11,'Our BFCM 2025'!$C:$C,0)))=0,"",INDEX('Our BFCM 2025'!$S:$S,MATCH($C11,'Our BFCM 2025'!$C:$C,0))),"") -> 2.5897224 | AC11: =IFERROR(IF(N(INDEX('Our BFCM 2025'!$H:$H,MATCH($C11,'Our BFCM 2025'!$C:$C,0)))=0,"",INDEX('Our BFCM 2025'!$H:$H,MATCH($C11,'Our BFCM 2025'!$C:$C,0))),"") -> 0.15765549 | AD11: 0.944 | AE11: 1.0089286 | AF11: =COUNTIFS(Competitors!$C$3:$C$618,$C11,Competitors!$AY$3:$AY$618,"<>") -> 0 | AG11: =IFERROR(AVERAGEIFS(Competitors!$BD$3:$BD$618,Competitors!$C$3:$C$618,$C11),"") | AH11: =IFERROR(AVERAGEIFS(Competitors!$BH$3:$BH$618,Competitors!$C$3:$C$618,$C11),"")
A12: Satin | B12: Sleephoria Satin Sheets 6pcs | C12: 74 | D12: Clearance with margin | E12: Production | F12: B0H41WN38B | G12: 116 | H12: 4 | I12: 29 | M12: 0 | N12: =COUNTIF(Competitors!$C$3:$C$618,$C12) -> 27 | O12: =COUNTIFS(Competitors!$C$3:$C$618,$C12,Competitors!$J$3:$J$618,"Aspirational") -> 0 | P12: =COUNTIFS(Competitors!$C$3:$C$618,$C12,Competitors!$J$3:$J$618,"Beatable") -> 0 | Q12: =COUNTIFS(Competitors!$C$3:$C$618,$C12,Competitors!$J$3:$J$618,"Poor") -> 0 | R12: 21.99 | S12: =IF(AND(ISNUMBER(J12),ISNUMBER(R12),R12>0),J12/R12-1,"") | T12: =COUNTIFS(Competitors!$C$3:$C$618,$C12,Competitors!$Q$3:$Q$618,"<0") -> 0 | U12: =COUNTIFS(Competitors!$C$3:$C$618,$C12,Competitors!$M$3:$M$618,">0") -> 4 | V12: =COUNTIFS(Competitors!$C$3:$C$618,$C12,Competitors!$M$3:$M$618,">0",Competitors!$M$3:$M$618,"<=0.12") -> 0 | W12: =IFERROR(AVERAGEIFS(Competitors!$M$3:$M$618,Competitors!$C$3:$C$618,$C12,Competitors!$M$3:$M$618,">0"),"") -> 0.25738583 | X12: =SUMIF(Competitors!$C$3:$C$618,$C12,Competitors!$T$3:$T$618) -> 5286 | Y12: =IF(ISNUMBER(M12),M12/4,"") -> 0 | Z12: =IF(AND(ISNUMBER(Y12),X12>0),Y12/(Y12+X12),"") -> 0 | AA12: 107 | AB12: =IFERROR(IF(N(INDEX('Our BFCM 2025'!$S:$S,MATCH($C12,'Our BFCM 2025'!$C:$C,0)))=0,"",INDEX('Our BFCM 2025'!$S:$S,MATCH($C12,'Our BFCM 2025'!$C:$C,0))),"") | AC12: =IFERROR(IF(N(INDEX('Our BFCM 2025'!$H:$H,MATCH($C12,'Our BFCM 2025'!$C:$C,0)))=0,"",INDEX('Our BFCM 2025'!$H:$H,MATCH($C12,'Our BFCM 2025'!$C:$C,0))),"") | AE12: 1.0178571 | AF12: =COUNTIFS(Competitors!$C$3:$C$618,$C12,Competitors!$AY$3:$AY$618,"<>") -> 0 | AG12: =IFERROR(AVERAGEIFS(Competitors!$BD$3:$BD$618,Competitors!$C$3:$C$618,$C12),"") | AH12: =IFERROR(AVERAGEIFS(Competitors!$BH$3:$BH$618,Competitors!$C$3:$C$618,$C12),"")
A13: Satin | B13: Decolure Satin Fitted Sheet | C13: 38 | D13: Opportunistic | E13: Maintenance | F13: B0DBVZV66D | G13: 68 | H13: 4 | I13: 17 | J13: 19.344242 | K13: 5.9104216 | L13: 0.30553906 | M13: 759 | N13: =COUNTIF(Competitors!$C$3:$C$618,$C13) -> 14 | O13: =COUNTIFS(Competitors!$C$3:$C$618,$C13,Competitors!$J$3:$J$618,"Aspirational") -> 0 | P13: =COUNTIFS(Competitors!$C$3:$C$618,$C13,Competitors!$J$3:$J$618,"Beatable") -> 5 | Q13: =COUNTIFS(Competitors!$C$3:$C$618,$C13,Competitors!$J$3:$J$618,"Poor") -> 5 | R13: 16.055 | S13: =IF(AND(ISNUMBER(J13),ISNUMBER(R13),R13>0),J13/R13-1,"") -> 0.2048734 | T13: =COUNTIFS(Competitors!$C$3:$C$618,$C13,Competitors!$Q$3:$Q$618,"<0") -> 12 | U13: =COUNTIFS(Competitors!$C$3:$C$618,$C13,Competitors!$M$3:$M$618,">0") -> 2 | V13: =COUNTIFS(Competitors!$C$3:$C$618,$C13,Competitors!$M$3:$M$618,">0",Competitors!$M$3:$M$618,"<=0.12") -> 0 | W13: =IFERROR(AVERAGEIFS(Competitors!$M$3:$M$618,Competitors!$C$3:$C$618,$C13,Competitors!$M$3:$M$618,">0"),"") -> 0.24512216 | X13: =SUMIF(Competitors!$C$3:$C$618,$C13,Competitors!$T$3:$T$618) -> 4248 | Y13: =IF(ISNUMBER(M13),M13/4,"") -> 189.75 | Z13: =IF(AND(ISNUMBER(Y13),X13>0),Y13/(Y13+X13),"") -> 0.042758154 | AA13: 128 | AB13: =IFERROR(IF(N(INDEX('Our BFCM 2025'!$S:$S,MATCH($C13,'Our BFCM 2025'!$C:$C,0)))=0,"",INDEX('Our BFCM 2025'!$S:$S,MATCH($C13,'Our BFCM 2025'!$C:$C,0))),"") -> 2.4693337 | AC13: =IFERROR(IF(N(INDEX('Our BFCM 2025'!$H:$H,MATCH($C13,'Our BFCM 2025'!$C:$C,0)))=0,"",INDEX('Our BFCM 2025'!$H:$H,MATCH($C13,'Our BFCM 2025'!$C:$C,0))),"") -> 0.077837782 | AD13: 1.0769231 | AE13: 1.1167535 | AF13: =COUNTIFS(Competitors!$C$3:$C$618,$C13,Competitors!$AY$3:$AY$618,"<>") -> 0 | AG13: =IFERROR(AVERAGEIFS(Competitors!$BD$3:$BD$618,Competitors!$C$3:$C$618,$C13),"") | AH13: =IFERROR(AVERAGEIFS(Competitors!$BH$3:$BH$618,Competitors!$C$3:$C$618,$C13),"")
A14: Silk | B14: Decolure Silk Pillowcase | C14: 55 | D14: Gifting | E14: Re-Launch | F14: B0DBR7PBVP | G14: 18 | H14: 3 | I14: 6 | J14: 50.203448 | K14: 18.460172 | L14: 0.36770726 | M14: 125 | N14: =COUNTIF(Competitors!$C$3:$C$618,$C14) -> 29 | O14: =COUNTIFS(Competitors!$C$3:$C$618,$C14,Competitors!$J$3:$J$618,"Aspirational") -> 5 | P14: =COUNTIFS(Competitors!$C$3:$C$618,$C14,Competitors!$J$3:$J$618,"Beatable") -> 6 | Q14: =COUNTIFS(Competitors!$C$3:$C$618,$C14,Competitors!$J$3:$J$618,"Poor") -> 1 | R14: 21.99 | S14: =IF(AND(ISNUMBER(J14),ISNUMBER(R14),R14>0),J14/R14-1,"") -> 1.2830127 | T14: =COUNTIFS(Competitors!$C$3:$C$618,$C14,Competitors!$Q$3:$Q$618,"<0") -> 25 | U14: =COUNTIFS(Competitors!$C$3:$C$618,$C14,Competitors!$M$3:$M$618,">0") -> 2 | V14: =COUNTIFS(Competitors!$C$3:$C$618,$C14,Competitors!$M$3:$M$618,">0",Competitors!$M$3:$M$618,"<=0.12") -> 2 | W14: =IFERROR(AVERAGEIFS(Competitors!$M$3:$M$618,Competitors!$C$3:$C$618,$C14,Competitors!$M$3:$M$618,">0"),"") -> 0.071286099 | X14: =SUMIF(Competitors!$C$3:$C$618,$C14,Competitors!$T$3:$T$618) -> 9718 | Y14: =IF(ISNUMBER(M14),M14/4,"") -> 31.25 | Z14: =IF(AND(ISNUMBER(Y14),X14>0),Y14/(Y14+X14),"") -> 0.0032053748 | AA14: 67 | AB14: =IFERROR(IF(N(INDEX('Our BFCM 2025'!$S:$S,MATCH($C14,'Our BFCM 2025'!$C:$C,0)))=0,"",INDEX('Our BFCM 2025'!$S:$S,MATCH($C14,'Our BFCM 2025'!$C:$C,0))),"") -> 1.3528479 | AC14: =IFERROR(IF(N(INDEX('Our BFCM 2025'!$H:$H,MATCH($C14,'Our BFCM 2025'!$C:$C,0)))=0,"",INDEX('Our BFCM 2025'!$H:$H,MATCH($C14,'Our BFCM 2025'!$C:$C,0))),"") -> 0.33571612 | AD14: 1.2977528 | AE14: 1.1650605 | AF14: =COUNTIFS(Competitors!$C$3:$C$618,$C14,Competitors!$AY$3:$AY$618,"<>") -> 0 | AG14: =IFERROR(AVERAGEIFS(Competitors!$BD$3:$BD$618,Competitors!$C$3:$C$618,$C14),"") | AH14: =IFERROR(AVERAGEIFS(Competitors!$BH$3:$BH$618,Competitors!$C$3:$C$618,$C14),"")
A15: Silk | B15: Sleephoria Silk Sleep Mask - Contoured | C15: 56 | D15: Gifting | E15: Liquidation | F15: B0F4XS1FWJ | G15: 4 | H15: 1 | I15: 4 | J15: 25.95 | K15: 8.34 | L15: 0.32138728 | M15: 4 | N15: =COUNTIF(Competitors!$C$3:$C$618,$C15) -> 27 | O15: =COUNTIFS(Competitors!$C$3:$C$618,$C15,Competitors!$J$3:$J$618,"Aspirational") -> 10 | P15: =COUNTIFS(Competitors!$C$3:$C$618,$C15,Competitors!$J$3:$J$618,"Beatable") -> 15 | Q15: =COUNTIFS(Competitors!$C$3:$C$618,$C15,Competitors!$J$3:$J$618,"Poor") -> 1 | R15: 22.49 | S15: =IF(AND(ISNUMBER(J15),ISNUMBER(R15),R15>0),J15/R15-1,"") -> 0.15384615 | T15: =COUNTIFS(Competitors!$C$3:$C$618,$C15,Competitors!$Q$3:$Q$618,"<0") -> 18 | U15: =COUNTIFS(Competitors!$C$3:$C$618,$C15,Competitors!$M$3:$M$618,">0") -> 7 | V15: =COUNTIFS(Competitors!$C$3:$C$618,$C15,Competitors!$M$3:$M$618,">0",Competitors!$M$3:$M$618,"<=0.12") -> 5 | W15: =IFERROR(AVERAGEIFS(Competitors!$M$3:$M$618,Competitors!$C$3:$C$618,$C15,Competitors!$M$3:$M$618,">0"),"") -> 0.22548917 | X15: =SUMIF(Competitors!$C$3:$C$618,$C15,Competitors!$T$3:$T$618) -> 28270 | Y15: =IF(ISNUMBER(M15),M15/4,"") -> 1 | Z15: =IF(AND(ISNUMBER(Y15),X15>0),Y15/(Y15+X15),"") -> 3.5371936e-05 | AA15: 5.5 | AB15: =IFERROR(IF(N(INDEX('Our BFCM 2025'!$S:$S,MATCH($C15,'Our BFCM 2025'!$C:$C,0)))=0,"",INDEX('Our BFCM 2025'!$S:$S,MATCH($C15,'Our BFCM 2025'!$C:$C,0))),"") | AC15: =IFERROR(IF(N(INDEX('Our BFCM 2025'!$H:$H,MATCH($C15,'Our BFCM 2025'!$C:$C,0)))=0,"",INDEX('Our BFCM 2025'!$H:$H,MATCH($C15,'Our BFCM 2025'!$C:$C,0))),"") | AE15: 1.0556398 | AF15: =COUNTIFS(Competitors!$C$3:$C$618,$C15,Competitors!$AY$3:$AY$618,"<>") -> 0 | AG15: =IFERROR(AVERAGEIFS(Competitors!$BD$3:$BD$618,Competitors!$C$3:$C$618,$C15),"") | AH15: =IFERROR(AVERAGEIFS(Competitors!$BH$3:$BH$618,Competitors!$C$3:$C$618,$C15),"")
A16: Silk | B16: Sleephoria Silk Sleep Mask - Velcro | C16: 57 | D16: Gifting | E16: Launch | F16: B0F4XQ7L8Q | G16: 4 | H16: 1 | I16: 4 | J16: 20.411538 | K16: 5.8323077 | L16: 0.28573582 | M16: 13 | N16: =COUNTIF(Competitors!$C$3:$C$618,$C16) -> 15 | O16: =COUNTIFS(Competitors!$C$3:$C$618,$C16,Competitors!$J$3:$J$618,"Aspirational") -> 6 | P16: =COUNTIFS(Competitors!$C$3:$C$618,$C16,Competitors!$J$3:$J$618,"Beatable") -> 5 | Q16: =COUNTIFS(Competitors!$C$3:$C$618,$C16,Competitors!$J$3:$J$618,"Poor") -> 0 | R16: 17.99 | S16: =IF(AND(ISNUMBER(J16),ISNUMBER(R16),R16>0),J16/R16-1,"") -> 0.13460469 | T16: =COUNTIFS(Competitors!$C$3:$C$618,$C16,Competitors!$Q$3:$Q$618,"<0") -> 10 | U16: =COUNTIFS(Competitors!$C$3:$C$618,$C16,Competitors!$M$3:$M$618,">0") -> 3 | V16: =COUNTIFS(Competitors!$C$3:$C$618,$C16,Competitors!$M$3:$M$618,">0",Competitors!$M$3:$M$618,"<=0.12") -> 2 | W16: =IFERROR(AVERAGEIFS(Competitors!$M$3:$M$618,Competitors!$C$3:$C$618,$C16,Competitors!$M$3:$M$618,">0"),"") -> 0.31967769 | X16: =SUMIF(Competitors!$C$3:$C$618,$C16,Competitors!$T$3:$T$618) -> 9878 | Y16: =IF(ISNUMBER(M16),M16/4,"") -> 3.25 | Z16: =IF(AND(ISNUMBER(Y16),X16>0),Y16/(Y16+X16),"") -> 0.00032890576 | AA16: 5.5 | AB16: =IFERROR(IF(N(INDEX('Our BFCM 2025'!$S:$S,MATCH($C16,'Our BFCM 2025'!$C:$C,0)))=0,"",INDEX('Our BFCM 2025'!$S:$S,MATCH($C16,'Our BFCM 2025'!$C:$C,0))),"") | AC16: =IFERROR(IF(N(INDEX('Our BFCM 2025'!$H:$H,MATCH($C16,'Our BFCM 2025'!$C:$C,0)))=0,"",INDEX('Our BFCM 2025'!$H:$H,MATCH($C16,'Our BFCM 2025'!$C:$C,0))),"") | AE16: 0.97139886 | AF16: =COUNTIFS(Competitors!$C$3:$C$618,$C16,Competitors!$AY$3:$AY$618,"<>") -> 0 | AG16: =IFERROR(AVERAGEIFS(Competitors!$BD$3:$BD$618,Competitors!$C$3:$C$618,$C16),"") | AH16: =IFERROR(AVERAGEIFS(Competitors!$BH$3:$BH$618,Competitors!$C$3:$C$618,$C16),"")
A17: Cooling | B17: Decolure Cooling Sheets 4 Piece | C17: 48 | D17: Off-season (aged variations only) | E17: Re-Launch | F17: B0CWJ2ZQJR | G17: 61 | H17: 6 | I17: 16 | J17: 40.326471 | K17: 11.542 | L17: 0.28621399 | M17: 89 | N17: =COUNTIF(Competitors!$C$3:$C$618,$C17) -> 28 | O17: =COUNTIFS(Competitors!$C$3:$C$618,$C17,Competitors!$J$3:$J$618,"Aspirational") -> 5 | P17: =COUNTIFS(Competitors!$C$3:$C$618,$C17,Competitors!$J$3:$J$618,"Beatable") -> 19 | Q17: =COUNTIFS(Competitors!$C$3:$C$618,$C17,Competitors!$J$3:$J$618,"Poor") -> 2 | R17: 84.99 | S17: =IF(AND(ISNUMBER(J17),ISNUMBER(R17),R17>0),J17/R17-1,"") -> -0.52551511 | T17: =COUNTIFS(Competitors!$C$3:$C$618,$C17,Competitors!$Q$3:$Q$618,"<0") -> 4 | U17: =COUNTIFS(Competitors!$C$3:$C$618,$C17,Competitors!$M$3:$M$618,">0") -> 10 | V17: =COUNTIFS(Competitors!$C$3:$C$618,$C17,Competitors!$M$3:$M$618,">0",Competitors!$M$3:$M$618,"<=0.12") -> 1 | W17: =IFERROR(AVERAGEIFS(Competitors!$M$3:$M$618,Competitors!$C$3:$C$618,$C17,Competitors!$M$3:$M$618,">0"),"") -> 0.27861813 | X17: =SUMIF(Competitors!$C$3:$C$618,$C17,Competitors!$T$3:$T$618) -> 2960 | Y17: =IF(ISNUMBER(M17),M17/4,"") -> 22.25 | Z17: =IF(AND(ISNUMBER(Y17),X17>0),Y17/(Y17+X17),"") -> 0.0074608098 | AA17: 70 | AB17: =IFERROR(IF(N(INDEX('Our BFCM 2025'!$S:$S,MATCH($C17,'Our BFCM 2025'!$C:$C,0)))=0,"",INDEX('Our BFCM 2025'!$S:$S,MATCH($C17,'Our BFCM 2025'!$C:$C,0))),"") -> 1.6283914 | AC17: =IFERROR(IF(N(INDEX('Our BFCM 2025'!$H:$H,MATCH($C17,'Our BFCM 2025'!$C:$C,0)))=0,"",INDEX('Our BFCM 2025'!$H:$H,MATCH($C17,'Our BFCM 2025'!$C:$C,0))),"") -> 0.068468955 | AE17: 1.3148085 | AF17: =COUNTIFS(Competitors!$C$3:$C$618,$C17,Competitors!$AY$3:$AY$618,"<>") -> 0 | AG17: =IFERROR(AVERAGEIFS(Competitors!$BD$3:$BD$618,Competitors!$C$3:$C$618,$C17),"") | AH17: =IFERROR(AVERAGEIFS(Competitors!$BH$3:$BH$618,Competitors!$C$3:$C$618,$C17),"")
A18: Cooling | B18: Sleephoria Cooling Sheets 4 Piece | C18: 45 | D18: Off-season (aged variations only) | E18: Re-Launch | F18: B0F7LXFGLX | G18: 61 | H18: 5 | I18: 13 | J18: 66.369518 | K18: 20.452831 | L18: 0.30816604 | M18: 332 | N18: =COUNTIF(Competitors!$C$3:$C$618,$C18) -> 36 | O18: =COUNTIFS(Competitors!$C$3:$C$618,$C18,Competitors!$J$3:$J$618,"Aspirational") -> 2 | P18: =COUNTIFS(Competitors!$C$3:$C$618,$C18,Competitors!$J$3:$J$618,"Beatable") -> 11 | Q18: =COUNTIFS(Competitors!$C$3:$C$618,$C18,Competitors!$J$3:$J$618,"Poor") -> 6 | R18: 79.495 | S18: =IF(AND(ISNUMBER(J18),ISNUMBER(R18),R18>0),J18/R18-1,"") -> -0.16511079 | T18: =COUNTIFS(Competitors!$C$3:$C$618,$C18,Competitors!$Q$3:$Q$618,"<0") -> 13 | U18: =COUNTIFS(Competitors!$C$3:$C$618,$C18,Competitors!$M$3:$M$618,">0") -> 15 | V18: =COUNTIFS(Competitors!$C$3:$C$618,$C18,Competitors!$M$3:$M$618,">0",Competitors!$M$3:$M$618,"<=0.12") -> 2 | W18: =IFERROR(AVERAGEIFS(Competitors!$M$3:$M$618,Competitors!$C$3:$C$618,$C18,Competitors!$M$3:$M$618,">0"),"") -> 0.22474776 | X18: =SUMIF(Competitors!$C$3:$C$618,$C18,Competitors!$T$3:$T$618) -> 4540 | Y18: =IF(ISNUMBER(M18),M18/4,"") -> 83 | Z18: =IF(AND(ISNUMBER(Y18),X18>0),Y18/(Y18+X18),"") -> 0.01795371 | AA18: 79 | AB18: =IFERROR(IF(N(INDEX('Our BFCM 2025'!$S:$S,MATCH($C18,'Our BFCM 2025'!$C:$C,0)))=0,"",INDEX('Our BFCM 2025'!$S:$S,MATCH($C18,'Our BFCM 2025'!$C:$C,0))),"") -> 1.1444276 | AC18: =IFERROR(IF(N(INDEX('Our BFCM 2025'!$H:$H,MATCH($C18,'Our BFCM 2025'!$C:$C,0)))=0,"",INDEX('Our BFCM 2025'!$H:$H,MATCH($C18,'Our BFCM 2025'!$C:$C,0))),"") -> 0.01606181 | AE18: 1.3124685 | AF18: =COUNTIFS(Competitors!$C$3:$C$618,$C18,Competitors!$AY$3:$AY$618,"<>") -> 0 | AG18: =IFERROR(AVERAGEIFS(Competitors!$BD$3:$BD$618,Competitors!$C$3:$C$618,$C18),"") | AH18: =IFERROR(AVERAGEIFS(Competitors!$BH$3:$BH$618,Competitors!$C$3:$C$618,$C18),"")
A19: Cooling | B19: Sleephoria Cooling Sheets 6 Piece | C19: 76 | D19: Off-season (aged variations only) | E19: Production | F19: B0H7JVGTZW | G19: 60 | H19: 5 | I19: 12 | M19: 0 | N19: =COUNTIF(Competitors!$C$3:$C$618,$C19) -> 7 | O19: =COUNTIFS(Competitors!$C$3:$C$618,$C19,Competitors!$J$3:$J$618,"Aspirational") -> 0 | P19: =COUNTIFS(Competitors!$C$3:$C$618,$C19,Competitors!$J$3:$J$618,"Beatable") -> 0 | Q19: =COUNTIFS(Competitors!$C$3:$C$618,$C19,Competitors!$J$3:$J$618,"Poor") -> 0 | R19: 139.99 | S19: =IF(AND(ISNUMBER(J19),ISNUMBER(R19),R19>0),J19/R19-1,"") | T19: =COUNTIFS(Competitors!$C$3:$C$618,$C19,Competitors!$Q$3:$Q$618,"<0") -> 0 | U19: =COUNTIFS(Competitors!$C$3:$C$618,$C19,Competitors!$M$3:$M$618,">0") -> 4 | V19: =COUNTIFS(Competitors!$C$3:$C$618,$C19,Competitors!$M$3:$M$618,">0",Competitors!$M$3:$M$618,"<=0.12") -> 1 | W19: =IFERROR(AVERAGEIFS(Competitors!$M$3:$M$618,Competitors!$C$3:$C$618,$C19,Competitors!$M$3:$M$618,">0"),"") -> 0.25997905 | X19: =SUMIF(Competitors!$C$3:$C$618,$C19,Competitors!$T$3:$T$618) -> 940 | Y19: =IF(ISNUMBER(M19),M19/4,"") -> 0 | Z19: =IF(AND(ISNUMBER(Y19),X19>0),Y19/(Y19+X19),"") -> 0 | AA19: 131 | AB19: =IFERROR(IF(N(INDEX('Our BFCM 2025'!$S:$S,MATCH($C19,'Our BFCM 2025'!$C:$C,0)))=0,"",INDEX('Our BFCM 2025'!$S:$S,MATCH($C19,'Our BFCM 2025'!$C:$C,0))),"") | AC19: =IFERROR(IF(N(INDEX('Our BFCM 2025'!$H:$H,MATCH($C19,'Our BFCM 2025'!$C:$C,0)))=0,"",INDEX('Our BFCM 2025'!$H:$H,MATCH($C19,'Our BFCM 2025'!$C:$C,0))),"") | AE19: 1.2549476 | AF19: =COUNTIFS(Competitors!$C$3:$C$618,$C19,Competitors!$AY$3:$AY$618,"<>") -> 0 | AG19: =IFERROR(AVERAGEIFS(Competitors!$BD$3:$BD$618,Competitors!$C$3:$C$618,$C19),"") | AH19: =IFERROR(AVERAGEIFS(Competitors!$BH$3:$BH$618,Competitors!$C$3:$C$618,$C19),"")
A20: Cooling | B20: CooLinens Cooling Sheets 4 Piece | C20: 69 | D20: Launch | E20: Production | F20: B0H6K5RPX6 | G20: 60 | H20: 5 | I20: 12 | M20: 42 | N20: =COUNTIF(Competitors!$C$3:$C$618,$C20) -> 14 | O20: =COUNTIFS(Competitors!$C$3:$C$618,$C20,Competitors!$J$3:$J$618,"Aspirational") -> 0 | P20: =COUNTIFS(Competitors!$C$3:$C$618,$C20,Competitors!$J$3:$J$618,"Beatable") -> 0 | Q20: =COUNTIFS(Competitors!$C$3:$C$618,$C20,Competitors!$J$3:$J$618,"Poor") -> 0 | R20: 137.995 | S20: =IF(AND(ISNUMBER(J20),ISNUMBER(R20),R20>0),J20/R20-1,"") | T20: =COUNTIFS(Competitors!$C$3:$C$618,$C20,Competitors!$Q$3:$Q$618,"<0") -> 0 | U20: =COUNTIFS(Competitors!$C$3:$C$618,$C20,Competitors!$M$3:$M$618,">0") -> 6 | V20: =COUNTIFS(Competitors!$C$3:$C$618,$C20,Competitors!$M$3:$M$618,">0",Competitors!$M$3:$M$618,"<=0.12") -> 0 | W20: =IFERROR(AVERAGEIFS(Competitors!$M$3:$M$618,Competitors!$C$3:$C$618,$C20,Competitors!$M$3:$M$618,">0"),"") -> 0.27311623 | X20: =SUMIF(Competitors!$C$3:$C$618,$C20,Competitors!$T$3:$T$618) -> 416 | Y20: =IF(ISNUMBER(M20),M20/4,"") -> 10.5 | Z20: =IF(AND(ISNUMBER(Y20),X20>0),Y20/(Y20+X20),"") -> 0.024618992 | AA20: 31 | AB20: =IFERROR(IF(N(INDEX('Our BFCM 2025'!$S:$S,MATCH($C20,'Our BFCM 2025'!$C:$C,0)))=0,"",INDEX('Our BFCM 2025'!$S:$S,MATCH($C20,'Our BFCM 2025'!$C:$C,0))),"") | AC20: =IFERROR(IF(N(INDEX('Our BFCM 2025'!$H:$H,MATCH($C20,'Our BFCM 2025'!$C:$C,0)))=0,"",INDEX('Our BFCM 2025'!$H:$H,MATCH($C20,'Our BFCM 2025'!$C:$C,0))),"") | AE20: 0.96406013 | AF20: =COUNTIFS(Competitors!$C$3:$C$618,$C20,Competitors!$AY$3:$AY$618,"<>") -> 0 | AG20: =IFERROR(AVERAGEIFS(Competitors!$BD$3:$BD$618,Competitors!$C$3:$C$618,$C20),"") | AH20: =IFERROR(AVERAGEIFS(Competitors!$BH$3:$BH$618,Competitors!$C$3:$C$618,$C20),"")
A21: Cooling | B21: CooLinens Cooling Pillowcases 2 Piece | C21: 70 | D21: Launch | E21: Launch | F21: B0H5X3L7M3 | G21: 12 | H21: 3 | I21: 4 | M21: 310 | N21: =COUNTIF(Competitors!$C$3:$C$618,$C21) -> 15 | O21: =COUNTIFS(Competitors!$C$3:$C$618,$C21,Competitors!$J$3:$J$618,"Aspirational") -> 3 | P21: =COUNTIFS(Competitors!$C$3:$C$618,$C21,Competitors!$J$3:$J$618,"Beatable") -> 11 | Q21: =COUNTIFS(Competitors!$C$3:$C$618,$C21,Competitors!$J$3:$J$618,"Poor") -> 1 | R21: 18.95 | S21: =IF(AND(ISNUMBER(J21),ISNUMBER(R21),R21>0),J21/R21-1,"") | T21: =COUNTIFS(Competitors!$C$3:$C$618,$C21,Competitors!$Q$3:$Q$618,"<0") -> 0 | U21: =COUNTIFS(Competitors!$C$3:$C$618,$C21,Competitors!$M$3:$M$618,">0") -> 3 | V21: =COUNTIFS(Competitors!$C$3:$C$618,$C21,Competitors!$M$3:$M$618,">0",Competitors!$M$3:$M$618,"<=0.12") -> 0 | W21: =IFERROR(AVERAGEIFS(Competitors!$M$3:$M$618,Competitors!$C$3:$C$618,$C21,Competitors!$M$3:$M$618,">0"),"") -> 0.29981515 | X21: =SUMIF(Competitors!$C$3:$C$618,$C21,Competitors!$T$3:$T$618) -> 737 | Y21: =IF(ISNUMBER(M21),M21/4,"") -> 77.5 | Z21: =IF(AND(ISNUMBER(Y21),X21>0),Y21/(Y21+X21),"") -> 0.095150399 | AA21: 14 | AB21: =IFERROR(IF(N(INDEX('Our BFCM 2025'!$S:$S,MATCH($C21,'Our BFCM 2025'!$C:$C,0)))=0,"",INDEX('Our BFCM 2025'!$S:$S,MATCH($C21,'Our BFCM 2025'!$C:$C,0))),"") | AC21: =IFERROR(IF(N(INDEX('Our BFCM 2025'!$H:$H,MATCH($C21,'Our BFCM 2025'!$C:$C,0)))=0,"",INDEX('Our BFCM 2025'!$H:$H,MATCH($C21,'Our BFCM 2025'!$C:$C,0))),"") | AE21: 1.1054243 | AF21: =COUNTIFS(Competitors!$C$3:$C$618,$C21,Competitors!$AY$3:$AY$618,"<>") -> 0 | AG21: =IFERROR(AVERAGEIFS(Competitors!$BD$3:$BD$618,Competitors!$C$3:$C$618,$C21),"") | AH21: =IFERROR(AVERAGEIFS(Competitors!$BH$3:$BH$618,Competitors!$C$3:$C$618,$C21),"")
A22: Cooling | B22: Sleephoria Cooling Pillowcases | C22: 43 | D22: Off-season | E22: Re-Launch | F22: B0F7LLMXSR | G22: 12 | H22: 3 | I22: 4 | J22: 20.878148 | K22: 6.8761111 | L22: 0.32934488 | M22: 54 | N22: =COUNTIF(Competitors!$C$3:$C$618,$C22) -> 21 | O22: =COUNTIFS(Competitors!$C$3:$C$618,$C22,Competitors!$J$3:$J$618,"Aspirational") -> 4 | P22: =COUNTIFS(Competitors!$C$3:$C$618,$C22,Competitors!$J$3:$J$618,"Beatable") -> 16 | Q22: =COUNTIFS(Competitors!$C$3:$C$618,$C22,Competitors!$J$3:$J$618,"Poor") -> 0 | R22: 18.95 | S22: =IF(AND(ISNUMBER(J22),ISNUMBER(R22),R22>0),J22/R22-1,"") -> 0.10174924 | T22: =COUNTIFS(Competitors!$C$3:$C$618,$C22,Competitors!$Q$3:$Q$618,"<0") -> 15 | U22: =COUNTIFS(Competitors!$C$3:$C$618,$C22,Competitors!$M$3:$M$618,">0") -> 5 | V22: =COUNTIFS(Competitors!$C$3:$C$618,$C22,Competitors!$M$3:$M$618,">0",Competitors!$M$3:$M$618,"<=0.12") -> 0 | W22: =IFERROR(AVERAGEIFS(Competitors!$M$3:$M$618,Competitors!$C$3:$C$618,$C22,Competitors!$M$3:$M$618,">0"),"") -> 0.26521448 | X22: =SUMIF(Competitors!$C$3:$C$618,$C22,Competitors!$T$3:$T$618) -> 2909 | Y22: =IF(ISNUMBER(M22),M22/4,"") -> 13.5 | Z22: =IF(AND(ISNUMBER(Y22),X22>0),Y22/(Y22+X22),"") -> 0.0046193328 | AA22: 12 | AB22: =IFERROR(IF(N(INDEX('Our BFCM 2025'!$S:$S,MATCH($C22,'Our BFCM 2025'!$C:$C,0)))=0,"",INDEX('Our BFCM 2025'!$S:$S,MATCH($C22,'Our BFCM 2025'!$C:$C,0))),"") | AC22: =IFERROR(IF(N(INDEX('Our BFCM 2025'!$H:$H,MATCH($C22,'Our BFCM 2025'!$C:$C,0)))=0,"",INDEX('Our BFCM 2025'!$H:$H,MATCH($C22,'Our BFCM 2025'!$C:$C,0))),"") | AE22: 1.0997375 | AF22: =COUNTIFS(Competitors!$C$3:$C$618,$C22,Competitors!$AY$3:$AY$618,"<>") -> 0 | AG22: =IFERROR(AVERAGEIFS(Competitors!$BD$3:$BD$618,Competitors!$C$3:$C$618,$C22),"") | AH22: =IFERROR(AVERAGEIFS(Competitors!$BH$3:$BH$618,Competitors!$C$3:$C$618,$C22),"")
A23: Cooling | B23: Sleephoria Cooling Comforter | C23: 42 | D23: Off-season (lost $2.4K at BFCM 2025) | E23: Re-Launch | F23: B0GHSH1BJK | G23: 20 | H23: 4 | I23: 5 | J23: 67.682308 | K23: 15.059846 | L23: 0.22250787 | M23: 78 | N23: =COUNTIF(Competitors!$C$3:$C$618,$C23) -> 18 | O23: =COUNTIFS(Competitors!$C$3:$C$618,$C23,Competitors!$J$3:$J$618,"Aspirational") -> 1 | P23: =COUNTIFS(Competitors!$C$3:$C$618,$C23,Competitors!$J$3:$J$618,"Beatable") -> 12 | Q23: =COUNTIFS(Competitors!$C$3:$C$618,$C23,Competitors!$J$3:$J$618,"Poor") -> 0 | R23: 46.945 | S23: =IF(AND(ISNUMBER(J23),ISNUMBER(R23),R23>0),J23/R23-1,"") -> 0.44173624 | T23: =COUNTIFS(Competitors!$C$3:$C$618,$C23,Competitors!$Q$3:$Q$618,"<0") -> 16 | U23: =COUNTIFS(Competitors!$C$3:$C$618,$C23,Competitors!$M$3:$M$618,">0") -> 5 | V23: =COUNTIFS(Competitors!$C$3:$C$618,$C23,Competitors!$M$3:$M$618,">0",Competitors!$M$3:$M$618,"<=0.12") -> 0 | W23: =IFERROR(AVERAGEIFS(Competitors!$M$3:$M$618,Competitors!$C$3:$C$618,$C23,Competitors!$M$3:$M$618,">0"),"") -> 0.27460384 | X23: =SUMIF(Competitors!$C$3:$C$618,$C23,Competitors!$T$3:$T$618) -> 1547 | Y23: =IF(ISNUMBER(M23),M23/4,"") -> 19.5 | Z23: =IF(AND(ISNUMBER(Y23),X23>0),Y23/(Y23+X23),"") -> 0.012448133 | AB23: =IFERROR(IF(N(INDEX('Our BFCM 2025'!$S:$S,MATCH($C23,'Our BFCM 2025'!$C:$C,0)))=0,"",INDEX('Our BFCM 2025'!$S:$S,MATCH($C23,'Our BFCM 2025'!$C:$C,0))),"") -> 3.3937629 | AC23: =IFERROR(IF(N(INDEX('Our BFCM 2025'!$H:$H,MATCH($C23,'Our BFCM 2025'!$C:$C,0)))=0,"",INDEX('Our BFCM 2025'!$H:$H,MATCH($C23,'Our BFCM 2025'!$C:$C,0))),"") -> 0.12283705 | AD23: 3.2537313 | AE23: 1.3749619 | AF23: =COUNTIFS(Competitors!$C$3:$C$618,$C23,Competitors!$AY$3:$AY$618,"<>") -> 0 | AG23: =IFERROR(AVERAGEIFS(Competitors!$BD$3:$BD$618,Competitors!$C$3:$C$618,$C23),"") | AH23: =IFERROR(AVERAGEIFS(Competitors!$BH$3:$BH$618,Competitors!$C$3:$C$618,$C23),"")
A24: Cooling | B24: Sleephoria Cooling Fitted Sheet | C24: 44 | D24: Off-season | E24: Re-Launch | F24: B0F7M4DPM6 | G24: 65 | H24: 5 | I24: 13 | J24: 33.225867 | K24: 8.3722222 | L24: 0.25197904 | M24: 513 | N24: =COUNTIF(Competitors!$C$3:$C$618,$C24) -> 11 | O24: =COUNTIFS(Competitors!$C$3:$C$618,$C24,Competitors!$J$3:$J$618,"Aspirational") -> 1 | P24: =COUNTIFS(Competitors!$C$3:$C$618,$C24,Competitors!$J$3:$J$618,"Beatable") -> 6 | Q24: =COUNTIFS(Competitors!$C$3:$C$618,$C24,Competitors!$J$3:$J$618,"Poor") -> 1 | R24: 62.99 | S24: =IF(AND(ISNUMBER(J24),ISNUMBER(R24),R24>0),J24/R24-1,"") -> -0.47252155 | T24: =COUNTIFS(Competitors!$C$3:$C$618,$C24,Competitors!$Q$3:$Q$618,"<0") -> 2 | U24: =COUNTIFS(Competitors!$C$3:$C$618,$C24,Competitors!$M$3:$M$618,">0") -> 5 | V24: =COUNTIFS(Competitors!$C$3:$C$618,$C24,Competitors!$M$3:$M$618,">0",Competitors!$M$3:$M$618,"<=0.12") -> 1 | W24: =IFERROR(AVERAGEIFS(Competitors!$M$3:$M$618,Competitors!$C$3:$C$618,$C24,Competitors!$M$3:$M$618,">0"),"") -> 0.28465465 | X24: =SUMIF(Competitors!$C$3:$C$618,$C24,Competitors!$T$3:$T$618) -> 2050 | Y24: =IF(ISNUMBER(M24),M24/4,"") -> 128.25 | Z24: =IF(AND(ISNUMBER(Y24),X24>0),Y24/(Y24+X24),"") -> 0.058877539 | AA24: 102.5 | AB24: =IFERROR(IF(N(INDEX('Our BFCM 2025'!$S:$S,MATCH($C24,'Our BFCM 2025'!$C:$C,0)))=0,"",INDEX('Our BFCM 2025'!$S:$S,MATCH($C24,'Our BFCM 2025'!$C:$C,0))),"") | AC24: =IFERROR(IF(N(INDEX('Our BFCM 2025'!$H:$H,MATCH($C24,'Our BFCM 2025'!$C:$C,0)))=0,"",INDEX('Our BFCM 2025'!$H:$H,MATCH($C24,'Our BFCM 2025'!$C:$C,0))),"") | AE24: 1.1787119 | AF24: =COUNTIFS(Competitors!$C$3:$C$618,$C24,Competitors!$AY$3:$AY$618,"<>") -> 0 | AG24: =IFERROR(AVERAGEIFS(Competitors!$BD$3:$BD$618,Competitors!$C$3:$C$618,$C24),"") | AH24: =IFERROR(AVERAGEIFS(Competitors!$BH$3:$BH$618,Competitors!$C$3:$C$618,$C24),"")
A25: Other | B25: Sleephoria Quilt Set | C25: 46 | D25: Liquidation | E25: Liquidation | F25: B0FGZF19SN | G25: 21 | H25: 3 | I25: 7 | J25: 29.02125 | K25: 1.4915625 | L25: 0.051395529 | M25: 32 | N25: =COUNTIF(Competitors!$C$3:$C$618,$C25) -> 19 | O25: =COUNTIFS(Competitors!$C$3:$C$618,$C25,Competitors!$J$3:$J$618,"Aspirational") -> 8 | P25: =COUNTIFS(Competitors!$C$3:$C$618,$C25,Competitors!$J$3:$J$618,"Beatable") -> 9 | Q25: =COUNTIFS(Competitors!$C$3:$C$618,$C25,Competitors!$J$3:$J$618,"Poor") -> 2 | R25: 33.99 | S25: =IF(AND(ISNUMBER(J25),ISNUMBER(R25),R25>0),J25/R25-1,"") -> -0.1461827 | T25: =COUNTIFS(Competitors!$C$3:$C$618,$C25,Competitors!$Q$3:$Q$618,"<0") -> 5 | U25: =COUNTIFS(Competitors!$C$3:$C$618,$C25,Competitors!$M$3:$M$618,">0") -> 3 | V25: =COUNTIFS(Competitors!$C$3:$C$618,$C25,Competitors!$M$3:$M$618,">0",Competitors!$M$3:$M$618,"<=0.12") -> 2 | W25: =IFERROR(AVERAGEIFS(Competitors!$M$3:$M$618,Competitors!$C$3:$C$618,$C25,Competitors!$M$3:$M$618,">0"),"") -> 0.13155026 | X25: =SUMIF(Competitors!$C$3:$C$618,$C25,Competitors!$T$3:$T$618) -> 2924 | Y25: =IF(ISNUMBER(M25),M25/4,"") -> 8 | Z25: =IF(AND(ISNUMBER(Y25),X25>0),Y25/(Y25+X25),"") -> 0.002728513 | AA25: 79 | AB25: =IFERROR(IF(N(INDEX('Our BFCM 2025'!$S:$S,MATCH($C25,'Our BFCM 2025'!$C:$C,0)))=0,"",INDEX('Our BFCM 2025'!$S:$S,MATCH($C25,'Our BFCM 2025'!$C:$C,0))),"") | AC25: =IFERROR(IF(N(INDEX('Our BFCM 2025'!$H:$H,MATCH($C25,'Our BFCM 2025'!$C:$C,0)))=0,"",INDEX('Our BFCM 2025'!$H:$H,MATCH($C25,'Our BFCM 2025'!$C:$C,0))),"") | AE25: 1.1020803 | AF25: =COUNTIFS(Competitors!$C$3:$C$618,$C25,Competitors!$AY$3:$AY$618,"<>") -> 0 | AG25: =IFERROR(AVERAGEIFS(Competitors!$BD$3:$BD$618,Competitors!$C$3:$C$618,$C25),"") | AH25: =IFERROR(AVERAGEIFS(Competitors!$BH$3:$BH$618,Competitors!$C$3:$C$618,$C25),"")
A26: Other | B26: Decolure Linen Curtains | C26: 53 | D26: Liquidation | E26: Liquidation | F26: B0F6371Q67 | G26: 42 | H26: 7 | I26: 6 | J26: 29.823333 | K26: -0.23 | L26: -0.77120823 | M26: 12 | N26: =COUNTIF(Competitors!$C$3:$C$618,$C26) -> 21 | O26: =COUNTIFS(Competitors!$C$3:$C$618,$C26,Competitors!$J$3:$J$618,"Aspirational") -> 7 | P26: =COUNTIFS(Competitors!$C$3:$C$618,$C26,Competitors!$J$3:$J$618,"Beatable") -> 8 | Q26: =COUNTIFS(Competitors!$C$3:$C$618,$C26,Competitors!$J$3:$J$618,"Poor") -> 6 | R26: 23.99 | S26: =IF(AND(ISNUMBER(J26),ISNUMBER(R26),R26>0),J26/R26-1,"") -> 0.24315687 | T26: =COUNTIFS(Competitors!$C$3:$C$618,$C26,Competitors!$Q$3:$Q$618,"<0") -> 16 | U26: =COUNTIFS(Competitors!$C$3:$C$618,$C26,Competitors!$M$3:$M$618,">0") -> 10 | V26: =COUNTIFS(Competitors!$C$3:$C$618,$C26,Competitors!$M$3:$M$618,">0",Competitors!$M$3:$M$618,"<=0.12") -> 1 | W26: =IFERROR(AVERAGEIFS(Competitors!$M$3:$M$618,Competitors!$C$3:$C$618,$C26,Competitors!$M$3:$M$618,">0"),"") -> 0.23840031 | X26: =SUMIF(Competitors!$C$3:$C$618,$C26,Competitors!$T$3:$T$618) -> 13914 | Y26: =IF(ISNUMBER(M26),M26/4,"") -> 3 | Z26: =IF(AND(ISNUMBER(Y26),X26>0),Y26/(Y26+X26),"") -> 0.0002155637 | AA26: 194 | AB26: =IFERROR(IF(N(INDEX('Our BFCM 2025'!$S:$S,MATCH($C26,'Our BFCM 2025'!$C:$C,0)))=0,"",INDEX('Our BFCM 2025'!$S:$S,MATCH($C26,'Our BFCM 2025'!$C:$C,0))),"") | AC26: =IFERROR(IF(N(INDEX('Our BFCM 2025'!$H:$H,MATCH($C26,'Our BFCM 2025'!$C:$C,0)))=0,"",INDEX('Our BFCM 2025'!$H:$H,MATCH($C26,'Our BFCM 2025'!$C:$C,0))),"") | AE26: 0.83017884 | AF26: =COUNTIFS(Competitors!$C$3:$C$618,$C26,Competitors!$AY$3:$AY$618,"<>") -> 0 | AG26: =IFERROR(AVERAGEIFS(Competitors!$BD$3:$BD$618,Competitors!$C$3:$C$618,$C26),"") | AH26: =IFERROR(AVERAGEIFS(Competitors!$BH$3:$BH$618,Competitors!$C$3:$C$618,$C26),"")
A27: Other | B27: Decolure Beach Towel | C27: 49 | D27: Other | E27: Liquidation | F27: B0DQ8NHCYM | G27: 14 | H27: 1 | I27: 7 | J27: 21.45 | K27: 5.475 | L27: 0.25524476 | M27: 2 | N27: =COUNTIF(Competitors!$C$3:$C$618,$C27) -> 13 | O27: =COUNTIFS(Competitors!$C$3:$C$618,$C27,Competitors!$J$3:$J$618,"Aspirational") -> 4 | P27: =COUNTIFS(Competitors!$C$3:$C$618,$C27,Competitors!$J$3:$J$618,"Beatable") -> 7 | Q27: =COUNTIFS(Competitors!$C$3:$C$618,$C27,Competitors!$J$3:$J$618,"Poor") -> 0 | R27: 14.99 | S27: =IF(AND(ISNUMBER(J27),ISNUMBER(R27),R27>0),J27/R27-1,"") -> 0.43095397 | T27: =COUNTIFS(Competitors!$C$3:$C$618,$C27,Competitors!$Q$3:$Q$618,"<0") -> 11 | U27: =COUNTIFS(Competitors!$C$3:$C$618,$C27,Competitors!$M$3:$M$618,">0") -> 1 | V27: =COUNTIFS(Competitors!$C$3:$C$618,$C27,Competitors!$M$3:$M$618,">0",Competitors!$M$3:$M$618,"<=0.12") -> 0 | W27: =IFERROR(AVERAGEIFS(Competitors!$M$3:$M$618,Competitors!$C$3:$C$618,$C27,Competitors!$M$3:$M$618,">0"),"") -> 0.28591851 | X27: =SUMIF(Competitors!$C$3:$C$618,$C27,Competitors!$T$3:$T$618) -> 154 | Y27: =IF(ISNUMBER(M27),M27/4,"") -> 0.5 | Z27: =IF(AND(ISNUMBER(Y27),X27>0),Y27/(Y27+X27),"") -> 0.003236246 | AA27: 7 | AB27: =IFERROR(IF(N(INDEX('Our BFCM 2025'!$S:$S,MATCH($C27,'Our BFCM 2025'!$C:$C,0)))=0,"",INDEX('Our BFCM 2025'!$S:$S,MATCH($C27,'Our BFCM 2025'!$C:$C,0))),"") | AC27: =IFERROR(IF(N(INDEX('Our BFCM 2025'!$H:$H,MATCH($C27,'Our BFCM 2025'!$C:$C,0)))=0,"",INDEX('Our BFCM 2025'!$H:$H,MATCH($C27,'Our BFCM 2025'!$C:$C,0))),"") | AF27: =COUNTIFS(Competitors!$C$3:$C$618,$C27,Competitors!$AY$3:$AY$618,"<>") -> 0 | AG27: =IFERROR(AVERAGEIFS(Competitors!$BD$3:$BD$618,Competitors!$C$3:$C$618,$C27),"") | AH27: =IFERROR(AVERAGEIFS(Competitors!$BH$3:$BH$618,Competitors!$C$3:$C$618,$C27),"")
A28: Other | B28: Decolure Front Door Welcome Sign | C28: 58 | D28: Other | E28: Liquidation | F28: B0DQ83G9MC | G28: 7 | H28: 1 | I28: 7 | J28: 37.95 | K28: 1.31 | L28: 0.034519104 | M28: 2 | N28: =COUNTIF(Competitors!$C$3:$C$618,$C28) -> 17 | O28: =COUNTIFS(Competitors!$C$3:$C$618,$C28,Competitors!$J$3:$J$618,"Aspirational") -> 3 | P28: =COUNTIFS(Competitors!$C$3:$C$618,$C28,Competitors!$J$3:$J$618,"Beatable") -> 13 | Q28: =COUNTIFS(Competitors!$C$3:$C$618,$C28,Competitors!$J$3:$J$618,"Poor") -> 0 | R28: 33.99 | S28: =IF(AND(ISNUMBER(J28),ISNUMBER(R28),R28>0),J28/R28-1,"") -> 0.11650485 | T28: =COUNTIFS(Competitors!$C$3:$C$618,$C28,Competitors!$Q$3:$Q$618,"<0") -> 12 | U28: =COUNTIFS(Competitors!$C$3:$C$618,$C28,Competitors!$M$3:$M$618,">0") -> 3 | V28: =COUNTIFS(Competitors!$C$3:$C$618,$C28,Competitors!$M$3:$M$618,">0",Competitors!$M$3:$M$618,"<=0.12") -> 1 | W28: =IFERROR(AVERAGEIFS(Competitors!$M$3:$M$618,Competitors!$C$3:$C$618,$C28,Competitors!$M$3:$M$618,">0"),"") -> 0.13975732 | X28: =SUMIF(Competitors!$C$3:$C$618,$C28,Competitors!$T$3:$T$618) -> 514 | Y28: =IF(ISNUMBER(M28),M28/4,"") -> 0.5 | Z28: =IF(AND(ISNUMBER(Y28),X28>0),Y28/(Y28+X28),"") -> 0.0009718173 | AA28: 3 | AB28: =IFERROR(IF(N(INDEX('Our BFCM 2025'!$S:$S,MATCH($C28,'Our BFCM 2025'!$C:$C,0)))=0,"",INDEX('Our BFCM 2025'!$S:$S,MATCH($C28,'Our BFCM 2025'!$C:$C,0))),"") | AC28: =IFERROR(IF(N(INDEX('Our BFCM 2025'!$H:$H,MATCH($C28,'Our BFCM 2025'!$C:$C,0)))=0,"",INDEX('Our BFCM 2025'!$H:$H,MATCH($C28,'Our BFCM 2025'!$C:$C,0))),"") | AF28: =COUNTIFS(Competitors!$C$3:$C$618,$C28,Competitors!$AY$3:$AY$618,"<>") -> 0 | AG28: =IFERROR(AVERAGEIFS(Competitors!$BD$3:$BD$618,Competitors!$C$3:$C$618,$C28),"") | AH28: =IFERROR(AVERAGEIFS(Competitors!$BH$3:$BH$618,Competitors!$C$3:$C$618,$C28),"")
A29: Other | B29: Decolure Waterproof Chair Cover | C29: 33 | D29: Other | E29: Liquidation | F29: B0CY6QPTVJ | G29: 12 | H29: 2 | I29: 6 | J29: 25.24 | K29: 3.2013333 | L29: 0.12683571 | M29: 30 | N29: =COUNTIF(Competitors!$C$3:$C$618,$C29) -> 23 | O29: =COUNTIFS(Competitors!$C$3:$C$618,$C29,Competitors!$J$3:$J$618,"Aspirational") -> 17 | P29: =COUNTIFS(Competitors!$C$3:$C$618,$C29,Competitors!$J$3:$J$618,"Beatable") -> 6 | Q29: =COUNTIFS(Competitors!$C$3:$C$618,$C29,Competitors!$J$3:$J$618,"Poor") -> 0 | R29: 22.94 | S29: =IF(AND(ISNUMBER(J29),ISNUMBER(R29),R29>0),J29/R29-1,"") -> 0.10026155 | T29: =COUNTIFS(Competitors!$C$3:$C$618,$C29,Competitors!$Q$3:$Q$618,"<0") -> 14 | U29: =COUNTIFS(Competitors!$C$3:$C$618,$C29,Competitors!$M$3:$M$618,">0") -> 5 | V29: =COUNTIFS(Competitors!$C$3:$C$618,$C29,Competitors!$M$3:$M$618,">0",Competitors!$M$3:$M$618,"<=0.12") -> 0 | W29: =IFERROR(AVERAGEIFS(Competitors!$M$3:$M$618,Competitors!$C$3:$C$618,$C29,Competitors!$M$3:$M$618,">0"),"") -> 0.19577708 | X29: =SUMIF(Competitors!$C$3:$C$618,$C29,Competitors!$T$3:$T$618) -> 1672 | Y29: =IF(ISNUMBER(M29),M29/4,"") -> 7.5 | Z29: =IF(AND(ISNUMBER(Y29),X29>0),Y29/(Y29+X29),"") -> 0.0044656148 | AA29: 68.5 | AB29: =IFERROR(IF(N(INDEX('Our BFCM 2025'!$S:$S,MATCH($C29,'Our BFCM 2025'!$C:$C,0)))=0,"",INDEX('Our BFCM 2025'!$S:$S,MATCH($C29,'Our BFCM 2025'!$C:$C,0))),"") | AC29: =IFERROR(IF(N(INDEX('Our BFCM 2025'!$H:$H,MATCH($C29,'Our BFCM 2025'!$C:$C,0)))=0,"",INDEX('Our BFCM 2025'!$H:$H,MATCH($C29,'Our BFCM 2025'!$C:$C,0))),"") | AF29: =COUNTIFS(Competitors!$C$3:$C$618,$C29,Competitors!$AY$3:$AY$618,"<>") -> 0 | AG29: =IFERROR(AVERAGEIFS(Competitors!$BD$3:$BD$618,Competitors!$C$3:$C$618,$C29),"") | AH29: =IFERROR(AVERAGEIFS(Competitors!$BH$3:$BH$618,Competitors!$C$3:$C$618,$C29),"")
A31: Medians are build-time values; every other grey cell is a live formula over the Competitors and Our BFCM 2025 tabs. Our PD 2026 organic visibility lift is for our best-selling child ASIN.

Sheet Competitors
A1: COMPETITOR (Command Center map) | K1: CURRENT MARKET - Command Center snapshot | S1: CURRENT MARKET - Command Center snapshot | V1: CURRENT MARKET - Command Center snapshot | Y1: LISTING DETAIL - Data Dive | AB1: LISTING DETAIL - Data Dive | AI1: CURRENT MARKET - Command Center snapshot | AK1: VISIBILITY HISTORY - Command Center (2026) | AO1: VISIBILITY HISTORY - Command Center (2026) | AR1: VISIBILITY HISTORY - Command Center (2026) | AU1: STR NOW - fill (Amazon page / Keepa) | AY1: BFCM 2025 + PRICE HISTORY - fill from Keepa | BE1: BFCM 2025 + PRICE HISTORY - fill from Keepa | BI1: BFCM 2025 + PRICE HISTORY - fill from Keepa | BO1: BFCM 2025 + PRICE HISTORY - fill from Keepa
A2: Family | B2: Our product | C2: Prod ID | D2: BFCM role (plan) | E2: Comp ID | F2: Brand | G2: Parent ASIN | H2: Tracked child ASIN | I2: Title | J2: Mapping tier | K2: Price now ($) | L2: List Price now ($) | M2: List Price % over price | N2: List Price band | O2: Size (from title) | P2: Our price, same size ($) | Q2: Their price vs ours (same size) | R2: Comparison basis | S2: BSR now | T2: Est weekly units | U2: Est monthly revenue ($) | V2: Rating | W2: Reviews | X2: Snapshot date | Y2: Variations (DD) | Z2: Listed (DD) | AA2: Listing age (yrs) | AB2: Family units 30d (DD est.) | AC2: Fulfilment | AD2: Active sellers | AE2: Seller country | AF2: Advertised KW % | AG2: TOS ad SV % | AH2: Page-1 KWs | AI2: ASINsight 7d traffic | AJ2: ASINsight keywords | AK2: Visibility history from | AL2: Organic score Jun 1-20 | AM2: Organic score PD Jun 23-26 | AN2: PD organic lift | AO2: Ad score Jun 1-20 | AP2: Ad score PD | AQ2: PD ad lift | AR2: Organic score Q2 (Apr 1-Jun 20) | AS2: Organic score Aug 18-Sep 16 | AT2: Organic trend (last30 vs Q2) | AU2: STR showing now? (Y/N) | AV2: STR label | AW2: Sold at List Price in last 90d? (Y/N) | AX2: Deal / coupon live now | AY2: BFCM 2025 deal type | AZ2: Deal start | BA2: Deal end | BB2: Pre-event typical price ($) | BC2: BFCM 2025 low price ($) | BD2: BFCM 2025 discount % | BE2: Coupon on top (%) | BF2: BSR pre-event avg | BG2: BSR BFCM week avg | BH2: BSR lift (x) | BI2: BSR Dec 2-31 avg | BJ2: OOS / lost Buy Box in BFCM? (Y/N) | BK2: PBDD 2025 deal price ($) | BL2: Lowest price last 90d ($) | BM2: Price below our price? | BN2: Below our 2026 deal price? | BO2: Notes
