Workbook

Sheet Overview
A1: Sleephoria Boho Throw Blanket: PPC clean-up, hard cap and rebuild plan
A2: For Shayan Rana, with Joseph Fisher | Data as of 22 Oct 2026 | Parent ASIN B0HGLF8X5Q, Amazon US
A4: Verdict
A5: Conversion is too low to buy traffic, so the account holds: only campaigns generating orders stay live ('bohemian throw blanket' and 'bohemian blanket', bids unchanged, top-of-search boosts capped at +300%) plus brand defence, inside a $25 a day ceiling. Every other campaign is paused, but not deleted: core terms with real demand are kept for a retest, mixed campaigns are rebuilt cleanly, and wrong-intent terms become negatives. The new campaign structure is built from scratch only after the listing and the other fixes pass their gates (Rebuild Plan tab).
A7: Key numbers
A8: Metric | B8: Since launch | C8: Last 30 days | D8: Last 15 days | E8: Note
A9: Ad spend | B9: =Campaigns!O46 -> 1648.02 | C9: =Campaigns!X46 -> 487.49 | D9: =Campaigns!AD46 -> 236.54
A10: Clicks | B10: =Campaigns!N46 -> 3093 | C10: =Campaigns!W46 -> 486 | D10: =Campaigns!AC46 -> 215
A11: Orders | B11: =Campaigns!P46 -> 34 | C11: =Campaigns!Y46 -> 4 | D11: =Campaigns!AE46 -> 2 | E11: Recent windows still filling in (7-day attribution)
A12: Ad sales | B12: =Campaigns!Q46 -> 1072.65 | C12: =Campaigns!Z46 -> 131.96 | D12: =Campaigns!AF46 -> 69.98
A13: Cost per click | B13: =IF(B10=0,"",B9/B10) -> 0.5328225 | C13: =IF(C10=0,"",C9/C10) -> 1.0030658 | D13: =IF(D10=0,"",D9/D10) -> 1.100186 | E13: Plan base bid $0.45 to $0.50
A14: Conversion (orders / clicks) | B14: =IF(B10=0,"",B11/B10) -> 0.010992564 | C14: =IF(C10=0,"",C11/C10) -> 0.0082304527 | D14: =IF(D10=0,"",D11/D10) -> 0.0093023256 | E14: Market CVR on boho searches about 1.3% to 2.4% (SQP)
A15: ACoS | B15: =IF(B12=0,"",B9/B12) -> 1.5364005 | C15: =IF(C12=0,"",C9/C12) -> 3.6942255 | D15: =IF(D12=0,"",D9/D12) -> 3.3801086 | E15: Break-even about 12.6% (Rules tab)
A16: Spend per order | B16: =IF(B11=0,"",B9/B11) -> 48.471176 | C16: =IF(C11=0,"",C9/C11) -> 121.8725 | D16: =IF(D11=0,"",D9/D11) -> 118.27 | E16: Contribution per unit $3.44 to $4.37
A18: Wasted ad spend
A19: Measure | B19: Amount | C19: Note
A20: Spend on search terms that never produced an order (since launch) | B20: ='Search Terms'!B141 -> 733.15 | C20: Search Terms tab
A21: Share of all search-term spend | B21: ='Search Terms'!B142 -> 0.44612866
A22: Spend on campaigns with 0 orders since launch | B22: =SUMIFS(Campaigns!$O$6:$O$45,Campaigns!$P$6:$P$45,0) -> 539.09 | C22: Decisions tab, 'Wasted spend' column
A23: Ad loss since launch (spend minus contribution earned on ad orders) | B23: =B9-B11*Rules!$B$34 -> 1515.25 | C23: Contribution is an estimate until D8
A24: Last 30 days: spend on campaigns now paused or kept paused | B24: ='Live Set'!B20 -> 390.61 | C24: This is the spend the pause list removes
A25: Expected spend per month after the change | B25: ='Live Set'!B17 -> 97.593793 | C25: 3 live campaigns, limited by search volume
A26: Maximum possible spend per month (budgets fully used) | B26: ='Live Set'!B18 -> 750 | C26: $25 a day ceiling (Phase 0 / D4)
A27: Expected cut vs the last 30 days | B27: ='Live Set'!B21 -> 0.7998035
A29: Decision summary (all 40 campaigns; SP exact and product targeting are the only ad types running)
A30: Decision category | B30: Campaigns | C30: Live after the change | D30: Spend since launch | E30: Orders since launch | F30: Spend, last 30 days
A31: =Decisions!A18 -> 1 RETAIN (generating orders) | B31: =Decisions!B18 -> 2 | C31: =Decisions!C18 -> 2 | D31: =Decisions!D18 -> 173.26 | E31: =Decisions!E18 -> 6 | F31: =Decisions!F18 -> 96.88
A32: =Decisions!A19 -> 2 ADJUST (bid / placement) | B32: =Decisions!B19 -> 1 | C32: =Decisions!C19 -> 1 | D32: =Decisions!D19 -> 1.38 | E32: =Decisions!E19 -> 0 | F32: =Decisions!F19 -> 0
A33: =Decisions!A20 -> 3 RETEST AFTER REBUILD | B33: =Decisions!B20 -> 6 | C33: =Decisions!C20 -> 0 | D33: =Decisions!D20 -> 480.77 | E33: =Decisions!E20 -> 13 | F33: =Decisions!F20 -> 51.91
A34: =Decisions!A21 -> 4 RESTRUCTURE IN REBUILD | B34: =Decisions!B21 -> 6 | C34: =Decisions!C21 -> 0 | D34: =Decisions!D21 -> 461.08 | E34: =Decisions!E21 -> 12 | F34: =Decisions!F21 -> 150.3
A35: =Decisions!A22 -> 5 PAUSE (wasted spend) | B35: =Decisions!B22 -> 25 | C35: =Decisions!C22 -> 0 | D35: =Decisions!D22 -> 531.53 | E35: =Decisions!E22 -> 3 | F35: =Decisions!F22 -> 188.4
A37: How each campaign was judged
A38: 1 RETAIN: orders on Amazon in the last 30 days and a cart-add rate in line with the market. Stays live with bids cut to what a click is worth.
A39: 2 ADJUST: kept live for protection (brand defence); settings brought inside the plan's limits.
A40: 3 RETEST AFTER REBUILD: real demand and the right intent, but the current page does not convert it (or no recent orders). Paused, not negated; first in line for the new structure with a pass mark.
A41: 4 RESTRUCTURE IN REBUILD: useful keywords stuck in a badly built campaign (mixed intents, wrong SKU, wrong size). Paused now; rebuilt correctly later.
A42: 5 PAUSE (wasted spend): no orders on Amazon after enough clicks, or the wrong product, size or colour. Paused; the search terms become negatives in the rebuild.
A43: Core terms were not paused on click count alone: each was checked for what a click is worth, bids and modifiers, placement results, relevance and the market's conversion on that search (Core Term Test tab).
A45: What changed from the last version
A46: 3 campaigns live with bids held (no tests). Budgets $10 / $10 / $5 = $25 a day, the Phase 0 / D4 ceiling, so no campaign runs out after one or two top-of-search clicks; expected spend stays about $3 to $5 a day because these terms are small. Top-of-search boosts on 'bohemian blanket' (+450%) and brand defence (+380%) come down to +300%.
...

Sheet Decisions
A1: Campaign-by-campaign decision: retain, adjust, retest, restructure or pause
A2: Every boho campaign, all ad types and match types. Numbers are looked up from the Campaigns and Search Terms tabs. Yellow column is for you.
A4: Ad type and match type coverage
A5: Ad type / match type | B5: Campaigns | C5: Enabled now | D5: Spend since launch | E5: Note
A6: Sponsored Products: Exact keyword | B6: =COUNTIF(Campaigns!$D$6:$D$45,"SP Exact keyword") -> 30 | C6: =COUNTIFS(Campaigns!$D$6:$D$45,"SP Exact keyword",Campaigns!$H$6:$H$45,"ENABLED") -> 15 | D6: =SUMIFS(Campaigns!$O$6:$O$45,Campaigns!$D$6:$D$45,"SP Exact keyword") -> 1444.15 | E6: All keyword campaigns are exact
A7: Sponsored Products: Product targeting (ASIN) | B7: =COUNTIF(Campaigns!$D$6:$D$45,"SP Product targeting") -> 10 | C7: =COUNTIFS(Campaigns!$D$6:$D$45,"SP Product targeting",Campaigns!$H$6:$H$45,"ENABLED") -> 7 | D7: =SUMIFS(Campaigns!$O$6:$O$45,Campaigns!$D$6:$D$45,"SP Product targeting") -> 203.87 | E7: All advertise Bouquet 60x80
A8: Sponsored Products: Phrase | B8: 0 | C8: 0 | D8: 0 | E8: None exist
A9: Sponsored Products: Broad | B9: 0 | C9: 0 | D9: 0 | E9: None exist
A10: Sponsored Products: Auto | B10: 0 | C10: 0 | D10: 0 | E10: None exist
A11: Sponsored Brands (headline) | B11: 0 | C11: 0 | D11: 0 | E11: None exist (no brand assets yet)
A12: Sponsored Brands Video | B12: 0 | C12: 0 | D12: 0 | E12: None exist (no product video yet)
A13: Sponsored Display | B13: 0 | C13: 0 | D13: 0 | E13: None exist
A14: Source: Command Center lists 40 campaigns for this product, all Sponsored Products (30 exact, 10 product targeting); DataDive's campaign list matches; the decision pack records 0% Sponsored Brands and Display. Nothing else to pause.
A16: Summary by decision
A17: Decision category | B17: Campaigns | C17: Live after the change | D17: Spend since launch | E17: Orders since launch | F17: Spend, last 30 days | G17: Orders, last 30 days | H17: Spend on zero-order campaigns since launch
A18: 1 RETAIN (generating orders) | B18: =COUNTIF(Campaigns!$AT$6:$AT$45,$A18) -> 2 | C18: =COUNTIFS(Campaigns!$AT$6:$AT$45,$A18,Campaigns!$AU$6:$AU$45,"ENABLED") -> 2 | D18: =SUMIFS(Campaigns!$O$6:$O$45,Campaigns!$AT$6:$AT$45,$A18) -> 173.26 | E18: =SUMIFS(Campaigns!$P$6:$P$45,Campaigns!$AT$6:$AT$45,$A18) -> 6 | F18: =SUMIFS(Campaigns!$X$6:$X$45,Campaigns!$AT$6:$AT$45,$A18) -> 96.88 | G18: =SUMIFS(Campaigns!$Y$6:$Y$45,Campaigns!$AT$6:$AT$45,$A18) -> 3 | H18: =SUMIFS(Campaigns!$O$6:$O$45,Campaigns!$AT$6:$AT$45,$A18,Campaigns!$P$6:$P$45,0) -> 0
A19: 2 ADJUST (bid / placement) | B19: =COUNTIF(Campaigns!$AT$6:$AT$45,$A19) -> 1 | C19: =COUNTIFS(Campaigns!$AT$6:$AT$45,$A19,Campaigns!$AU$6:$AU$45,"ENABLED") -> 1 | D19: =SUMIFS(Campaigns!$O$6:$O$45,Campaigns!$AT$6:$AT$45,$A19) -> 1.38 | E19: =SUMIFS(Campaigns!$P$6:$P$45,Campaigns!$AT$6:$AT$45,$A19) -> 0 | F19: =SUMIFS(Campaigns!$X$6:$X$45,Campaigns!$AT$6:$AT$45,$A19) -> 0 | G19: =SUMIFS(Campaigns!$Y$6:$Y$45,Campaigns!$AT$6:$AT$45,$A19) -> 0 | H19: =SUMIFS(Campaigns!$O$6:$O$45,Campaigns!$AT$6:$AT$45,$A19,Campaigns!$P$6:$P$45,0) -> 1.38
A20: 3 RETEST AFTER REBUILD | B20: =COUNTIF(Campaigns!$AT$6:$AT$45,$A20) -> 6 | C20: =COUNTIFS(Campaigns!$AT$6:$AT$45,$A20,Campaigns!$AU$6:$AU$45,"ENABLED") -> 0 | D20: =SUMIFS(Campaigns!$O$6:$O$45,Campaigns!$AT$6:$AT$45,$A20) -> 480.77 | E20: =SUMIFS(Campaigns!$P$6:$P$45,Campaigns!$AT$6:$AT$45,$A20) -> 13 | F20: =SUMIFS(Campaigns!$X$6:$X$45,Campaigns!$AT$6:$AT$45,$A20) -> 51.91 | G20: =SUMIFS(Campaigns!$Y$6:$Y$45,Campaigns!$AT$6:$AT$45,$A20) -> 0 | H20: =SUMIFS(Campaigns!$O$6:$O$45,Campaigns!$AT$6:$AT$45,$A20,Campaigns!$P$6:$P$45,0) -> 42.81
A21: 4 RESTRUCTURE IN REBUILD | B21: =COUNTIF(Campaigns!$AT$6:$AT$45,$A21) -> 6 | C21: =COUNTIFS(Campaigns!$AT$6:$AT$45,$A21,Campaigns!$AU$6:$AU$45,"ENABLED") -> 0 | D21: =SUMIFS(Campaigns!$O$6:$O$45,Campaigns!$AT$6:$AT$45,$A21) -> 461.08 | E21: =SUMIFS(Campaigns!$P$6:$P$45,Campaigns!$AT$6:$AT$45,$A21) -> 12 | F21: =SUMIFS(Campaigns!$X$6:$X$45,Campaigns!$AT$6:$AT$45,$A21) -> 150.3 | G21: =SUMIFS(Campaigns!$Y$6:$Y$45,Campaigns!$AT$6:$AT$45,$A21) -> 1 | H21: =SUMIFS(Campaigns!$O$6:$O$45,Campaigns!$AT$6:$AT$45,$A21,Campaigns!$P$6:$P$45,0) -> 22.9
A22: 5 PAUSE (wasted spend) | B22: =COUNTIF(Campaigns!$AT$6:$AT$45,$A22) -> 25 | C22: =COUNTIFS(Campaigns!$AT$6:$AT$45,$A22,Campaigns!$AU$6:$AU$45,"ENABLED") -> 0 | D22: =SUMIFS(Campaigns!$O$6:$O$45,Campaigns!$AT$6:$AT$45,$A22) -> 531.53 | E22: =SUMIFS(Campaigns!$P$6:$P$45,Campaigns!$AT$6:$AT$45,$A22) -> 3 | F22: =SUMIFS(Campaigns!$X$6:$X$45,Campaigns!$AT$6:$AT$45,$A22) -> 188.4 | G22: =SUMIFS(Campaigns!$Y$6:$Y$45,Campaigns!$AT$6:$AT$45,$A22) -> 0 | H22: =SUMIFS(Campaigns!$O$6:$O$45,Campaigns!$AT$6:$AT$45,$A22,Campaigns!$P$6:$P$45,0) -> 472
A23: TOTAL | B23: =SUM(B18:B22) -> 40 | C23: =SUM(C18:C22) -> 3 | D23: =SUM(D18:D22) -> 1648.02 | E23: =SUM(E18:E22) -> 34 | F23: =SUM(F18:F22) -> 487.49 | G23: =SUM(G18:G22) -> 4 | H23: =SUM(H18:H22) -> 539.09
A25: Campaign list (sorted by decision, then spend)
A26: Decision category | B26: Campaign | C26: Campaign ID | D26: Ad type / match | E26: Main keyword or ASIN | F26: State now | G26: New state | H26: Clicks since launch | I26: Orders since launch | J26: Spend since launch | K26: ACoS since launch | L26: CPC since launch | M26: On-Amazon clicks | N26: On-Amazon orders | O26: Clicks, last 30 days | P26: Orders, last 30 days | Q26: Spend, last 30 days | R26: Wasted spend (campaign had 0 orders) | S26: TOS modifier | T26: Search volume | U26: Relevancy | V26: Organic rank | W26: Action | X26: Why (data) | Y26: In the rebuild | Z26: Approver | AA26: Done? (Y/N)
A27: 1 RETAIN (generating orders) | B27: bohemian throw blanket | C27: 271118311398471 | D27: =INDEX(Campaigns!$D$6:$D$45,MATCH($C27,Campaigns!$A$6:$A$45,0)) -> SP Exact keyword | E27: bohemian throw blanket | F27: =INDEX(Campaigns!$H$6:$H$45,MATCH($C27,Campaigns!$A$6:$A$45,0)) -> ENABLED | G27: =INDEX(Campaigns!$AU$6:$AU$45,MATCH($C27,Campaigns!$A$6:$A$45,0)) -> ENABLED | H27: =INDEX(Campaigns!$N$6:$N$45,MATCH($C27,Campaigns!$A$6:$A$45,0)) -> 184 | I27: =INDEX(Campaigns!$P$6:$P$45,MATCH($C27,Campaigns!$A$6:$A$45,0)) -> 4 | J27: =INDEX(Campaigns!$O$6:$O$45,MATCH($C27,Campaigns!$A$6:$A$45,0)) -> 128.41 | K27: =INDEX(Campaigns!$U$6:$U$45,MATCH($C27,Campaigns!$A$6:$A$45,0)) -> 0.85067903 | L27: =INDEX(Campaigns!$T$6:$T$45,MATCH($C27,Campaigns!$A$6:$A$45,0)) -> 0.69788043 | M27: =INDEX(Campaigns!$AH$6:$AH$45,MATCH($C27,Campaigns!$A$6:$A$45,0))+INDEX(Campaigns!$AJ$6:$AJ$45,MATCH($C27,Campaigns!$A$6:$A$45,0))+INDEX(Campaigns!$AL$6:$AL$45,MATCH($C27,Campaigns!$A$6:$A$45,0)) -> 184 | N27: 4 | O27: =INDEX(Campaigns!$W$6:$W$45,MATCH($C27,Campaigns!$A$6:$A$45,0)) -> 92 | P27: =INDEX(Campaigns!$Y$6:$Y$45,MATCH($C27,Campaigns!$A$6:$A$45,0)) -> 1 | Q27: =INDEX(Campaigns!$X$6:$X$45,MATCH($C27,Campaigns!$A$6:$A$45,0)) -> 69.17 | R27: =IF(I27=0,J27,0) -> 0 | S27: =IF(INDEX(Campaigns!$J$6:$J$45,MATCH($C27,Campaigns!$A$6:$A$45,0))="","",INDEX(Campaigns!$J$6:$J$45,MATCH($C27,Campaigns!$A$6:$A$45,0))) -> 2.8 | T27: =IFERROR(INDEX('Search Terms'!$C$5:$C$137,MATCH($E27,'Search Terms'!$A$5:$A$137,0)),"") -> 725 | U27: =IFERROR(INDEX('Search Terms'!$B$5:$B$137,MATCH($E27,'Search Terms'!$A$5:$A$137,0)),"") -> Relevant | V27: =IFERROR(INDEX('Search Terms'!$D$5:$D$137,MATCH($E27,'Search Terms'!$A$5:$A$137,0)),"") -> 79 | W27: Keep live. Bid unchanged ($0.52); TOS +280% unchanged; budget $9.41 to $10 a day | X27: Only live core term still converting: 4 on-Amazon orders since launch, 1 in the last 30 days. SQP cart adds in line with the market (3 on 24 clicks vs 3.2 expected). ACoS 85%. Held as is (no bid test); the budget covers about 6 top-of-search clicks a day at its real CPC ($1.72). | Y27: Core exact, single keyword, Butterfly 50x60 | Z27: Joseph approves; Shayan applies
A28: 1 RETAIN (generating orders) | B28: bohemian blanket | C28: 274384612784893 | D28: =INDEX(Campaigns!$D$6:$D$45,MATCH($C28,Campaigns!$A$6:$A$45,0)) -> SP Exact keyword | E28: bohemian blanket | F28: =INDEX(Campaigns!$H$6:$H$45,MATCH($C28,Campaigns!$A$6:$A$45,0)) -> PAUSED | G28: =INDEX(Campaigns!$AU$6:$AU$45,MATCH($C28,Campaigns!$A$6:$A$45,0)) -> ENABLED | H28: =INDEX(Campaigns!$N$6:$N$45,MATCH($C28,Campaigns!$A$6:$A$45,0)) -> 50 | I28: =INDEX(Campaigns!$P$6:$P$45,MATCH($C28,Campaigns!$A$6:$A$45,0)) -> 2 | J28: =INDEX(Campaigns!$O$6:$O$45,MATCH($C28,Campaigns!$A$6:$A$45,0)) -> 44.85 | K28: =INDEX(Campaigns!$U$6:$U$45,MATCH($C28,Campaigns!$A$6:$A$45,0)) -> 0.72362052 | L28: =INDEX(Campaigns!$T$6:$T$45,MATCH($C28,Campaigns!$A$6:$A$45,0)) -> 0.897 | M28: =INDEX(Campaigns!$AH$6:$AH$45,MATCH($C28,Campaigns!$A$6:$A$45,0))+INDEX(Campaigns!$AJ$6:$AJ$45,MATCH($C28,Campaigns!$A$6:$A$45,0))+INDEX(Campaigns!$AL$6:$AL$45,MATCH($C28,Campaigns!$A$6:$A$45,0)) -> 50 | N28: 2 | O28: =INDEX(Campaigns!$W$6:$W$45,MATCH($C28,Campaigns!$A$6:$A$45,0)) -> 28 | P28: =INDEX(Campaigns!$Y$6:$Y$45,MATCH($C28,Campaigns!$A$6:$A$45,0)) -> 2 | Q28: =INDEX(Campaigns!$X$6:$X$45,MATCH($C28,Campaigns!$A$6:$A$45,0)) -> 27.71 | R28: =IF(I28=0,J28,0) -> 0 | S28: =IF(INDEX(Campaigns!$J$6:$J$45,MATCH($C28,Campaigns!$A$6:$A$45,0))="","",INDEX(Campaigns!$J$6:$J$45,MATCH($C28,Campaigns!$A$6:$A$45,0))) | T28: =IFERROR(INDEX('Search Terms'!$C$5:$C$137,MATCH($E28,'Search Terms'!$A$5:$A$137,0)),"") -> 591 | U28: =IFERROR(INDEX('Search Terms'!$B$5:$B$137,MATCH($E28,'Search Terms'!$A$5:$A$137,0)),"") -> Highly Relevant | V28: =IFERROR(INDEX('Search Terms'!$D$5:$D$137,MATCH($E28,'Search Terms'!$A$5:$A$137,0)),"") -> 85 | W28: Re-enable. Bid unchanged ($0.69); TOS +450% to +300%; budget $10 a day | X28: Best converter on the product: 2 orders on 50 clicks (4.0%), both in the last 30 days, ACoS 72%. It was paused on early-September data. TOS +450% let it pay up to $3.80 a click; +300% caps that at $2.76. | Y28: Core exact, single keyword | Z28: Joseph approves; Shayan applies
A29: 2 ADJUST (bid / placement) | B29: sleephoria boho throw blanket | C29: 94080520861158 | D29: =INDEX(Campaigns!$D$6:$D$45,MATCH($C29,Campaigns!$A$6:$A$45,0)) -> SP Exact keyword | E29: sleephoria boho throw blanket | F29: =INDEX(Campaigns!$H$6:$H$45,MATCH($C29,Campaigns!$A$6:$A$45,0)) -> ENABLED | G29: =INDEX(Campaigns!$AU$6:$AU$45,MATCH($C29,Campaigns!$A$6:$A$45,0)) -> ENABLED | H29: =INDEX(Campaigns!$N$6:$N$45,MATCH($C29,Campaigns!$A$6:$A$45,0)) -> 4 | I29: =INDEX(Campaigns!$P$6:$P$45,MATCH($C29,Campaigns!$A$6:$A$45,0)) -> 0 | J29: =INDEX(Campaigns!$O$6:$O$45,MATCH($C29,Campaigns!$A$6:$A$45,0)) -> 1.38 | K29: =INDEX(Campaigns!$U$6:$U$45,MATCH($C29,Campaigns!$A$6:$A$45,0)) | L29: =INDEX(Campaigns!$T$6:$T$45,MATCH($C29,Campaigns!$A$6:$A$45,0)) -> 0.345 | M29: =INDEX(Campaigns!$AH$6:$AH$45,MATCH($C29,Campaigns!$A$6:$A$45,0))+INDEX(Campaigns!$AJ$6:$AJ$45,MATCH($C29,Campaigns!$A$6:$A$45,0))+INDEX(Campaigns!$AL$6:$AL$45,MATCH($C29,Campaigns!$A$6:$A$45,0)) -> 4 | N29: 0 | O29: =INDEX(Campaigns!$W$6:$W$45,MATCH($C29,Campaigns!$A$6:$A$45,0)) -> 0 | P29: =INDEX(Campaigns!$Y$6:$Y$45,MATCH($C29,Campaigns!$A$6:$A$45,0)) -> 0 | Q29: =INDEX(Campaigns!$X$6:$X$45,MATCH($C29,Campaigns!$A$6:$A$45,0)) -> 0 | R29: =IF(I29=0,J29,0) -> 1.38 | S29: =IF(INDEX(Campaigns!$J$6:$J$45,MATCH($C29,Campaigns!$A$6:$A$45,0))="","",INDEX(Campaigns!$J$6:$J$45,MATCH($C29,Campaigns!$A$6:$A$45,0))) -> 3.8 | T29: =IFERROR(INDEX('Search Terms'!$C$5:$C$137,MATCH($E29,'Search Terms'!$A$5:$A$137,0)),"") -> 9 | U29: =IFERROR(INDEX('Search Terms'!$B$5:$B$137,MATCH($E29,'Search Terms'!$A$5:$A$137,0)),"") -> Branded | V29: =IFERROR(INDEX('Search Terms'!$D$5:$D$137,MATCH($E29,'Search Terms'!$A$5:$A$137,0)),"") -> 1 | W29: Keep live. Bid unchanged ($0.68); TOS +380% to +300%; budget $11.32 to $5 a day | X29: Own-brand searches: 4 clicks, $1.38 since launch. Cheap protection for the listing, but the modifier is above the plan's +300% cap. | Y29: Brand defence SP exact; add a Sponsored Brands headline once brand assets exist | Z29: Joseph approves; Shayan applies
A30: 3 RETEST AFTER REBUILD | B30: boho throw blankets for couch | C30: 240955455575163 | D30: =INDEX(Campaigns!$D$6:$D$45,MATCH($C30,Campaigns!$A$6:$A$45,0)) -> SP Exact keyword | E30: boho throw blankets for couch | F30: =INDEX(Campaigns!$H$6:$H$45,MATCH($C30,Campaigns!$A$6:$A$45,0)) -> ENABLED | G30: =INDEX(Campaigns!$AU$6:$AU$45,MATCH($C30,Campaigns!$A$6:$A$45,0)) -> PAUSED | H30: =INDEX(Campaigns!$N$6:$N$45,MATCH($C30,Campaigns!$A$6:$A$45,0)) -> 476 | I30: =INDEX(Campaigns!$P$6:$P$45,MATCH($C30,Campaigns!$A$6:$A$45,0)) -> 5 | J30: =INDEX(Campaigns!$O$6:$O$45,MATCH($C30,Campaigns!$A$6:$A$45,0)) -> 158.98 | K30: =INDEX(Campaigns!$U$6:$U$45,MATCH($C30,Campaigns!$A$6:$A$45,0)) -> 1.0531964 | L30: =INDEX(Campaigns!$T$6:$T$45,MATCH($C30,Campaigns!$A$6:$A$45,0)) -> 0.3339916 | M30: =INDEX(Campaigns!$AH$6:$AH$45,MATCH($C30,Campaigns!$A$6:$A$45,0))+INDEX(Campaigns!$AJ$6:$AJ$45,MATCH($C30,Campaigns!$A$6:$A$45,0))+INDEX(Campaigns!$AL$6:$AL$45,MATCH($C30,Campaigns!$A$6:$A$45,0)) -> 54 | N30: 1 | O30: =INDEX(Campaigns!$W$6:$W$45,MATCH($C30,Campaigns!$A$6:$A$45,0)) -> 31 | P30: =INDEX(Campaigns!$Y$6:$Y$45,MATCH($C30,Campaigns!$A$6:$A$45,0)) -> 0 | Q30: =INDEX(Campaigns!$X$6:$X$45,MATCH($C30,Campaigns!$A$6:$A$45,0)) -> 44.99 | R30: =IF(I30=0,J30,0) -> 0 | S30: =IF(INDEX(Campaigns!$J$6:$J$45,MATCH($C30,Campaigns!$A$6:$A$45,0))="","",INDEX(Campaigns!$J$6:$J$45,MATCH($C30,Campaigns!$A$6:$A$45,0))) -> 3 | T30: =IFERROR(INDEX('Search Terms'!$C$5:$C$137,MATCH($E30,'Search Terms'!$A$5:$A$137,0)),"") -> 497 | U30: =IFERROR(INDEX('Search Terms'!$B$5:$B$137,MATCH($E30,'Search Terms'!$A$5:$A$137,0)),"") -> Relevant | V30: =IFERROR(INDEX('Search Terms'!$D$5:$D$137,MATCH($E30,'Search Terms'!$A$5:$A$137,0)),"") -> 85 | W30: Pause now; retest after the rebuild | X30: 5 orders since launch, but 4 came from Off-Amazon traffic (422 of 476 clicks), which has stopped. On Amazon: 1 order on 54 clicks, and 0 orders on 31 clicks ($45) in the last 30 days. SQP cart adds are fine (3 on 23 clicks), so the term fits; the page does not close. | Y30: Couch-intent exact, Butterfly 50x60 | Z30: Joseph approves; Shayan applies
A31: 3 RETEST AFTER REBUILD | B31: boho blanket | C31: 131359054806082 | D31: =INDEX(Campaigns!$D$6:$D$45,MATCH($C31,Campaigns!$A$6:$A$45,0)) -> SP Exact keyword | E31: boho blanket | F31: =INDEX(Campaigns!$H$6:$H$45,MATCH($C31,Campaigns!$A$6:$A$45,0)) -> PAUSED | G31: =INDEX(Campaigns!$AU$6:$AU$45,MATCH($C31,Campaigns!$A$6:$A$45,0)) -> PAUSED | H31: =INDEX(Campaigns!$N$6:$N$45,MATCH($C31,Campaigns!$A$6:$A$45,0)) -> 187 | I31: =INDEX(Campaigns!$P$6:$P$45,MATCH($C31,Campaigns!$A$6:$A$45,0)) -> 3 | J31: =INDEX(Campaigns!$O$6:$O$45,MATCH($C31,Campaigns!$A$6:$A$45,0)) -> 138.56 | K31: =INDEX(Campaigns!$U$6:$U$45,MATCH($C31,Campaigns!$A$6:$A$45,0)) -> 1.5573789 | L31: =INDEX(Campaigns!$T$6:$T$45,MATCH($C31,Campaigns!$A$6:$A$45,0)) -> 0.74096257 | M31: =INDEX(Campaigns!$AH$6:$AH$45,MATCH($C31,Campaigns!$A$6:$A$45,0))+INDEX(Campaigns!$AJ$6:$AJ$45,MATCH($C31,Campaigns!$A$6:$A$45,0))+INDEX(Campaigns!$AL$6:$AL$45,MATCH($C31,Campaigns!$A$6:$A$45,0)) -> 185 | N31: 3 | O31: =INDEX(Campaigns!$W$6:$W$45,MATCH($C31,Campaigns!$A$6:$A$45,0)) -> 0 | P31: =INDEX(Campaigns!$Y$6:$Y$45,MATCH($C31,Campaigns!$A$6:$A$45,0)) -> 0 | Q31: =INDEX(Campaigns!$X$6:$X$45,MATCH($C31,Campaigns!$A$6:$A$45,0)) -> 0 | R31: =IF(I31=0,J31,0) -> 0 | S31: =IF(INDEX(Campaigns!$J$6:$J$45,MATCH($C31,Campaigns!$A$6:$A$45,0))="","",INDEX(Campaigns!$J$6:$J$45,MATCH($C31,Campaigns!$A$6:$A$45,0))) | T31: =IFERROR(INDEX('Search Terms'!$C$5:$C$137,MATCH($E31,'Search Terms'!$A$5:$A$137,0)),"") -> 4932 | U31: =IFERROR(INDEX('Search Terms'!$B$5:$B$137,MATCH($E31,'Search Terms'!$A$5:$A$137,0)),"") -> Relevant | V31: =IFERROR(INDEX('Search Terms'!$D$5:$D$137,MATCH($E31,'Search Terms'!$A$5:$A$137,0)),"") -> 133 | W31: Keep paused; retest after the rebuild | X31: 3 orders on 185 on-Amazon clicks (1.6%), all from product pages; ACoS 156% on a $40 a day budget. SQP cart adds are normal for the market (3 on 29 vs 3.4 expected), so the term fits; the old page does not close. Large demand (4,932 a month): worth retesting on the new page, not worth paying for on the old one. | Y31: Core exact, single keyword | Z31: Joseph approves; Shayan applies
A32: 3 RETEST AFTER REBUILD | B32: boho throw | C32: 143967856454663 | D32: =INDEX(Campaigns!$D$6:$D$45,MATCH($C32,Campaigns!$A$6:$A$45,0)) -> SP Exact keyword | E32: boho throw | F32: =INDEX(Campaigns!$H$6:$H$45,MATCH($C32,Campaigns!$A$6:$A$45,0)) -> PAUSED | G32: =INDEX(Campaigns!$AU$6:$AU$45,MATCH($C32,Campaigns!$A$6:$A$45,0)) -> PAUSED | H32: =INDEX(Campaigns!$N$6:$N$45,MATCH($C32,Campaigns!$A$6:$A$45,0)) -> 125 | I32: =INDEX(Campaigns!$P$6:$P$45,MATCH($C32,Campaigns!$A$6:$A$45,0)) -> 3 | J32: =INDEX(Campaigns!$O$6:$O$45,MATCH($C32,Campaigns!$A$6:$A$45,0)) -> 92.74 | K32: =INDEX(Campaigns!$U$6:$U$45,MATCH($C32,Campaigns!$A$6:$A$45,0)) -> 1.1453625 | L32: =INDEX(Campaigns!$T$6:$T$45,MATCH($C32,Campaigns!$A$6:$A$45,0)) -> 0.74192 | M32: =INDEX(Campaigns!$AH$6:$AH$45,MATCH($C32,Campaigns!$A$6:$A$45,0))+INDEX(Campaigns!$AJ$6:$AJ$45,MATCH($C32,Campaigns!$A$6:$A$45,0))+INDEX(Campaigns!$AL$6:$AL$45,MATCH($C32,Campaigns!$A$6:$A$45,0)) -> 125 | N32: 3 | O32: =INDEX(Campaigns!$W$6:$W$45,MATCH($C32,Campaigns!$A$6:$A$45,0)) -> 0 | P32: =INDEX(Campaigns!$Y$6:$Y$45,MATCH($C32,Campaigns!$A$6:$A$45,0)) -> 0 | Q32: =INDEX(Campaigns!$X$6:$X$45,MATCH($C32,Campaigns!$A$6:$A$45,0)) -> 0 | R32: =IF(I32=0,J32,0) -> 0 | S32: =IF(INDEX(Campaigns!$J$6:$J$45,MATCH($C32,Campaigns!$A$6:$A$45,0))="","",INDEX(Campaigns!$J$6:$J$45,MATCH($C32,Campaigns!$A$6:$A$45,0))) | T32: =IFERROR(INDEX('Search Terms'!$C$5:$C$137,MATCH($E32,'Search Terms'!$A$5:$A$137,0)),"") -> 1229 | U32: =IFERROR(INDEX('Search Terms'!$B$5:$B$137,MATCH($E32,'Search Terms'!$A$5:$A$137,0)),"") -> Relevant | V32: =IFERROR(INDEX('Search Terms'!$D$5:$D$137,MATCH($E32,'Search Terms'!$A$5:$A$137,0)),"") -> 94 | W32: Keep paused; retest first after the rebuild | X32: 3 orders on 125 clicks (2.4%), all at Top of Search; ACoS 115%. The closest of the core terms to break-even, but no orders since September and SQP shows 1 cart add on 34 clicks vs about 3.9 expected. | Y32: Core exact, single keyword | Z32: Joseph approves; Shayan applies
A33: 3 RETEST AFTER REBUILD | B33: boho throw blanket | C33: 136479271696362 | D33: =INDEX(Campaigns!$D$6:$D$45,MATCH($C33,Campaigns!$A$6:$A$45,0)) -> SP Exact keyword | E33: boho throw blanket | F33: =INDEX(Campaigns!$H$6:$H$45,MATCH($C33,Campaigns!$A$6:$A$45,0)) -> PAUSED | G33: =INDEX(Campaigns!$AU$6:$AU$45,MATCH($C33,Campaigns!$A$6:$A$45,0)) -> PAUSED | H33: =INDEX(Campaigns!$N$6:$N$45,MATCH($C33,Campaigns!$A$6:$A$45,0)) -> 44 | I33: =INDEX(Campaigns!$P$6:$P$45,MATCH($C33,Campaigns!$A$6:$A$45,0)) -> 0 | J33: =INDEX(Campaigns!$O$6:$O$45,MATCH($C33,Campaigns!$A$6:$A$45,0)) -> 42.81 | K33: =INDEX(Campaigns!$U$6:$U$45,MATCH($C33,Campaigns!$A$6:$A$45,0)) | L33: =INDEX(Campaigns!$T$6:$T$45,MATCH($C33,Campaigns!$A$6:$A$45,0)) -> 0.97295455 | M33: =INDEX(Campaigns!$AH$6:$AH$45,MATCH($C33,Campaigns!$A$6:$A$45,0))+INDEX(Campaigns!$AJ$6:$AJ$45,MATCH($C33,Campaigns!$A$6:$A$45,0))+INDEX(Campaigns!$AL$6:$AL$45,MATCH($C33,Campaigns!$A$6:$A$45,0)) -> 43 | N33: 0 | O33: =INDEX(Campaigns!$W$6:$W$45,MATCH($C33,Campaigns!$A$6:$A$45,0)) -> 0 | P33: =INDEX(Campaigns!$Y$6:$Y$45,MATCH($C33,Campaigns!$A$6:$A$45,0)) -> 0 | Q33: =INDEX(Campaigns!$X$6:$X$45,MATCH($C33,Campaigns!$A$6:$A$45,0)) -> 0 | R33: =IF(I33=0,J33,0) -> 42.81 | S33: =IF(INDEX(Campaigns!$J$6:$J$45,MATCH($C33,Campaigns!$A$6:$A$45,0))="","",INDEX(Campaigns!$J$6:$J$45,MATCH($C33,Campaigns!$A$6:$A$45,0))) | T33: =IFERROR(INDEX('Search Terms'!$C$5:$C$137,MATCH($E33,'Search Terms'!$A$5:$A$137,0)),"") -> 9420 | U33: =IFERROR(INDEX('Search Terms'!$B$5:$B$137,MATCH($E33,'Search Terms'!$A$5:$A$137,0)),"") -> Relevant | V33: =IFERROR(INDEX('Search Terms'!$D$5:$D$137,MATCH($E33,'Search Terms'!$A$5:$A$137,0)),"") -> 99 | W33: Keep paused. Do not negate. First exact test after the rebuild at the worth-based bid | X33: Hero term (9,420 searches a month; organic rank about 99). 42 clicks, 0 orders, $39. SQP: 0 add-to-carts on 38 clicks where the market rate (13%) predicts about 5, a chance of about 0.5%. The listing is not converting this search, and a lower bid cannot fix that. It paid $0.94 a click (Top of Search $1.33 at +300%) against about $0.17 a click is worth at the market's 1.6% CVR. Full workings: Core Term Test tab. | Y33: Core exact, single keyword, Butterfly 50x60. Pass mark: 2+ cart adds per 20 clicks, 1+ order per 50 clicks | Z33: Joseph approves; Shayan applies
A34: 3 RETEST AFTER REBUILD | B34: boho cotton blanket | C34: 153632991648836 | D34: =INDEX(Campaigns!$D$6:$D$45,MATCH($C34,Campaigns!$A$6:$A$45,0)) -> SP Exact keyword | E34: boho cotton blanket | F34: =INDEX(Campaigns!$H$6:$H$45,MATCH($C34,Campaigns!$A$6:$A$45,0)) -> PAUSED | G34: =INDEX(Campaigns!$AU$6:$AU$45,MATCH($C34,Campaigns!$A$6:$A$45,0)) -> PAUSED | H34: =INDEX(Campaigns!$N$6:$N$45,MATCH($C34,Campaigns!$A$6:$A$45,0)) -> 35 | I34: =INDEX(Campaigns!$P$6:$P$45,MATCH($C34,Campaigns!$A$6:$A$45,0)) -> 1 | J34: =INDEX(Campaigns!$O$6:$O$45,MATCH($C34,Campaigns!$A$6:$A$45,0)) -> 36.98 | K34: =INDEX(Campaigns!$U$6:$U$45,MATCH($C34,Campaigns!$A$6:$A$45,0)) -> 1.0568734 | L34: =INDEX(Campaigns!$T$6:$T$45,MATCH($C34,Campaigns!$A$6:$A$45,0)) -> 1.0565714 | M34: =INDEX(Campaigns!$AH$6:$AH$45,MATCH($C34,Campaigns!$A$6:$A$45,0))+INDEX(Campaigns!$AJ$6:$AJ$45,MATCH($C34,Campaigns!$A$6:$A$45,0))+INDEX(Campaigns!$AL$6:$AL$45,MATCH($C34,Campaigns!$A$6:$A$45,0)) -> 35 | N34: 1 | O34: =INDEX(Campaigns!$W$6:$W$45,MATCH($C34,Campaigns!$A$6:$A$45,0)) -> 0 | P34: =INDEX(Campaigns!$Y$6:$Y$45,MATCH($C34,Campaigns!$A$6:$A$45,0)) -> 0 | Q34: =INDEX(Campaigns!$X$6:$X$45,MATCH($C34,Campaigns!$A$6:$A$45,0)) -> 0 | R34: =IF(I34=0,J34,0) -> 0 | S34: =IF(INDEX(Campaigns!$J$6:$J$45,MATCH($C34,Campaigns!$A$6:$A$45,0))="","",INDEX(Campaigns!$J$6:$J$45,MATCH($C34,Campaigns!$A$6:$A$45,0))) | T34: =IFERROR(INDEX('Search Terms'!$C$5:$C$137,MATCH($E34,'Search Terms'!$A$5:$A$137,0)),"") -> 365 | U34: =IFERROR(INDEX('Search Terms'!$B$5:$B$137,MATCH($E34,'Search Terms'!$A$5:$A$137,0)),"") -> Highly Relevant | V34: =IFERROR(INDEX('Search Terms'!$D$5:$D$137,MATCH($E34,'Search Terms'!$A$5:$A$137,0)),"") -> 55 | W34: Keep paused; retest after the rebuild | X34: 1 order on 35 clicks (Top of Search); rated Highly Relevant; organic rank about 55. Too little data to justify spend before the page is fixed. | Y34: Material lane exact | Z34: Joseph approves; Shayan applies
A35: 3 RETEST AFTER REBUILD | B35: rustic floral boho blanket | C35: 122105077616953 | D35: =INDEX(Campaigns!$D$6:$D$45,MATCH($C35,Campaigns!$A$6:$A$45,0)) -> SP Exact keyword | E35: rustic floral boho blanket | F35: =INDEX(Campaigns!$H$6:$H$45,MATCH($C35,Campaigns!$A$6:$A$45,0)) -> ENABLED | G35: =INDEX(Campaigns!$AU$6:$AU$45,MATCH($C35,Campaigns!$A$6:$A$45,0)) -> PAUSED | H35: =INDEX(Campaigns!$N$6:$N$45,MATCH($C35,Campaigns!$A$6:$A$45,0)) -> 7 | I35: =INDEX(Campaigns!$P$6:$P$45,MATCH($C35,Campaigns!$A$6:$A$45,0)) -> 1 | J35: =INDEX(Campaigns!$O$6:$O$45,MATCH($C35,Campaigns!$A$6:$A$45,0)) -> 10.7 | K35: =INDEX(Campaigns!$U$6:$U$45,MATCH($C35,Campaigns!$A$6:$A$45,0)) -> 0.30580166 | L35: =INDEX(Campaigns!$T$6:$T$45,MATCH($C35,Campaigns!$A$6:$A$45,0)) -> 1.5285714 | M35: =INDEX(Campaigns!$AH$6:$AH$45,MATCH($C35,Campaigns!$A$6:$A$45,0))+INDEX(Campaigns!$AJ$6:$AJ$45,MATCH($C35,Campaigns!$A$6:$A$45,0))+INDEX(Campaigns!$AL$6:$AL$45,MATCH($C35,Campaigns!$A$6:$A$45,0)) -> 7 | N35: 1 | O35: =INDEX(Campaigns!$W$6:$W$45,MATCH($C35,Campaigns!$A$6:$A$45,0)) -> 4 | P35: =INDEX(Campaigns!$Y$6:$Y$45,MATCH($C35,Campaigns!$A$6:$A$45,0)) -> 0 | Q35: =INDEX(Campaigns!$X$6:$X$45,MATCH($C35,Campaigns!$A$6:$A$45,0)) -> 6.92 | R35: =IF(I35=0,J35,0) -> 0 | S35: =IF(INDEX(Campaigns!$J$6:$J$45,MATCH($C35,Campaigns!$A$6:$A$45,0))="","",INDEX(Campaigns!$J$6:$J$45,MATCH($C35,Campaigns!$A$6:$A$45,0))) -> 3 | T35: =IFERROR(INDEX('Search Terms'!$C$5:$C$137,MATCH($E35,'Search Terms'!$A$5:$A$137,0)),"") -> 33 | U35: =IFERROR(INDEX('Search Terms'!$B$5:$B$137,MATCH($E35,'Search Terms'!$A$5:$A$137,0)),"") -> Lower Relevant | V35: =IFERROR(INDEX('Search Terms'!$D$5:$D$137,MATCH($E35,'Search Terms'!$A$5:$A$137,0)),"") -> 39 | W35: Pause now; retest after the rebuild | X35: 1 order on 7 clicks since launch; 0 orders on 4 clicks at $1.73 a click in the last 30 days. Too few clicks to judge, and it advertises Bouquet 50x60, the weakest pattern. | Y35: Design lane (vintage floral), Bloom or Bouquet | Z35: Joseph approves; Shayan applies
A36: 4 RESTRUCTURE IN REBUILD | B36: boho king size blanket | C36: 43669682187702 | D36: =INDEX(Campaigns!$D$6:$D$45,MATCH($C36,Campaigns!$A$6:$A$45,0)) -> SP Exact keyword | E36: boho king size blanket | F36: =INDEX(Campaigns!$H$6:$H$45,MATCH($C36,Campaigns!$A$6:$A$45,0)) -> ENABLED | G36: =INDEX(Campaigns!$AU$6:$AU$45,MATCH($C36,Campaigns!$A$6:$A$45,0)) -> PAUSED | H36: =INDEX(Campaigns!$N$6:$N$45,MATCH($C36,Campaigns!$A$6:$A$45,0)) -> 1063 | I36: =INDEX(Campaigns!$P$6:$P$45,MATCH($C36,Campaigns!$A$6:$A$45,0)) -> 9 | J36: =INDEX(Campaigns!$O$6:$O$45,MATCH($C36,Campaigns!$A$6:$A$45,0)) -> 239.23 | K36: =INDEX(Campaigns!$U$6:$U$45,MATCH($C36,Campaigns!$A$6:$A$45,0)) -> 0.84560461 | L36: =INDEX(Campaigns!$T$6:$T$45,MATCH($C36,Campaigns!$A$6:$A$45,0)) -> 0.22505174 | M36: =INDEX(Campaigns!$AH$6:$AH$45,MATCH($C36,Campaigns!$A$6:$A$45,0))+INDEX(Campaigns!$AJ$6:$AJ$45,MATCH($C36,Campaigns!$A$6:$A$45,0))+INDEX(Campaigns!$AL$6:$AL$45,MATCH($C36,Campaigns!$A$6:$A$45,0)) -> 36 | N36: 0 | O36: =INDEX(Campaigns!$W$6:$W$45,MATCH($C36,Campaigns!$A$6:$A$45,0)) -> 28 | P36: =INDEX(Campaigns!$Y$6:$Y$45,MATCH($C36,Campaigns!$A$6:$A$45,0)) -> 0 | Q36: =INDEX(Campaigns!$X$6:$X$45,MATCH($C36,Campaigns!$A$6:$A$45,0)) -> 34.14 | R36: =IF(I36=0,J36,0) -> 0 | S36: =IF(INDEX(Campaigns!$J$6:$J$45,MATCH($C36,Campaigns!$A$6:$A$45,0))="","",INDEX(Campaigns!$J$6:$J$45,MATCH($C36,Campaigns!$A$6:$A$45,0))) -> 4.13 | T36: =IFERROR(INDEX('Search Terms'!$C$5:$C$137,MATCH($E36,'Search Terms'!$A$5:$A$137,0)),"") -> 94 | U36: =IFERROR(INDEX('Search Terms'!$B$5:$B$137,MATCH($E36,'Search Terms'!$A$5:$A$137,0)),"") -> Lower Relevant | V36: =IFERROR(INDEX('Search Terms'!$D$5:$D$137,MATCH($E36,'Search Terms'!$A$5:$A$137,0)),"") -> 113 | W36: Pause now. In the rebuild: negate king terms; move the 60x80 size terms to a size lane on the 60x80 SKU | X36: All 9 orders came from Off-Amazon (1,027 of 1,063 clicks), which stopped in late September. On Amazon: 0 orders on 36 clicks; bid $0.97 x +413% = up to $4.98 a click; the largest budget ($30). It mixes king-size terms (wrong size for a 60x80 throw) with 'boho blanket 60x 80' (the right size; organic rank 32). | Y36: Size lane exact (60x80, 50x60), SKU-matched | Z36: Joseph approves; Shayan applies
A37: 4 RESTRUCTURE IN REBUILD | B37: B0BLRBXBX5 | C37: 103168292442380 | D37: =INDEX(Campaigns!$D$6:$D$45,MATCH($C37,Campaigns!$A$6:$A$45,0)) -> SP Product targeting | E37: b0blrbxbx5 | F37: =INDEX(Campaigns!$H$6:$H$45,MATCH($C37,Campaigns!$A$6:$A$45,0)) -> ENABLED | G37: =INDEX(Campaigns!$AU$6:$AU$45,MATCH($C37,Campaigns!$A$6:$A$45,0)) -> PAUSED | H37: =INDEX(Campaigns!$N$6:$N$45,MATCH($C37,Campaigns!$A$6:$A$45,0)) -> 67 | I37: =INDEX(Campaigns!$P$6:$P$45,MATCH($C37,Campaigns!$A$6:$A$45,0)) -> 1 | J37: =INDEX(Campaigns!$O$6:$O$45,MATCH($C37,Campaigns!$A$6:$A$45,0)) -> 103.08 | K37: =INDEX(Campaigns!$U$6:$U$45,MATCH($C37,Campaigns!$A$6:$A$45,0)) -> 2.9459846 | L37: =INDEX(Campaigns!$T$6:$T$45,MATCH($C37,Campaigns!$A$6:$A$45,0)) -> 1.5385075 | M37: =INDEX(Campaigns!$AH$6:$AH$45,MATCH($C37,Campaigns!$A$6:$A$45,0))+INDEX(Campaigns!$AJ$6:$AJ$45,MATCH($C37,Campaigns!$A$6:$A$45,0))+INDEX(Campaigns!$AL$6:$AL$45,MATCH($C37,Campaigns!$A$6:$A$45,0)) -> 67 | N37: 1 | O37: =INDEX(Campaigns!$W$6:$W$45,MATCH($C37,Campaigns!$A$6:$A$45,0)) -> 66 | P37: =INDEX(Campaigns!$Y$6:$Y$45,MATCH($C37,Campaigns!$A$6:$A$45,0)) -> 1 | Q37: =INDEX(Campaigns!$X$6:$X$45,MATCH($C37,Campaigns!$A$6:$A$45,0)) -> 102.49 | R37: =IF(I37=0,J37,0) -> 0 | S37: =IF(INDEX(Campaigns!$J$6:$J$45,MATCH($C37,Campaigns!$A$6:$A$45,0))="","",INDEX(Campaigns!$J$6:$J$45,MATCH($C37,Campaigns!$A$6:$A$45,0))) -> 2.8 | T37: =IFERROR(INDEX('Search Terms'!$C$5:$C$137,MATCH($E37,'Search Terms'!$A$5:$A$137,0)),"") -> 0 | U37: =IFERROR(INDEX('Search Terms'!$B$5:$B$137,MATCH($E37,'Search Terms'!$A$5:$A$137,0)),"") -> Not Relevant | V37: =IFERROR(INDEX('Search Terms'!$D$5:$D$137,MATCH($E37,'Search Terms'!$A$5:$A$137,0)),"") -> 0 | W37: Pause now; rebuild as a size- and price-matched product-targeting lane | X37: The only competitor target with an order: 1 on 67 clicks, $103 per order, $1.54 a click, 90% of spend at Top of Search (+280%). All 10 product-targeting campaigns advertise Bouquet 60x80 whatever the competitor's size or price (MSGKV 60x80 sells at $29.99 vs our $34.99). | Y37: PAT by size and price match, Butterfly first, keyword-parity bids | Z37: Joseph approves; Shayan applies
A38: 4 RESTRUCTURE IN REBUILD | B38: boho scandinavian cotton blanket | C38: 143960123876477 | D38: =INDEX(Campaigns!$D$6:$D$45,MATCH($C38,Campaigns!$A$6:$A$45,0)) -> SP Exact keyword | E38: boho scandinavian cotton blanket | F38: =INDEX(Campaigns!$H$6:$H$45,MATCH($C38,Campaigns!$A$6:$A$45,0)) -> PAUSED | G38: =INDEX(Campaigns!$AU$6:$AU$45,MATCH($C38,Campaigns!$A$6:$A$45,0)) -> PAUSED | H38: =INDEX(Campaigns!$N$6:$N$45,MATCH($C38,Campaigns!$A$6:$A$45,0)) -> 77 | I38: =INDEX(Campaigns!$P$6:$P$45,MATCH($C38,Campaigns!$A$6:$A$45,0)) -> 1 | J38: =INDEX(Campaigns!$O$6:$O$45,MATCH($C38,Campaigns!$A$6:$A$45,0)) -> 62.97 | K38: =INDEX(Campaigns!$U$6:$U$45,MATCH($C38,Campaigns!$A$6:$A$45,0)) -> 2.3330863 | L38: =INDEX(Campaigns!$T$6:$T$45,MATCH($C38,Campaigns!$A$6:$A$45,0)) -> 0.81779221 | M38: =INDEX(Campaigns!$AH$6:$AH$45,MATCH($C38,Campaigns!$A$6:$A$45,0))+INDEX(Campaigns!$AJ$6:$AJ$45,MATCH($C38,Campaigns!$A$6:$A$45,0))+INDEX(Campaigns!$AL$6:$AL$45,MATCH($C38,Campaigns!$A$6:$A$45,0)) -> 62 | N38: 1 | O38: =INDEX(Campaigns!$W$6:$W$45,MATCH($C38,Campaigns!$A$6:$A$45,0)) -> 0 | P38: =INDEX(Campaigns!$Y$6:$Y$45,MATCH($C38,Campaigns!$A$6:$A$45,0)) -> 0 | Q38: =INDEX(Campaigns!$X$6:$X$45,MATCH($C38,Campaigns!$A$6:$A$45,0)) -> 0 | R38: =IF(I38=0,J38,0) -> 0 | S38: =IF(INDEX(Campaigns!$J$6:$J$45,MATCH($C38,Campaigns!$A$6:$A$45,0))="","",INDEX(Campaigns!$J$6:$J$45,MATCH($C38,Campaigns!$A$6:$A$45,0))) | T38: =IFERROR(INDEX('Search Terms'!$C$5:$C$137,MATCH($E38,'Search Terms'!$A$5:$A$137,0)),"") -> 122 | U38: =IFERROR(INDEX('Search Terms'!$B$5:$B$137,MATCH($E38,'Search Terms'!$A$5:$A$137,0)),"") -> Relevant | V38: =IFERROR(INDEX('Search Terms'!$D$5:$D$137,MATCH($E38,'Search Terms'!$A$5:$A$137,0)),"") -> 11 | W38: Keep paused; split in the rebuild | X38: 5 keywords in one campaign; 1 order on 62 on-Amazon clicks; TOS +450%. 'Scandinavian' does not describe this product. | Y38: 'boho cotton throw blanket' to the material lane; drop 'scandinavian' | Z38: Joseph approves; Shayan applies
... A66: 5 PAUSE (wasted spend) | B66: boho cotton throw blanket no fringe | C66: 194745831752971 | D66: =INDEX(Campaigns!$D$6:$D$45,MATCH($C66,Campaigns!$A$6:$A$45,0)) -> SP Exact keyword | E66: boho cotton throw blanket no fringe | F66: =INDEX(Campaigns!$H$6:$H$45,MATCH($C66,Campaigns!$A$6:$A$45,0)) -> ENABLED | G66: =INDEX(Campaigns!$AU$6:$AU$45,MATCH($C66,Campaigns!$A$6:$A$45,0)) -> PAUSED | H66: =INDEX(Campaigns!$N$6:$N$45,MATCH($C66,Campaigns!$A$6:$A$45,0)) -> 1 | I66: =INDEX(Campaigns!$P$6:$P$45,MATCH($C66,Campaigns!$A$6:$A$45,0)) -> 0 | J66: =INDEX(Campaigns!$O$6:$O$45,MATCH($C66,Campaigns!$A$6:$A$45,0)) -> 0.5 | K66: =INDEX(Campaigns!$U$6:$U$45,MATCH($C66,Campaigns!$A$6:$A$45,0)) | L66: =INDEX(Campaigns!$T$6:$T$45,MATCH($C66,Campaigns!$A$6:$A$45,0)) -> 0.5 | M66: =INDEX(Campaigns!$AH$6:$AH$45,MATCH($C66,Campaigns!$A$6:$A$45,0))+INDEX(Campaigns!$AJ$6:$AJ$45,MATCH($C66,Campaigns!$A$6:$A$45,0))+INDEX(Campaigns!$AL$6:$AL$45,MATCH($C66,Campaigns!$A$6:$A$45,0)) -> 1 | N66: 0 | O66: =INDEX(Campaigns!$W$6:$W$45,MATCH($C66,Campaigns!$A$6:$A$45,0)) -> 0 | P66: =INDEX(Campaigns!$Y$6:$Y$45,MATCH($C66,Campaigns!$A$6:$A$45,0)) -> 0 | Q66: =INDEX(Campaigns!$X$6:$X$45,MATCH($C66,Campaigns!$A$6:$A$45,0)) -> 0 | R66: =IF(I66=0,J66,0) -> 0.5 | S66: =IF(INDEX(Campaigns!$J$6:$J$45,MATCH($C66,Campaigns!$A$6:$A$45,0))="","",INDEX(Campaigns!$J$6:$J$45,MATCH($C66,Campaigns!$A$6:$A$45,0))) -> 3.8 | T66: =IFERROR(INDEX('Search Terms'!$C$5:$C$137,MATCH($E66,'Search Terms'!$A$5:$A$137,0)),"") -> 2 | U66: =IFERROR(INDEX('Search Terms'!$B$5:$B$137,MATCH($E66,'Search Terms'!$A$5:$A$137,0)),"") -> Relevant | V66: =IFERROR(INDEX('Search Terms'!$D$5:$D$137,MATCH($E66,'Search Terms'!$A$5:$A$137,0)),"") -> 58 | W66: Pause now | X66: 'No fringe' contradicts the product (it has tassels). 1 click. | Y66: Negative phrase 'no fringe' | Z66: Joseph approves; Shayan applies

Sheet Live Set
A1: What stays live: hold settings, budgets and the $25 a day ceiling
A2: Only the campaigns generating orders, plus brand defence. Bids are held (no tests). Top-of-search boosts are capped at the plan's +300%. Budgets are sized to cover several clicks a day at the real CPC, so a campaign does not run out after one click.
A4: Campaign | B4: Campaign ID | C4: State now | D4: New state | E4: Orders, last 30 days | F4: On-Amazon orders since launch | G4: Base bid (held) | H4: TOS boost now | I4: TOS boost new | J4: Max TOS bid now | K4: Max TOS bid new | L4: Real CPC, Top of Search | M4: Real CPC, product page | N4: Clicks per day (last 30 days) | O4: Spend per day (last 30 days) | P4: Daily budget now | Q4: Daily budget new | R4: TOS clicks the budget covers (real CPC) | S4: TOS clicks at the max bid | T4: Product-page clicks the budget covers | U4: Expected spend per day | V4: A click is worth (38% target ACoS)
A5: bohemian throw blanket | B5: 271118311398471 | C5: =INDEX(Campaigns!$H$6:$H$45,MATCH($B5,Campaigns!$A$6:$A$45,0)) -> ENABLED | D5: =INDEX(Campaigns!$AU$6:$AU$45,MATCH($B5,Campaigns!$A$6:$A$45,0)) -> ENABLED | E5: =INDEX(Campaigns!$Y$6:$Y$45,MATCH($B5,Campaigns!$A$6:$A$45,0)) -> 1 | F5: 4 | G5: 0.52 | H5: 2.8 | I5: 2.8 | J5: =G5*(1+H5) -> 1.976 | K5: =G5*(1+I5) -> 1.976 | L5: =IF(INDEX(Campaigns!$AH$6:$AH$45,MATCH($B5,Campaigns!$A$6:$A$45,0))=0,0,INDEX(Campaigns!$AI$6:$AI$45,MATCH($B5,Campaigns!$A$6:$A$45,0))/INDEX(Campaigns!$AH$6:$AH$45,MATCH($B5,Campaigns!$A$6:$A$45,0))) -> 1.58 | M5: =IF(INDEX(Campaigns!$AJ$6:$AJ$45,MATCH($B5,Campaigns!$A$6:$A$45,0))=0,0,INDEX(Campaigns!$AK$6:$AK$45,MATCH($B5,Campaigns!$A$6:$A$45,0))/INDEX(Campaigns!$AJ$6:$AJ$45,MATCH($B5,Campaigns!$A$6:$A$45,0))) -> 0.53283871 | N5: =INDEX(Campaigns!$W$6:$W$45,MATCH($B5,Campaigns!$A$6:$A$45,0))/30 -> 3.0666667 | O5: =INDEX(Campaigns!$X$6:$X$45,MATCH($B5,Campaigns!$A$6:$A$45,0))/30 -> 2.3056667 | P5: 9.41 | Q5: 10 | R5: =IF(L5=0,"",Q5/L5) -> 6.3291139 | S5: =IF(K5=0,"",Q5/K5) -> 5.0607287 | T5: =IF(M5=0,"",Q5/M5) -> 18.767405 | U5: =MIN(Q5,MAX(O5,INDEX(Campaigns!$O$6:$O$45,MATCH($B5,Campaigns!$A$6:$A$45,0))/Rules!$B$25)) -> 2.3056667 | V5: =Rules!$B$19*IF(INDEX(Campaigns!$P$6:$P$45,MATCH($B5,Campaigns!$A$6:$A$45,0))=0,Rules!$B$35,INDEX(Campaigns!$Q$6:$Q$45,MATCH($B5,Campaigns!$A$6:$A$45,0))/INDEX(Campaigns!$P$6:$P$45,MATCH($B5,Campaigns!$A$6:$A$45,0)))*(F5+Rules!$B$36*Rules!$B$20)/(INDEX(Campaigns!$AH$6:$AH$45,MATCH($B5,Campaigns!$A$6:$A$45,0))+INDEX(Campaigns!$AJ$6:$AJ$45,MATCH($B5,Campaigns!$A$6:$A$45,0))+INDEX(Campaigns!$AL$6:$AL$45,MATCH($B5,Campaigns!$A$6:$A$45,0))+Rules!$B$20) -> 0.28441653
A6: bohemian blanket | B6: 274384612784893 | C6: =INDEX(Campaigns!$H$6:$H$45,MATCH($B6,Campaigns!$A$6:$A$45,0)) -> PAUSED | D6: =INDEX(Campaigns!$AU$6:$AU$45,MATCH($B6,Campaigns!$A$6:$A$45,0)) -> ENABLED | E6: =INDEX(Campaigns!$Y$6:$Y$45,MATCH($B6,Campaigns!$A$6:$A$45,0)) -> 2 | F6: 2 | G6: 0.69 | H6: 4.5 | I6: 3 | J6: =G6*(1+H6) -> 3.795 | K6: =G6*(1+I6) -> 2.76 | L6: =IF(INDEX(Campaigns!$AH$6:$AH$45,MATCH($B6,Campaigns!$A$6:$A$45,0))=0,0,INDEX(Campaigns!$AI$6:$AI$45,MATCH($B6,Campaigns!$A$6:$A$45,0))/INDEX(Campaigns!$AH$6:$AH$45,MATCH($B6,Campaigns!$A$6:$A$45,0))) -> 1.2410526 | M6: =IF(INDEX(Campaigns!$AJ$6:$AJ$45,MATCH($B6,Campaigns!$A$6:$A$45,0))=0,0,INDEX(Campaigns!$AK$6:$AK$45,MATCH($B6,Campaigns!$A$6:$A$45,0))/INDEX(Campaigns!$AJ$6:$AJ$45,MATCH($B6,Campaigns!$A$6:$A$45,0))) -> 0.69 | N6: =INDEX(Campaigns!$W$6:$W$45,MATCH($B6,Campaigns!$A$6:$A$45,0))/30 -> 0.93333333 | O6: =INDEX(Campaigns!$X$6:$X$45,MATCH($B6,Campaigns!$A$6:$A$45,0))/30 -> 0.92366667 | P6: 6.38 | Q6: 10 | R6: =IF(L6=0,"",Q6/L6) -> 8.057676 | S6: =IF(K6=0,"",Q6/K6) -> 3.6231884 | T6: =IF(M6=0,"",Q6/M6) -> 14.492754 | U6: =MIN(Q6,MAX(O6,INDEX(Campaigns!$O$6:$O$45,MATCH($B6,Campaigns!$A$6:$A$45,0))/Rules!$B$25)) -> 0.92366667 | V6: =Rules!$B$19*IF(INDEX(Campaigns!$P$6:$P$45,MATCH($B6,Campaigns!$A$6:$A$45,0))=0,Rules!$B$35,INDEX(Campaigns!$Q$6:$Q$45,MATCH($B6,Campaigns!$A$6:$A$45,0))/INDEX(Campaigns!$P$6:$P$45,MATCH($B6,Campaigns!$A$6:$A$45,0)))*(F6+Rules!$B$36*Rules!$B$20)/(INDEX(Campaigns!$AH$6:$AH$45,MATCH($B6,Campaigns!$A$6:$A$45,0))+INDEX(Campaigns!$AJ$6:$AJ$45,MATCH($B6,Campaigns!$A$6:$A$45,0))+INDEX(Campaigns!$AL$6:$AL$45,MATCH($B6,Campaigns!$A$6:$A$45,0))+Rules!$B$20) -> 0.31101246
A7: sleephoria boho throw blanket | B7: 94080520861158 | C7: =INDEX(Campaigns!$H$6:$H$45,MATCH($B7,Campaigns!$A$6:$A$45,0)) -> ENABLED | D7: =INDEX(Campaigns!$AU$6:$AU$45,MATCH($B7,Campaigns!$A$6:$A$45,0)) -> ENABLED | E7: =INDEX(Campaigns!$Y$6:$Y$45,MATCH($B7,Campaigns!$A$6:$A$45,0)) -> 0 | F7: 0 | G7: 0.68 | H7: 3.8 | I7: 3 | J7: =G7*(1+H7) -> 3.264 | K7: =G7*(1+I7) -> 2.72 | L7: =IF(INDEX(Campaigns!$AH$6:$AH$45,MATCH($B7,Campaigns!$A$6:$A$45,0))=0,0,INDEX(Campaigns!$AI$6:$AI$45,MATCH($B7,Campaigns!$A$6:$A$45,0))/INDEX(Campaigns!$AH$6:$AH$45,MATCH($B7,Campaigns!$A$6:$A$45,0))) -> 0.345 | M7: =IF(INDEX(Campaigns!$AJ$6:$AJ$45,MATCH($B7,Campaigns!$A$6:$A$45,0))=0,0,INDEX(Campaigns!$AK$6:$AK$45,MATCH($B7,Campaigns!$A$6:$A$45,0))/INDEX(Campaigns!$AJ$6:$AJ$45,MATCH($B7,Campaigns!$A$6:$A$45,0))) -> 0 | N7: =INDEX(Campaigns!$W$6:$W$45,MATCH($B7,Campaigns!$A$6:$A$45,0))/30 -> 0 | O7: =INDEX(Campaigns!$X$6:$X$45,MATCH($B7,Campaigns!$A$6:$A$45,0))/30 -> 0 | P7: 11.32 | Q7: 5 | R7: =IF(L7=0,"",Q7/L7) -> 14.492754 | S7: =IF(K7=0,"",Q7/K7) -> 1.8382353 | T7: =IF(M7=0,"",Q7/M7) | U7: =MIN(Q7,MAX(O7,INDEX(Campaigns!$O$6:$O$45,MATCH($B7,Campaigns!$A$6:$A$45,0))/Rules!$B$25)) -> 0.023793103 | V7: =Rules!$B$19*IF(INDEX(Campaigns!$P$6:$P$45,MATCH($B7,Campaigns!$A$6:$A$45,0))=0,Rules!$B$35,INDEX(Campaigns!$Q$6:$Q$45,MATCH($B7,Campaigns!$A$6:$A$45,0))/INDEX(Campaigns!$P$6:$P$45,MATCH($B7,Campaigns!$A$6:$A$45,0)))*(F7+Rules!$B$36*Rules!$B$20)/(INDEX(Campaigns!$AH$6:$AH$45,MATCH($B7,Campaigns!$A$6:$A$45,0))+INDEX(Campaigns!$AJ$6:$AJ$45,MATCH($B7,Campaigns!$A$6:$A$45,0))+INDEX(Campaigns!$AL$6:$AL$45,MATCH($B7,Campaigns!$A$6:$A$45,0))+Rules!$B$20) -> 0.13979345
A8: TOTAL live set | E8: =SUM(E5:E7) -> 3 | F8: =SUM(F5:F7) -> 6 | N8: =SUM(N5:N7) -> 4 | O8: =SUM(O5:O7) -> 3.2293333 | P8: =SUM(P5:P7) -> 27.11 | Q8: =SUM(Q5:Q7) -> 25 | U8: =SUM(U5:U7) -> 3.2531264
A10: Ceiling, expected spend and savings
A11: Hard portfolio ceiling per day (Phase 0 / D4, Rules tab) | B11: =Rules!$B$5 -> 25
A12: Ceiling per week | B12: =B11*7 -> 175
A13: Sum of live campaign budgets per day | B13: =Q8 -> 25
A14: Status | B14: =IF(B13<=B11,"Budgets fit inside the ceiling","Budgets exceed the ceiling: the portfolio cap stops spend at "&TEXT(B11,"$0")&" a day") -> Budgets fit inside the ceiling
A15: Expected spend per day (limited by search volume) | B15: =U8 -> 3.2531264
A16: Expected spend per week | B16: =B15*7 -> 22.771885
A17: Expected spend per month | B17: =B15*30 -> 97.593793
A18: Maximum possible spend per month (budgets fully used) | B18: =MIN(B13,B11)*30 -> 750
A19: Last 30 days: total spend | B19: =Campaigns!X46 -> 487.49
A20: Last 30 days: spend on campaigns now paused or kept paused | B20: =SUMIFS(Campaigns!$X$6:$X$45,Campaigns!$AU$6:$AU$45,"PAUSED") -> 390.61
A21: Expected cut vs the last 30 days | B21: =IF(B19=0,0,1-B17/B19) -> 0.7998035
A22: D4 weekly ceiling | B22: =Rules!$B$7 -> 175
A23: Weekly headroom at full budgets | B23: =B22-MIN(B13,B11)*7 -> 0
A25: Notes
A26: Budgets are ceilings, not spend targets. These are exact-match terms with about 20 to 25 searches a day each, so actual spend should stay near the last 30 days' rate; the budgets only stop a campaign going out of budget after one or two top-of-search clicks.
A27: Bids are held as they are (no bid tests). Only the two top-of-search boosts above the plan's +300% are brought down, so a single click can cost at most about $2.76.
A28: The +450% to +300% and +380% to +300% steps are larger than the 20-point rule in config/thresholds.yml, so they need Joseph's sign-off (in the bulk file as two 'Bidding Adjustment' rows).
A29: 'A click is worth' is for reference only: on the current listing no live campaign earns its clicks back. That is accepted while the account holds until the rebuild.
A30: Set the $25 ceiling as the 'SLEEPHORIA - Boho Blanket' portfolio budget in the console (the bulk file cannot set it). Then leave everything for 14 days.

Sheet Core Term Test
A1: Core terms: is it the bid, the placement, or the listing? (evidence before any pause or bid cut)
A2: Market columns: Amazon Search Query Performance (Brand Analytics) for the whole search, 23 Aug to 17 Oct (weekly). Ours: our 6 live ASINs. PPC columns: our search-term report since launch. SQP is a sample; read it as rates.
A4: Search query | B4: Weeks | C4: Market searches | D4: Market impressions | E4: Market clicks | F4: Market cart adds | G4: Market purchases | H4: Market cart-add rate | I4: Market CVR | J4: Our impressions | K4: Our impression share | L4: Our clicks | M4: Our click share | N4: Our cart adds | O4: Cart adds expected at market rate | P4: Chance of this few cart adds | Q4: Our purchases (SQP) | R4: PPC clicks since launch | S4: PPC orders | T4: PPC spend | U4: CPC paid | V4: Organic rank | W4: A click is worth (target ACoS, market CVR) | X4: Break-even CPC (market CVR) | Y4: Paid vs worth | Z4: Read
A5: boho throw blanket | B5: 8 | C5: 53763 | D5: 1764878 | E5: 21938 | F5: 2842 | G5: 360 | H5: =IF(E5=0,0,F5/E5) -> 0.1295469 | I5: =IF(E5=0,0,G5/E5) -> 0.016409882 | J5: 6756 | K5: =IF(D5=0,0,J5/D5) -> 0.0038280266 | L5: 38 | M5: =IF(E5=0,0,L5/E5) -> 0.0017321543 | N5: 0 | O5: =L5*H5 -> 4.9227824 | P5: =BINOMDIST(N5,L5,H5,TRUE()) -> 0.0051324438 | Q5: 0 | R5: =IFERROR(INDEX('Search Terms'!$F$5:$F$137,MATCH($A5,'Search Terms'!$A$5:$A$137,0)),0) -> 42 | S5: =IFERROR(INDEX('Search Terms'!$G$5:$G$137,MATCH($A5,'Search Terms'!$A$5:$A$137,0)),0) -> 0 | T5: =IFERROR(INDEX('Search Terms'!$H$5:$H$137,MATCH($A5,'Search Terms'!$A$5:$A$137,0)),0) -> 39.35 | U5: =IF(R5=0,0,T5/R5) -> 0.93690476 | V5: =IFERROR(INDEX('Search Terms'!$D$5:$D$137,MATCH($A5,'Search Terms'!$A$5:$A$137,0)),"") -> 99 | W5: =Rules!$B$19*Rules!$B$35*I5 -> 0.19324606 | X5: =Rules!$B$34*I5 -> 0.064080591 | Y5: =IF(W5=0,"",U5/W5) -> 4.8482478 | Z5: Listing problem on this search: 0 cart adds where about 5 were expected. Bid cuts cannot fix it. Keep paused; first retest after the rebuild.
A6: boho blanket | B6: 8 | C6: 31570 | D6: 1162248 | E6: 10184 | F6: 1193 | G6: 171 | H6: =IF(E6=0,0,F6/E6) -> 0.11714454 | I6: =IF(E6=0,0,G6/E6) -> 0.016791045 | J6: 3089 | K6: =IF(D6=0,0,J6/D6) -> 0.0026577804 | L6: 29 | M6: =IF(E6=0,0,L6/E6) -> 0.0028476041 | N6: 3 | O6: =L6*H6 -> 3.3971917 | P6: =BINOMDIST(N6,L6,H6,TRUE()) -> 0.55365087 | Q6: 0 | R6: =IFERROR(INDEX('Search Terms'!$F$5:$F$137,MATCH($A6,'Search Terms'!$A$5:$A$137,0)),0) -> 179 | S6: =IFERROR(INDEX('Search Terms'!$G$5:$G$137,MATCH($A6,'Search Terms'!$A$5:$A$137,0)),0) -> 2 | T6: =IFERROR(INDEX('Search Terms'!$H$5:$H$137,MATCH($A6,'Search Terms'!$A$5:$A$137,0)),0) -> 132.1 | U6: =IF(R6=0,0,T6/R6) -> 0.73798883 | V6: =IFERROR(INDEX('Search Terms'!$D$5:$D$137,MATCH($A6,'Search Terms'!$A$5:$A$137,0)),"") -> 133 | W6: =Rules!$B$19*Rules!$B$35*I6 -> 0.1977347 | X6: =Rules!$B$34*I6 -> 0.06556903 | Y6: =IF(W6=0,"",U6/W6) -> 3.7322171 | Z6: Cart adds normal for the market; orders came only from product pages. Retest after the rebuild.
A7: boho throw | B7: 7 | C7: 5417 | D7: 154631 | E7: 2731 | F7: 311 | G7: 58 | H7: =IF(E7=0,0,F7/E7) -> 0.1138777 | I7: =IF(E7=0,0,G7/E7) -> 0.021237642 | J7: 1542 | K7: =IF(D7=0,0,J7/D7) -> 0.0099721272 | L7: 34 | M7: =IF(E7=0,0,L7/E7) -> 0.012449652 | N7: 1 | O7: =L7*H7 -> 3.8718418 | P7: =BINOMDIST(N7,L7,H7,TRUE()) -> 0.088046508 | Q7: 1 | R7: =IFERROR(INDEX('Search Terms'!$F$5:$F$137,MATCH($A7,'Search Terms'!$A$5:$A$137,0)),0) -> 113 | S7: =IFERROR(INDEX('Search Terms'!$G$5:$G$137,MATCH($A7,'Search Terms'!$A$5:$A$137,0)),0) -> 1 | T7: =IFERROR(INDEX('Search Terms'!$H$5:$H$137,MATCH($A7,'Search Terms'!$A$5:$A$137,0)),0) -> 81.58 | U7: =IF(R7=0,0,T7/R7) -> 0.7219469 | V7: =IFERROR(INDEX('Search Terms'!$D$5:$D$137,MATCH($A7,'Search Terms'!$A$5:$A$137,0)),"") -> 94 | W7: =Rules!$B$19*Rules!$B$35*I7 -> 0.25009872 | X7: =Rules!$B$34*I7 -> 0.082932992 | Y7: =IF(W7=0,"",U7/W7) -> 2.8866477 | Z7: Fewer cart adds than the market (1 vs about 4). Retest first after the rebuild: best PPC CVR of the core terms.
A8: throw blanket boho | B8: 7 | C8: 4113 | D8: 125312 | E8: 1921 | F8: 242 | G8: 29 | H8: =IF(E8=0,0,F8/E8) -> 0.12597605 | I8: =IF(E8=0,0,G8/E8) -> 0.015096304 | J8: 893 | K8: =IF(D8=0,0,J8/D8) -> 0.007126213 | L8: 14 | M8: =IF(E8=0,0,L8/E8) -> 0.0072878709 | N8: 1 | O8: =L8*H8 -> 1.7636648 | P8: =BINOMDIST(N8,L8,H8,TRUE()) -> 0.45817021 | Q8: 0 | R8: =IFERROR(INDEX('Search Terms'!$F$5:$F$137,MATCH($A8,'Search Terms'!$A$5:$A$137,0)),0) -> 69 | S8: =IFERROR(INDEX('Search Terms'!$G$5:$G$137,MATCH($A8,'Search Terms'!$A$5:$A$137,0)),0) -> 0 | T8: =IFERROR(INDEX('Search Terms'!$H$5:$H$137,MATCH($A8,'Search Terms'!$A$5:$A$137,0)),0) -> 59.04 | U8: =IF(R8=0,0,T8/R8) -> 0.85565217 | V8: =IFERROR(INDEX('Search Terms'!$D$5:$D$137,MATCH($A8,'Search Terms'!$A$5:$A$137,0)),"") -> 125 | W8: =Rules!$B$19*Rules!$B$35*I8 -> 0.1777771 | X8: =Rules!$B$34*I8 -> 0.058951067 | Y8: =IF(W8=0,"",U8/W8) -> 4.813062 | Z8: Few clicks, 1 cart add. Covered by the 'boho throw blanket' retest.
A9: boho blanket throw | B9: 6 | C9: 2927 | D9: 79741 | E9: 1468 | F9: 199 | G9: 35 | H9: =IF(E9=0,0,F9/E9) -> 0.13555858 | I9: =IF(E9=0,0,G9/E9) -> 0.023841962 | J9: 852 | K9: =IF(D9=0,0,J9/D9) -> 0.010684591 | L9: 22 | M9: =IF(E9=0,0,L9/E9) -> 0.014986376 | N9: 1 | O9: =L9*H9 -> 2.9822888 | P9: =BINOMDIST(N9,L9,H9,TRUE()) -> 0.18052553 | Q9: 0 | R9: =IFERROR(INDEX('Search Terms'!$F$5:$F$137,MATCH($A9,'Search Terms'!$A$5:$A$137,0)),0) -> 98 | S9: =IFERROR(INDEX('Search Terms'!$G$5:$G$137,MATCH($A9,'Search Terms'!$A$5:$A$137,0)),0) -> 0 | T9: =IFERROR(INDEX('Search Terms'!$H$5:$H$137,MATCH($A9,'Search Terms'!$A$5:$A$137,0)),0) -> 81.77 | U9: =IF(R9=0,0,T9/R9) -> 0.83438776 | V9: =IFERROR(INDEX('Search Terms'!$D$5:$D$137,MATCH($A9,'Search Terms'!$A$5:$A$137,0)),"") -> 120 | W9: =Rules!$B$19*Rules!$B$35*I9 -> 0.28076771 | X9: =Rules!$B$34*I9 -> 0.093102861 | Y9: =IF(W9=0,"",U9/W9) -> 2.9718081 | Z9: 1 cart add on 22 clicks; 0 PPC orders on 98 clicks. No separate campaign in the rebuild.
A10: bohemian throw blanket | B10: 8 | C10: 2828 | D10: 83010 | E10: 1390 | F10: 184 | G10: 18 | H10: =IF(E10=0,0,F10/E10) -> 0.1323741 | I10: =IF(E10=0,0,G10/E10) -> 0.01294964 | J10: 1427 | K10: =IF(D10=0,0,J10/D10) -> 0.0171907 | L10: 24 | M10: =IF(E10=0,0,L10/E10) -> 0.017266187 | N10: 3 | O10: =L10*H10 -> 3.1769784 | P10: =BINOMDIST(N10,L10,H10,TRUE()) -> 0.60510068 | Q10: 0 | R10: =IFERROR(INDEX('Search Terms'!$F$5:$F$137,MATCH($A10,'Search Terms'!$A$5:$A$137,0)),0) -> 182 | S10: =IFERROR(INDEX('Search Terms'!$G$5:$G$137,MATCH($A10,'Search Terms'!$A$5:$A$137,0)),0) -> 4 | T10: =IFERROR(INDEX('Search Terms'!$H$5:$H$137,MATCH($A10,'Search Terms'!$A$5:$A$137,0)),0) -> 124.87 | U10: =IF(R10=0,0,T10/R10) -> 0.6860989 | V10: =IFERROR(INDEX('Search Terms'!$D$5:$D$137,MATCH($A10,'Search Terms'!$A$5:$A$137,0)),"") -> 79 | W10: =Rules!$B$19*Rules!$B$35*I10 -> 0.15249755 | X10: =Rules!$B$34*I10 -> 0.050568345 | Y10: =IF(W10=0,"",U10/W10) -> 4.4990814 | Z10: Cart adds in line with the market. Converting in PPC: keep live at a lower bid.
A11: bohemian blanket | B11: 7 | C11: 1719 | D11: 51710 | E11: 671 | F11: 75 | G11: 10 | H11: =IF(E11=0,0,F11/E11) -> 0.11177347 | I11: =IF(E11=0,0,G11/E11) -> 0.01490313 | J11: 690 | K11: =IF(D11=0,0,J11/D11) -> 0.013343647 | L11: 14 | M11: =IF(E11=0,0,L11/E11) -> 0.020864382 | N11: 1 | O11: =L11*H11 -> 1.5648286 | P11: =BINOMDIST(N11,L11,H11,TRUE()) -> 0.52543128 | Q11: 0 | R11: =IFERROR(INDEX('Search Terms'!$F$5:$F$137,MATCH($A11,'Search Terms'!$A$5:$A$137,0)),0) -> 41 | S11: =IFERROR(INDEX('Search Terms'!$G$5:$G$137,MATCH($A11,'Search Terms'!$A$5:$A$137,0)),0) -> 1 | T11: =IFERROR(INDEX('Search Terms'!$H$5:$H$137,MATCH($A11,'Search Terms'!$A$5:$A$137,0)),0) -> 35.93 | U11: =IF(R11=0,0,T11/R11) -> 0.87634146 | V11: =IFERROR(INDEX('Search Terms'!$D$5:$D$137,MATCH($A11,'Search Terms'!$A$5:$A$137,0)),"") -> 85 | W11: =Rules!$B$19*Rules!$B$35*I11 -> 0.17550224 | X11: =Rules!$B$34*I11 -> 0.058196721 | Y11: =IF(W11=0,"",U11/W11) -> 4.993335 | Z11: Small sample; best PPC CVR (4%). Keep live at the worth-based bid.
A12: boho throws | B12: 7 | C12: 1768 | D12: 53387 | E12: 985 | F12: 73 | G12: 13 | H12: =IF(E12=0,0,F12/E12) -> 0.074111675 | I12: =IF(E12=0,0,G12/E12) -> 0.01319797 | J12: 540 | K12: =IF(D12=0,0,J12/D12) -> 0.010114822 | L12: 12 | M12: =IF(E12=0,0,L12/E12) -> 0.012182741 | N12: 1 | O12: =L12*H12 -> 0.8893401 | P12: =BINOMDIST(N12,L12,H12,TRUE()) -> 0.77817266 | Q12: 1 | R12: =IFERROR(INDEX('Search Terms'!$F$5:$F$137,MATCH($A12,'Search Terms'!$A$5:$A$137,0)),0) -> 11 | S12: =IFERROR(INDEX('Search Terms'!$G$5:$G$137,MATCH($A12,'Search Terms'!$A$5:$A$137,0)),0) -> 2 | T12: =IFERROR(INDEX('Search Terms'!$H$5:$H$137,MATCH($A12,'Search Terms'!$A$5:$A$137,0)),0) -> 10.44 | U12: =IF(R12=0,0,T12/R12) -> 0.94909091 | V12: =IFERROR(INDEX('Search Terms'!$D$5:$D$137,MATCH($A12,'Search Terms'!$A$5:$A$137,0)),"") -> 80 | W12: =Rules!$B$19*Rules!$B$35*I12 -> 0.15542193 | X12: =Rules!$B$34*I12 -> 0.051538071 | Y12: =IF(W12=0,"",U12/W12) -> 6.1065444 | Z12: 1 SQP purchase; 2 PPC orders on 11 clicks. Include in the rebuild's core exact set.
A13: boho cotton blanket | B13: 7 | C13: 1365 | D13: 38806 | E13: 878 | F13: 45 | G13: 8 | H13: =IF(E13=0,0,F13/E13) -> 0.051252847 | I13: =IF(E13=0,0,G13/E13) -> 0.0091116173 | J13: 640 | K13: =IF(D13=0,0,J13/D13) -> 0.016492295 | L13: 29 | M13: =IF(E13=0,0,L13/E13) -> 0.033029613 | N13: 1 | O13: =L13*H13 -> 1.4863326 | P13: =BINOMDIST(N13,L13,H13,TRUE()) -> 0.55811896 | Q13: 0 | R13: =IFERROR(INDEX('Search Terms'!$F$5:$F$137,MATCH($A13,'Search Terms'!$A$5:$A$137,0)),0) -> 35 | S13: =IFERROR(INDEX('Search Terms'!$G$5:$G$137,MATCH($A13,'Search Terms'!$A$5:$A$137,0)),0) -> 1 | T13: =IFERROR(INDEX('Search Terms'!$H$5:$H$137,MATCH($A13,'Search Terms'!$A$5:$A$137,0)),0) -> 37.34 | U13: =IF(R13=0,0,T13/R13) -> 1.0668571 | V13: =IFERROR(INDEX('Search Terms'!$D$5:$D$137,MATCH($A13,'Search Terms'!$A$5:$A$137,0)),"") -> 55 | W13: =Rules!$B$19*Rules!$B$35*I13 -> 0.10730023 | X13: =Rules!$B$34*I13 -> 0.035580866 | Y13: =IF(W13=0,"",U13/W13) -> 9.9427295 | Z13: Cart-add rate is low for the whole market (5%). Material lane, low priority.
A14: boho throw blankets for couch | B14: 7 | C14: 1537 | D14: 41780 | E14: 879 | F14: 83 | G14: 15 | H14: =IF(E14=0,0,F14/E14) -> 0.094425484 | I14: =IF(E14=0,0,G14/E14) -> 0.017064846 | J14: 940 | K14: =IF(D14=0,0,J14/D14) -> 0.022498803 | L14: 23 | M14: =IF(E14=0,0,L14/E14) -> 0.026166098 | N14: 3 | O14: =L14*H14 -> 2.1717861 | P14: =BINOMDIST(N14,L14,H14,TRUE()) -> 0.8332473 | Q14: 1 | R14: =IFERROR(INDEX('Search Terms'!$F$5:$F$137,MATCH($A14,'Search Terms'!$A$5:$A$137,0)),0) -> 108 | S14: =IFERROR(INDEX('Search Terms'!$G$5:$G$137,MATCH($A14,'Search Terms'!$A$5:$A$137,0)),0) -> 1 | T14: =IFERROR(INDEX('Search Terms'!$H$5:$H$137,MATCH($A14,'Search Terms'!$A$5:$A$137,0)),0) -> 85.08 | U14: =IF(R14=0,0,T14/R14) -> 0.78777778 | V14: =IFERROR(INDEX('Search Terms'!$D$5:$D$137,MATCH($A14,'Search Terms'!$A$5:$A$137,0)),"") -> 85 | W14: =Rules!$B$19*Rules!$B$35*I14 -> 0.20095904 | X14: =Rules!$B$34*I14 -> 0.066638225 | Y14: =IF(W14=0,"",U14/W14) -> 3.9200912 | Z14: Cart adds normal (3 on 23). Couch lane in the rebuild.
A16: Deep dive: 'boho throw blanket' (core term, 42 clicks, 0 orders)
A17: Check | B17: What the data says | G17: Conclusion
A18: Portable CPC (what a click is worth) | B18: Market CVR 1.64% x average price $30.99 x 38% target ACoS = about $0.19 a click (cell W5). At break-even it is about $0.06. We paid $0.94 on average. | G18: No bid level makes this term pay on the current page.
A19: Bid and bid adjustments | B19: Campaign paused; Fixed bids; TOS modifier +300%; budget $30 a day. Top of Search clicks cost about $1.33, product-page clicks about $0.61 (Command Center, campaign-level split). | G19: The +300% modifier bought expensive TOS clicks that did not convert.
A20: Placement performance | B20: About 18 TOS clicks and 18 product-page clicks, 5 rest-of-search, 0 Off-Amazon; 0 orders in every placement. | G20: Not a placement mix problem: nothing converted anywhere.
A21: Search-term relevance | B21: Rated Relevant; 9,420 searches a month (H10), about 6,000 to 7,000 a week in SQP; 25 of 35 page-one results are natural or woven throws, median $29.69 (pack file 06). | G21: The term fits the product. Do not negate it.
A22: Conversion potential | B22: Market: 13% of clicks add to cart, 1.64% buy. Ours: 0 cart adds on 38 clicks; about 5 expected; chance of 0 by luck about 0.5% (cell P5). Organic rank about 99. | G22: Shoppers on this search reject our listing before the cart. Fix the page (main image, title, price-to-value, A+), then retest.
A23: Decision | B23: Keep paused (already paused). No negative, no archive. First exact campaign in the rebuild at the worth-based bid, Butterfly 50x60. | G23: Pass mark after the rebuild: 2+ cart adds per 20 clicks and 1+ order per 50 clicks; otherwise stop.

Sheet Search Terms
A1: Every search term since launch: what it cost, what it returned, and what happens to it in the rebuild
