Workbook

Sheet START HERE
A1: Topic | B1: Read me
A2: Status | B2: Evidence-limited research package. Public evidence collected; domestic rank panels, measured keyword demand/CPC/CVR, competitor sales, quotes and review histories are NOT verified.
A3: Date | B3: 26 October 2026; geography split US/CA/UK. Monetary currency explicit in every financial table.
A4: Legend | B4: FACT=observed official/page evidence; CLAIM=seller assertion; ESTIMATE=publisher model; CALC=derived; ASSUMPTION=analyst scenario; GAP=unavailable.
A5: Edit | B5: Economics numeric inputs F:AG and BH (runway months) are blue. Derived formulas black. All commercial scenario inputs require replacement with approved quotes/pilot results.
A6: Samples | B6: 1627 query-ASIN observations, 1568 distinct marketplace-ASIN pairs, 33 query pages. Not a probability sample.
A7: Prices | B7: Title-screened but mixed sizes/sets; US/UK retained Colombia delivery destination. Currency corrected through UI. No normalized domestic price distribution claimed.
A8: Ratings | B8: Displayed total ratings, not written review count; K/M rounded; pooled variants/countries possible. No review-growth trend from one snapshot.
A9: Review corpus | B9: 122 visible review cards: 40 Canadian, 33 UK, 25 US, 24 other by reviewer location. US reviews obtained from imported reviews on CA/UK pages. Top/helpful sample, not complaint prevalence.
A10: Formula basis | B10: Per shipped order; discounts and refunds reduce revenue; landed cost charged once with zero returned-inventory recovery; referral refund and admin approximated. FBA charged on every shipment.
A11: UK accounting | B11: Retail price assumed VAT-inclusive at20%; referral charged on VAT-inclusive order amount. Fee VAT assumed recoverable. Customs base is factory+packaging proxy, NOT a legal valuation.
A12: Break-even | B12: BE ACoS=pre-ad contribution / initial gross discounted order revenue. BE CPC=pre-ad contribution*CVR. Blended CM assumes stated paid-order share; attribution halo ignored.
... A15: Use | B15: Choose feasibility work, not production purchase orders. No outreach, ads, purchases or launch commitments made.

Sheet Market
A1: Country | B1: Broad bedding2024 USDm | C1: GVR CAGR2025-33 % | D1: Offline2024 % | E1: Home textiles2025 USDm | F1: Bed linen share2025 % | G1: Home textiles2026 USDm | H1: Mordor CAGR2026-31 % | I1: Sources | J1: Derived bed linen2025 USDm | K1: Derived broad online2024 USDm
A2: US | B2: 32748.9 | C2: 8.8 | D2: 75.19 | E2: 26480 | F2: 42.15 | G2: 27500 | H2: 3.86 | I2: M01; M07 | J2: =E2*F2/100 -> 11161.32 | K2: =B2*(1-D2/100) -> 8125.0021
A3: CA | B3: 6061.7 | C3: 10.9 | D3: 78.07 | E3: 3120 | F3: 43.77 | G3: 3290 | H3: 4.58 | I3: M02; M09 | J3: =E3*F3/100 -> 1365.624 | K3: =B3*(1-D3/100) -> 1329.3308
A4: UK | B4: 8016.7 | C4: 7.2 | D4: 67.46 | E4: 7620 | F4: 45.92 | G4: 7750 | H4: 1.76 | I4: M03; M08 | J4: =E4*F4/100 -> 3499.104 | K4: =B4*(1-D4/100) -> 2608.6342

Sheet Product segments
A1: Segment | B1: Query bucket | C1: Demand/use cases (judgement) | D1: Materials | E1: Proposed specs to test | F1: Competition | G1: Differentiation hypothesis | H1: Manufacturing | I1: Recommendation
A2: Sheets / sheet sets | B2: sheets | C2: Replacement, first-home, guest-room and gifting use cases; exact demand unmeasured | D2: Cotton percale/sateen; microfiber; regenerated cellulose | E2: Proposed: 200-300 single-ply percale or 300-500 sateen; declare fibre percentages; fit after washing, not just cut dimensions | F2: High price transparency, entrenched ratings; generic cooling/organic is already common | G2: Differentiated cotton with measured fit and wash durability; narrow colours/sizes | H2: Medium: weaving/finishing, shrink allowance, consistent dye lots | I2: Investigate differentiated; avoid undifferentiated head-term launch
A3: Fitted sheets | B3: fitted | C3: Replacement-only purchases and difficult mattress depths; niche size volumes unmeasured | D3: Cotton, cotton/polyester, microfiber, jersey | E3: Proposed: explicit mattress-depth range, elastic recovery, orientation label; separate shallow/deep patterns | F3: Deep-pocket and orientation features already offered; feature presence alone is not a moat | G3: Verified post-wash fit for specific depth/size; replacement availability | H3: Medium: corner seam, elastic tension and shrink fit | I3: Investigate; willingness-to-pay unvalidated
A4: Pillowcases | B4: pillowcase | C4: Replacement, extra pillows, hair/skin-positioning and gifts | D4: Cotton, polyester satin, silk, lyocell | E4: State pair vs single; internal usable length; envelope/zip closure; silk momme only for actual silk | F4: Low AOV makes shipping and acquisition disproportionately expensive | G4: Add-on, replacement pair, coordinated colours; bundle to improve basket economics | H4: Low-medium: seam/closure finish and sizing | I4: Investigate as niche/bundle; weak standalone broad-PPC economics
A5: Duvet covers | B5: duvet | C5: Decor refresh and washable protection; country-specific naming and size | D5: Cotton percale/sateen, cotton blend, linen, lyocell | E5: Actual insert dimensions; corner/side ties, seam and zipper cycling; clarify no insert; colourfastness | F5: Washed-cotton linen-look and ties already widespread | G5: Easy assembly plus tested fit/colourfastness; UK-native dimensions | H5: Medium: large-panel alignment, shrinkage and closure | I5: Investigate US/UK differentiated and hospitality
A6: Comforters / duvet inserts | B6: comforter | C6: Seasonal warmth, room bundles and all-in-one convenience | D6: Polyester/down alternative, down/feather, cotton shell | E6: Fill weight/composition; UK tog where tested; baffle/box construction; washing/drying instructions | F6: Value bed-in-a-bag bundles set a low reference price; bulk inflates logistics | G6: Specific warmth/weight need backed by testing, not generic all-season claim | H6: High: fill uniformity, migration, compression, drying and product-rule checks | I6: Postpone broad launch; niche feasibility only
A7: Quilts / coverlets | B7: quilt | C7: Decorative layering and lightweight seasonal use | D7: Cotton shell/fill, blends, microfiber | E7: Distinguish cotton shell from fill; finished dimensions, quilting density, wash behaviour | F7: Pattern/style inventory fragments demand; UK quilt query can mean duvet insert | G7: Wash-durable lightweight layer for specific climate/use | H7: Medium-high: quilting capacity, stitch durability, colour and fill | I7: Investigate design-led narrow assortment; no inferred UK demand from query
A8: Mattress protectors | B8: protector | C8: Spills, hygiene and mattress preservation | D8: Cotton or viscose blend top, polyurethane membrane, polyester skirt | E8: Waterproof after repeated washes, noise, thermal comfort, fit depth; verify actual layers | F8: SafeRest/Utopia/PlushDeluxe/Silentnight have substantial visible trust signals | G8: Quiet leak-tested protector with honest composition and clear care | H8: High: membrane lamination, seal integrity and product classification | I8: Postpone commodity; differentiated only after lab validation
A9: Mattress toppers / pads | B9: topper | C9: Comfort retrofit and dorm/guest use | D9: Foam, latex, hollowfibre, down/feather; cellulose cover claims | E9: Separate foam thickness/density from quilted pad loft; recovery and durability tests | F9: Search mixes thin pads and thick foam; high volume/return risk; health claims require support | G9: Narrow comfort use case with measured retention and realistic imagery | H9: High: bulky freight, compression recovery, flammability scope and returns | I9: Postpone for capital-light entrant
A10: Blankets, throws, flannel and other | B10: other | C10: Seasonal warmth, decoration; nursery and heated products are distinct risk classes | D10: Cotton, wool, fleece, flannel; electric components if heated | E10: GSM and dimensions; lint/pilling, wash shrinkage; special child/electrical requirements | F10: Gift/style-driven promotion and seasonal leftovers | G10: Non-electrical adult-use layers; hospitality replenishment | H10: Medium; higher for weighted/heated/child products | I10: Investigate selectively; exclude regulated extensions from initial launch

Sheet Materials
A1: Material | B1: Definition | C1: Consumer proposition | D1: Proposed checks | E1: Risk | F1: Evidence
A2: Cotton percale | B2: Fibre cotton; plain weave, not a fibre called percale | C2: Crisp, matte, breathable positioning; wrinkles may be accepted or disliked | D2: Proposed 200-300 single-ply TC, documented yarn/weight; post-wash shrink and tear tests | E2: Avoid assuming high TC or Egyptian wording proves quality | F2: D01; LIVE_US_sheets; LIVE_CA_sheets
A3: Cotton sateen | B3: Cotton in a sateen weave | C3: Smooth, lustrous hand; warmth and snag sensitivity depend on construction | D3: Proposed 300-500 single-ply TC; abrasion, pilling, dimensional stability | E3: Not interchangeable with polyester satin | F3: D01; LIVE_US_sheets
A4: Microfiber / polyester satin | B4: Synthetic fibre; satin is a weave | C4: Affordable, soft and easy-care positioning; thermal comfort is subjective | D4: Specify GSM, yarn and finish; pilling/static/colourfastness testing | E4: Low differentiation and low selling prices challenge paid acquisition | F4: LIVE_US_fitted; LIVE_UK_sheets
A5: Cotton blends | B5: Percentages determine actual material | C5: Easy-care and laundry durability may suit hospitality | D5: Declare fibre percentages; measure dry time and repeated-wash serviceability | E5: Do not market as 100% cotton or infer equal breathability | F5: D07; M07; M09
A6: Bamboo-derived viscose/rayon | B6: Regenerated cellulose, not raw bamboo fibre | C6: Soft/drapey positioning; wet strength, shrinkage and authenticity concerns | D6: Correct generic name, fabric weight and construction; independent composition and wash tests | E6: FTC requires rayon/viscose made from bamboo wording; no unsupported natural-antibacterial or eco claim | F6: R02; PDP_CA_bamboo; PDP_CA_protector
A7: Lyocell | B7: Regenerated cellulose; TENCEL is a trademark not generic composition proof | C7: Smooth hand and moisture-management positioning | D7: Verify licensed branding if used; composition, process evidence, pilling/shrink tests | E7: Low observed search coverage is not proof of an open market | F7: D06; LIVE_US_lyocell; LIVE_CA_lyocell; LIVE_UK_lyocell
A8: Linen / flax | B8: Flax fibre; linen-look cotton is not linen | C8: Textured premium positioning, wrinkles and initial roughness tradeoffs | D8: Proposed 150-180 GSM for testing, not universal optimal weight; seam slippage/shrink tests | E8: Higher material/capital exposure; source certified chain if claimed | F8: D01; LIVE_US_linen
A9: Silk / wool / down / latex / foam | B9: Distinct fibres/fills and regulatory pathways | C9: Specialized feel, insulation or support; not one comparable category | D9: Verify silk momme, wool content, down fill and foam density as applicable | E9: Separate filled-product, flammability, allergen and health-claim diligence | F9: R01; R11; LIVE_US_topper

Sheet Competitor observations
A1: country | B1: currency | C1: segment | D1: query | E1: position | F1: asin | G1: brand | H1: title | I1: size | J1: material_claim | K1: display_price | L1: rating | M1: ratings_approx | N1: sponsored_visible | O1: promotion_text | P1: query_match_screen | Q1: bought_badge | R1: source | S1: url | T1: research_date | U1: limitation
A2: CA | B2: CAD | C2: bamboo | D2: bamboo viscose sheet set | E2: 1 | F2: B0H9QD7RD5 | G2: Sasttie | H2: Sasttie White Silky-Soft Bamboo Sheets Queen Size 4-Piece, 100% Rayon Made from Bamboo 300TC, Cooling Sheet for Hot Sleepers, 16" Deep Pocket, Secure Corner Straps, Head Tag, Washable & Breathable | I2: Queen | J2: Regenerated cellulose or blend claim | K2: 49.99 | L2: 4.4 | M2: 44 | N2: =FALSE() -> FALSE | P2: =TRUE() -> TRUE | R2: LIVE_CA_bamboo | S2: https://www.amazon.ca/dp/B0H9QD7RD5 | T2: 2026-10-26 | U2: No fixed postal code; mixed variants; rating counts may be pooled/global and K/M rounded. No sales inference from badges.
A3: CA | B3: CAD | C3: bamboo | D3: bamboo viscose sheet set | E3: 2 | F3: B0CQ2ZWGNQ | G3: DECOLURE | H3: DECOLURE 100% Organic Viscose Derived from Bamboo Sheets Queen Size 6pcs - Ultra Soft & Luxuriously Cooling, 17" Deep Pocket, Double Stitching, Perfect for Hot Sleepers - Queen Bed Sheets (White) | I3: Queen | J3: Regenerated cellulose or blend claim | K3: 99.99 | L3: 4.4 | M3: 3300 | N3: =FALSE() -> FALSE | P3: =TRUE() -> TRUE | R3: LIVE_CA_bamboo | S3: https://www.amazon.ca/dp/B0CQ2ZWGNQ | T3: 2026-10-26 | U3: No fixed postal code; mixed variants; rating counts may be pooled/global and K/M rounded. No sales inference from badges.
A4: CA | B4: CAD | C4: bamboo | D4: bamboo viscose sheet set | E4: 3 | F4: B07YKCQBBL | G4: Bedsure | H4: Bedsure Sheet King Size - 4 Piece 100% Bamboo Rayon Sheet Set Dark Grey | I4: King | J4: Regenerated cellulose or blend claim | K4: 74.98 | L4: 4.3 | M4: 60900 | N4: =FALSE() -> FALSE | O4: Limited-time deal | List: $129.99 | List: | P4: =TRUE() -> TRUE | Q4: 100+ bought in past month | R4: LIVE_CA_bamboo | S4: https://www.amazon.ca/dp/B07YKCQBBL | T4: 2026-10-26 | U4: No fixed postal code; mixed variants; rating counts may be pooled/global and K/M rounded. No sales inference from badges.
A5: CA | B5: CAD | C5: bamboo | D5: bamboo viscose sheet set | E5: 4 | F5: B0H4LQTR5T | G5: Unresolved (title insufficient) | H5: Queen Size Sheet Set, Viscose Bamboo Sheets 4-Piece, 100% Viscose Derived from Bamboo, Hotel Luxury Silky & Cooling for Hot Sleepers, Deep Pocket Up to 17", Navy Blue | I5: Queen | J5: Regenerated cellulose or blend claim | K5: 79.99 | L5: 4.5 | M5: 26 | N5: =FALSE() -> FALSE | O5: Save 8% | Was: $87.39 | Was: | Save 5% on any 2 | P5: =TRUE() -> TRUE | R5: LIVE_CA_bamboo | S5: https://www.amazon.ca/dp/B0H4LQTR5T | T5: 2026-10-26 | U5: No fixed postal code; mixed variants; rating counts may be pooled/global and K/M rounded. No sales inference from badges.
A6: CA | B6: CAD | C6: bamboo | D6: bamboo viscose sheet set | E6: 5 | F6: B0C3R5NGGQ | G6: Unresolved (title insufficient) | H6: Cooling 100% Viscose Derived from Bamboo Sheet Set, Full, 4 Pc, White | I6: Full | J6: Regenerated cellulose or blend claim | K6: 59.99 | L6: 4.3 | M6: 108 | N6: =FALSE() -> FALSE | O6: Save 14% | List: $69.99 | List: | P6: =TRUE() -> TRUE | R6: LIVE_CA_bamboo | S6: https://www.amazon.ca/dp/B0C3R5NGGQ | T6: 2026-10-26 | U6: No fixed postal code; mixed variants; rating counts may be pooled/global and K/M rounded. No sales inference from badges.
A7: CA | B7: CAD | C7: bamboo | D7: bamboo viscose sheet set | E7: 6 | F7: B0FT7LV7PP | G7: Unresolved (title insufficient) | H7: Bamboo Viscose Sheet Set Queen Size, Cooling Sheets Bed Set 4pcs | I7: Queen | J7: Regenerated cellulose or blend claim | K7: 84.99 | L7: 4.4 | M7: 827 | N7: =FALSE() -> FALSE | O7: Save 5% on any 2 | P7: =TRUE() -> TRUE | R7: LIVE_CA_bamboo | S7: https://www.amazon.ca/dp/B0FT7LV7PP | T7: 2026-10-26 | U7: No fixed postal code; mixed variants; rating counts may be pooled/global and K/M rounded. No sales inference from badges.
A8: CA | B8: CAD | C8: bamboo | D8: bamboo viscose sheet set | E8: 7 | F8: B0CQ2XQF9N | G8: DECOLURE | H8: DECOLURE 100% Organic Viscose Derived from Bamboo Sheets King Size 6pcs - Ultra Soft & Luxuriously Cooling, 17" Deep Pocket, Double Stitching, Perfect for Hot Sleepers - King Bed Sheets (White) | I8: King | J8: Regenerated cellulose or blend claim | K8: 99.99 | L8: 4.4 | M8: 3300 | N8: =FALSE() -> FALSE | P8: =TRUE() -> TRUE | Q8: 50+ bought in past month | R8: LIVE_CA_bamboo | S8: https://www.amazon.ca/dp/B0CQ2XQF9N | T8: 2026-10-26 | U8: No fixed postal code; mixed variants; rating counts may be pooled/global and K/M rounded. No sales inference from badges.
A9: CA | B9: CAD | C9: bamboo | D9: bamboo viscose sheet set | E9: 8 | F9: B0H4LW9WBT | G9: Unresolved (title insufficient) | H9: Full Size Sheet Set, Viscose Bamboo Sheets 4-Piece, 100% Viscose Derived from Bamboo, Hotel Luxury Silky & Cooling for Hot Sleepers, Deep Pocket Up to 17", Grey | I9: Full | J9: Regenerated cellulose or blend claim | K9: 79.99 | L9: 4.5 | M9: 26 | N9: =FALSE() -> FALSE | O9: Save 11% | Was: $89.99 | Was: | Save 5% on any 2 | P9: =TRUE() -> TRUE | R9: LIVE_CA_bamboo | S9: https://www.amazon.ca/dp/B0H4LW9WBT | T9: 2026-10-26 | U9: No fixed postal code; mixed variants; rating counts may be pooled/global and K/M rounded. No sales inference from badges.
A10: CA | B10: CAD | C10: bamboo | D10: bamboo viscose sheet set | E10: 9 | F10: B0CQ33C286 | G10: DECOLURE | H10: DECOLURE 100% Organic Viscose Derived from Bamboo Sheets Queen Size 6pcs - Ultra Soft & Luxuriously Cooling, 17" Deep Pocket, Double Stitching, Perfect for Hot Sleepers - Queen Bed Sheets (Charcoal) | I10: Queen | J10: Regenerated cellulose or blend claim | K10: 99.99 | L10: 4.4 | M10: 3300 | N10: =FALSE() -> FALSE | P10: =TRUE() -> TRUE | R10: LIVE_CA_bamboo | S10: https://www.amazon.ca/dp/B0CQ33C286 | T10: 2026-10-26 | U10: No fixed postal code; mixed variants; rating counts may be pooled/global and K/M rounded. No sales inference from badges.
A11: CA | B11: CAD | C11: bamboo | D11: bamboo viscose sheet set | E11: 10 | F11: B0F1KK74XH | G11: Unresolved (title insufficient) | H11: Viviland Cooling Queen Sheets, 100% Viscose Derived Bamboo, Sky Blue | I11: Queen | J11: Regenerated cellulose or blend claim | K11: 66.49 | L11: 4.4 | M11: 155 | N11: =FALSE() -> FALSE | O11: Was: $69.99 | Was: | P11: =TRUE() -> TRUE | R11: LIVE_CA_bamboo | S11: https://www.amazon.ca/dp/B0F1KK74XH | T11: 2026-10-26 | U11: No fixed postal code; mixed variants; rating counts may be pooled/global and K/M rounded. No sales inference from badges.
A12: CA | B12: CAD | C12: bamboo | D12: bamboo viscose sheet set | E12: 11 | F12: B0CGZR147P | G12: Unresolved (title insufficient) | H12: Andency Bamboo Cooling Beige Sheet Set, 4pcs King Sheets for Hot Sleepers | I12: King | J12: Regenerated cellulose or blend claim | K12: 69.99 | L12: 4.4 | M12: 742 | N12: =FALSE() -> FALSE | O12: Was: $74.99 | Was: | P12: =TRUE() -> TRUE | R12: LIVE_CA_bamboo | S12: https://www.amazon.ca/dp/B0CGZR147P | T12: 2026-10-26 | U12: No fixed postal code; mixed variants; rating counts may be pooled/global and K/M rounded. No sales inference from badges.
A13: CA | B13: CAD | C13: bamboo | D13: bamboo viscose sheet set | E13: 12 | F13: B0GCZS2W4S | G13: Unresolved (title insufficient) | H13: Viviland Cooling Full Sheets, 100% Viscose Derived Bamboo, Coral | I13: Full | J13: Regenerated cellulose or blend claim | K13: 56.83 | L13: 4.4 | M13: 155 | N13: =FALSE() -> FALSE | O13: Was: $61.99 | Was: | P13: =TRUE() -> TRUE | R13: LIVE_CA_bamboo | S13: https://www.amazon.ca/dp/B0GCZS2W4S | T13: 2026-10-26 | U13: No fixed postal code; mixed variants; rating counts may be pooled/global and K/M rounded. No sales inference from badges.
A14: CA | B14: CAD | C14: bamboo | D14: bamboo viscose sheet set | E14: 13 | F14: B07XF1NLLW | G14: Unresolved (title insufficient) | H14: BAMPURE 100% Organic Bamboo Sheets King 4PC - Cooling Sheets Set | I14: King | J14: Regenerated cellulose or blend claim | K14: 104.99 | L14: 4.3 | M14: 7300 | N14: =FALSE() -> FALSE | O14: Save 50% on 1 when you buy 2 | P14: =TRUE() -> TRUE | R14: LIVE_CA_bamboo | S14: https://www.amazon.ca/dp/B07XF1NLLW | T14: 2026-10-26 | U14: No fixed postal code; mixed variants; rating counts may be pooled/global and K/M rounded. No sales inference from badges.
A15: CA | B15: CAD | C15: bamboo | D15: bamboo viscose sheet set | E15: 14 | F15: B0BZPZPGDC | G15: DECOLURE | H15: DECOLURE 100% Organic Bamboo Viscose Sheets Full Size 4 pcs - Ultra Soft & Luxuriously Cooling, 16" Deep Pocket, Double Stitching,Perfect for Hot Sleepers - Luxury Full Bed Sheets Set (Light Olive) | I15: Full | J15: Regenerated cellulose or blend claim | K15: 79.99 | L15: 4.4 | M15: 5800 | N15: =FALSE() -> FALSE | P15: =TRUE() -> TRUE | R15: LIVE_CA_bamboo | S15: https://www.amazon.ca/dp/B0BZPZPGDC | T15: 2026-10-26 | U15: No fixed postal code; mixed variants; rating counts may be pooled/global and K/M rounded. No sales inference from badges.
A16: CA | B16: CAD | C16: bamboo | D16: bamboo viscose sheet set | E16: 15 | F16: B0DR99Q37Y | G16: Bambaw | H16: Bambaw 100% Viscose Derived from Bamboo Sheets Queen Size Set – 4pcs Cooling Sheet Set, Super Soft Sheets Queen Size, Luxury Bed Sheets, Deep Pocket Fits Up to 16'' Mattresses (Charcoal) | I16: Queen | J16: Regenerated cellulose or blend claim | K16: 125.94 | L16: 4.3 | M16: 3000 | N16: =FALSE() -> FALSE | O16: Limited-time deal | Was: $139.95 | Was: | P16: =TRUE() -> TRUE | R16: LIVE_CA_bamboo | S16: https://www.amazon.ca/dp/B0DR99Q37Y | T16: 2026-10-26 | U16: No fixed postal code; mixed variants; rating counts may be pooled/global and K/M rounded. No sales inference from badges.
A17: CA | B17: CAD | C17: bamboo | D17: bamboo viscose sheet set | E17: 16 | F17: B09PYB9C45 | G17: Unresolved (title insufficient) | H17: ACCURATEX Bamboo Cooling Sheets for Hot Sleepers, King Size,Grey | I17: King | J17: Regenerated cellulose or blend claim | K17: 104.99 | L17: 4.3 | M17: 1000 | N17: =FALSE() -> FALSE | P17: =TRUE() -> TRUE | Q17: 50+ bought in past month | R17: LIVE_CA_bamboo | S17: https://www.amazon.ca/dp/B09PYB9C45 | T17: 2026-10-26 | U17: No fixed postal code; mixed variants; rating counts may be pooled/global and K/M rounded. No sales inference from badges.
A18: CA | B18: CAD | C18: bamboo | D18: bamboo viscose sheet set | E18: 17 | F18: B08MJW1N18 | G18: Unresolved (title insufficient) | H18: Bamboo Bay Luxury Bamboo Sheets Twin Size - 4 Piece Ultra Soft Twin Cooling Sheets for Hot Sleepers - 100% Organic Bamboo Twin Sheet Set Fits Up to 16" Deep Pocket - Eco Friendly - Twin - Light Blue | I18: Twin | J18: Regenerated cellulose or blend claim | K18: 46.99 | L18: 4.4 | M18: 2800 | N18: =FALSE() -> FALSE | P18: =TRUE() -> TRUE | R18: LIVE_CA_bamboo | S18: https://www.amazon.ca/dp/B08MJW1N18 | T18: 2026-10-26 | U18: No fixed postal code; mixed variants; rating counts may be pooled/global and K/M rounded. No sales inference from badges.
A19: CA | B19: CAD | C19: bamboo | D19: bamboo viscose sheet set | E19: 18 | F19: B0DL5NCTYF | G19: Unresolved (title insufficient) | H19: MR&HM Queen Sheets 4 Pieces, Rayon Derived from Bamboo Blend, Dark Grey | I19: Queen | J19: Regenerated cellulose or blend claim | K19: 58.99 | L19: 4.2 | M19: 617 | N19: =FALSE() -> FALSE | P19: =TRUE() -> TRUE | R19: LIVE_CA_bamboo | S19: https://www.amazon.ca/dp/B0DL5NCTYF | T19: 2026-10-26 | U19: No fixed postal code; mixed variants; rating counts may be pooled/global and K/M rounded. No sales inference from badges.
A20: CA | B20: CAD | C20: bamboo | D20: bamboo viscose sheet set | E20: 19 | F20: B0F2HW8MY2 | G20: Bambaw | H20: Bambaw 3pcs Set - 100% Viscose Derived from Bamboo Duvet Cover Queen Size Set, Duvet Cover Cooling for Hot Sleepers, Super Soft & Breathable, OEKO-TEX® STANDARD 100 Certified, No Comforter (Sand) | I20: Queen | J20: Regenerated cellulose or blend claim | K20: 125.95 | L20: 4.5 | M20: 256 | N20: =FALSE() -> FALSE | P20: =TRUE() -> TRUE | R20: LIVE_CA_bamboo | S20: https://www.amazon.ca/dp/B0F2HW8MY2 | T20: 2026-10-26 | U20: No fixed postal code; mixed variants; rating counts may be pooled/global and K/M rounded. No sales inference from badges.
A21: CA | B21: CAD | C21: bamboo | D21: bamboo viscose sheet set | E21: 20 | F21: B0GVDDCJVT | G21: Unresolved (title insufficient) | H21: 100% Bamboo Viscose Twin XL Size Sheets Set, 400 Thread Count, 3 Pieces | I21: Twin XL | J21: Regenerated cellulose or blend claim | L21: 4.4 | M21: 82 | N21: =FALSE() -> FALSE | P21: =TRUE() -> TRUE | R21: LIVE_CA_bamboo | S21: https://www.amazon.ca/dp/B0GVDDCJVT | T21: 2026-10-26 | U21: No fixed postal code; mixed variants; rating counts may be pooled/global and K/M rounded. No sales inference from badges.
A22: CA | B22: CAD | C22: bamboo | D22: bamboo viscose sheet set | E22: 21 | F22: B0G34XJ831 | G22: Unresolved (title insufficient) | H22: 100% Bamboo Viscose Cooling Fitted Sheet Queen Olive Green and Pillowcases | I22: Queen | J22: Regenerated cellulose or blend claim | K22: 59.99 | L22: 4.1 | M22: 36 | N22: =FALSE() -> FALSE | P22: =TRUE() -> TRUE | R22: LIVE_CA_bamboo | S22: https://www.amazon.ca/dp/B0G34XJ831 | T22: 2026-10-26 | U22: No fixed postal code; mixed variants; rating counts may be pooled/global and K/M rounded. No sales inference from badges.
A23: CA | B23: CAD | C23: bamboo | D23: bamboo viscose sheet set | E23: 22 | F23: B0DJTGXZQF | G23: Unresolved (title insufficient) | H23: Luxury Viscose from Bamboo Bath Towel Set, Set of 6, Graphite | I23: Unspecified | J23: Regenerated cellulose or blend claim | K23: 89.99 | L23: 4.3 | M23: 186 | N23: =FALSE() -> FALSE | P23: =TRUE() -> TRUE | R23: LIVE_CA_bamboo | S23: https://www.amazon.ca/dp/B0DJTGXZQF | T23: 2026-10-26 | U23: No fixed postal code; mixed variants; rating counts may be pooled/global and K/M rounded. No sales inference from badges.
A24: CA | B24: CAD | C24: bamboo | D24: bamboo viscose sheet set | E24: 23 | F24: B01M16WBW1 | G24: Unresolved (title insufficient) | H24: Queen Size 4 Piece Sheet Set - Comfy Breathable & Cooling Sheets - White | I24: Queen | J24: Not resolved from title | K24: 25.49 | L24: 4.4 | M24: 444800 | N24: =FALSE() -> FALSE | O24: List: $39.99 | List: | P24: =TRUE() -> TRUE | Q24: 4K+ bought in past month | R24: LIVE_CA_bamboo | S24: https://www.amazon.ca/dp/B01M16WBW1 | T24: 2026-10-26 | U24: No fixed postal code; mixed variants; rating counts may be pooled/global and K/M rounded. No sales inference from badges.
A25: CA | B25: CAD | C25: bamboo | D25: bamboo viscose sheet set | E25: 24 | F25: B0GTYZS5B9 | G25: Unresolved (title insufficient) | H25: QUTOOL 100% Viscose Made from Bamboo Queen Sheet Sets, 4PC Cooling Bed Sheets with Extra Deep Pocket up to 18'', Hotel Luxury Silky Bedding for Hot Sleepers, Breathable, Light Gray | I25: Queen | J25: Regenerated cellulose or blend claim | K25: 101.59 | L25: 4.5 | M25: 49 | N25: =FALSE() -> FALSE | P25: =TRUE() -> TRUE | R25: LIVE_CA_bamboo | S25: https://www.amazon.ca/dp/B0GTYZS5B9 | T25: 2026-10-26 | U25: No fixed postal code; mixed variants; rating counts may be pooled/global and K/M rounded. No sales inference from badges.
A26: CA | B26: CAD | C26: bamboo | D26: bamboo viscose sheet set | E26: 25 | F26: B0FDB3L3Y3 | G26: Unresolved (title insufficient) | H26: ROYALE LINENS Bamboo Viscose Queen Sheet Set - Cooling Bed Sheet Set - 1 Fitted, 1 Flat & 2 Pillowcase - Fits Up to 16" - Organic Viscose Derived from Bamboo - Bedding Sheet Set (Queen, Nimbus Cloud) | I26: Queen | J26: Regenerated cellulose or blend claim | K26: 42.99 | L26: 4.2 | M26: 254 | N26: =FALSE() -> FALSE | P26: =TRUE() -> TRUE | R26: LIVE_CA_bamboo | S26: https://www.amazon.ca/dp/B0FDB3L3Y3 | T26: 2026-10-26 | U26: No fixed postal code; mixed variants; rating counts may be pooled/global and K/M rounded. No sales inference from badges.
A27: CA | B27: CAD | C27: bamboo | D27: bamboo viscose sheet set | E27: 26 | F27: B0DS21FNX6 | G27: Unresolved (title insufficient) | H27: 100% Viscose Derived from Bamboo Fitted Sheet Set 3 Piece - 2 Pillowcase 1 Fitted Sheet with 16" Deep Pocket, Hotel Luxury Silky Bedding, Ultra Soft, Cooling for Hot Sleepers(Blue Queen) | I27: Queen | J27: Regenerated cellulose or blend claim | K27: 33.8 | L27: 4.2 | M27: 51 | N27: =FALSE() -> FALSE | P27: =TRUE() -> TRUE | R27: LIVE_CA_bamboo | S27: https://www.amazon.ca/dp/B0DS21FNX6 | T27: 2026-10-26 | U27: No fixed postal code; mixed variants; rating counts may be pooled/global and K/M rounded. No sales inference from badges.
A28: CA | B28: CAD | C28: bamboo | D28: bamboo viscose sheet set | E28: 27 | F28: B0FXWFJ9C1 | G28: Unresolved (title insufficient) | H28: 100% Bamboo Rayon Cooling Sheets Twin Set Dark Gray Silky Soft Bedding | I28: Twin | J28: Regenerated cellulose or blend claim | K28: 74.99 | L28: 4.7 | M28: 12 | N28: =FALSE() -> FALSE | P28: =TRUE() -> TRUE | R28: LIVE_CA_bamboo | S28: https://www.amazon.ca/dp/B0FXWFJ9C1 | T28: 2026-10-26 | U28: No fixed postal code; mixed variants; rating counts may be pooled/global and K/M rounded. No sales inference from badges.
A29: CA | B29: CAD | C29: bamboo | D29: bamboo viscose sheet set | E29: 28 | F29: B0BYPL2QXC | G29: Unresolved (title insufficient) | H29: Bare Home 100% Rayon Made from Bamboo Sheet Set (Full, Grey) | I29: Full | J29: Regenerated cellulose or blend claim | K29: 98.99 | L29: 4.4 | M29: 870 | N29: =FALSE() -> FALSE | O29: Was: $105.99 | Was: | P29: =TRUE() -> TRUE | R29: LIVE_CA_bamboo | S29: https://www.amazon.ca/dp/B0BYPL2QXC | T29: 2026-10-26 | U29: No fixed postal code; mixed variants; rating counts may be pooled/global and K/M rounded. No sales inference from badges.
A30: CA | B30: CAD | C30: bamboo | D30: bamboo viscose sheet set | E30: 29 | F30: B0CGX4G67T | G30: Unresolved (title insufficient) | H30: HENGWEITEXT Bamboo Sheets King Bed Sheet Set,Textured 60% Viscose from Bamboo 40% Cotton Sheets Set King Size,Wrinkle Free 4 Piece Shrinkage and Fade Resistant | I30: King | J30: Regenerated cellulose or blend claim | K30: 23.99 | L30: 3 | M30: 5 | N30: =FALSE() -> FALSE | P30: =TRUE() -> TRUE | R30: LIVE_CA_bamboo | S30: https://www.amazon.ca/dp/B0CGX4G67T | T30: 2026-10-26 | U30: No fixed postal code; mixed variants; rating counts may be pooled/global and K/M rounded. No sales inference from badges.
A31: CA | B31: CAD | C31: bamboo | D31: bamboo viscose sheet set | E31: 30 | F31: B0H3BVJ68C | G31: Bambaw | H31: Bambaw 100% Viscose Derived from Bamboo Fitted Sheet Twin XL – Twin XL Single Fitted Sheet, Cooling, Soft & Breathable, Crisp & Smooth Feel, Deep Pocket Fits Up to 15" Mattresses (White) | I31: Twin XL | J31: Regenerated cellulose or blend claim | K31: 65.95 | L31: 4.4 | M31: 871 | N31: =FALSE() -> FALSE | P31: =TRUE() -> TRUE | R31: LIVE_CA_bamboo | S31: https://www.amazon.ca/dp/B0H3BVJ68C | T31: 2026-10-26 | U31: No fixed postal code; mixed variants; rating counts may be pooled/global and K/M rounded. No sales inference from badges.
A32: CA | B32: CAD | C32: bamboo | D32: bamboo viscose sheet set | E32: 31 | F32: B096BM64KC | G32: Pure Bamboo | H32: PURE BAMBOO Sheets 100% Genuine Bamboo Viscose, King, Pesto | I32: King | J32: Regenerated cellulose or blend claim | K32: 164.99 | L32: 4.3 | M32: 20600 | N32: =FALSE() -> FALSE | P32: =TRUE() -> TRUE | R32: LIVE_CA_bamboo | S32: https://www.amazon.ca/dp/B096BM64KC | T32: 2026-10-26 | U32: No fixed postal code; mixed variants; rating counts may be pooled/global and K/M rounded. No sales inference from badges.
A33: CA | B33: CAD | C33: bamboo | D33: bamboo viscose sheet set | E33: 32 | F33: B0FCZRHF11 | G33: Unresolved (title insufficient) | H33: 100% Organically Grown Bamboo Viscose Full Sheet Set, 4Pcs, Light Blue | I33: Full | J33: Regenerated cellulose or blend claim | K33: 93.57 | N33: =FALSE() -> FALSE | P33: =TRUE() -> TRUE | R33: LIVE_CA_bamboo | S33: https://www.amazon.ca/dp/B0FCZRHF11 | T33: 2026-10-26 | U33: No fixed postal code; mixed variants; rating counts may be pooled/global and K/M rounded. No sales inference from badges.
A34: CA | B34: CAD | C34: bamboo | D34: bamboo viscose sheet set | E34: 33 | F34: B0DZHJHSNX | G34: Unresolved (title insufficient) | H34: 18-24 Inch Extra Deep Pocket Queen Size Sheets Set, 100% Viscose Derived from Bamboo Sheets Queen Size Bed Sheets, 4Pcs Soft Forest Green Cooling Sheets for Hot Sleepers | I34: Queen | J34: Regenerated cellulose or blend claim | K34: 108.51 | L34: 4.4 | M34: 125 | N34: =FALSE() -> FALSE | P34: =TRUE() -> TRUE | R34: LIVE_CA_bamboo | S34: https://www.amazon.ca/dp/B0DZHJHSNX | T34: 2026-10-26 | U34: No fixed postal code; mixed variants; rating counts may be pooled/global and K/M rounded. No sales inference from badges.
A35: CA | B35: CAD | C35: bamboo | D35: bamboo viscose sheet set | E35: 34 | F35: B07V49Z6H6 | G35: Hotel Sheets Direct | H35: Hotel Sheets Direct Bamboo Bed Sheet Set - 100% Viscose from Bamboo Sheet Set, Cooling, Thermoregulating, Hypoallergenic (Queen, Light Pink) | I35: Queen | J35: Regenerated cellulose or blend claim | K35: 110.99 | L35: 4.3 | M35: 14100 | N35: =FALSE() -> FALSE | P35: =TRUE() -> TRUE | R35: LIVE_CA_bamboo | S35: https://www.amazon.ca/dp/B07V49Z6H6 | T35: 2026-10-26 | U35: No fixed postal code; mixed variants; rating counts may be pooled/global and K/M rounded. No sales inference from badges.
A36: CA | B36: CAD | C36: bamboo | D36: bamboo viscose sheet set | E36: 35 | F36: B0DSZMTCL2 | G36: JSD | H36: JSD Dusty Pink 100% Viscose Derived from Bamboo Queen Sheet Set, Cooling Sheets for Hot Sleepers, 300TC Sateen Weave Breathable Silky, Deep Pocket with Corner Straps, Oeko-Tex Certified | I36: Queen | J36: Regenerated cellulose or blend claim | K36: 80.52 | L36: 4.4 | M36: 285 | N36: =FALSE() -> FALSE | O36: Was: $99.76 | Was: | P36: =TRUE() -> TRUE | R36: LIVE_CA_bamboo | S36: https://www.amazon.ca/dp/B0DSZMTCL2 | T36: 2026-10-26 | U36: No fixed postal code; mixed variants; rating counts may be pooled/global and K/M rounded. No sales inference from badges.
A37: CA | B37: CAD | C37: bamboo | D37: bamboo viscose sheet set | E37: 36 | F37: B08F3DFWJM | G37: Unresolved (title insufficient) | H37: Gökotta Queen Bed Sheets 4 Piece, 100% FSC® Certified Bamboo, Cooling | I37: Queen | J37: Regenerated cellulose or blend claim | K37: 139.99 | L37: 4.4 | M37: 2700 | N37: =FALSE() -> FALSE | O37: You pay $129.99 with coupon | P37: =TRUE() -> TRUE | R37: LIVE_CA_bamboo | S37: https://www.amazon.ca/dp/B08F3DFWJM | T37: 2026-10-26 | U37: No fixed postal code; mixed variants; rating counts may be pooled/global and K/M rounded. No sales inference from badges.
A38: CA | B38: CAD | C38: bamboo | D38: bamboo viscose sheet set | E38: 37 | F38: B0F6J9CMW4 | G38: Unresolved (title insufficient) | H38: 100% Organic Bamboo 4 Pcs Bed Sheet Set – Cooling Sheets for Hot Sleepers | Ultra Soft, Breathable | 17" Deep Pocket (Silver Mist, Queen Size 4 pcs Set) | I38: Queen | J38: Regenerated cellulose or blend claim | K38: 73.97 | L38: 4.3 | M38: 48 | N38: =FALSE() -> FALSE | P38: =TRUE() -> TRUE | R38: LIVE_CA_bamboo | S38: https://www.amazon.ca/dp/B0F6J9CMW4 | T38: 2026-10-26 | U38: No fixed postal code; mixed variants; rating counts may be pooled/global and K/M rounded. No sales inference from badges.
A39: CA | B39: CAD | C39: bamboo | D39: bamboo viscose sheet set | E39: 38 | F39: B09RJSYCKR | G39: Unresolved (title insufficient) | H39: Bella Coterie Luxury Bamboo Viscose Split King Sheet Set, Organically Grown | I39: King | J39: Regenerated cellulose or blend claim | L39: 4.4 | M39: 6200 | N39: =FALSE() -> FALSE | P39: =TRUE() -> TRUE | R39: LIVE_CA_bamboo | S39: https://www.amazon.ca/dp/B09RJSYCKR | T39: 2026-10-26 | U39: No fixed postal code; mixed variants; rating counts may be pooled/global and K/M rounded. No sales inference from badges.
A40: CA | B40: CAD | C40: bamboo | D40: bamboo viscose sheet set | E40: 39 | F40: B0DPLJ4BN4 | G40: Unresolved (title insufficient) | H40: BAMPURE 100% Organic Bamboo Sheets Queen 4PC - Cooling Sheets Set | I40: Queen | J40: Regenerated cellulose or blend claim | K40: 72.99 | L40: 3.3 | M40: 18 | N40: =FALSE() -> FALSE | O40: List: $89.99 | List: | P40: =TRUE() -> TRUE | R40: LIVE_CA_bamboo | S40: https://www.amazon.ca/dp/B0DPLJ4BN4 | T40: 2026-10-26 | U40: No fixed postal code; mixed variants; rating counts may be pooled/global and K/M rounded. No sales inference from badges.
...

Sheet Price review barriers
A1: country | B1: segment | C1: cards | D1: matched_prices | E1: min | F1: p25 | G1: median | H1: p75 | I1: max | J1: ratings_n | K1: median_ratings | L1: sponsored_cards | M1: brand_resolved | N1: top3_known_card_share | O1: top3 | P1: source
A2: CA | B2: bamboo | C2: 48 | D2: 44 | E2: 23.99 | F2: 61.48 | G2: 80.255 | H2: 104.14 | I2: 164.99 | J2: 47 | K2: 617 | L2: 0 | M2: 15 | N2: 0.66666667 | O2: DECOLURE / Bambaw / Hotel Sheets Direct | P2: LIVE_CA_bamboo
A3: CA | B3: comforter | C3: 48 | D3: 48 | E3: 23.8 | F3: 47.84 | G3: 56.49 | H3: 64.74 | I3: 149.05 | J3: 48 | K3: 1850 | L3: 0 | M3: 12 | N3: 0.83333333 | O3: Bedsure / Wake In Cloud / Sasttie | P3: LIVE_CA_comforter
A4: CA | B4: duvet | C4: 48 | D4: 43 | E4: 38.99 | F4: 50.99 | G4: 69.99 | H4: 79.99 | I4: 179.99 | J4: 43 | K4: 1000 | L4: 0 | M4: 25 | N4: 0.68 | O4: Wake In Cloud / Bedsure / LIFETOWN | P4: LIVE_CA_duvet
A5: CA | B5: fitted | C5: 48 | D5: 48 | E5: 10.96 | F5: 19.8775 | G5: 26.74 | H5: 36.365 | I5: 64.99 | J5: 48 | K5: 1550 | L5: 0 | M5: 15 | N5: 0.66666667 | O5: Utopia Bedding / Linen Home / CGK | P5: LIVE_CA_fitted
A6: CA | B6: linen | C6: 48 | D6: 12 | E6: 154.84 | F6: 160.49 | G6: 189.99 | H6: 243.5875 | I6: 319.47 | J6: 12 | K6: 272 | L6: 0 | M6: 20 | N6: 0.6 | O6: Simple&Opulence / Bedsure / MooMee | P6: LIVE_CA_linen
A7: CA | B7: lyocell | C7: 48 | D7: 47 | E7: 33.99 | F7: 76.49 | G7: 99.99 | H7: 122.51 | I7: 376.53 | J7: 46 | K7: 210.5 | L7: 0 | M7: 13 | N7: 0.53846154 | O7: Linenwalas / Bedsure / California Design Den | P7: LIVE_CA_lyocell
A8: CA | B8: pillowcase | C8: 48 | D8: 48 | E8: 10.99 | F8: 15.99 | G8: 18.49 | H8: 29.235 | I8: 56.96 | J8: 48 | K8: 1200 | L8: 0 | M8: 16 | N8: 0.5625 | O8: Amazon Basics / California Design Den / Deep Dream | P8: LIVE_CA_pillowcase
A9: CA | B9: protector | C9: 48 | D9: 48 | E9: 13 | F9: 23.105 | G9: 30.945 | H9: 36.9675 | I9: 79.99 | J9: 48 | K9: 3650 | L9: 0 | M9: 17 | N9: 0.82352941 | O9: Utopia Bedding / BEDLORE / Sasttie | P9: LIVE_CA_protector
A10: CA | B10: quilt | C10: 48 | D10: 44 | E10: 34.19 | F10: 56.615 | G10: 98.44 | H10: 119.99 | I10: 176.76 | J10: 48 | K10: 453 | L10: 0 | M10: 8 | N10: 0.875 | O10: Joyreap / Utopia Bedding / PHF | P10: LIVE_CA_quilt
A11: CA | B11: sheets | C11: 58 | D11: 47 | E11: 32.77 | F11: 44.99 | G11: 56.99 | H11: 75.99 | I11: 119.99 | J11: 48 | K11: 1950 | L11: 10 | M11: 25 | N11: 0.56 | O11: California Design Den / Amazon Basics / THREAD SPREAD | P11: LIVE_CA_sheets
A12: CA | B12: topper | C12: 48 | D12: 48 | E12: 25.99 | F12: 56.24 | G12: 74.945 | H12: 111.5925 | I12: 554 | J12: 48 | K12: 1049 | L12: 0 | M12: 7 | N12: 0.57142857 | O12: Utopia Bedding / Niagara Sleep Solution / BEDLORE | P12: LIVE_CA_topper
A13: UK | B13: bamboo | C13: 48 | D13: 47 | E13: 19.5 | F13: 48.29 | G13: 69.38 | H13: 99.77 | I13: 353.34 | J13: 47 | K13: 186 | L13: 0 | M13: 10 | N13: 0.8 | O13: Love's cabin / DECOLURE / PHF | P13: LIVE_UK_bamboo
A14: UK | B14: comforter | C14: 48 | D14: 0 | J14: 0 | L14: 0 | M14: 20 | N14: 0.85 | O14: GC GAVENO CAVAILIA / PRIME LINENS / Utopia Bedding | P14: LIVE_UK_comforter
A15: UK | B15: duvet | C15: 48 | D15: 29 | E15: 10.55 | F15: 13.99 | G15: 21.04 | H15: 26.845 | I15: 38 | J15: 34 | K15: 895 | L15: 0 | M15: 19 | N15: 0.68421053 | O15: GC GAVENO CAVAILIA / Yard / Dreams & Drapes | P15: LIVE_UK_duvet
A16: UK | B16: fitted | C16: 48 | D16: 25 | E16: 7.16 | F16: 8.99 | G16: 11.37 | H16: 22.665 | I16: 31.18 | J16: 48 | K16: 1350 | L16: 0 | M16: 18 | N16: 0.66666667 | O16: Utopia Bedding / Amazon Basics / Sapphire Collection | P16: LIVE_UK_fitted
A17: UK | B17: linen | C17: 48 | D17: 8 | E17: 24.04 | F17: 26.18 | G17: 82.89 | H17: 147.955 | I17: 166.23 | J17: 8 | K17: 2000 | L17: 0 | M17: 13 | N17: 0.46153846 | O17: Utopia Bedding / TEXAS LINEN CO. / Yard | P17: LIVE_UK_linen
A18: UK | B18: lyocell | C18: 48 | D18: 47 | E18: 29.24 | F18: 66.34 | G18: 78.07 | H18: 103.36 | I18: 189.31 | J18: 42 | K18: 47 | L18: 0 | M18: 0 | P18: LIVE_UK_lyocell
A19: UK | B19: pillowcase | C19: 48 | D19: 19 | E19: 3.99 | F19: 6.08 | G19: 9.89 | H19: 12 | I19: 22.92 | J19: 48 | K19: 540.5 | L19: 0 | M19: 14 | N19: 0.85714286 | O19: Sapphire Collection / Amazon Basics / Yard | P19: LIVE_UK_pillowcase
A20: UK | B20: protector | C20: 48 | D20: 24 | E20: 6.99 | F20: 8.9925 | G20: 11.385 | H20: 16.7425 | I20: 26 | J20: 48 | K20: 540.5 | L20: 0 | M20: 13 | N20: 0.84615385 | O20: Silentnight / Amazon Basics / Utopia Bedding | P20: LIVE_UK_protector
A21: UK | B21: quilt | C21: 48 | D21: 0 | J21: 0 | L21: 0 | M21: 24 | N21: 0.625 | O21: Silentnight / Littens / GC GAVENO CAVAILIA | P21: LIVE_UK_quilt
A22: UK | B22: sheets | C22: 48 | D22: 17 | E22: 12.05 | F22: 31.075 | G22: 47.22 | H22: 58.145 | I22: 77.1 | J22: 30 | K22: 430 | L22: 0 | M22: 14 | N22: 0.5 | O22: Utopia Bedding / GC GAVENO CAVAILIA / Elegant Comfort | P22: LIVE_UK_sheets
A23: UK | B23: topper | C23: 60 | D23: 29 | E23: 9.94 | F23: 19.99 | G23: 31.99 | H23: 47.27 | I23: 130.24 | J23: 60 | K23: 307.5 | L23: 12 | M23: 18 | N23: 0.88888889 | O23: Silentnight / GC GAVENO CAVAILIA / GMTEXTILES | P23: LIVE_UK_topper
A24: US | B24: bamboo | C24: 48 | D24: 48 | E24: 24.99 | F24: 43.4825 | G24: 59.99 | H24: 79.74 | I24: 134.99 | J24: 48 | K24: 463 | L24: 0 | M24: 23 | N24: 0.60869565 | O24: Pure Bamboo / Bedsure / Love's cabin | P24: LIVE_US_bamboo
A25: US | B25: comforter | C25: 48 | D25: 48 | E25: 21.98 | F25: 30.4875 | G25: 36.99 | H25: 49.9675 | I25: 309 | J25: 48 | K25: 4400 | L25: 0 | M25: 9 | N25: 1 | O25: Bedsure / Love's cabin / Sasttie | P25: LIVE_US_comforter
A26: US | B26: duvet | C26: 48 | D26: 41 | E26: 14.99 | F26: 48.17 | G26: 55.99 | H26: 68.99 | I26: 89.99 | J26: 42 | K26: 1300 | L26: 0 | M26: 28 | N26: 0.67857143 | O26: Bedsure / OAITE / BESTOUCH | P26: LIVE_US_duvet
A27: US | B27: fitted | C27: 48 | D27: 46 | E27: 8.99 | F27: 17.8775 | G27: 19.99 | H27: 29.99 | I27: 79.99 | J27: 48 | K27: 20500 | L27: 0 | M27: 19 | N27: 0.84210526 | O27: CGK / California Design Den / Hearth & Harbor | P27: LIVE_US_fitted
A28: US | B28: linen | C28: 48 | D28: 31 | E28: 90.24 | F28: 103.99 | G28: 119.99 | H28: 129.99 | I28: 145.99 | J28: 31 | K28: 1600 | L28: 0 | M28: 17 | N28: 0.58823529 | O28: Bedsure / LANE LINEN / Simple&Opulence | P28: LIVE_US_linen
A29: US | B29: lyocell | C29: 48 | D29: 47 | E29: 26.79 | F29: 55.99 | G29: 70.84 | H29: 89.99 | I29: 159.99 | J29: 47 | K29: 158 | L29: 0 | M29: 4 | N29: 0.75 | O29: Bedsure / Love's cabin / SIJO | P29: LIVE_US_lyocell
A30: US | B30: pillowcase | C30: 59 | D30: 58 | E30: 8.99 | F30: 14.99 | G30: 19.99 | H30: 23.92 | I30: 65.99 | J30: 58 | K30: 1800 | L30: 12 | M30: 23 | N30: 0.82608696 | O30: California Design Den / THREAD SPREAD / LANE LINEN | P30: LIVE_US_pillowcase
A31: US | B31: protector | C31: 48 | D31: 46 | E31: 11.99 | F31: 20.49 | G31: 32.49 | H31: 42.88 | I31: 119 | J31: 48 | K31: 9700 | L31: 0 | M31: 23 | N31: 0.69565217 | O31: SafeRest / PlushDeluxe / Utopia Bedding | P31: LIVE_US_protector
A32: US | B32: quilt | C32: 58 | D32: 57 | E32: 15.29 | F32: 52.09 | G32: 69.99 | H32: 87.74 | I32: 169.99 | J32: 58 | K32: 696 | L32: 12 | M32: 8 | N32: 1 | O32: Love's cabin / Bedsure | P32: LIVE_US_quilt
A33: US | B33: sheets | C33: 48 | D33: 38 | E33: 15 | F33: 33.065 | G33: 41.99 | H33: 53.49 | I33: 149.99 | J33: 38 | K33: 3100 | L33: 0 | M33: 24 | N33: 0.54166667 | O33: LANE LINEN / TEXAS LINEN CO. / Casa Platino | P33: LIVE_US_sheets
A34: US | B34: topper | C34: 48 | D34: 44 | E34: 13.99 | F34: 49.9825 | G34: 69.99 | H34: 105.99 | I34: 349 | J34: 48 | K34: 1850 | L34: 0 | M34: 12 | N34: 0.83333333 | O34: LINENSPA / EASELAND / Lucid | P34: LIVE_US_topper

Sheet Listing detail
A1: Country | B1: Segment | C1: ASIN | D1: Byline | E1: Aplus DOM nodes | F1: Image thumbs | G1: Video/quality limitation | H1: Visible review cards | I1: URL | J1: Source | K1: Notes | L1: Observed seller | M1: Observed shipper
A2: CA | B2: duvet | C2: B0C699R8B6 | D2: Visit the LIFETOWN Store | E2: 3 | F2: 7 | G2: Video count not verified; DOM presence is not quality score | H2: 13 | I2: https://www.amazon.ca/dp/B0C699R8B6 | J2: PDP_CA_duvet | K2: Page text/specifications in evidence archive. Brand != seller != manufacturer. No inferred seller revenue. | L2: LIFETOWN | M2: Amazon
A3: UK | B3: topper | C3: B072M5ZT78 | D3: Visit the GMTEXTILES Store | E3: 3 | F3: 7 | G3: Video count not verified; DOM presence is not quality score | H3: 13 | I3: https://www.amazon.co.uk/dp/B072M5ZT78 | J3: PDP_UK_topper | K3: Page text/specifications in evidence archive. Brand != seller != manufacturer. No inferred seller revenue. | L3: Unverified | M3: Unverified
A4: UK | B4: protector | C4: B08FRKXJ9R | D4: Visit the Silentnight Store | E4: 3 | F4: 7 | G4: Video count not verified; DOM presence is not quality score | H4: 13 | I4: https://www.amazon.co.uk/dp/B08FRKXJ9R | J4: PDP_UK_protector | K4: Page text/specifications in evidence archive. Brand != seller != manufacturer. No inferred seller revenue. | L4: Unverified | M4: Unverified
A5: UK | B5: bamboo | C5: B0DN1DDRHR | D5: Brand: Love's cabin | E5: 1 | F5: 7 | G5: 2 video references; DOM presence is not quality score | H5: 5 | I5: https://www.amazon.co.uk/dp/B0DN1DDRHR | J5: PDP_UK_bamboo | K5: Page text/specifications in evidence archive. Brand != seller != manufacturer. No inferred seller revenue. | L5: Unverified | M5: Unverified
A6: UK | B6: sheets | C6: B0CGJGRFW9 | D6: Visit the Utopia Bedding Store | E6: 1 | F6: 7 | G6: Video count not verified; DOM presence is not quality score | H6: 13 | I6: https://www.amazon.co.uk/dp/B0CGJGRFW9 | J6: PDP_UK_sheets | K6: Page text/specifications in evidence archive. Brand != seller != manufacturer. No inferred seller revenue. | L6: Unverified | M6: Unverified
A7: UK | B7: duvet | C7: B00J4RM850 | D7: Visit the Sapphire Collection Store | E7: 2 | F7: 5 | G7: Video count not verified; DOM presence is not quality score | H7: 13 | I7: https://www.amazon.co.uk/dp/B00J4RM850 | J7: PDP_UK_duvet | K7: Page text/specifications in evidence archive. Brand != seller != manufacturer. No inferred seller revenue. | L7: Unverified | M7: Unverified
A8: US | B8: protector | C8: B07HC2WHS1 | D8: Visit the PlushDeluxe Store | E8: 3 | F8: 7 | G8: 8 video references; DOM presence is not quality score | H8: 0 | I8: https://www.amazon.com/dp/B07HC2WHS1 | J8: PDP_US_protector | K8: Page text/specifications in evidence archive. Brand != seller != manufacturer. No inferred seller revenue. | L8: PlushDeluxe | M8: Amazon
A9: US | B9: sheets | C9: B07RY59C3W | D9: Visit the LANE LINEN Store | E9: 3 | F9: 7 | G9: 8 video references; DOM presence is not quality score | H9: 0 | I9: https://www.amazon.com/dp/B07RY59C3W | J9: PDP_US_sheets | K9: Page text/specifications in evidence archive. Brand != seller != manufacturer. No inferred seller revenue. | L9: Homespun Global | M9: Amazon
A10: CA | B10: sheets | C10: B0DST3PF14 | D10: Visit the THREAD SPREAD Store | E10: 2 | F10: 7 | G10: Video count not verified; DOM presence is not quality score | H10: 13 | I10: https://www.amazon.ca/dp/B0DST3PF14 | J10: PDP_CA_sheets | K10: Page text/specifications in evidence archive. Brand != seller != manufacturer. No inferred seller revenue. | L10: Thread Spread | M10: Amazon
A11: US | B11: duvet | C11: B0BP6DZ862 | D11: Visit the Bedsure Store | E11: 3 | F11: 7 | G11: 11 video references; DOM presence is not quality score | H11: 0 | I11: https://www.amazon.com/dp/B0BP6DZ862 | J11: PDP_US_duvet | K11: Page text/specifications in evidence archive. Brand != seller != manufacturer. No inferred seller revenue. | L11: Bedsure Collections | M11: Amazon
A12: US | B12: bamboo | C12: B0F29F1JM5 | D12: Visit the SONORO KATE Store | E12: 2 | F12: 7 | G12: Video count not verified; DOM presence is not quality score | H12: 0 | I12: https://www.amazon.com/dp/B0F29F1JM5 | J12: PDP_US_bamboo | K12: Page text/specifications in evidence archive. Brand != seller != manufacturer. No inferred seller revenue. | L12: SONORO KATE | M12: Amazon
A13: CA | B13: topper | C13: B07D5DN269 | D13: Visit the Niagara Sleep Solution Store | E13: 2 | F13: 7 | G13: 4 video references; DOM presence is not quality score | H13: 13 | I13: https://www.amazon.ca/dp/B07D5DN269 | J13: PDP_CA_topper | K13: Page text/specifications in evidence archive. Brand != seller != manufacturer. No inferred seller revenue. | L13: Niagara Sleep Solutions | M13: Amazon
... A16: CA | B16: bamboo | C16: B0H9QD7RD5 | D16: Visit the Sasttie Store | E16: 2 | F16: 7 | G16: 3 video references; DOM presence is not quality score | H16: 13 | I16: https://www.amazon.ca/dp/B0H9QD7RD5 | J16: PDP_CA_bamboo | K16: Page text/specifications in evidence archive. Brand != seller != manufacturer. No inferred seller revenue. | L16: MMT_SASTTIE | M16: Amazon

Sheet Review evidence
A1: source | B1: asin | C1: market | D1: review_id | E1: geo_date | F1: text | G1: reviewer_country | H1: vine | I1: verified | J1: themes | K1: method
A2: PDP_CA_bamboo | B2: B0H9QD7RD5 | C2: CA | D2: RL9SNNH75OSSL | E2: Canada on October 22, 2026 | F2: MM2 5 out of 5 stars Softest Sheets EVER + Amazing Price Reviewed in Canada on October 22, 2026 Colour Name: WhiteSize: King Verified Purchase I just got into bed in these sheets and they are SO incredibly soft and airy. I’ll definitely be ordering at least another set. The price is is super reasonable as well, and they are much nicer than any other sheets I have that cost more than twice the price. 2 people found this helpful Helpful Report | G2: CA | H2: =FALSE() -> FALSE | I2: =TRUE() -> TRUE | J2: comfort_softness; value | K2: Case-insensitive keyword mentions; multi-label; no positive/negative classification; displayed helpfulness sample, not random.
A3: PDP_CA_bamboo | B3: B0H9QD7RD5 | C3: CA | D3: R1H0ZZKCIPN647 | E3: Canada on October 3, 2026 | F3: Linda B 4 out of 5 stars Lovely soft and blue. Please don’t pill Reviewed in Canada on October 3, 2026 Colour Name: Light BlueSize: Queen Vine customer review of free product I desperately needed new sheets. I had managed to accidentally rip a hole in my current fitted sheet while aggressively scrubbing at a stain, which seemed like a reasonably good indication that its two-year career had come to an end. Enter these lovely blue sheets. First impressions are very good. They’re extremely soft and have the silky, smooth feel you expect from bamboo-derived rayon. I also really like the colour. The light blue is pretty without being overly bright, and it gives the bed a fresh look. There are a couple of design details here that I particularly appreciate. The fitted sheet has a tag clearly marked for the head of the bed. This may sound ridiculous, but if you have ever stood there turning and flipping a fitted sheet several times trying to figure out which way it goes, you hear me. Anything that eliminates unnecessary fitted-sheet gymnastics is welcome. They’ve also added extra elastic straps at the corners to help keep the fitted sheet anchored to the mattress. It’s designed for mattresses up to 16 inches deep and has elastic around the entire edge as well. I’m hoping these features will keep it from working loose during the night, because a fitted sheet that slowly migrates off the mattress or folds under your butt is one of my particular pet peeves. The bamboo-derived rayon is lightweight and breathable, and this type of fabric is known for helping move moisture away from the skin. That’s part of the appeal for people who tend to sleep warm. The 300-thread-count weave also gives the sheets a nice balance between being lightweight and feeling substantial rather than paper-thin. There is one thing I’m reserving judgment on, though: durability. I’ve had inexpensive silky sheets before that felt wonderful when they were new and then developed pilling after only a handful of washes. Rayon made from bamboo is soft and comfortable, but that doesn’t automatically make it exceptionally durable. The fibres can be more vulnerable to friction and rough washing than some sturdier cotton fabrics, and pilling can occur when they break or work their way to the surface. These sheets specifically recommend washing separately on a gentle cycle and tumble drying on low, which I intend to follow. Hopefully, that will help preserve the fabric. I’m just not willing to declare them long-term winners until they’ve survived a reasonable number of trips through the laundry. After all, sheets need to be washed regularly. At $70 for the queen-size four-piece set, I think the price is reasonable. Comparable bamboo-derived rayon sheet sets in Canada generally fall in the $50–$80 range, while more established bamboo-sheet brands can easily cost over $100. So these aren’t dirt cheap, but they’re also not unusually expensive for this type of fabric. For that price, you’re getting some nice features beyond simply a pretty set of sheets: the bamboo-derived fabric, 300-thread-count construction, deep 16-inch pocket, full elastic edge, extra corner straps, envelope-style pillowcases and the extremely useful head-of-bed tag. Please don’t pill. I’m begging you. If they stay this soft and smooth after a few months of regular use, I’ll be very impressed. Read more One person found this helpful Helpful Report | G3: CA | H3: =TRUE() -> TRUE | I3: =FALSE() -> FALSE | J3: comfort_softness; thermal_breathability; fit_sizing; durability_pilling; colour_fading; care_wrinkles; value; authenticity_material | K3: Case-insensitive keyword mentions; multi-label; no positive/negative classification; displayed helpfulness sample, not random.
A4: PDP_CA_bamboo | B4: B0H9QD7RD5 | C4: CA | D4: R6URC0AT3TOOK | E4: Canada on October 24, 2026 | F4: Sylvie V. 5 out of 5 stars Très doux Reviewed in Canada on October 24, 2026 Colour Name: Dark GreySize: Queen Verified Purchase Très bonne qualité pour le prix. Helpful Report Translate review to English | G4: CA | H4: =FALSE() -> FALSE | I4: =TRUE() -> TRUE | J4: value | K4: Case-insensitive keyword mentions; multi-label; no positive/negative classification; displayed helpfulness sample, not random.
A5: PDP_CA_bamboo | B5: B0H9QD7RD5 | C5: CA | D5: R2VTZ23634KZWD | E5: Canada on October 11, 2026 | F5: Maya 4 out of 5 stars Fitted sheets that deliver what they promise. Reviewed in Canada on October 11, 2026 Colour Name: Light GreySize: Queen Vine customer review of free product This add says these sheets are silky smooth, and they absolutely are. They feel so fresh and soft, have a beautiful silk feel to them, without being as silky as silk (if that makes sense). If you try them, you will absolutely understand what I am trying to say. Regardless, they are quite lovely to sleep in, and do keep one quite cool. They also cool down so fast, so if you like to constantly looking for a new colder spot with your feet, this will be great for you. When I first opened the pack, there were a lot of lose strings all over the sheets. Nothing that made any seems come undone, but I was worried for a minute. The stitching overall also felt a bit less-than, but in the end they have held up very well so far. I love the extra stretch bands on the corners, and am so happy it has a side-marker, letting me know what way is up and down. Of course I am a rebel though, and always but the head end towards the bottom. I have washed it twice already now, and it does really well on a cold-gentle cycle and then on a low tumble dry. The material dries pretty quickly too, so even hanging them (if you have the room) is absolutely an option. The sizing for my queen bed is quite giving, and even my very thick pillows fit into them without any problems, and the fitted sheet still has plenty of room on the corners, even though I have quite a high pillow-top on my mattress. This means however that the corners of the sheet are a bit lower than the corners of my mattress. They get covered up with the other sheet and blankets anyways, but I understand how this might not please everyone. Overall, I still quite like these ones, and love the many colour options they have available. 100% Rayon, they truly help me stay cool at night, the colour is very close to the pictures in the add, they wash well, and at a current price-point of just under $70, they seem quite average for this material and size. Read more Helpful Report | G5: CA | H5: =TRUE() -> TRUE | I5: =FALSE() -> FALSE | J5: comfort_softness; thermal_breathability; fit_sizing; colour_fading; care_wrinkles; value; authenticity_material | K5: Case-insensitive keyword mentions; multi-label; no positive/negative classification; displayed helpfulness sample, not random.
A6: PDP_CA_bamboo | B6: B0H9QD7RD5 | C6: CA | D6: R24MPMD6GE3V1D | E6: Canada on October 16, 2026 | F6: Amazon Customer 5 out of 5 stars Incredibly soft Reviewed in Canada on October 16, 2026 Colour Name: WhiteSize: Queen Vine customer review of free product These are easily the softest sheets and pillowcases I've used. They're comfortable, breathable, fit our queen bedding properly, and have a clean, simple appearance. Coles Notes: - The sheets arrive in a nicely presented package made from the same material as the bedding. Rather than being crammed into a disposable plastic bag, the set feels properly packaged, which makes a good first impression. - The colour and appearance match the listing photos accurately, so there were no surprises when I unpacked them. It is worth noting that they are fairly opaque so you may see darker pillows through them. - The overall manufacturing quality seems good. I didn't notice any problematic seams, loose threads, or other obvious defects. - The standout feature is the softness. These are genuinely the softest sheets and pillowcases I've used, and you can tell as soon as you touch the material. They're very comfortable to sleep on and under, and I wish I'd switched to this type of bedding sooner. - The fabric also feels breathable and comfortable during use. While I haven't done any specific temperature testing, I appreciate how pleasant they feel when sleeping. - Went through washer/dryer without any issues. - The set fits our queen-sized mattress and queen-sized pillows without any issues. The fitted sheet has enough stretch to get over the mattress fairly easily and stayed in place during use. - The pillowcases have a simple flap at the opening that tucks the end of the pillow inside. It's a small detail, but it gives the bed a neater appearance and keeps the pillow from sticking out. - At the time of ordering, the four-piece set was $64.99. Considering the quality, fit, and especially the softness, I think that's a fair price for a set of sheets I'm genuinely happy to use. Read more Helpful Report | G6: CA | H6: =TRUE() -> TRUE | I6: =FALSE() -> FALSE | J6: comfort_softness; thermal_breathability; fit_sizing; colour_fading; care_wrinkles; value; packaging | K6: Case-insensitive keyword mentions; multi-label; no positive/negative classification; displayed helpfulness sample, not random.
A7: PDP_CA_bamboo | B7: B0H9QD7RD5 | C7: CA | D7: R2K6HB1NFLH630 | E7: Canada on October 14, 2026 | F7: Amazon Customer 3 out of 5 stars No cooling provided Reviewed in Canada on October 14, 2026 Colour Name: BeigeSize: King Vine customer review of free product I was impressed with how smooth and silky these sheets were right out of the package. I usually prefer cotton sheets but was drawn to these rayon ones as they claimed to be cooling sheets for hot sleepers. I have been sleeping on them for over 2 weeks now and do not find them to be cooling at all. The fabric feels a bit scratchy now that they have been washed a few times. What I do like about them is the deep secure pockets and especially the corner straps. Those are an amazing addition and they work really well to keep the sheet in place on the bed. Rayon does wrinkle so you need to get them out of the washer and dryer quickly. Overall I would say they are “okay”, however, I am disappointed in the fact that they do not provide any coolness while sleeping, as advertised. One person found this helpful Helpful Report | G7: CA | H7: =TRUE() -> TRUE | I7: =FALSE() -> FALSE | J7: thermal_breathability; fit_sizing; care_wrinkles; authenticity_material; packaging | K7: Case-insensitive keyword mentions; multi-label; no positive/negative classification; displayed helpfulness sample, not random.
