Workbook

Sheet Overall analysis
A1: Satin Sheets 4 Piece (US): exact decisions on the 29 Sep audit, run 20260929-6050bf68
A2: Every figure carries its date range; figures are compared only on identical days. Sources: Data sources tab.
A4: Key findings
A5: Satin is a maintenance product with a thin margin: profit after ads is 4.1% (Sellerboard 30 Aug–29 Sep) and Queen loses money after ads (−$540). Queen Black spends $267–310 a day on ads against about $102–127 that would break even.
A6: The run does nothing for rank and cuts or re-colours the campaigns that own the terms we can win. Push a small set where we convert and click at or above market: the King and Full head terms (scores 71–83).
A7: The Queen head terms score Low: our like-for-like conversion is about half the market (satin sheets queen size 3.36% vs 6.83%, search-query data 30 Aug–26 Sep) and rivals at #1–2 sell at $17.99–19.99 against our $29.95. Fix the offer before buying rank.
A8: Deal days are nearly margin-free: break-even ACoS at the Lightning Deal price is 7.5% on Queen Black and 4.8% on King Grey. The last deal lifted rank through the badge, not the ads. Hold prices on deal days.
A9: Break-even is 23.3% on the audit window (Sellerboard), not the engine's 28.5%; at full price about 25%. The audit window includes 6 deal days.
A10: 103 campaigns held as "not serving" spent $4,634 (CC 31 Aug–29 Sep), mostly Queen Black at 39–87% ACoS. Releasing and pricing them to break-even is the largest saving.
A11: Full Black runs out about 4 Dec with no purchase order; Queen Red about 10 Oct and Queen Dark Green about 2 Oct.
A13: Where the product stands
A14: Metric | B14: Window | C14: Value | D14: Engine | E14: Source
A15: Break-even ACoS (all-in) | B15: 30 Aug–29 Sep | C15: 0.2326 | D15: 0.2847 | E15: Sellerboard; engine margin block
A16: Profit per unit before ads | B16: 30 Aug–29 Sep | C16: 7.02 | D16: 8.56 | E16: Sellerboard
A17: Profit after ads, all sizes | B17: 30 Aug–29 Sep | C17: 4700 | E17: Sellerboard
A18: Profit after ads, Queen | B18: 30 Aug–29 Sep | C18: -540 | E18: Sellerboard
A19: Ad spend per day | B19: 15–28 Sep | C19: 586.93 | D19: 630.38 | E19: Command Center campaign view
A20: TACoS | B20: 15–27 Sep | C20: 0.1664 | D20: 0.1749 | E20: Command Center product view
A21: Queen Black units per day | B21: 30 Aug–29 Sep | C21: 20.3 | E21: Sellerboard
A22: Queen Black available | B22: 29 Sep | C22: 1807 | E22: Sellerboard
A23: Full Black available | B23: 29 Sep | C23: 722 | E23: Sellerboard
A24: King (all colours) available | B24: 29 Sep | C24: 4186 | D24: 47 | E24: Sellerboard; engine size map
A26: Decisions by type (every campaign)
A27: Decision type | B27: Campaigns | C27: 30d spend $ (CC 31 Aug–29 Sep) | D27: Share of spend
A28: Retag only | B28: =COUNTIF('Every campaign'!$AH$2:$AH$565,A28) -> 121 | C28: =SUMIF('Every campaign'!$AH$2:$AH$565,A28,'Every campaign'!$AA$2:$AA$565) -> 571.79 | D28: =IF($C$50=0,0,C28/$C$50) -> 0.029728039
A29: Pause | B29: =COUNTIF('Every campaign'!$AH$2:$AH$565,A29) -> 78 | C29: =SUMIF('Every campaign'!$AH$2:$AH$565,A29,'Every campaign'!$AA$2:$AA$565) -> 763.51 | D29: =IF($C$50=0,0,C29/$C$50) -> 0.039695789
A30: Rename only | B30: =COUNTIF('Every campaign'!$AH$2:$AH$565,A30) -> 53 | C30: =SUMIF('Every campaign'!$AH$2:$AH$565,A30,'Every campaign'!$AA$2:$AA$565) -> 696.63 | D30: =IF($C$50=0,0,C30/$C$50) -> 0.036218619
A31: Release hold + price to break-even | B31: =COUNTIF('Every campaign'!$AH$2:$AH$565,A31) -> 52 | C31: =SUMIF('Every campaign'!$AH$2:$AH$565,A31,'Every campaign'!$AA$2:$AA$565) -> 3389.56 | D31: =IF($C$50=0,0,C31/$C$50) -> 0.17622724
A32: No change | B32: =COUNTIF('Every campaign'!$AH$2:$AH$565,A32) -> 48 | C32: =SUMIF('Every campaign'!$AH$2:$AH$565,A32,'Every campaign'!$AA$2:$AA$565) -> 1139.36 | D32: =IF($C$50=0,0,C32/$C$50) -> 0.059236676
A33: No change (engine move rejected/held) | B33: =COUNTIF('Every campaign'!$AH$2:$AH$565,A33) -> 45 | C33: =SUMIF('Every campaign'!$AH$2:$AH$565,A33,'Every campaign'!$AA$2:$AA$565) -> 111.36 | D33: =IF($C$50=0,0,C33/$C$50) -> 0.0057897383
A34: Release hold, keep price | B34: =COUNTIF('Every campaign'!$AH$2:$AH$565,A34) -> 37 | C34: =SUMIF('Every campaign'!$AH$2:$AH$565,A34,'Every campaign'!$AA$2:$AA$565) -> 103.55 | D34: =IF($C$50=0,0,C34/$C$50) -> 0.0053836871
A35: Price cut | B35: =COUNTIF('Every campaign'!$AH$2:$AH$565,A35) -> 34 | C35: =SUMIF('Every campaign'!$AH$2:$AH$565,A35,'Every campaign'!$AA$2:$AA$565) -> 4327.76 | D35: =IF($C$50=0,0,C35/$C$50) -> 0.22500537
A36: Keep paused | B36: =COUNTIF('Every campaign'!$AH$2:$AH$565,A36) -> 27 | C36: =SUMIF('Every campaign'!$AH$2:$AH$565,A36,'Every campaign'!$AA$2:$AA$565) -> 52.97 | D36: =IF($C$50=0,0,C36/$C$50) -> 0.002753973
A37: Child swap | B37: =COUNTIF('Every campaign'!$AH$2:$AH$565,A37) -> 18 | C37: =SUMIF('Every campaign'!$AH$2:$AH$565,A37,'Every campaign'!$AA$2:$AA$565) -> 427.75 | D37: =IF($C$50=0,0,C37/$C$50) -> 0.022239229
A38: Reject pause | B38: =COUNTIF('Every campaign'!$AH$2:$AH$565,A38) -> 10 | C38: =SUMIF('Every campaign'!$AH$2:$AH$565,A38,'Every campaign'!$AA$2:$AA$565) -> 65.74 | D38: =IF($C$50=0,0,C38/$C$50) -> 0.0034179005
A39: Ranking push | B39: =COUNTIF('Every campaign'!$AH$2:$AH$565,A39) -> 9 | C39: =SUMIF('Every campaign'!$AH$2:$AH$565,A39,'Every campaign'!$AA$2:$AA$565) -> 2506.83 | D39: =IF($C$50=0,0,C39/$C$50) -> 0.13033306
... A49: Ranking push (your decision) | B49: =COUNTIF('Every campaign'!$AH$2:$AH$565,A49) -> 1 | C49: =SUMIF('Every campaign'!$AH$2:$AH$565,A49,'Every campaign'!$AA$2:$AA$565) -> 1514.72 | D49: =IF($C$50=0,0,C49/$C$50) -> 0.078752087
A50: Total | B50: =SUM(B28:B49) -> 564 | C50: =SUM(C28:C49) -> 19234.03
A52: Ranking push (Ranking push tab)
A53: Set | B53: Terms | C53: TOS clicks/day now | D53: TOS clicks/day planned | E53: Budget/day $ | F53: Loss/day, full price $ | G53: Loss/day, deal days $
...

Sheet Every campaign
A1: Campaign ID | B1: Campaign name | C1: Keywords / targets | D1: Keyword acted on | E1: Status now | F1: Objective now | G1: Correct objective | H1: Syntax | I1: Match / targeting | J1: Advertised child now | K1: Advertised child after | L1: Base bid now | M1: Base bid after | N1: TOS % now | O1: TOS % after | P1: TOS price now | Q1: TOS price after | R1: PP % now | S1: PP % after | T1: ROS % now | U1: ROS % after | V1: Budget now | W1: Budget after | X1: State after | Y1: Negatives | Z1: Rename | AA1: 30d spend $ | AB1: 30d clicks | AC1: 30d orders | AD1: 30d ACoS % | AE1: 30d TOS click share % | AF1: 30d PP click share % | AG1: 90d orders | AH1: Decision type | AI1: Decision | AJ1: Why | AK1: Source | AL1: Ranking push
A2: 504037860004352 | B2: D-S4-SP-satin sheets queen-(Satin)-HSV-Exact-Rank-DO-SATIN-WHITE-QUEEN-V2 | C2: satin sheets queen size [exact, $2.12, 443 clicks]; satin sheets queen [exact, $2.15, 101 clicks]; satin sheet queen [exact, paused, $3.00] | D2: satin sheets queen / satin sheets queen size | E2: ENABLED | F2: Ranking | G2: Ranking | H2: Satin|Queen | I2: Exact | J2: SATIN-QUEEN-BLACK | K2: SATIN-QUEEN-BLACK | L2: $2.12 / $2.15 | M2: $1.59 / $1.61 | N2: 80 | O2: 104 | P2: 3.82 | Q2: 3.24 | R2: 0 | S2: 0 | T2: 0 | U2: 0 | V2: 120 | W2: 120 | X2: ENABLED | Y2: none | Z2: defer — engine name wrong (SKU token SATIN-QUEEN-BLACK); load a corrected name after 28 Oct | AA2: 1522.55 | AB2: 544 | AC2: 104 | AD2: 46.7 | AE2: 40.07 | AF2: 56.62 | AG2: 202 | AH2: Price cut | AI2: MAINTAIN: cut base 25% ($2.12 → $1.59, $2.15 → $1.61); TOS +80% → +104% (TOS $3.82 → $3.24); re-score on the 1 Oct and 6 Oct deal days before any Queen push | AJ2: 46.7% ACoS on 104 orders / 544 clicks (CC 31 Aug–29 Sep). The class step undoes the mix fix: Today TOS $2.12×1.80 = $3.82. Written $1.83×1.77 = $3.24. TOS:PP ratio goes 1.80 → 1.77 on a campaign at 57% PP / 40% TOS (audit read, 308 of 544 clicks). | AK2: seq 1 tos: correct to 104%; seq 4 bid: correct to 1.59; seq 5 bid: correct to 1.61; seq 1798 child: reject — keep SATIN-QUEEN-BLACK; seq 2867 rename CHANGE; seq 0 budget hold $120 → pass | AL2: MAINTAIN · score 49 and 42 · CVR half the market like-for-like; re-score on the 1 Oct and 6 Oct deal days; push 16–28 Oct only if deal-day TOS CVR reaches market
A3: 527361393975073 | B3: D-S4-SP-satin sheets-(Satin)-HSV-Exact-Rank-DO-SATIN-QUEEN-GREY | C3: satin sheets [exact, $1.15, 739 clicks] | D3: satin sheets | E3: ENABLED | F3: Ranking | G3: Ranking | H3: Satin | I3: Exact | J3: SATIN-QUEEN-BLACK | K3: SATIN-QUEEN-BLACK | L3: $1.15 | M3: $1.15 | N3: 100 | O3: 100 | P3: 2.3 | Q3: 2.3 | R3: 0 | S3: 0 | T3: 0 | U3: 0 | V3: 70 | W3: 70 | X3: ENABLED | Y3: none | Z3: load (clean): DSS4-SP-Satin Sheets-[Satin]-(HSV)-Exact-(Ranking)-DO-SATIN-QUEEN-BLACK | AA3: 1514.72 | AB3: 739 | AC3: 127 | AD3: 39 | AE3: 88.36 | AF3: 7.85 | AG3: 366 | AH3: Ranking push (your decision) | AI3: HOLD satin sheets (#5) at today's price: base $1.15, TOS $2.30 (+100%), budget $70 through 28 Oct; no class cut. Full-plan option: TOS $2.32 and budget $145, then +20% steps to $2.48 if under 70% of 60 TOS clicks/day arrive | AJ3: 39.0% ACoS on 127 orders / 739 clicks (CC 31 Aug–29 Sep). Head term "satin sheets" at #5 (our crawl 29 Sep), SV 30,210, three deals ahead (1, 6 and 16–28 Oct). | AK3: seq 2868 rename LOAD; seq 8 hold → hold through 28 Oct; re-issue −15% on 29 Oct; seq 11 hold → hold through 28 Oct; re-issue −15% on 29 Oct | AL3: PUSH-SMALL in the full plan only · score 51 · 60 TOS clicks/day (now 21) · TOS $2.32–2.48 · $142/day · loss $7.30/order full price, $12.15 deal
A4: 512077609025515 | B4: DECOLURE - SATIN 4 - LTSF Campaign | C4: Auto: close-match; loose-match; substitutes | D4: whole campaign | E4: ENABLED | F4: Liquidation | G4: Liquidation | I4: Auto | J4: SATIN-FULL-PURPLE | K4: SATIN-FULL-PURPLE | L4: n/a (no target bid in audit) | M4: n/a | N4: 0 | O4: 0 | V4: 50 | W4: 50 | X4: ENABLED | Y4: add 13 negatives (seq 2266) · add negative exact: satin sheets full; silk sheets twin; king satin sheets; silk bed sheets queen; silk bed sheets; satin sheets queen; queen satin sheet set; king size satin sheets | Z4: none | AA4: 787.5 | AB4: 1438 | AC4: 86 | AD4: 29.2 | AE4: 3.27 | AF4: 27.68 | AG4: 220 | AH4: Negatives only | AI4: Add negatives | AJ4: Negative rows agreed with review 40 (add 13 negatives (seq 2266)); 29.2% ACoS on 86 orders / 1438 clicks (CC 31 Aug–29 Sep). | AK4: seq 2266 negatives: agree with review 40
A5: 414850094869263 | B5: D-S4-SP-Auto-Agr-Auto-Disc-DO-SATIN-QUEEN-BLACK | C5: complements [auto, $0.70]; substitutes [auto, $0.79] | D5: all enabled targets: complements; substitutes | E5: ENABLED | F5: Discovery | G5: Discovery | I5: Auto | J5: SATIN-QUEEN-BLACK | K5: SATIN-QUEEN-BLACK | L5: $0.70 / $0.79 | M5: $0.52 / $0.59 | N5: 0 | O5: 0 | P5: 0.7 | Q5: 0.52 | V5: 40 | W5: 40 | X5: ENABLED | Y5: hold seq 1788 (terms not named); add 9 negatives (seq 2269) · add negative exact: satin sheets full; silk bed sheets; silk bed sheets full · negative product target B0839MKJMV | Z5: load (clean): DSS4-SP-Auto-(AUTO)-Auto-(Discovery)-DO-SATIN-QUEEN-BLACK | AA5: 687.93 | AB5: 801 | AC5: 53 | AD5: 43.3 | AE5: 4.74 | AF5: 15.48 | AG5: 214 | AH5: Release hold + price to break-even | AI5: Release hold; cut base $0.70 / $0.79 → $0.52 / $0.59 | AJ5: 43.3% ACoS, 53 orders on 801 clicks (CC 31 Aug–29 Sep) vs Queen Black break-even 17.8%; BE base = $5.03 contribution (Queen Black) × 6.6% CVR = $0.33; cap 25% cut. | AK5: seq 1788 negatives: flag: unverifiable; seq 2269 negatives: agree with review 40; seq 2871 rename LOAD; seq 1719,1720 NOT SERVING hold(s) → release; price to break-even (our addition, reviewer D)
A6: 379276084224195 | B6: Decolure_SP_Exact_PAT_Defensive | C6: Product targets: B0839KG4VY; B0839L4HWH; B0839L5PDJ +530 more targets | D6: — | E6: ENABLED | F6: Defensive | G6: Defensive | I6: ASIN | J6: SATIN-QUEEN-BLACK | K6: SATIN-QUEEN-BLACK | L6: n/a (no target bid in audit) | M6: n/a | N6: 0 | O6: 0 | V6: 48.46 | W6: 48.46 | X6: ENABLED | Y6: none | Z6: none | AA6: 674.61 | AB6: 843 | AC6: 99 | AD6: 20.6 | AE6: 2.49 | AF6: 84.46 | AG6: 403 | AH6: No change | AI6: No change | AJ6: No run decision and no issue found; 20.6% ACoS on 99 orders / 843 clicks (CC 31 Aug–29 Sep). | AK6: no run decision
A7: 265771609218691 | B7: D-S4-king silk sheet set - [Silk|King] - Exact - Ran - DO - SATIN-4PC-KING-GREY | C7: king silk sheet set [exact, $2.75, 170 clicks] | D7: king silk sheet set (buys the search term: king size silk sheets set) | E7: ENABLED | F7: Ranking | G7: Ranking | H7: OUT | I7: Exact | J7: SATIN-4PC-KING-GREY | K7: SATIN-4PC-KING-GREY | L7: $2.75 | M7: $2.07 | N7: 100 | O7: 100 | P7: 5.5 | Q7: 4.14 | R7: 0 | S7: 0 | T7: 30 | U7: 0 | V7: 30 | W7: 30 | X7: ENABLED | Y7: none | Z7: load (clean): DSS4-SP-King Silk Sheet Set-[Silk|King]-(LSV)-Exact-(Ranking)-DO-SATIN-4PC-KING-GREY | AA7: 614.8 | AB7: 170 | AC7: 32 | AD7: 58.4 | AE7: 89.41 | AF7: 0 | AG7: 71 | AH7: Ranking push | AI7: PUSH-SMALL king size silk sheets set (10 → 3): cut base 25% ($2.75 → $2.07), TOS $5.50 → $4.14 (the market bound is $4.06); ROS 30% → 0%; budget $30 | AJ7: 58.4% ACoS (CC 31 Aug–29 Sep, 32 orders / 170 clicks) on King Grey, break-even ≈15%. | AK7: seq 15 ros: agree with review 40; seq 2869 rename LOAD; seq 16 bid hold → load (correct: load it) | AL7: PUSH-SMALL · score 64 · 3.7 TOS clicks/day · TOS ≈$4.06–4.14 · $15/day · loss $14.10/order full price, $19.12 deal
A8: 96870561028328 | B8: D-S4-king size silk sheets - [Silk|King] - Exact - Ran - DO - SATIN-4PC-KING-GREY | C8: king size silk sheets [exact, $2.30, 161 clicks] | D8: king size silk sheets | E8: ENABLED | F8: Ranking | G8: Ranking | H8: OUT | I8: Exact | J8: SATIN-4PC-KING-GREY | K8: SATIN-4PC-KING-GREY | L8: $2.30 | M8: $1.73 | N8: 100 | O8: 100 | P8: 4.6 | Q8: 3.46 | R8: 0 | S8: 0 | T8: 0 | U8: 0 | V8: 23.28 | W8: 14.67 | X8: ENABLED | Y8: none | Z8: load (clean): DSS4-SP-King Size Silk Sheets-[Silk|King]-(LSV)-Exact-(Ranking)-DO-SATIN-4PC-KING-GREY | AA8: 545.81 | AB8: 161 | AC8: 23 | AD8: 71.2 | AE8: 76.4 | AF8: 13.66 | AG8: 46 | AH8: Price cut | AI8: Cut base 25% ($2.30 → $1.73); Budget $23.28 → $14.67 | AJ8: 71.2% ACoS (CC 30d). The cut fails only because of an engine defect. | AK8: seq 17 budget: agree with review 40; seq 18 tos: correct: drop the no-move row 18, load 21; seq 21 bid: pass: load alone; seq 2872 rename LOAD
A9: 103662305423437 | B9: D-S4-SP-satin sheets queen-(Satin)-HSV-Broad-Disc-DO-SATIN-QUEEN-GREY | C9: satin sheets queen [broad, $1.30]; satin sheets queen [broad, $1.36] | D9: satin sheets queen | E9: ENABLED | F9: Discovery | G9: Discovery | I9: Broad | J9: SATIN-QUEEN-BLACK | K9: SATIN-QUEEN-BLACK | L9: $1.30 | M9: $0.98 | N9: 25 | O9: 25 | P9: 1.62 | Q9: 1.23 | V9: 20 | W9: 20 | X9: ENABLED | Y9: add 5 negatives (seq 2259) · add negative exact: black satin sheets; silk bed sheets; king size satin sheets; queen satin sheet set; silk queen bed sheets set; satin bed sheets full; silk sheets full size | Z9: none | AA9: 505.75 | AB9: 331 | AC9: 48 | AD9: 33.8 | AE9: 47.43 | AF9: 16.62 | AG9: 214 | AH9: Release hold + price to break-even | AI9: Release hold; cut base $1.30 → $0.98; Keep enabled (fold held) | AJ9: 33.8% ACoS on 48 orders / 331 clicks (CC 31 Aug–29 Sep). The survivors are smaller (e.g. 2849: 215 orders folded into a 14-order survivor, 90d). 2857 repeats review 28's 2868. | AK9: seq 2259 negatives: agree with review 40; seq 2849 structure: hold (agree); seq 1717,1971 NOT SERVING hold(s) → release; price to break-even (our addition, reviewer D)
A10: 82540637405662 | B10: D-S4-satin sheets full size - [Satin|Full] - Exact - Ran - DO - SATIN-FULL-BLACK | C10: satin sheets full size [exact, $1.13, 138 clicks] | D10: satin sheets full size (buys the search term: satin sheets full) | E10: ENABLED | F10: Ranking | G10: Ranking | H10: OUT | I10: Exact | J10: SATIN-FULL-BLACK | K10: SATIN-FULL-BLACK | L10: $1.13 | M10: $1.13 | N10: 230 | O10: 230 | P10: 3.73 | Q10: 3.73 | R10: 0 | S10: 0 | T10: 0 | U10: 0 | V10: 30 | W10: 30 | X10: ENABLED | Y10: none | Z10: defer — engine name wrong (SKU token SATIN-FULL-BLACK); load a corrected name after 28 Oct | AA10: 445.56 | AB10: 138 | AC10: 45 | AD10: 33.2 | AE10: 99.28 | AF10: 0.72 | AG10: 65 | AH10: Ranking push | AI10: PUSH satin sheets full (4 → 3): hold base $1.13 and TOS $3.73 (+230%, at the market bound); budget $30; target 8.0 TOS clicks/day (now 3.9) | AJ10: Engine swap SATIN-FULL-BLACK → SATIN-4PCS-FULL-ROSEWOOD rejected: the pick comes from the broken size map, and SATIN-FULL-BLACK is the size's best seller with cover (SB 30 Aug–29 Sep); the engine rename writes a wrong token and is deferred; 33.2% ACoS on 45 orders / 138 clicks (CC 31 Aug–29 Sep). | AK10: seq 1800 child: reject — keep SATIN-FULL-BLACK; seq 2873 rename CHANGE | AL10: PUSH · score 82 · 8.0 TOS clicks/day (now 3.9) · TOS $3.73 (market bound $3.69) · $30/day · 1.9 orders/day · loss $7.19/order full price, $11.66 deal
A11: 274586208953923 | B11: D-S4-king satin sheets - [Satin|King] - Exact - Ran - DO - SATIN-4PC-KING-GREY | C11: king satin sheets [exact] | D11: king satin sheets | E11: ENABLED | F11: Ranking | G11: Ranking | H11: Satin|King | I11: Exact | J11: SATIN-4PC-KING-GREY | K11: SATIN-4PC-KING-GREY | L11: $2.00 | M11: $1.50 | N11: 44 | O11: 73 | P11: 2.88 | Q11: 2.59 | U11: 0 | V11: 20.42 | W11: 20.42 | X11: ENABLED | Y11: none | Z11: load (clean): DSS4-SP-King Satin Sheets-[Satin|King]-(LSV)-Exact-(Ranking)-DO-SATIN-4PC-KING-GREY | AA11: 395.83 | AB11: 169 | AC11: 25 | AD11: 48.7 | AE11: 55.62 | AF11: 37.28 | AG11: 58 | AH11: Mix fix + price cut | AI11: Mix fix in one write: base $2.00 → $1.50, boost → 73% (top of search $2.88 → $2.59); 48.7% ACoS vs King Grey 18.9% break-even at full price; product pages 37% of clicks | AJ11: Clean rename (SKU token and objective match what the campaign advertises); 48.7% ACoS on 25 orders / 169 clicks (CC 31 Aug–29 Sep). Note: above break-even with no pricing row in the run; price at the next cycle unless it is chosen for the ranking push. | AK11: seq 2071 retag LOAD; seq 2876 rename LOAD
A12: 33389871513217 | B12: D-S4-satin sheets king - [Satin|King] - Exact - Ran - DO - SATIN-4PC-KING-GREY | C12: satin sheets king [exact, $1.27, 153 clicks] | D12: satin sheets king | E12: ENABLED | F12: Ranking | G12: Ranking | H12: Satin|King | I12: Exact | J12: SATIN-4PC-KING-GREY | K12: SATIN-4PC-KING-GREY | L12: $1.27 | M12: $1.27 | N12: 120 | O12: 120 | P12: 2.79 | Q12: 2.79 | R12: 0 | S12: 0 | T12: 0 | U12: 0 | V12: 15 | W12: 20 | X12: ENABLED | Y12: add negative exact: satin sheets king size | Z12: load (clean): DSS4-SP-Satin Sheets King-[Satin|King]-(MSV)-Exact-(Ranking)-DO-SATIN-4PC-KING-GREY | AA12: 359.53 | AB12: 153 | AC12: 36 | AD12: 28.3 | AE12: 84.21 | AF12: 15.13 | AG12: 51 | AH12: Ranking push | AI12: PUSH satin sheets king (4 → 3): reject the 10% base cut; hold base $1.27 and TOS $2.79 (+120%); budget $15 → $20; tune daily to 5.3 TOS clicks/day | AJ12: 28.3% ACoS on 36 orders / 153 clicks (CC 31 Aug–29 Sep) vs King Grey break-even 15.3%; audit row loads as written (review 40 agrees). | AK12: seq 31 bid: pass (flag); seq 2879 rename LOAD | AL12: PUSH · score 83 · 5.3 TOS clicks/day (now 5.3) · TOS $2.79 · $16/day · 1.2 orders/day · loss $6.29/order full price, $11.31 deal
A13: 137973631643313 | B13: D-S4-SP-EXACT-silk sheets full size-Silk|Full-SATIN-FULL-BLACK | C13: silk sheets full size [exact] | D13: silk sheets full size (buys the search term: silk sheets full) | E13: ENABLED | F13: Ranking | G13: Ranking | I13: Exact | J13: SATIN-FULL-BLACK | K13: SATIN-FULL-BLACK | L13: n/a (no target bid in audit) | M13: n/a | N13: 50 | O13: 52 | Q13: 2.6 | V13: 12 | W13: 15 | X13: ENABLED | Y13: hold seq 2775 (held) | Z13: none | AA13: 348.4 | AB13: 146 | AC13: 37 | AD13: 31.8 | AE13: 80.82 | AF13: 8.9 | AG13: 42 | AH13: Ranking push | AI13: PUSH silk sheets full (5 → 3): TOS +50% → +52% (TOS $2.56 → $2.60); budget $12 → $15 (budget-capped now) | AJ13: 31.8% ACoS on 37 orders / 146 clicks (CC 31 Aug–29 Sep). This pause and #2771 each name the other as the survivor, so "silk sheets full size" goes dark. Keep this campaign: 42 orders in 90d, $12.38/day. | AK13: seq 1440 state: hold; seq 2775 negatives: agree with review 40 | AL13: PUSH · score 80 · 3.3 TOS clicks/day (now 2.9) · TOS $2.60 · $10/day on the term · 0.8 orders/day · loss $2.17/order full price, $6.64 deal
A14: 34079573232348 | B14: D-S4-SP-BROAD-silk bedsheets-Silk-SATIN-QUEEN-GREY | C14: silk bedsheets [broad, $1.20]; silk bedsheets [broad, $1.20] | D14: whole campaign | E14: ENABLED | F14: Discovery | G14: Discovery | I14: Broad | J14: SATIN-QUEEN-GREY | K14: SATIN-QUEEN-GREY | L14: $1.20 | M14: $1.20 | N14: 0 | O14: 0 | P14: 1.2 | Q14: 1.2 | V14: 15 | W14: 15 | X14: PAUSED | Y14: hold seq 1789 (terms not named); add 3 negatives (seq 2257) | Z14: none | AA14: 310.92 | AB14: 239 | AC14: 25 | AD14: 39.1 | AE14: 2.94 | AF14: 30.67 | AG14: 28 | AH14: Pause | AI14: Pause (seq 2856) | AJ14: 39.1% ACoS on 25 orders / 239 clicks (CC 31 Aug–29 Sep). The survivor's budget is $5/day and it spent $46.20 in 14 days. It cannot absorb the loser's $205.07 in 14 days (audit spend_14d), so this is a pause of a 38.4%-ACoS broad (CC 7/2–9/29), not a merge. | AK14: seq 1789 negatives: flag: unverifiable; seq 2257 negatives: agree with review 40; seq 2856 structure: pass as a pause (flag); seq 1721 NOT SERVING hold(s) moot — campaign paused
A15: 108995710931187 | B15: D-S4-silk sheets twin - [Silk|Twin] - Exact - Ran - DO - SATIN-TWIN-BLACK-NEW | C15: silk sheets twin [exact, $1.10, 97 clicks] | D15: silk sheets twin | E15: ENABLED | F15: Ranking | G15: Ranking | H15: OUT | I15: Exact | J15: SATIN-TWIN-BLACK-NEW | K15: SATIN-TWIN-BLACK-NEW | L15: $1.10 | M15: $1.10 | N15: 220 | O15: 220 | P15: 3.52 | Q15: 3.52 | R15: 0 | S15: 0 | T15: 30 | U15: 0 | V15: 16 | W15: 16 | X15: ENABLED | Y15: none | Z15: defer — engine name wrong (SKU token SATIN-TWIN-BLACK-NEW); load a corrected name after 28 Oct | AA15: 292.64 | AB15: 97 | AC15: 13 | AD15: 81.2 | AE15: 98.97 | AF15: 1.03 | AG15: 20 | AH15: Hold (price) | AI15: HOLD: don't load the run's cuts (budget $16 → $8, TOS $3.52 → $2.65) while "silk sheets twin" is unranked and Twin Black may be losing its featured offer; close tuner record 2851 as superseded | AJ15: 81.2% ACoS on 13 orders / 97 clicks (CC 31 Aug–29 Sep) vs Twin Black break-even 31.4%; audit row loads as written (review 40 agrees). Note: plan move to SATIN-TWIN-GREY before 16 Oct (Twin Black 66 units, ~34 days). | AK15: seq 32 budget: pass (flag); seq 33 tos: pass (flag); seq 35 ros: pass the cuts; drop the rank claim; close the 27 Sep tuner r…; seq 36 bid: pass (flag); seq 1803 child: reject — keep SATIN-TWIN-BLACK-NEW; seq 2880 rename CHANGE | AL15: MAINTAIN · score 46 · Twin Black cover 33 days; unranked 29 Sep
A16: 428094781835473 | B16: DCS-SP-Auto/LTSF-Def-Multi LTSF SKUs | C16: Auto: close-match; complements; loose-match +1 more targets | D16: — | E16: ENABLED | F16: Liquidation | G16: Liquidation | I16: Auto | J16: SATIN-STRIPE-FULL-GOLD | K16: SATIN-STRIPE-FULL-GOLD | L16: n/a (no target bid in audit) | M16: n/a | N16: 0 | O16: 0 | V16: 20 | W16: 20 | X16: ENABLED | Y16: add negative exact in the satin-sheet ad group only: chair covers; chair covers for dining chairs | Z16: none | AA16: 270.33 | AB16: 612 | AC16: 31 | AD16: 24.5 | AE16: 1.8 | AF16: 68.46 | AG16: 141 | AH16: No change | AI16: No change | AJ16: No run decision and no issue found; 24.5% ACoS on 31 orders / 612 clicks (CC 31 Aug–29 Sep). | AK16: no run decision
A17: 40865602759529 | B17: D-S4-silk sheets queen size - [Silk|Queen] - Exact - Ran - DO - SATIN-QUEEN-BLACK | C17: silk sheets queen size [exact] | D17: silk sheets queen size (buys the search term: silk sheets queen) | E17: ENABLED | F17: Ranking | G17: Ranking | H17: Silk|Queen | I17: Exact | J17: SATIN-QUEEN-BLACK | K17: SATIN-QUEEN-BLACK | L17: $1.41 | M17: $1.41 | N17: 30 | O17: 66 | P17: 1.83 | Q17: 2.34 | V17: 25 | W17: 40 | X17: ENABLED | Y17: none | Z17: defer — engine name wrong (SKU token SATIN-QUEEN-BLACK); load a corrected name after 28 Oct | AA17: 261.91 | AB17: 151 | AC17: 32 | AD17: 27.1 | AE17: 82.78 | AF17: 0 | AG17: 91 | AH17: Ranking push | AI17: OWNER of silk sheets queen (#10; was #6 before its clicks fell on 8 Sep): release the hold; keep base $1.41, boost 30% → 66% (TOS $1.83 → $2.34, what the duplicate already pays); budget $25 → $40 (takes the duplicate's $15); restore about 10 TOS clicks a day. Full-plan option: 20 a day | AJ17: 27.1% ACoS, 32 orders on 151 clicks (CC 31 Aug–29 Sep) vs Queen Black break-even 17.8%; BE base = $5.03 contribution (Queen Black) × 21.2% CVR = $1.07; cap 25% cut. | AK17: seq 1813 child: reject — keep SATIN-QUEEN-BLACK; seq 2076 retag LOAD; seq 2898 rename CHANGE; seq 1975 NOT SERVING hold(s) → release; price to break-even (our addition, reviewer D) | AL17: RESTORE · score 55 · ~10 TOS clicks/day (7.2 now; ~10 before 8 Sep) · TOS $2.34 · full plan: 20/day at $2.33, $47/day
A18: 234075729975572 | B18: D-S4-black silk sheets - [Silk] - Exact - Ran - DO - SATIN-QUEEN-BLACK | C18: black silk sheets [exact] | D18: black silk sheets | E18: ENABLED | F18: Ranking | G18: Conversions | H18: Silk | I18: Exact | J18: SATIN-QUEEN-BLACK | K18: SATIN-QUEEN-BLACK | L18: $1.42 | M18: $1.06 | N18: 35 | O18: 35 | P18: 1.92 | Q18: 1.43 | V18: 10 | W18: 10 | X18: ENABLED | Y18: none | Z18: defer — engine name wrong ((Conversion)); load a corrected name after 28 Oct | AA18: 261.61 | AB18: 155 | AC18: 19 | AD18: 40.4 | AE18: 57.79 | AF18: 33.77 | AG18: 45 | AH18: Release hold + price to break-even | AI18: Release hold; cut base $1.42 → $1.06; retag → Conversions | AJ18: 40.4% ACoS, 19 orders on 155 clicks (CC 31 Aug–29 Sep) vs Queen Black break-even 17.8%; BE base = $5.03 contribution (Queen Black) × 12.3% CVR = $0.62; cap 25% cut. | AK18: seq 2072 retag correct to Conversions; seq 2882 rename CHANGE; seq 1973 NOT SERVING hold(s) → release; price to break-even (our addition, reviewer D) | AL18: MAINTAIN · score 29
A19: 509115242799026 | B19: D-S4-SP-king satin sheet set-(Satin)-VLSV-Exact-Rank-DO-SATIN-KING-BLACK-V2 | C19: king size satin sheet set [exact, $2.60, 81 clicks]; king satin sheets set [exact, $2.35, 4 clicks]; king satin sheet set [exact, $1.43]; king size satin sheets set [exact, $1.65] | D19: whole campaign | E19: PAUSED | F19: Ranking | G19: Ranking | H19: Satin|King | I19: Exact | J19: SATIN-4PC-KING-GREY | K19: SATIN-KING-BLACK | L19: $2.60 / $2.35 / $1.43 / $1.65 | M19: $1.70 / $1.70 / $1.43 / $1.65 | N19: 50 | O19: 50 | P19: 3.9 | Q19: 2.55 | R19: 0 | S19: 0 | T19: 0 | U19: 0 | V19: 12 | W19: 12 | X19: ENABLED | Y19: none | Z19: load (clean): DSS4-SP-King Size Satin Sheet Set-[Satin|King]-(LSV)-Exact-(Ranking)-DO-SATIN-4PC-KING-GREY | AA19: 247.68 | AB19: 85 | AC19: 9 | AD19: 85.9 | AE19: 80 | AF19: 8.24 | AG19: 51 | AH19: Revive at break-even | AI19: Revive at break-even base ($1.70 max); Swap child to SATIN-KING-BLACK | AJ19: 85.9% ACoS on 9 orders / 85 clicks (CC 31 Aug–29 Sep). The review's "King on 10 shelf days" is wrong: King Grey has 1,057 units (210 days, SB 9/29). The real reason is margin. | AK19: seq 2827 structure: hold, reason corrected; seq 2891 rename LOAD
A20: 287639399820558 | B20: D-S4-SP-red satin sheet-(Satin)-LSV-Exact-Rank-DO-SATIN-RED-QUEEN | C20: red satin sheet [exact, $1.40, 157 clicks] | D20: whole campaign | E20: ENABLED | F20: Ranking | G20: Conversions | H20: Satin | I20: Exact | J20: SATIN-4PC-RED-QUEEN | K20: SATIN-4PCS-KING-RED | L20: $1.40 | M20: $1.32 | N20: 65 | O20: 65 | P20: 2.31 | Q20: 2.18 | R20: 0 | S20: 0 | T20: 0 | U20: 0 | V20: 13 | W20: 9.1 | X20: ENABLED | Y20: none | Z20: defer — engine name wrong (SKU token SATIN-4PC-RED-QUEEN; (Conversion)); load a corrected name after 28 Oct | AA20: 245.96 | AB20: 157 | AC20: 28 | AD20: 29.7 | AE20: 33.12 | AF20: 64.97 | AG20: 32 | AH20: Child swap | AI20: Swap child to SATIN-4PCS-KING-RED; Cut base 6% ($1.40 → $1.32); Budget $13 → $9.1; retag → Conversions | AJ20: 29.7% ACoS on 28 orders / 157 clicks (CC 31 Aug–29 Sep). Swap by hand now (seq 1804); Queen Red 34 units, out ~10 Oct (SB 29 Sep). | AK20: seq 45 budget: pass (flag); seq 49 bid: agree with review 40; seq 1804 child: pass — apply NOW (outside the held group); seq 2881 rename CHANGE; our addition: standard → Conversions (colour term "red satin sheet")
A21: 520117564893402 | B21: SATIN-QUEEN-GREY SP - Silk Sheets - Exact 091323 | C21: silk sheets [exact, $0.98, 118 clicks] | D21: silk sheets | E21: ENABLED | F21: Ranking | G21: Ranking | H21: OUT | I21: Exact | J21: SATIN-QUEEN-GREY | K21: SATIN-QUEEN-BLACK | L21: $0.98 | M21: $0.98 | N21: 130 | O21: 72 | P21: 2.25 | Q21: 1.69 | R21: 0 | S21: 0 | T21: 0 | U21: 0 | V21: 20 | W21: 20 | X21: ENABLED | Y21: none | Z21: load (clean): DSS4-SP-Silk Sheets-[Silk]-(VHSV)-Exact-(Ranking)-DO-SATIN-QUEEN-GREY | AA21: 245.75 | AB21: 118 | AC21: 21 | AD21: 33.8 | AE21: 91.53 | AF21: 5.93 | AG21: 28 | AH21: Price cut | AI21: MAINTAIN silk sheets (#28): swap the ad from Queen Grey to Queen Black (the Queen velocity leader); TOS +130% → +72% (TOS $2.25 → $1.69); 33.8% ACoS against Queen Grey 11.2% break-even | AJ21: Clean rename (SKU token and objective match what the campaign advertises); 33.8% ACoS on 21 orders / 118 clicks (CC 31 Aug–29 Sep). Note: above break-even with no pricing row in the run; price at the next cycle unless it is chosen for the ranking push. | AK21: seq 2877 rename LOAD | AL21: MAINTAIN · score 29 · wrong child (Queen Grey)
A22: 152213290901148 | B22: D-S4-TESTING-NEW-FEATURE | C22: keyword-group="Keywords related to your product category" [$0.69] | D22: keyword-group="Keywords related to your product category" | E22: ENABLED | F22: Conversions | G22: Discovery | I22: Theme | J22: SATIN-4PCS-FULL-ROSEWOOD | K22: SATIN-4PCS-FULL-ROSEWOOD | L22: $0.69 | M22: $0.52 | N22: 0 | O22: 0 | P22: 0.69 | Q22: 0.52 | V22: 10 | W22: 10 | X22: ENABLED | Y22: none | Z22: defer — engine name wrong ((Discovery)); load a corrected name after 28 Oct | AA22: 243.74 | AB22: 304 | AC22: 18 | AD22: 46.4 | AE22: 1.32 | AF22: 28.95 | AG22: 37 | AH22: Release hold + price to break-even | AI22: Release hold; cut base $0.69 → $0.52; retag → Discovery | AJ22: 46.4% ACoS, 18 orders on 304 clicks (CC 31 Aug–29 Sep) vs Full Rosewood break-even 15.0%; BE base = $4.50 contribution (Full Rosewood) × 5.9% CVR = $0.27; cap 25% cut. | AK22: seq 2073 retag correct to Discovery; seq 2883 rename CHANGE; seq 1725 NOT SERVING hold(s) → release; price to break-even (our addition, reviewer D)
A23: 323452708337783 | B23: D-S4-SP-Auto-Agr-Auto-Disc-DO-SATIN-WHITE-QUEEN | C23: close-match [auto, $0.84]; loose-match [auto, $0.70] | D23: all enabled targets: close-match; loose-match | E23: ENABLED | F23: Discovery | G23: Discovery | I23: Auto | J23: SATIN-QUEEN-BLACK | K23: SATIN-QUEEN-BLACK | L23: $0.84 / $0.70 | M23: $0.63 / $0.52 | N23: 0 | O23: 0 | P23: 0.84 | Q23: 0.63 | V23: 40 | W23: 40 | X23: ENABLED | Y23: hold seq 1791 (terms not named); add 9 negatives (seq 2264) · add negative exact: silk sheets queen; silk bed sheets · negative product target B0839MKJMV | Z23: defer — engine name wrong (SKU token SATIN-QUEEN-BLACK + suffix elsewhere); load a corrected name after 28 Oct | AA23: 242.28 | AB23: 296 | AC23: 19 | AD23: 43.8 | AE23: 14.19 | AF23: 5.07 | AG23: 106 | AH23: Release hold + price to break-even | AI23: Release hold; cut base $0.84 / $0.70 → $0.63 / $0.52 | AJ23: 43.8% ACoS, 19 orders on 296 clicks (CC 31 Aug–29 Sep) vs Queen Black break-even 17.8%; BE base = $5.03 contribution (Queen Black) × 6.4% CVR = $0.32; cap 25% cut. | AK23: seq 1791 negatives: flag: unverifiable; seq 2264 negatives: agree with review 40; seq 2896 rename CHANGE; seq 1730,1731 NOT SERVING hold(s) → release; price to break-even (our addition, reviewer D)
A24: 100830568607053 | B24: D-S4-SP-silk sheets queen-(Silk)-HSV-Exact-Rank-DO-SATIN-QUEEN-BLACK | C24: silk sheets queen [exact, $1.17, 104 clicks] | D24: silk sheets queen | E24: ENABLED | F24: Ranking | G24: Ranking | H24: OUT | I24: Exact | J24: SATIN-QUEEN-BLACK | K24: SATIN-QUEEN-BLACK | L24: $1.17 | M24: $1.17 | N24: 100 | O24: 100 | P24: 2.34 | Q24: 2.34 | R24: 0 | S24: 0 | T24: 0 | U24: 0 | V24: 15 | W24: 15 | X24: PAUSED | Y24: none | Z24: defer — engine name wrong (SKU token SATIN-QUEEN-BLACK); load a corrected name after 28 Oct | AA24: 234.7 | AB24: 104 | AC24: 32 | AD24: 24 | AE24: 95.19 | AF24: 4.81 | AG24: 73 | AH24: Pause (duplicate) | AI24: PAUSE: duplicate exact on silk sheets queen (same keyword, same Queen Black ad as 40865602759529, which keeps the term with 142 of its 245 clicks); its $15 budget moves to the owner | AJ24: No run decision and no issue found; 24.0% ACoS on 32 orders / 104 clicks (CC 31 Aug–29 Sep). Note: above break-even with no pricing row in the run; price at the next cycle unless it is chosen for the ranking push. | AK24: seq 1802 child: reject — keep SATIN-QUEEN-BLACK; seq 2878 rename CHANGE | AL24: Duplicate owner of silk sheets queen · paused into 40865602759529
A25: 34608790713465 | B25: D-S4-SP-EXACT-silk bedsheets-Silk-SATIN-QUEEN-BLACK | C25: silk bedsheets [exact] | D25: silk bedsheets (buys the search term: silk bed sheets) | E25: ENABLED | F25: Ranking | G25: Conversions | I25: Exact | J25: SATIN-QUEEN-BLACK | K25: SATIN-QUEEN-BLACK | L25: $1.78 | M25: $1.33 | N25: 0 | O25: 0 | P25: 1.78 | Q25: 1.33 | V25: 10 | W25: 10 | X25: ENABLED | Y25: none | Z25: defer — engine name wrong ((Conversion)); load a corrected name after 28 Oct | AA25: 234.04 | AB25: 130 | AC25: 9 | AD25: 86.6 | AE25: 56.15 | AF25: 23.85 | AG25: 16 | AH25: Price cut | AI25: Cut base $1.78 → $1.33 (break-even, 25% cap); retag → Conversions | AJ25: 86.6% ACoS, 9 orders on 130 clicks (CC 31 Aug–29 Sep) vs Queen Black break-even 17.8%; BE base = $5.03 contribution (Queen Black) × 6.9% CVR = $0.35; cap 25% cut. | AK25: seq 2074 retag correct to Conversions; seq 2884 rename CHANGE; seq 1453 state hold → correct: cut the bid | AL25: MAINTAIN · score 37
A26: 238180925389130 | B26: D-S4-SP-queen size silk sheets-(Silk)-MSV-Exact-Rank-DO-SATIN-QUEEN-BLACK | C26: queen satin sheets [exact, $1.99, 107 clicks]; queen bed sheet set silk satin [exact, $0.50]; queen comforter sets with sheets and pillows [exact, paused, $1.25]; queen fitted sheet deep pocket satin [exact, $0.50]; queen fitted sheet pillow case satin taupe [exact, $0.50]; queen size silk sheets [exact, $0.50] | D26: queen satin sheets | E26: ENABLED | F26: Ranking | G26: Ranking | H26: Satin|Queen | I26: Exact | J26: SATIN-QUEEN-BLACK | K26: SATIN-QUEEN-BLACK | L26: $1.99 | M26: $1.49 | N26: 30 | O26: 56 | P26: 2.59 | Q26: 2.33 | R26: 0 | S26: 0 | T26: 0 | U26: 0 | V26: 10 | W26: 10 | X26: ENABLED | Y26: none | Z26: defer — engine name wrong (SKU token SATIN-QUEEN-BLACK); load a corrected name after 28 Oct | AA26: 228.69 | AB26: 107 | AC26: 27 | AD26: 27 | AE26: 37.38 | AF26: 57.94 | AG26: 48 | AH26: Mix fix + price cut | AI26: Mix fix in one write: base $1.99 → $1.49, boost → 56% (top of search $2.59 → $2.33); target "queen satin sheets"; 27.0% ACoS vs Queen Black 22.5%; product pages 58% | AJ26: No run decision and no issue found; 27.0% ACoS on 27 orders / 107 clicks (CC 31 Aug–29 Sep). Note: above break-even with no pricing row in the run; price at the next cycle unless it is chosen for the ranking push. | AK26: seq 1808 child: reject — keep SATIN-QUEEN-BLACK; seq 2888 rename CHANGE
A27: 244008066214488 | B27: D-S4-satin bed sheets full - [Satin|Full] - Exact - Ran - DO - SATIN-FULL-BLACK | C27: satin bed sheets full [exact, $1.14, 63 clicks] | D27: satin bed sheets full | E27: ENABLED | F27: Ranking | G27: Ranking | H27: OUT | I27: Exact | J27: SATIN-FULL-BLACK | K27: SATIN-FULL-BLACK | L27: $1.14 | M27: $0.93 | N27: 300 | O27: 300 | P27: 4.56 | Q27: 3.72 | R27: 0 | S27: 0 | T27: 0 | U27: 0 | V27: 9.53 | W27: 9.53 | X27: ENABLED | Y27: none | Z27: defer — engine name wrong (SKU token SATIN-FULL-BLACK); load a corrected name after 28 Oct | AA27: 198.58 | AB27: 63 | AC27: 11 | AD27: 60.6 | AE27: 95.24 | AF27: 1.59 | AG27: 16 | AH27: Price cut | AI27: Cut base 18% ($1.14 → $0.93) | AJ27: 60.6% ACoS on 11 orders / 63 clicks (CC 31 Aug–29 Sep). PROTECT −10% leaves TOS at $4.12, still above the engine's market bound of $3.74. The row is at 2.17× BE with 11 orders. $0.93 × 4.00 = $3.72, a −18% cut, inside the cap. | AK27: seq 74 bid: correct to 0.93; seq 1806 child: reject — keep SATIN-FULL-BLACK; seq 2886 rename CHANGE; seq 71 TOS hold → correct: cut (delivered by the base cut, TOS % kept)
A28: 224280280721130 | B28: D-S4-silk twin bed sheets - [Silk|Twin] - Exact - Ran - DO - SATIN-TWIN-BLACK-NEW | C28: silk twin bed sheets [exact, $1.29, 58 clicks] | D28: silk twin bed sheets | E28: PAUSED | F28: Ranking | G28: Ranking | H28: OUT | I28: Exact | J28: SATIN-TWIN-BLACK-NEW | K28: SATIN-TWIN-BLACK-NEW | L28: $1.29 | M28: $1.29 | N28: 300 | O28: 300 | P28: 5.16 | Q28: 5.16 | R28: 0 | S28: 0 | T28: 0 | U28: 0 | V28: 15 | W28: 15 | X28: ENABLED | Y28: none | Z28: load (clean): DSS4-SP-Silk Twin Bed Sheets-[Silk|Twin]-(LSV)-Exact-(Ranking)-DO-SATIN-TWIN-BLACK-NEW | AA28: 196.59 | AB28: 58 | AC28: 9 | AD28: 78.5 | AE28: 100 | AF28: 0 | AG28: 25 | AH28: Restart | AI28: RESTART after the Twin Black listing check: the silk twin bed sheets exact was paused outside the tuner (last served 22 Sep; rank 8 → 100 on 24 Sep). Keep base $1.29 and boost +300% | AJ28: 78.5% ACoS on 9 orders / 58 clicks (CC 31 Aug–29 Sep). Revive rejected: 30d ACoS 78.5%. The child is a 3-pc set with 66 units and 33 days of cover (SB, out ~1 Nov). | AK28: seq 2816 structure: hold; seq 2890 rename LOAD
A29: 152138103637187 | B29: D-S4-SP-satin sheets king-(Satin)-HSV-Phrase-Disc-DO-SATIN-4PC-KING-GREY | C29: satin sheets king [phrase, $1.90]; satin sheets king [phrase, $1.90] | D29: satin sheets king | E29: ENABLED | F29: Discovery | G29: Discovery | I29: Phrase | J29: SATIN-4PC-KING-GREY | K29: SATIN-4PC-KING-GREY | L29: $1.90 | M29: $1.42 | N29: 50 | O29: 50 | P29: 2.85 | Q29: 2.13 | V29: 15 | W29: 15 | X29: ENABLED | Y29: add negative exact: satin sheets king | Z29: load (clean): DSS4-SP-Satin Sheets King-[Satin|King]-(MSV)-Phrase-(Discovery)-DO-SATIN-4PC-KING-GREY | AA29: 189.86 | AB29: 79 | AC29: 12 | AD29: 44.5 | AE29: 74.68 | AF29: 10.13 | AG29: 21 | AH29: Release hold + price to break-even | AI29: Release hold; cut base $1.90 → $1.42 | AJ29: 44.5% ACoS, 12 orders on 79 clicks (CC 31 Aug–29 Sep) vs King Grey break-even 15.3%; BE base = $4.93 contribution (King Grey) × 15.2% CVR = $0.75; cap 25% cut. | AK29: seq 2875 rename LOAD; seq 1723,1972 NOT SERVING hold(s) → release; price to break-even (our addition, reviewer D)
A30: 246449445739132 | B30: D-S4-full satin sheets set - [Satin|Full] - Exact - Ran - DO - SATIN-FULL-BLACK | C30: full satin sheets set [exact, $1.10, 55 clicks] | D30: full satin sheets set | E30: ENABLED | F30: Ranking | G30: Ranking | H30: OUT | I30: Exact | J30: SATIN-FULL-BLACK | K30: SATIN-FULL-BLACK | L30: $1.10 | M30: $0.99 | N30: 300 | O30: 300 | P30: 4.4 | Q30: 3.96 | R30: 0 | S30: 0 | T30: 0 | U30: 0 | V30: 9.7 | W30: 9.7 | X30: ENABLED | Y30: none | Z30: defer — engine name wrong (SKU token SATIN-FULL-BLACK); load a corrected name after 28 Oct | AA30: 187.29 | AB30: 55 | AC30: 15 | AD30: 43 | AE30: 98.18 | AF30: 0 | AG30: 20 | AH30: Price cut | AI30: Cut base 10% ($1.10 → $0.99) | AJ30: 43.0% ACoS on 15 orders / 55 clicks (CC 31 Aug–29 Sep) vs Full Black break-even 27.5%; audit row loads as written (review 40 agrees). | AK30: seq 84 bid: agree with review 40; seq 1807 child: reject — keep SATIN-FULL-BLACK; seq 2887 rename CHANGE; seq 81 TOS hold → correct: cut (delivered by the base cut, TOS % kept)
A31: 189967409565927 | B31: D-S4-satin sheets king size - [Satin|King] - Exact - Ran - DO - SATIN-4PC-KING-GREY | C31: satin sheets king size [exact] | D31: satin sheets king size | E31: ENABLED | F31: Ranking | G31: Ranking | H31: Satin|King | I31: Exact | J31: SATIN-4PC-KING-GREY | K31: SATIN-4PC-KING-GREY | L31: n/a (no target bid in audit) | M31: n/a | N31: 60 | O31: 60 | V31: 20 | W31: 20 | X31: ENABLED | Y31: add negative exact: satin sheets king | Z31: load (clean): DSS4-SP-Satin Sheets King Size-[Satin|King]-(LSV)-Exact-(Ranking)-DO-SATIN-4PC-KING-GREY | AA31: 167.72 | AB31: 81 | AC31: 12 | AD31: 45.4 | AE31: 67.9 | AF31: 7.41 | AG31: 44 | AH31: Ranking push | AI31: HOLD AT TARGET satin sheets king size (#2): hold TOS $2.51 (+60%) through 28 Oct; after 11 Nov probe TOS −3–5% | AJ31: Clean rename (SKU token and objective match what the campaign advertises); 45.4% ACoS on 12 orders / 81 clicks (CC 31 Aug–29 Sep). Note: above break-even with no pricing row in the run; price at the next cycle unless it is chosen for the ranking push. | AK31: seq 2077 retag LOAD; seq 2899 rename LOAD | AL31: HOLD-AT-TARGET · score 80 · 0.8 TOS clicks/day · TOS $2.51 · $2/day · loss $7.86/order full price
A32: 173283715685585 | B32: D-S4-full silk bed sheets - [Silk|Full] - Exact - Ran - DO - SATIN-FULL-BLACK | C32: full silk bed sheets [exact, $1.45, 57 clicks] | D32: full silk bed sheets | E32: ENABLED | F32: Ranking | G32: Ranking | H32: OUT | I32: Exact | J32: SATIN-FULL-BLACK | K32: SATIN-FULL-BLACK | L32: $1.45 | M32: $1.09 | N32: 120 | O32: 120 | P32: 3.19 | Q32: 2.4 | R32: 0 | S32: 0 | T32: 0 | U32: 0 | V32: 11.29 | W32: 5.65 | X32: ENABLED | Y32: none | Z32: defer — engine name wrong (SKU token SATIN-FULL-BLACK); load a corrected name after 28 Oct | AA32: 162.64 | AB32: 57 | AC32: 14 | AD32: 39.8 | AE32: 98.25 | AF32: 0 | AG32: 26 | AH32: Price cut | AI32: Cut base 25% ($1.45 → $1.09); Budget $11.29 → $5.65 | AJ32: 39.8% ACoS on 14 orders / 57 clicks (CC 31 Aug–29 Sep). The written −29.7% breaks the team's 25% base-cut cap for a target with real sales (14 orders on 57 clicks, audit read). No orders at risk are named. | AK32: seq 85 budget: agree with review 40; seq 86 tos: drop (hold 120); seq 89 bid: correct to 1.09; seq 1810 child: reject — keep SATIN-FULL-BLACK; seq 2893 rename CHANGE
A33: 48825734993999 | B33: D-S4-SP-EXACT-queen silk sheet-Silk|Queen-SATIN-QUEEN-BLACK | C33: queen silk sheet [exact] | D33: queen silk sheet | E33: ENABLED | F33: Ranking | G33: Ranking | I33: Exact | J33: SATIN-QUEEN-BLACK | K33: SATIN-QUEEN-BLACK | L33: $1.86 | M33: $1.40 | N33: 0 | O33: 19 | P33: 1.86 | Q33: 1.67 | U33: 0 | V33: 10 | W33: 10 | X33: ENABLED | Y33: none | Z33: defer — engine name wrong (SKU token SATIN-QUEEN-BLACK); load a corrected name after 28 Oct | AA33: 151.01 | AB33: 81 | AC33: 9 | AD33: 56.4 | AE33: 30.86 | AF33: 56.79 | AG33: 17 | AH33: Mix fix + price cut | AI33: Mix fix in one write: base $1.86 → $1.40, boost → 19% (top of search $1.86 → $1.67); rest of search 20% → 0%; 56.4% ACoS vs Queen Black 22.5%; product pages 57% | AJ33: No run decision and no issue found; 56.4% ACoS on 9 orders / 81 clicks (CC 31 Aug–29 Sep). Note: above break-even with no pricing row in the run; price at the next cycle unless it is chosen for the ranking push. | AK33: seq 1820 child: reject — keep SATIN-QUEEN-BLACK; seq 2086 retag LOAD; seq 2913 rename CHANGE
A34: 208595143922254 | B34: D-S4-SP-AUTO-CATCH ALL | C34: complements [auto, $0.78] | D34: complements | E34: ENABLED | F34: Discovery | G34: Discovery | I34: Auto | J34: SATIN-QUEEN-GREY | K34: SATIN-QUEEN-GREY | L34: $0.78 | M34: $0.58 | N34: 0 | O34: 0 | P34: 0.78 | Q34: 0.58 | V34: 100 | W34: 100 | X34: ENABLED | Y34: hold seq 1792 (terms not named); add 9 negatives (seq 2273) · negative product target B0839MKJMV | Z34: load (clean): DSS4-SP-Auto-(AUTO)-Auto-(Discovery)-DO-SATIN-QUEEN-GREY | AA34: 146.82 | AB34: 231 | AC34: 13 | AD34: 40.3 | AE34: 1.73 | AF34: 61.47 | AG34: 141 | AH34: Release hold + price to break-even | AI34: Release hold; cut base $0.78 → $0.58 | AJ34: 40.3% ACoS, 13 orders on 231 clicks (CC 31 Aug–29 Sep) vs Queen Grey break-even 11.2%; BE base = $3.28 contribution (Queen Grey) × 5.6% CVR = $0.18; cap 25% cut. | AK34: seq 1792 negatives: flag: unverifiable; seq 2080 retag LOAD; seq 2273 negatives: agree with review 40; seq 2903 rename LOAD; seq 1732 NOT SERVING hold(s) → release; price to break-even (our addition, reviewer D)
A35: 167888639670385 | B35: D-S4-SP-EXACT-silk sheets king size-Silk|King-SATIN-4PC-KING-GREY | C35: silk sheets king size [exact] | D35: silk sheets king size (buys the search term: silk sheets king) | E35: ENABLED | F35: Ranking | G35: Ranking | I35: Exact | J35: SATIN-4PC-KING-GREY | K35: SATIN-4PC-KING-GREY | L35: $1.50 | M35: $1.12 | N35: 0 | O35: 34 | P35: 1.5 | Q35: 1.5 | U35: 0 | V35: 10 | W35: 10 | X35: ENABLED | Y35: none | Z35: load (clean): DSS4-SP-Silk Sheets King Size-[Silk|King]-(LSV)-Exact-(Ranking)-DO-SATIN-4PC-KING-GREY | AA35: 144.79 | AB35: 84 | AC35: 15 | AD35: 28.7 | AE35: 15.48 | AF35: 1.19 | AG35: 20 | AH35: Ranking push | AI35: Mix fix in one write: base $1.50 → $1.12, boost → 34% (top of search $1.50 → $1.50); rest of search 20% → 0% (83% of clicks); FIX FIRST silk sheets king (#40): get 70% of clicks to the top before any push | AJ35: Clean rename (SKU token and objective match what the campaign advertises); 28.7% ACoS on 15 orders / 84 clicks (CC 31 Aug–29 Sep). Note: above break-even with no pricing row in the run; price at the next cycle unless it is chosen for the ranking push. | AK35: seq 2083 retag LOAD; seq 2909 rename LOAD | AL35: FIX-FIRST · score 50 · TOS 15% of clicks · ceiling $0.74
A36: 162964778769639 | B36: SSS4-PHRASE-(silk sheet set)-Browse Kws Migr. | C36: silk sheet set [phrase, $1.01]; silk sheet set [phrase, $2.00] | D36: silk sheet set | E36: ENABLED | F36: Discovery | G36: Discovery | I36: Phrase | J36: SATIN-QUEEN-BLACK | K36: SATIN-QUEEN-BLACK | L36: $1.01 | M36: $0.76 | N36: 0 | O36: 0 | P36: 1.01 | Q36: 0.76 | V36: 30 | W36: 30 | X36: ENABLED | Y36: hold seq 1794 (terms not named); add 1 negatives (seq 2275) · add negative exact: queen silk sheets set; king size silk sheets set | Z36: load (clean): DSS4-SP-Silk Sheet Set-[Silk]-(LSV)-Phrase-(Discovery)-DO-SATIN-QUEEN-BLACK | AA36: 143.73 | AB36: 106 | AC36: 9 | AD36: 53.9 | AE36: 34.29 | AF36: 13.33 | AG36: 61 | AH36: Release hold + price to break-even | AI36: Release hold; cut base $1.01 → $0.76 | AJ36: 53.9% ACoS, 9 orders on 106 clicks (CC 31 Aug–29 Sep) vs Queen Black break-even 17.8%; BE base = $5.03 contribution (Queen Black) × 8.5% CVR = $0.43; cap 25% cut. | AK36: seq 1794 negatives: flag: unverifiable; seq 2101 retag LOAD; seq 2275 negatives: agree with review 40; seq 2942 rename LOAD; seq 1743 NOT SERVING hold(s) → release; price to break-even (our addition, reviewer D)
A37: 47024149807888 | B37: D-S4-SP-PHRASE-silk bedsheets-Silk-SATIN-QUEEN-GREY | C37: silk bedsheets [phrase, $1.50]; silk bedsheets [phrase, $1.50] | D37: whole campaign | E37: ENABLED | F37: Discovery | G37: Discovery | I37: Phrase | J37: SATIN-QUEEN-GREY | K37: SATIN-QUEEN-GREY | L37: $1.50 | M37: $1.50 | N37: 0 | O37: 0 | P37: 1.5 | Q37: 1.5 | V37: 5 | W37: 5 | X37: PAUSED | Y37: none | Z37: none | AA37: 143.6 | AB37: 87 | AC37: 9 | AD37: 55.8 | AE37: 10.34 | AF37: 27.59 | AG37: 11 | AH37: Pause | AI37: Pause (seq 2859) | AJ37: 55.8% ACoS on 9 orders / 87 clicks (CC 31 Aug–29 Sep). Second discovery campaign in its family (fold = pause; only negatives move). | AK37: seq 2859 structure: agree with review 40; seq 1728 NOT SERVING hold(s) moot — campaign paused
A38: 24229225667028 | B38: D-S4-SP-queen sheet silk-(Silk)-LSV-Exact-Rank-DO-SATIN-WHITE-QUEEN | C38: silk fitted sheet [exact, $1.68, 25 clicks]; queen sheet silk [exact, $1.83, 18 clicks]; queen bed sheet silk [exact, $1.35, 8 clicks]; satin silk sheet set queen [exact, $1.90]; silk bed sheet [exact, paused, $1.41]; silk bedsheet [exact, paused, $2.66]; silk sheet [exact, paused, $3.17] | D38: 117005423745524; 13334085515870; 46784893351913; 77370120349440 | E38: ENABLED | F38: Ranking | G38: Ranking | H38: OUT | I38: Exact | J38: SATIN-QUEEN-BLACK | K38: SATIN-QUEEN-BLACK | L38: $1.68 / $1.83 / $1.35 / $1.90 / $1.68 / $1.83 / $1.35 / $1.90 | M38: $1.68 / $1.83 / $1.35 / $1.90 / $1.26 / $1.37 / $1.01 / $1.43 | N38: 100 | O38: 100 | P38: 3.36 | Q38: 3.36 | R38: 0 | S38: 0 | T38: 0 | U38: 0 | V38: 10 | W38: 5 | X38: ENABLED | Y38: none | Z38: defer — engine name wrong (SKU token SATIN-QUEEN-BLACK); load a corrected name after 28 Oct | AA38: 142.72 | AB38: 51 | AC38: 9 | AD38: 52.6 | AE38: 86.27 | AF38: 11.76 | AG38: 31 | AH38: Price cut | AI38: Cut base 25% ($1.68 / $1.83 / $1.35 / $1.90 / $1.68 / $1.83 / $1.35 / $1.90 → $1.68 / $1.83 / $1.35 / $1.90 / $1.26 / $1.37 / $1.01 / $1.43); Budget $10 → $5 | AJ38: 52.6% ACoS on 9 orders / 51 clicks (CC 31 Aug–29 Sep). Cuts of −29.6% to −30.1% on targets with 1, 5 and 3 orders break the 25% cap. With the modifier at 100% the TOS price still falls 25%. Mix is right: 86% TOS, 12% PP (CC 30d). | AK38: seq 90 budget: agree with review 40; seq 91 tos: drop (hold 100); seq 94 bid: correct to 1.26/1.37/1.01/1.43; seq 95 bid: correct to 1.26/1.37/1.01/1.43; seq 96 bid: correct to 1.26/1.37/1.01/1.43; seq 97 bid: correct to 1.26/1.37/1.01/1.43; seq 1805 child: reject — keep SATIN-QUEEN-BLACK; seq 2885 rename CHANGE
A39: 173446552008266 | B39: D-S4-satin queen sheets set - [Satin|Queen] - Exact - Ran - DO - SATIN-QUEEN-BLACK | C39: satin queen sheets set [exact] | D39: satin queen sheets set | E39: ENABLED | F39: Ranking | G39: Ranking | H39: Satin|Queen | I39: Exact | J39: SATIN-QUEEN-BLACK | K39: SATIN-QUEEN-BLACK | L39: $1.65 | M39: $1.24 | N39: 30 | O39: 73 | P39: 2.15 | Q39: 2.15 | U39: 0 | V39: 14.13 | W39: 14.13 | X39: ENABLED | Y39: none | Z39: defer — engine name wrong (SKU token SATIN-QUEEN-BLACK); load a corrected name after 28 Oct | AA39: 139.09 | AB39: 77 | AC39: 6 | AD39: 75.7 | AE39: 49.35 | AF39: 41.56 | AG39: 44 | AH39: Ranking push | AI39: Mix fix in one write: base $1.65 → $1.24, boost → 73% (top of search $2.15 → $2.15); PUSH-SMALL satin queen sheets set (8 → 3): hold the top-of-search price; product pages 42% | AJ39: No run decision and no issue found; 75.7% ACoS on 6 orders / 77 clicks (CC 31 Aug–29 Sep). Note: above break-even with no pricing row in the run; price at the next cycle unless it is chosen for the ranking push. | AK39: seq 1815 child: reject — keep SATIN-QUEEN-BLACK; seq 2079 retag LOAD; seq 2902 rename CHANGE | AL39: PUSH-SMALL · score 50 · 1.7 TOS clicks/day (now 1.2) · TOS $2.03 · $5/day · loss $4.01/order full price, $8.86 deal
A40: 50488152164936 | B40: D-S4-SP-satin sheets for queen-(Satin)-HSV-Exact-Rank-DO-SATIN-QUEEN-BLACK | C40: satin sheets for queen [exact, $1.42, 53 clicks] | D40: satin sheets for queen (buys the search term: satin sheets queen) | E40: ENABLED | F40: Ranking | G40: Ranking | H40: OUT | I40: Exact | J40: SATIN-QUEEN-BLACK | K40: SATIN-QUEEN-BLACK | L40: $1.42 | M40: $1.07 | N40: 120 | O40: 163 | P40: 3.12 | Q40: 2.81 | R40: 0 | S40: 0 | T40: 5 | U40: 0 | V40: 9 | W40: 5 | X40: ENABLED | Y40: add negative exact: satin sheets queen; satin sheets queen size | Z40: defer — engine name wrong (SKU token SATIN-QUEEN-BLACK); load a corrected name after 28 Oct | AA40: 132.41 | AB40: 53 | AC40: 10 | AD40: 42.7 | AE40: 69.81 | AF40: 28.3 | AG40: 29 | AH40: Mix fix + price cut | AI40: Mix fix in one write: base $1.42 → $1.07, boost → 163% (top of search $3.12 → $2.81); rest of search 5% → 0%; 42.7% ACoS vs Queen Black 22.5%; product pages 28% | AJ40: 42.7% ACoS on 10 orders / 53 clicks (CC 31 Aug–29 Sep). −25% base with the modifier at 120% gives TOS $2.35 and PP $1.07. The TOS:PP ratio stays 2.2 instead of dropping to 1.83. | AK40: seq 101 budget: pass (flag); seq 102 tos: drop (hold 120); seq 104 ros: flag: take the cuts only after closing tuner record 2848 as…; seq 105 bid: correct to 1.07; seq 1812 child: reject — keep SATIN-QUEEN-BLACK; seq 2897 rename CHANGE | AL40: MAINTAIN · score 49
...

Sheet Ranking push
A1: Term | B1: Score components: CVR (25) | C1: CTR (20) | D1: Rank (15) | E1: Competitors (15) | F1: Inventory (15) | G1: Economics (10) | H1: Score | I1: Tier | J1: Action | K1: Rank 29 Sep | L1: Target | M1: Advertised child | N1: Monthly search volume | O1: TOS clicks/day now | P1: TOS clicks/day planned | Q1: TOS CVR 30d % | R1: Our CVR (SQP) % | S1: Market CVR (SQP) % | T1: Our CTR (SQP) % | U1: Market CTR (SQP) % | V1: TOS share of term clicks % | W1: Product-page share % | X1: TOS price now $ | Y1: This write $ | Z1: Budget/day $ | AA1: Orders/day planned | AB1: Cost per order at this write $ | AC1: Profit per unit, full price $ | AD1: Profit per unit, deal price $ | AE1: Loss per order, full price $ | AF1: Loss per order, deal price $ | AG1: Loss/day, full price $ | AH1: Loss/day, deal days $ | AI1: Recommended now | AJ1: Missing condition | AK1: Owning campaign(s)
A2: satin sheets king | B2: 15.54 | C2: 20 | D2: 14 | E2: 15 | F2: 15 | G2: 3.46 | H2: =ROUND(SUM(B2:G2),0) -> 83 | I2: =IF(H2>=70,"High",IF(H2>=50,"Medium","Low")) -> High | J2: PUSH | K2: 4 | L2: 3 | M2: King Grey | N2: 4280 | O2: 5.2643 | P2: 5.2643 | Q2: 22.0247 | R2: 4.77 | S2: 4.95 | T2: 3.02 | U2: 1.93 | V2: 76.6649 | W2: 13.6375 | X2: 2.794 | Y2: 2.794 | Z2: 15.8978 | AA2: =P2*Q2/100 -> 1.1594463 | AB2: 12.6858 | AC2: 6.4 | AD2: 1.38 | AE2: =AB2-AC2 -> 6.2858 | AF2: =AB2-AD2 -> 11.3058 | AG2: =AA2*AE2 -> 7.2880474 | AH2: =AA2*AF2 -> 13.108468 | AI2: Yes | AJ2: CVR not above market like-for-like (SQP); economics: CPO 2.3x contribution | AK2: 33389871513217 D-S4-satin sheets king - [Satin|King] - Exact - Ran - DO - SATIN-4PC-KING-GREY
A3: satin sheets full | B3: 16.06 | C3: 20 | D3: 14 | E3: 13 | F3: 12 | G3: 6.49 | H3: =ROUND(SUM(B3:G3),0) -> 82 | I3: =IF(H3>=70,"High",IF(H3>=50,"Medium","Low")) -> High | J3: PUSH | K3: 4 | L3: 3 | M3: Full Black | N3: 4438 | O3: 3.9108 | P3: 8 | Q3: 23.425 | R3: 10.01 | S3: 6.96 | T3: 2.82 | U3: 2.06 | V3: 71.5395 | W3: 10.0886 | X3: 3.729 | Y3: 3.6861 | Z3: 30.1118 | AA3: =P3*Q3/100 -> 1.874 | AB3: 15.7356 | AC3: 8.55 | AD3: 4.08 | AE3: =AB3-AC3 -> 7.1856 | AF3: =AB3-AD3 -> 11.6556 | AG3: =AA3*AE3 -> 13.465814 | AH3: =AA3*AF3 -> 21.842594 | AI3: Yes | AJ3: — | AK3: 82540637405662 D-S4-satin sheets full size - [Satin|Full] - Exact - Ran - DO - SATIN-FULL-BLACK
A4: satin sheets king size | B4: 13.78 | C4: 20 | D4: 15 | E4: 15 | F4: 15 | G4: 1.38 | H4: =ROUND(SUM(B4:G4),0) -> 80 | I4: =IF(H4>=70,"High",IF(H4>=50,"Medium","Low")) -> High | J4: HOLD-AT-TARGET | K4: 2 | L4: 2 | M4: King Grey | N4: 695 | O4: 0.8122 | P4: 0.8122 | Q4: 17.6116 | R4: 6.88 | S4: 5.35 | T4: 2.87 | U4: 2 | V4: 73.8319 | W4: 10.2162 | X4: 2.512 | Y4: 2.512 | Z4: 2.2166 | AA4: =P4*Q4/100 -> 0.14304142 | AB4: 14.2634 | AC4: 6.4 | AD4: 1.38 | AE4: =AB4-AC4 -> 7.8634 | AF4: =AB4-AD4 -> 12.8834 | AG4: =AA4*AE4 -> 1.1247919 | AH4: =AA4*AF4 -> 1.8428598 | AI4: Yes | AJ4: economics: CPO 2.7x contribution | AK4: 189967409565927 D-S4-satin sheets king size - [Satin|King] - Exact - Ran - DO - SATIN-4PC-KING-GREY
A5: silk sheets full | B5: 20.04 | C5: 8.31 | D5: 13 | E5: 15 | F5: 15 | G5: 8.33 | H5: =ROUND(SUM(B5:G5),0) -> 80 | I5: =IF(H5>=70,"High",IF(H5>=50,"Medium","Low")) -> High | J5: PUSH | K5: 5 | L5: 3 | M5: Full Black | N5: 6739 | O5: 2.872 | P5: 3.2879 | Q5: 24.2078 | R5: 10.11 | S5: 6.04 | T5: 1.41 | U5: 1.97 | V5: 67.3113 | W5: 14.4755 | X5: 2.565 | Y5: 2.5951 | Z5: 9.5885 | AA5: =P5*Q5/100 -> 0.79592826 | AB5: 10.72 | AC5: 8.55 | AD5: 4.08 | AE5: =AB5-AC5 -> 2.17 | AF5: =AB5-AD5 -> 6.64 | AG5: =AA5*AE5 -> 1.7271643 | AH5: =AA5*AF5 -> 5.2849636 | AI5: Yes | AJ5: CTR not above market (SQP) | AK5: 137973631643313 D-S4-SP-EXACT-silk sheets full size-Silk|Full-SATIN-FULL-BLACK
A6: silk bed sheets full | B6: 6.37 | C6: 14 | D6: 14 | E6: 15 | F6: 15 | G6: 6.89 | H6: =ROUND(SUM(B6:G6),0) -> 71 | I6: =IF(H6>=70,"High",IF(H6>=50,"Medium","Low")) -> High | J6: PUSH | K6: 4 | L6: 3 | M6: Full Black | N6: 2200 | O6: 1.0301 | P6: 1.4286 | Q6: 15.0119 | R6: 5.87 | S6: 5.91 | T6: 1.87 | U6: 1.87 | V6: 73.5772 | W6: 7.0102 | X6: 1.9573 | Y6: 1.9573 | Z6: 2.8922 | AA6: =P6*Q6/100 -> 0.21446 | AB6: 13.0382 | AC6: 8.55 | AD6: 4.08 | AE6: =AB6-AC6 -> 4.4882 | AF6: =AB6-AD6 -> 8.9582 | AG6: =AA6*AE6 -> 0.96253939 | AH6: =AA6*AF6 -> 1.9211756 | AI6: Yes | AJ6: CVR not above market like-for-like (SQP) | AK6: 276865047785028 D-S4-silk bed sheets full size - [Silk|Full] - Exact - Ran - DO - SATIN-FULL-BLACK (PAUSED); 50992822442833 D-S4-SP-silk bed sheets full size-(Silk)-MSV-Exact-Rank-DO-SATIN-FULL-GREY
A7: king size silk sheets set | B7: 11.71 | C7: 20 | D7: 2 | E7: 15 | F7: 15 | G7: 0 | H7: =ROUND(SUM(B7:G7),0) -> 64 | I7: =IF(H7>=70,"High",IF(H7>=50,"Medium","Low")) -> Medium | J7: PUSH-SMALL | K7: 10 | L7: 3 | M7: King Grey | N7: 1961 | O7: 3.7092 | P7: 3.7092 | Q7: 19.8145 | R7: 8.06 | S7: 6.56 | T7: 3.6 | U7: 1.96 | V7: 87.619 | W7: 0.4121 | X7: 5.5 | Y7: 4.0619 | Z7: 15.1145 | AA7: =P7*Q7/100 -> 0.73495943 | AB7: 20.4997 | AC7: 6.4 | AD7: 1.38 | AE7: =AB7-AC7 -> 14.0997 | AF7: =AB7-AD7 -> 19.1197 | AG7: =AA7*AE7 -> 10.362708 | AH7: =AA7*AF7 -> 14.052204 | AI7: Yes | AJ7: economics: CPO 3.6x contribution | AK7: 265771609218691 D-S4-king silk sheet set - [Silk|King] - Exact - Ran - DO - SATIN-4PC-KING-GREY
A8: satin bed sheets queen | B8: 15.39 | C8: 9.53 | D8: 6 | E8: 9 | F8: 15 | G8: 5.57 | H8: =ROUND(SUM(B8:G8),0) -> 60 | I8: =IF(H8>=70,"High",IF(H8>=50,"Medium","Low")) -> Medium | J8: PUSH-SMALL | K8: 6 | L8: 3 | M8: Queen Black | N8: 2200 | O8: 0.6811 | P8: 0.6811 | Q8: 18.6169 | R8: 12.33 | S8: 6.05 | T8: 1.53 | U8: 1.97 | V8: 45.4075 | W8: 10.8385 | X8: 1.7666 | Y8: 1.7666 | Z8: 1.3468 | AA8: =P8*Q8/100 -> 0.12679971 | AB8: 9.4891 | AC8: 6.74 | AD8: 1.89 | AE8: =AB8-AC8 -> 2.7491 | AF8: =AB8-AD8 -> 7.5991 | AG8: =AA8*AE8 -> 0.34858507 | AH8: =AA8*AF8 -> 0.96356365 | AI8: Yes | AJ8: CTR not above market (SQP) | AK8: 47941523261030 D-S4-SP-EXACT-satin bedsheets queen size-Satin|Queen-SATIN-QUEEN-BLACK; 79231677791815 D-S4-satin bed sheets queen - [Satin|Queen] - Exact - Ran - DO - SATIN-QUEEN-BLACK
A9: silk sheets queen | B9: 10.45 | C9: 12.67 | D9: 4 | E9: 9 | F9: 15 | G9: 3.94 | H9: =ROUND(SUM(B9:G9),0) -> 55 | I9: =IF(H9>=70,"High",IF(H9>=50,"Medium","Low")) -> Medium | J9: PUSH-SMALL | K9: 10 | L9: 3 | M9: Queen Black | N9: 15189 | O9: 7.2246 | P9: 20.0408 | Q9: 20.9483 | R9: 6.01 | S9: 6.16 | T9: 1.82 | U9: 1.95 | V9: 75.518 | W9: 5.0047 | X9: 2.0276 | Y9: 2.3318 | Z9: 47.2166 | AA9: =P9*Q9/100 -> 4.1982069 | AB9: 11.1312 | AC9: 6.74 | AD9: 1.89 | AE9: =AB9-AC9 -> 4.3912 | AF9: =AB9-AD9 -> 9.2412 | AG9: =AA9*AE9 -> 18.435166 | AH9: =AA9*AF9 -> 38.79647 | AI9: Restore to about 10 TOS clicks/day on one exact; the push to 20 is your decision | AJ9: CTR not above market (SQP); CVR not above market like-for-like (SQP); economics: CPO 2.2x contribution | AK9: 40865602759529 D-S4-silk sheets queen size - [Silk|Queen] - Exact - Ran - DO - SATIN-QUEEN-BLACK; 100830568607053 D-S4-SP-silk sheets queen-(Silk)-HSV-Exact-Rank-DO-SATIN-QUEEN-BLACK
A10: satin sheets | B10: 14.28 | C10: 10.08 | D10: 10 | E10: 4 | F10: 12 | G10: 1.05 | H10: =ROUND(SUM(B10:G10),0) -> 51 | I10: =IF(H10>=70,"High",IF(H10>=50,"Medium","Low")) -> Medium | J10: PUSH-SMALL | K10: 5 | L10: 3 | M10: Queen Black | N10: 30210 | O10: 21.4229 | P10: 59.7829 | Q10: 16.5564 | R10: 4.08 | S10: 4.05 | T10: 1.95 | U10: 1.95 | V10: 79.3442 | W10: 10.2569 | X10: 2.3 | Y10: 2.324 | Z10: 142.1185 | AA10: =P10*Q10/100 -> 9.8978961 | AB10: 14.0367 | AC10: 6.74 | AD10: 1.89 | AE10: =AB10-AC10 -> 7.2967 | AF10: =AB10-AD10 -> 12.1467 | AG10: =AA10*AE10 -> 72.221978 | AH10: =AA10*AF10 -> 120.22677 | AI10: Your decision (full plan) | AJ10: economics: CPO 2.8x contribution; target rank held by strong rivals | AK10: 527361393975073 D-S4-SP-satin sheets-(Satin)-HSV-Exact-Rank-DO-SATIN-QUEEN-GREY
