Workbook

Sheet Read_Me
A1: How to read this workbook
A2: CooLinens Cooling Sheets 4PC launch · Amazon US · prepared 8 Oct 2026 · analysis and proposal only — nothing has been changed in the account.
A4: Main_Strategy | B4: The decision tab. One row per keyword we keep (Batch 1, 2 or 3). Filter column B. Each row carries relevance, confidence, demand, rank history, competitors, live Sleephoria/Decolure PPC history, the ranking calculation, campaign structure, budget, stock and the full story.
A5: Batch_Summary | B5: Live totals per batch and the rules that put a keyword in a batch, plus the weekly decision rule.
A6: Campaigns | B6: One row per campaign. Daily budget = SUMIF of its keywords' planned spend × (1 + headroom), minimum $10. Main_Strategy reads its budget from here.
A7: Assumptions | B7: Every input the formulas use: paid click share, probe cap, modifier limits, the rank → click-share table (measured on Sleephoria) and economics by size. Change a blue cell and the whole plan recalculates.
A8: Inventory | B8: Stock, inbound, velocity and days of cover per SKU; preferred / backup per size; stock-out history; constraints. Main_Strategy reads stock status and cover from here.
A9: Competitors | B9: Profiles (price, material, variations, keywords, organic and PPC presence, strengths / weaknesses, comparison) and a keyword × rival rank matrix for every Main_Strategy keyword.
A10: Decolure_History / Sleephoria_History | B10: Full product history: summary, monthly business + PPC, year-on-year windows, size and SKU performance, ad formats and placements, organic rank history, stock-outs, rises and declines with causes, and the keyword table that Main_Strategy looks up.
A11: Excluded | B11: Every keyword considered and rejected, with its reason.
A12: Relevance % | B12: Product type 25 + use case (cooling / hot sleeper) 30 + material 15 + intent 15 + size fit 15 (specific size 15, no size 10). ✓ = full points, ⚠ = half, ✗ = 0 (and the keyword is excluded). Research wording ("best …") −5.
A13: Confidence | B13: Evidence score out of 12: Sleephoria PPC on the exact term (−2 to +4; same product, strongest weight) + root|size syntax proven on Sleephoria when the term itself has < 20 clicks (+1.5) + Sleephoria organic rank reached (0 to +2) + market CVR from SQP (0 to +2) + rivals in the organic top 20 (0 to +1) + Decolure term history and rank (−0.5 to +1.5, adjacent product). High ≥ 6.5 · Medium 4–6.4 · Low < 4. "Medium (syntax-proven)" = a long-tail with little data of its own whose root|size syntax Sleephoria proved — used only inside capped Halo campaigns. The build-up is shown on every row.
A14: Ranking calculation | B14: Searches/day × market clicks per search = market clicks/day → × click share needed for the target rank (Sleephoria-measured table) × paid share = clicks/day needed. Funded clicks: Ranking = needed, floored at 1/day so CVR can be read; capped probes = 50 clicks / 14 days (they build first sales and read CVR until the size is assigned to CooLinens); Halo probes = 0.75/day per term; support terms = needed. Every term is limited to 10% of its daily searches (what an exact ad can realistically buy). Orders = clicks × expected CVR. Base bid = Sleephoria's CPC on the same term, capped at the max ranking CPC. Top-of-Search modifier = the largest 25% step that keeps base × (1 + modifier) ≤ price × ranking-ceiling ACoS × CVR, limited to +100% where Sleephoria proved CVR on the term and +50% where it did not; 0 for probes and support terms. Effective CPC × clicks = spend; campaign budget sums its keywords.
A15: Expected CVR | B15: Sleephoria CVR on the exact term (≥ 50 clicks), otherwise its root/size group, × 0.8 for a new listing (24 Vine ratings vs Sleephoria's 889), bounded 3–14%.
... A17: Structure rule | B17: Launch-window SV > 300/mo → Hero single-keyword campaign; ≤ 300 → Halo campaign per size, ad groups by intent. Exact match only on day 1. Naming: CLCS4-SP-{keyword}-{SV tier}-Exact-{objective}-Fix-{SKU}.

Sheet Main_Strategy
A1: CooLinens Cooling Sheets 4PC — Main Strategy (Batch 1 / 2 / 3)
A2: One row per keyword we keep. Filter column B for Batch 1, 2 or 3. Blue = input value; black = live formula; green = pulled live from a supporting tab. Excluded keywords and their reasons are on the Excluded tab.
A4: Keyword | F4: Relevance & Confidence | K4: Demand | O4: Organic Rank | U4: Competitors | V4: Historical PPC (Live from History Tabs) | AD4: Click & Order Model (Live) | AW4: Bid & Placement Model (Live) | BL4: Campaign Structure | BR4: Budget & Stock (Live) | BU4: Keyword Story — Why We Chose It
A5: Exact search term | B5: 1 · 2 · 3 | C5: Launch date / gate | D5: Size in the query | E5: Action for this keyword | F5: Type 25 + Use 30 + Material 15 + Intent 15 + Size 15 | G5: Type · Use · Material · Intent (✓ / ⚠ / ✗) | H5: High ≥ 6.5 · Medium 4–6.4 · Low < 4 | I5: Sum of the build-up | J5: Sleephoria PPC + rank, market CVR, rivals, Decolure | K5: DataDive MKL build 618 | L5: Oct–Jan seasonal level | M5: Calc: Launch SV ÷ 30 | N5: All brands: purchases ÷ clicks, 12 mo | O5: Best · median · now | P5: Best · PPC-period median · now | Q5: Best-ranked tracked rival | R5: Of 20 tracked rivals | S5: Exact rank to reach by week 8 | T5: Checkpoints for the weekly verdict | U5: ASINsight, late Sep 2026 | V5: Sleephoria_History §12 | W5: Sleephoria_History §12 | X5: Sleephoria_History §12 | Y5: Sleephoria_History §12 | Z5: Sleephoria_History §12 | AA5: Decolure_History §10 | AB5: Decolure_History §10 | AC5: Decolure_History §10 | AD5: Sleephoria CVR × 0.8 (new listing) | AE5: Source of the CVR | AF5: SQP clicks ÷ searches | AG5: Calc: Searches/day × clicks per search | AH5: Sleephoria-measured (Assumptions) | AI5: Ads share during a push | AJ5: Calc: Market clicks × share × paid | AK5: Calc: Required clicks × expected CVR | AL5: Calc: Required clicks/day × 56 | AM5: Calc: Required orders/day × 56 | AN5: Calc: Searches/day × 10% | AO5: All campaigns are ranking campaigns | AP5: Reason for the objective and its funding level | AQ5: Exact on day 1 | AS5: Full push: MAX(required, 1) · capped: MAX(required, 1) up to 3.57 · long-tail: required up to 0.75 — all ≤ supply | AT5: Planned ÷ required clicks | AU5: Calc: Planned clicks × CVR | AV5: Calc: Orders × price | AW5: What Sleephoria paid | AX5: Term or size average | AY5: Assumptions · economics | AZ5: Calc: MIN(80%, 1.5 × break-even) | BA5: Calc: Margin ÷ price | BB5: Calc: Price × ceiling × CVR | BC5: Calc: MIN(reference CPC, max ranking CPC) | BD5: ≥ 50 clicks and CVR ≥ 8% | BE5: Largest 25% step keeping effective CPC ≤ max | BF5: Decision with the ceiling maths and final values | BG5: Calc: Base bid × (1 + modifier) | BH5: Calc: Planned clicks × effective CPC | BI5: Calc: Effective CPC ÷ (price × CVR) | BJ5: vs break-even and ceiling | BK5: Full chain with final values | BL5: Root | size | BM5: Hero > 300 SV/mo · Halo ≤ 300 | BN5: CLCS4 · SP · keyword/size · SV tier · match · objective · bid type · SKU | BO5: Hero: keyword · Halo: intent | BP5: Preferred child (colour terms: colour child) | BR5: Calc: Campaign spend × 1.25, min $10 | BS5: Inventory tab | BT5: Inventory tab
A6: Keyword | B6: Batch | C6: Go-Live | D6: Size | E6: Launch Recommendation | F6: Relevance (%) | G6: Relevance Check | H6: Confidence Level | I6: Evidence Score (/12) | J6: Evidence Score Build-Up | K6: Search Volume / Month (MKL) | L6: Search Volume / Month (Launch Window) | M6: Searches / Day | N6: Market CVR (SQP) | O6: Decolure Organic Rank (History) | P6: Sleephoria Organic Rank (History) | Q6: Market Organic Leader | R6: Rivals in Organic Top 20 | S6: Target Organic Rank (#) | T6: Rank Path (Wk 2 → Wk 4 → Wk 8) | U6: Competitor Presence (Organic · Sponsored) | V6: Sleephoria Clicks | W6: Sleephoria CVR | X6: Sleephoria CPC ($) | Y6: Sleephoria ACoS | Z6: Sleephoria Ad Sales ($) | AA6: Decolure Clicks | AB6: Decolure CVR | AC6: Decolure ACoS | AD6: Expected CVR | AE6: CVR Basis | AF6: Market Clicks per Search | AG6: Market Clicks / Day | AH6: Click Share for Target Rank | AI6: Paid Share of Clicks | AJ6: Clicks / Day Required for Target Rank | AK6: Orders / Day Required for Target Rank | AL6: Clicks Required — 8-Week Push | AM6: Orders Required — 8-Week Push | AN6: Click Supply Cap / Day | AO6: Campaign Objective | AP6: Why This Objective | AQ6: Match Type | AR6: Why This Match Type | AS6: Planned Clicks / Day | AT6: Funding vs Requirement | AU6: Expected Orders / Day | AV6: Expected Ad Sales / Day ($) | AW6: Reference CPC ($) | AX6: Reference CPC Source | AY6: Price ($) | AZ6: Ranking Ceiling ACoS | BA6: Break-Even ACoS | BB6: Max Ranking CPC ($) | BC6: Base Bid ($) | BD6: Sleephoria CVR Proven? | BE6: TOS Modifier (%) | BF6: TOS Modifier Decision (+100%?) | BG6: Effective TOS CPC ($) | BH6: Planned Spend / Day ($) | BI6: Expected ACoS | BJ6: ACoS Check | BK6: Bid & Budget Calculation (Worked Example) | BL6: Syntax Group (Root | Size) | BM6: Campaign Structure | BN6: Campaign Name | BO6: Ad Group | BP6: Advertised SKU | BQ6: Advertised ASIN | BR6: Campaign Daily Budget ($) | BS6: Stock Status | BT6: Days of Cover | BU6: Why It Is Relevant to CooLinens | BV6: Evidence from Decolure | BW6: Evidence from Sleephoria | BX6: Market Demand and Trend | BY6: Who Ranks and Who Advertises | BZ6: Competitive Opportunity | CA6: Why Launch It Now | CB6: Why This Batch (1 vs 2 vs 3) | CC6: Target Rank Rationale
A7: cooling sheets queen | B7: 1 | C7: 15 Oct 2026 | D7: Queen | E7: LAUNCH 15 Oct — rank push | F7: 1 | G7: Type ✓ · Use ✓ · Material ✓ · Intent ✓ | H7: High | I7: 9.5 | J7: Sleephoria PPC +4 · Sleephoria rank +2 · market CVR +1.5 · competitors +1 · Decolure +1 | K7: 30225 | L7: 36640 | M7: =L7/30 -> 1221.3333 | N7: 0.033473097 | O7: best #3 (2025-04-25) · median #27 · now #110 | P7: best #2 (2025-10-23) · PPC-period median #23 · now #45 | Q7: #3 Pillcase | R7: 5 | S7: 15 | T7: #50 → #30 → #15 | U7: Pillcase #3, Love's cabin #5, Bedsure PW #6, TRUE BAMBOO #7, Bambaw #12; Ads: Bedsure PW Cooling SP#2, Love's cabin SP#4, Bedsure PW SP#4, California Design Den SP#4 | V7: =IFERROR(INDEX(Sleephoria_History!$F$454:$F$2115,MATCH($A7,Sleephoria_History!$A$454:$A$2115,0)),"") -> 2552 | W7: =IFERROR(INDEX(Sleephoria_History!$J$454:$J$2115,MATCH($A7,Sleephoria_History!$A$454:$A$2115,0)),"") -> 0.1187 | X7: =IFERROR(INDEX(Sleephoria_History!$H$454:$H$2115,MATCH($A7,Sleephoria_History!$A$454:$A$2115,0)),"") -> 2.24 | Y7: =IFERROR(INDEX(Sleephoria_History!$M$454:$M$2115,MATCH($A7,Sleephoria_History!$A$454:$A$2115,0)),"") -> 0.289 | Z7: =IFERROR(INDEX(Sleephoria_History!$L$454:$L$2115,MATCH($A7,Sleephoria_History!$A$454:$A$2115,0)),"") -> 19776.51 | AA7: =IFERROR(INDEX(Decolure_History!$F$397:$F$709,MATCH($A7,Decolure_History!$A$397:$A$709,0)),"") -> 2048 | AB7: =IFERROR(INDEX(Decolure_History!$J$397:$J$709,MATCH($A7,Decolure_History!$A$397:$A$709,0)),"") -> 0.0693 | AC7: =IFERROR(INDEX(Decolure_History!$M$397:$M$709,MATCH($A7,Decolure_History!$A$397:$A$709,0)),"") -> 0.459 | AD7: 0.095 | AE7: Sleephoria term CVR 11.9% on 2552 clicks ×0.8 launch | AF7: 0.476 | AG7: =M7*AF7 -> 581.35467 | AH7: =IF(AO7="Brand Defense",0,IFERROR(VLOOKUP(S7,Assumptions!$A$24:$B$28,2,FALSE()),0)) -> 0.0149 | AI7: =Assumptions!$B$6 -> 0.66 | AJ7: =AG7*AH7*AI7 -> 5.7170418 | AK7: =AJ7*AD7 -> 0.54311897 | AL7: =AJ7*56 -> 320.15434 | AM7: =AK7*56 -> 30.414662 | AN7: =M7*Assumptions!$B$8 -> 122.13333 | AO7: Ranking — Full Push | AP7: Full ranking push: Queen is CooLinens' own size (its keywords are not shared with Sleephoria) and the evidence is High (9.5/12). Every click the target rank requires is funded, with a Top-of-Search modifier where the ceiling allows. | AQ7: Exact | AR7: Exact: organic rank is earned per exact query, so sales must land on this wording; one keyword per campaign gives full control of bid, TOS modifier and budget, and clean attribution. Phrase / broad / auto open from week 4 for harvesting only. | AS7: =IF(AO7="Ranking — Full Push",MIN(MAX(AJ7,Assumptions!$B$9),AN7),IF(AO7="Brand Defense",MIN(Assumptions!$B$7,AN7),IF(OR(AO7="Ranking — Head Term (Capped)",AO7="Ranking — Capped Entry"),MIN(MAX(AJ7,Assumptions!$B$9),Assumptions!$B$7,AN7),IF(AO7="Ranking — Capped Long-Tail",MIN(AJ7,Assumptions!$B$10,AN7),MIN(AJ7,AN7))))) -> 5.7170418 | AT7: =IF(AJ7<=0,"",IF(AS7>=AJ7,IF(AS7>AJ7*1.05,"Floor of "&TEXT(AS7,"0.0")&" click/day to read CVR (rank needs "&TEXT(AJ7,"0.00")&")","Fully funded (100%)"),"Capped at "&TEXT(AS7/AJ7,"0%")&" of required")) -> Fully funded (100%) | AU7: =AS7*AD7 -> 0.54311897 | AV7: =AU7*AY7 -> 43.444086 | AW7: 2.24 | AX7: Sleephoria CPC on this exact term (2552 clicks) | AY7: =INDEX(Assumptions!$B$33:$B$37,MATCH(IF($D7="","Queen",$D7),Assumptions!$A$33:$A$37,0)) -> 79.99 | AZ7: =INDEX(Assumptions!$K$33:$K$37,MATCH(IF($D7="","Queen",$D7),Assumptions!$A$33:$A$37,0)) -> 0.55866046 | BA7: =INDEX(Assumptions!$H$33:$H$37,MATCH(IF($D7="","Queen",$D7),Assumptions!$A$33:$A$37,0)) -> 0.37244031 | BB7: =AY7*AZ7*AD7 -> 4.2452888 | BC7: =ROUND(MIN(AW7*Assumptions!$B$11,BB7),2) -> 2.24 | BD7: Yes | BE7: =IF(AO7="Ranking — Full Push",MAX(0,MIN(IF(BD7="Yes",Assumptions!$B$12,Assumptions!$B$13),FLOOR(MAX(0,BB7/BC7-1),Assumptions!$B$14))),0) -> 0.75 | BF7: =IF(AO7="Ranking — Full Push",IF(BE7>=1,"YES — +100% Top of Search. Effective CPC $"&TEXT(BG7,"0.00")&" (= $"&TEXT(BC7,"0.00")&" × 2) stays within the $"&TEXT(BB7,"0.00")&" max ranking CPC"&" (= $"&TEXT(AY7,"0.00")&" price × "&TEXT(AZ7,"0.0%")&" ranking ceiling × "&TEXT(AD7,"0.0%")&" CVR)"&". Sleephoria CVR is proven on this term, so the full push is justified.",IF(AND(BD7="No",BE7>=Assumptions!$B$13),"PARTIAL — +"&TEXT(BE7,"0%")&" Top of Search (limit for terms without proven CVR). Effective CPC $"&TEXT(BG7,"0.00")&" vs $"&TEXT(BB7,"0.00")&" max ranking CPC"&" (= $"&TEXT(AY7,"0.00")&" price × "&TEXT(AZ7,"0.0%")&" ranking ceiling × "&TEXT(AD7,"0.0%")&" CVR)"&". Raise to +100% only after CooLinens converts at ≥ "&TEXT(AD7,"0.0%")&" on 50+ clicks and $"&TEXT(BC7*2,"0.00")&" ≤ the max.",IF(BE7>0,"PARTIAL — +"&TEXT(BE7,"0%")&" Top of Search. Effective CPC $"&TEXT(BG7,"0.00")&" stays within the $"&TEXT(BB7,"0.00")&" max ranking CPC"&" (= $"&TEXT(AY7,"0.00")&" price × "&TEXT(AZ7,"0.0%")&" ranking ceiling × "&TEXT(AD7,"0.0%")&" CVR)"&". +100% would cost $"&TEXT(BC7*2,"0.00")&" per click and push ACoS to "&TEXT(BC7*2/(AY7*AD7),"0.0%")&", above the "&TEXT(AZ7,"0.0%")&" ceiling.","NO — 0%. Base bid $"&TEXT(BC7,"0.00")&" already equals the $"&TEXT(BB7,"0.00")&" max ranking CPC"&" (= $"&TEXT(AY7,"0.00")&" price × "&TEXT(AZ7,"0.0%")&" ranking ceiling × "&TEXT(AD7,"0.0%")&" CVR)"&"; any modifier would push ACoS above the "&TEXT(AZ7,"0.0%")&" ceiling."))),IF(OR(AO7="Ranking — Head Term (Capped)",AO7="Ranking — Capped Entry",AO7="Ranking — Capped Long-Tail"),"NO — 0% (capped ranking entry). Bid $"&TEXT(BC7,"0.00")&" vs $"&TEXT(BB7,"0.00")&" max ranking CPC"&" (= $"&TEXT(AY7,"0.00")&" price × "&TEXT(AZ7,"0.0%")&" ranking ceiling × "&TEXT(AD7,"0.0%")&" CVR)"&". While spend is capped at "&TEXT(AS7,"0.00")&" clicks/day, a placement premium would only raise CPC without buying more rank; the modifier is set when this term moves to a full push.","NO — 0% (support / brand term). Bid $"&TEXT(BC7,"0.00")&" vs $"&TEXT(BB7,"0.00")&" max ranking CPC"&" (= $"&TEXT(AY7,"0.00")&" price × "&TEXT(AZ7,"0.0%")&" ranking ceiling × "&TEXT(AD7,"0.0%")&" CVR)"&"; expected ACoS "&TEXT(BI7,"0.0%")&" vs the "&TEXT(AZ7,"0.0%")&" ceiling.")) -> PARTIAL — +75% Top of Search. Effective CPC $3.92 stays within the $4.25 max ranking CPC (= $79.99 price × 55.9% ranking ceiling × 9.5% CVR). +100% would cost $4.48 per click and push ACoS to 59.0%, above the 55.9% ceiling. | BG7: =BC7*(1+BE7) -> 3.92 | BH7: =AS7*BG7 -> 22.410804 | BI7: =IFERROR(BG7/(AY7*AD7),"") -> 0.51585396 | BJ7: =IF(BI7="","",IF(BI7<=BA7,"Profitable (≤ break-even)",IF(BI7<=AZ7,"Ranking investment (≤ ceiling)","Above ceiling — reduce bid"))) -> Ranking investment (≤ ceiling) | BK7: ="Base $"&TEXT(BC7,"0.00")&" × (1 + "&TEXT(BE7,"0%")&" TOS) = $"&TEXT(BG7,"0.00")&" effective CPC [max $"&TEXT(BB7,"0.00")&"]. "&TEXT(AG7,"0.0")&" market clicks/day × "&TEXT(AH7,"0.00%")&" click share × "&TEXT(AI7,"0%")&" paid = "&TEXT(AJ7,"0.00")&" clicks/day needed; "&"planned "&TEXT(AS7,"0.00")&" clicks/day × "&TEXT(AD7,"0.0%")&" CVR = "&TEXT(AU7,"0.00")&" orders/day. "&"Spend $"&TEXT(BH7,"0.00")&"/day, ACoS "&TEXT(BI7,"0.0%")&" (ceiling "&TEXT(AZ7,"0.0%")&", break-even "&TEXT(BA7,"0.0%")&"). "&"Target organic rank #"&S7&" by week 8 ("&T7&")." -> Base $2.24 × (1 + 75% TOS) = $3.92 effective CPC [max $4.25]. 581.4 market clicks/day × 1.49% click share × 66% paid = 5.72 clicks/day needed; planned 5.72 clicks/day × 9.5% CVR = 0.54 orders/day. Spend $22.41/day, ACoS 51.6% (ceiling 55.9%, break-even 37.2%). Target organic rank #15 by week 8 (#50 → #30 → #15). | BL7: cooling sheets|Queen | BM7: Hero (single-keyword campaign) | BN7: CLCS4-SP-cooling sheets queen-VHSV-Exact-Rank-Fix-Q-GRAPHITE | BO7: cooling sheets queen | BP7: CL-COOLING-SHEET-QUEEN-GRAPHITE | BQ7: B0H6K1MKQW | BR7: =IFERROR(INDEX(Campaigns!$L:$L,MATCH(BN7,Campaigns!$A:$A,0)),"") -> 29 | BS7: =IFERROR(INDEX(Inventory!$O:$O,MATCH(BP7,Inventory!$A:$A,0)),"") -> OK | BT7: =IFERROR(INDEX(Inventory!$N:$N,MATCH(BP7,Inventory!$A:$A,0)),"") -> 91.53226 | BU7: "cooling sheets queen" asks for a Queen cooling sheet product that CooLinens sells (BreezeWeave nylon/spandex knit, 16″ pocket, 4-piece set). Relevance 100%: product type ✓, use case ✓, material ✓, intent ✓. | BV7: Decolure ($38 microfiber — adjacent, lower weight): converted but costly at the $38 tier (2048 clicks, CVR 6.9%, ACoS 46%); organic best #3 (2025-04-25), 73 days in top 10, median #28. | BW7: Sleephoria (same product and price — strongest evidence): proven on the same product (2552 clicks, CVR 11.9%, ACoS 29%); organic best #2 (2025-10-23), first top-10 2025-10-12, now #45. Launch entry Oct-25: 7.8 clicks/day, 1.34 orders/day, $41/day → top 10 in 9 days. | BX7: SV 30,225/mo (MKL (DataDive)); launch window ≈ 36,640/mo; SQP 12-mo 589,245 searches, peak 2026-06, Oct at 0.80× its avg; Mar-24→Mar-26 ×1.94; market CVR 3.3% (head term 1.5%). | BY7: Organic top 20: Pillcase #3, Love's cabin #5, Bedsure PW #6, TRUE BAMBOO #7. Advertising: Bedsure PW Cooling SP#2, Love's cabin SP#4, Bedsure PW SP#4, California Design Den SP#4. Rival ad share 54%. | BZ7: Top-20 is held by bamboo/viscose sets (Pillcase, Love's cabin, Bedsure PW); no synthetic cooling-knit rival ranks here. CooLinens is the only nylon/spandex cooling option on the page at $79.99 — Sleephoria proved the knit ranks here. | CA7: Launch-window demand is ~35% of the June peak but these are the terms where evidence is strongest; ranking now means CooLinens holds position before the March ramp (SQP March ≈ 2× January). Queen roots belong to CooLinens, so this can be pushed at ranking spend from day 1. | CB7: Batch 1 Hero: relevance 100% ≥ 90%, clean wording, launch-window demand 36,640 searches/mo > 300 (own campaign), and evidence score 9.5/12 ≥ 6.0 (Sleephoria PPC +4 · Sleephoria rank +2 · market CVR +1.5 · competitors +1 · Decolure +1). Sleephoria did not overpay on it beyond the ranking ceiling. | CC7: ≤15 (≤50 by wk 2, ≤30 by wk 4, ≤15 by wk 8): a 36,640-searches/mo page. Sleephoria's best was #2 (2025-10-23), but its launch ran into Prime Big Deal Days (7–8 Oct 2025). CooLinens launches with 24 Vine ratings and no deal tailwind in a 35%-of-peak window, so top 15 is the evidence-supported goal.
A8: queen sheets cooling | B8: 1 | C8: 15 Oct 2026 | D8: Queen | E8: LAUNCH 15 Oct — rank push | F8: 1 | G8: Type ✓ · Use ✓ · Material ✓ · Intent ✓ | H8: High | I8: 9.5 | J8: Sleephoria PPC +4 · Sleephoria rank +2 · market CVR +2 · competitors +1 · Decolure +0.5 | K8: 4964 | L8: 5693 | M8: =L8/30 -> 189.76667 | N8: 0.05029491 | O8: now #127 | P8: best #4 (2025-10-17) · PPC-period median #30 · now #69 | Q8: #5 Love's cabin | R8: 3 | S8: 10 | T8: #40 → #20 → #10 | U8: Love's cabin #5, Bedsure PW #9, Bambaw #18; Ads: Bambaw SP#6, TRUE BAMBOO SP#8, Breescape SP#9, Pure Bamboo SP#10 | V8: =IFERROR(INDEX(Sleephoria_History!$F$454:$F$2115,MATCH($A8,Sleephoria_History!$A$454:$A$2115,0)),"") -> 55 | W8: =IFERROR(INDEX(Sleephoria_History!$J$454:$J$2115,MATCH($A8,Sleephoria_History!$A$454:$A$2115,0)),"") -> 0.0909 | X8: =IFERROR(INDEX(Sleephoria_History!$H$454:$H$2115,MATCH($A8,Sleephoria_History!$A$454:$A$2115,0)),"") -> 2.42 | Y8: =IFERROR(INDEX(Sleephoria_History!$M$454:$M$2115,MATCH($A8,Sleephoria_History!$A$454:$A$2115,0)),"") -> 0.37 | Z8: =IFERROR(INDEX(Sleephoria_History!$L$454:$L$2115,MATCH($A8,Sleephoria_History!$A$454:$A$2115,0)),"") -> 359.95 | AA8: =IFERROR(INDEX(Decolure_History!$F$397:$F$709,MATCH($A8,Decolure_History!$A$397:$A$709,0)),"") -> 45 | AB8: =IFERROR(INDEX(Decolure_History!$J$397:$J$709,MATCH($A8,Decolure_History!$A$397:$A$709,0)),"") -> 0.0889 | AC8: =IFERROR(INDEX(Decolure_History!$M$397:$M$709,MATCH($A8,Decolure_History!$A$397:$A$709,0)),"") -> 0.481 | AD8: 0.0727 | AE8: Sleephoria term CVR 9.1% on 55 clicks ×0.8 launch | AF8: 0.471 | AG8: =M8*AF8 -> 89.3801 | AH8: =IF(AO8="Brand Defense",0,IFERROR(VLOOKUP(S8,Assumptions!$A$24:$B$28,2,FALSE()),0)) -> 0.028 | AI8: =Assumptions!$B$6 -> 0.66 | AJ8: =AG8*AH8*AI8 -> 1.6517442 | AK8: =AJ8*AD8 -> 0.12008181 | AL8: =AJ8*56 -> 92.497678 | AM8: =AK8*56 -> 6.7245812 | AN8: =M8*Assumptions!$B$8 -> 18.976667 | AO8: Ranking — Full Push | AP8: Full ranking push: Queen is CooLinens' own size (its keywords are not shared with Sleephoria) and the evidence is High (9.5/12). Every click the target rank requires is funded, with a Top-of-Search modifier where the ceiling allows. | AQ8: Exact | AR8: Exact: organic rank is earned per exact query, so sales must land on this wording; one keyword per campaign gives full control of bid, TOS modifier and budget, and clean attribution. Phrase / broad / auto open from week 4 for harvesting only. | AS8: =IF(AO8="Ranking — Full Push",MIN(MAX(AJ8,Assumptions!$B$9),AN8),IF(AO8="Brand Defense",MIN(Assumptions!$B$7,AN8),IF(OR(AO8="Ranking — Head Term (Capped)",AO8="Ranking — Capped Entry"),MIN(MAX(AJ8,Assumptions!$B$9),Assumptions!$B$7,AN8),IF(AO8="Ranking — Capped Long-Tail",MIN(AJ8,Assumptions!$B$10,AN8),MIN(AJ8,AN8))))) -> 1.6517442 | AT8: =IF(AJ8<=0,"",IF(AS8>=AJ8,IF(AS8>AJ8*1.05,"Floor of "&TEXT(AS8,"0.0")&" click/day to read CVR (rank needs "&TEXT(AJ8,"0.00")&")","Fully funded (100%)"),"Capped at "&TEXT(AS8/AJ8,"0%")&" of required")) -> Fully funded (100%) | AU8: =AS8*AD8 -> 0.12008181 | AV8: =AU8*AY8 -> 9.6053437 | AW8: 2.42 | AX8: Sleephoria CPC on this exact term (55 clicks) | AY8: =INDEX(Assumptions!$B$33:$B$37,MATCH(IF($D8="","Queen",$D8),Assumptions!$A$33:$A$37,0)) -> 79.99 | AZ8: =INDEX(Assumptions!$K$33:$K$37,MATCH(IF($D8="","Queen",$D8),Assumptions!$A$33:$A$37,0)) -> 0.55866046 | BA8: =INDEX(Assumptions!$H$33:$H$37,MATCH(IF($D8="","Queen",$D8),Assumptions!$A$33:$A$37,0)) -> 0.37244031 | BB8: =AY8*AZ8*AD8 -> 3.2487631 | BC8: =ROUND(MIN(AW8*Assumptions!$B$11,BB8),2) -> 2.42 | BD8: Yes | BE8: =IF(AO8="Ranking — Full Push",MAX(0,MIN(IF(BD8="Yes",Assumptions!$B$12,Assumptions!$B$13),FLOOR(MAX(0,BB8/BC8-1),Assumptions!$B$14))),0) -> 0.25 | BF8: =IF(AO8="Ranking — Full Push",IF(BE8>=1,"YES — +100% Top of Search. Effective CPC $"&TEXT(BG8,"0.00")&" (= $"&TEXT(BC8,"0.00")&" × 2) stays within the $"&TEXT(BB8,"0.00")&" max ranking CPC"&" (= $"&TEXT(AY8,"0.00")&" price × "&TEXT(AZ8,"0.0%")&" ranking ceiling × "&TEXT(AD8,"0.0%")&" CVR)"&". Sleephoria CVR is proven on this term, so the full push is justified.",IF(AND(BD8="No",BE8>=Assumptions!$B$13),"PARTIAL — +"&TEXT(BE8,"0%")&" Top of Search (limit for terms without proven CVR). Effective CPC $"&TEXT(BG8,"0.00")&" vs $"&TEXT(BB8,"0.00")&" max ranking CPC"&" (= $"&TEXT(AY8,"0.00")&" price × "&TEXT(AZ8,"0.0%")&" ranking ceiling × "&TEXT(AD8,"0.0%")&" CVR)"&". Raise to +100% only after CooLinens converts at ≥ "&TEXT(AD8,"0.0%")&" on 50+ clicks and $"&TEXT(BC8*2,"0.00")&" ≤ the max.",IF(BE8>0,"PARTIAL — +"&TEXT(BE8,"0%")&" Top of Search. Effective CPC $"&TEXT(BG8,"0.00")&" stays within the $"&TEXT(BB8,"0.00")&" max ranking CPC"&" (= $"&TEXT(AY8,"0.00")&" price × "&TEXT(AZ8,"0.0%")&" ranking ceiling × "&TEXT(AD8,"0.0%")&" CVR)"&". +100% would cost $"&TEXT(BC8*2,"0.00")&" per click and push ACoS to "&TEXT(BC8*2/(AY8*AD8),"0.0%")&", above the "&TEXT(AZ8,"0.0%")&" ceiling.","NO — 0%. Base bid $"&TEXT(BC8,"0.00")&" already equals the $"&TEXT(BB8,"0.00")&" max ranking CPC"&" (= $"&TEXT(AY8,"0.00")&" price × "&TEXT(AZ8,"0.0%")&" ranking ceiling × "&TEXT(AD8,"0.0%")&" CVR)"&"; any modifier would push ACoS above the "&TEXT(AZ8,"0.0%")&" ceiling."))),IF(OR(AO8="Ranking — Head Term (Capped)",AO8="Ranking — Capped Entry",AO8="Ranking — Capped Long-Tail"),"NO — 0% (capped ranking entry). Bid $"&TEXT(BC8,"0.00")&" vs $"&TEXT(BB8,"0.00")&" max ranking CPC"&" (= $"&TEXT(AY8,"0.00")&" price × "&TEXT(AZ8,"0.0%")&" ranking ceiling × "&TEXT(AD8,"0.0%")&" CVR)"&". While spend is capped at "&TEXT(AS8,"0.00")&" clicks/day, a placement premium would only raise CPC without buying more rank; the modifier is set when this term moves to a full push.","NO — 0% (support / brand term). Bid $"&TEXT(BC8,"0.00")&" vs $"&TEXT(BB8,"0.00")&" max ranking CPC"&" (= $"&TEXT(AY8,"0.00")&" price × "&TEXT(AZ8,"0.0%")&" ranking ceiling × "&TEXT(AD8,"0.0%")&" CVR)"&"; expected ACoS "&TEXT(BI8,"0.0%")&" vs the "&TEXT(AZ8,"0.0%")&" ceiling.")) -> PARTIAL — +25% Top of Search. Effective CPC $3.03 stays within the $3.25 max ranking CPC (= $79.99 price × 55.9% ranking ceiling × 7.3% CVR). +100% would cost $4.84 per click and push ACoS to 83.2%, above the 55.9% ceiling. | BG8: =BC8*(1+BE8) -> 3.025 | BH8: =AS8*BG8 -> 4.9965264 | BI8: =IFERROR(BG8/(AY8*AD8),"") -> 0.52018194 | BJ8: =IF(BI8="","",IF(BI8<=BA8,"Profitable (≤ break-even)",IF(BI8<=AZ8,"Ranking investment (≤ ceiling)","Above ceiling — reduce bid"))) -> Ranking investment (≤ ceiling) | BK8: ="Base $"&TEXT(BC8,"0.00")&" × (1 + "&TEXT(BE8,"0%")&" TOS) = $"&TEXT(BG8,"0.00")&" effective CPC [max $"&TEXT(BB8,"0.00")&"]. "&TEXT(AG8,"0.0")&" market clicks/day × "&TEXT(AH8,"0.00%")&" click share × "&TEXT(AI8,"0%")&" paid = "&TEXT(AJ8,"0.00")&" clicks/day needed; "&"planned "&TEXT(AS8,"0.00")&" clicks/day × "&TEXT(AD8,"0.0%")&" CVR = "&TEXT(AU8,"0.00")&" orders/day. "&"Spend $"&TEXT(BH8,"0.00")&"/day, ACoS "&TEXT(BI8,"0.0%")&" (ceiling "&TEXT(AZ8,"0.0%")&", break-even "&TEXT(BA8,"0.0%")&"). "&"Target organic rank #"&S8&" by week 8 ("&T8&")." -> Base $2.42 × (1 + 25% TOS) = $3.03 effective CPC [max $3.25]. 89.4 market clicks/day × 2.80% click share × 66% paid = 1.65 clicks/day needed; planned 1.65 clicks/day × 7.3% CVR = 0.12 orders/day. Spend $5.00/day, ACoS 52.0% (ceiling 55.9%, break-even 37.2%). Target organic rank #10 by week 8 (#40 → #20 → #10). | BL8: cooling sheets|Queen | BM8: Hero (single-keyword campaign) | BN8: CLCS4-SP-queen sheets cooling-HSV-Exact-Rank-Fix-Q-GRAPHITE | BO8: queen sheets cooling | BP8: CL-COOLING-SHEET-QUEEN-GRAPHITE | BQ8: B0H6K1MKQW | BR8: =IFERROR(INDEX(Campaigns!$L:$L,MATCH(BN8,Campaigns!$A:$A,0)),"") -> 10 | BS8: =IFERROR(INDEX(Inventory!$O:$O,MATCH(BP8,Inventory!$A:$A,0)),"") -> OK | BT8: =IFERROR(INDEX(Inventory!$N:$N,MATCH(BP8,Inventory!$A:$A,0)),"") -> 91.53226 | BU8: "queen sheets cooling" asks for a Queen cooling sheet product that CooLinens sells (BreezeWeave nylon/spandex knit, 16″ pocket, 4-piece set). Relevance 100%: product type ✓, use case ✓, material ✓, intent ✓. | BV8: Decolure ($38 microfiber — adjacent, lower weight): converted but costly at the $38 tier (45 clicks, CVR 8.9%, ACoS 48%). | BW8: Sleephoria (same product and price — strongest evidence): proven on the same product (55 clicks, CVR 9.1%, ACoS 37%); organic best #4 (2025-10-17), first top-10 2025-10-15, now #69. | BX8: SV 4,964/mo (MKL (DataDive)); launch window ≈ 5,693/mo; SQP 12-mo 78,457 searches, peak 2026-07, Oct at 0.94× its avg; market CVR 5.0% (head term 1.5%). | BY8: Organic top 20: Love's cabin #5, Bedsure PW #9, Bambaw #18. Advertising: Bambaw SP#6, TRUE BAMBOO SP#8, Breescape SP#9, Pure Bamboo SP#10. Rival ad share 52%. | BZ8: Top-20 is held by bamboo/viscose sets (Love's cabin, Bedsure PW, Bambaw); no synthetic cooling-knit rival ranks here. CooLinens is the only nylon/spandex cooling option on the page at $79.99 — Sleephoria proved the knit ranks here. | CA8: Launch-window demand is ~35% of the June peak but these are the terms where evidence is strongest; ranking now means CooLinens holds position before the March ramp (SQP March ≈ 2× January). Queen roots belong to CooLinens, so this can be pushed at ranking spend from day 1. | CB8: Batch 1 Hero: relevance 100% ≥ 90%, clean wording, launch-window demand 5,693 searches/mo > 300 (own campaign), and evidence score 9.5/12 ≥ 6.0 (Sleephoria PPC +4 · Sleephoria rank +2 · market CVR +2 · competitors +1 · Decolure +0.5). Sleephoria did not overpay on it beyond the ranking ceiling. | CC8: ≤10 (≤40 by wk 2, ≤20 by wk 4, ≤10 by wk 8): Sleephoria, the same product, reached #4 here; 3 tracked rival(s) in the top 20.
A9: queen cooling sheets | B9: 1 | C9: 15 Oct 2026 | D9: Queen | E9: LAUNCH 15 Oct — rank push | F9: 1 | G9: Type ✓ · Use ✓ · Material ✓ · Intent ✓ | H9: High | I9: 9 | J9: Sleephoria PPC +4 · Sleephoria rank +2 · market CVR +2 · competitors +0.5 · Decolure +0.5 | K9: 4728 | L9: 5605 | M9: =L9/30 -> 186.83333 | N9: 0.049716135 | O9: best #4 (2025-06-18) · median #20 · now #130 | P9: best #3 (2025-11-08) · PPC-period median #29 · now #45 | Q9: #1 Love's cabin | R9: 2 | S9: 10 | T9: #40 → #20 → #10 | U9: Love's cabin #1, Bedsure PW #4; Ads: OMERAI SP#4, Bambaw SP#5, BEDELITE SP#8, Breescape SP#9 | V9: =IFERROR(INDEX(Sleephoria_History!$F$454:$F$2115,MATCH($A9,Sleephoria_History!$A$454:$A$2115,0)),"") -> 78 | W9: =IFERROR(INDEX(Sleephoria_History!$J$454:$J$2115,MATCH($A9,Sleephoria_History!$A$454:$A$2115,0)),"") -> 0.1282 | X9: =IFERROR(INDEX(Sleephoria_History!$H$454:$H$2115,MATCH($A9,Sleephoria_History!$A$454:$A$2115,0)),"") -> 2.38 | Y9: =IFERROR(INDEX(Sleephoria_History!$M$454:$M$2115,MATCH($A9,Sleephoria_History!$A$454:$A$2115,0)),"") -> 0.23 | Z9: =IFERROR(INDEX(Sleephoria_History!$L$454:$L$2115,MATCH($A9,Sleephoria_History!$A$454:$A$2115,0)),"") -> 804.9 | AA9: =IFERROR(INDEX(Decolure_History!$F$397:$F$709,MATCH($A9,Decolure_History!$A$397:$A$709,0)),"") -> 88 | AB9: =IFERROR(INDEX(Decolure_History!$J$397:$J$709,MATCH($A9,Decolure_History!$A$397:$A$709,0)),"") -> 0.0455 | AC9: =IFERROR(INDEX(Decolure_History!$M$397:$M$709,MATCH($A9,Decolure_History!$A$397:$A$709,0)),"") -> 0.657 | AD9: 0.1026 | AE9: Sleephoria term CVR 12.8% on 78 clicks ×0.8 launch | AF9: 0.492 | AG9: =M9*AF9 -> 91.922 | AH9: =IF(AO9="Brand Defense",0,IFERROR(VLOOKUP(S9,Assumptions!$A$24:$B$28,2,FALSE()),0)) -> 0.028 | AI9: =Assumptions!$B$6 -> 0.66 | AJ9: =AG9*AH9*AI9 -> 1.6987186 | AK9: =AJ9*AD9 -> 0.17428852 | AL9: =AJ9*56 -> 95.128239 | AM9: =AK9*56 -> 9.7601574 | AN9: =M9*Assumptions!$B$8 -> 18.683333 | AO9: Ranking — Full Push | AP9: Full ranking push: Queen is CooLinens' own size (its keywords are not shared with Sleephoria) and the evidence is High (9.0/12). Every click the target rank requires is funded, with a Top-of-Search modifier where the ceiling allows. | AQ9: Exact | AR9: Exact: organic rank is earned per exact query, so sales must land on this wording; one keyword per campaign gives full control of bid, TOS modifier and budget, and clean attribution. Phrase / broad / auto open from week 4 for harvesting only. | AS9: =IF(AO9="Ranking — Full Push",MIN(MAX(AJ9,Assumptions!$B$9),AN9),IF(AO9="Brand Defense",MIN(Assumptions!$B$7,AN9),IF(OR(AO9="Ranking — Head Term (Capped)",AO9="Ranking — Capped Entry"),MIN(MAX(AJ9,Assumptions!$B$9),Assumptions!$B$7,AN9),IF(AO9="Ranking — Capped Long-Tail",MIN(AJ9,Assumptions!$B$10,AN9),MIN(AJ9,AN9))))) -> 1.6987186 | AT9: =IF(AJ9<=0,"",IF(AS9>=AJ9,IF(AS9>AJ9*1.05,"Floor of "&TEXT(AS9,"0.0")&" click/day to read CVR (rank needs "&TEXT(AJ9,"0.00")&")","Fully funded (100%)"),"Capped at "&TEXT(AS9/AJ9,"0%")&" of required")) -> Fully funded (100%) | AU9: =AS9*AD9 -> 0.17428852 | AV9: =AU9*AY9 -> 13.941339 | AW9: 2.38 | AX9: Sleephoria CPC on this exact term (78 clicks) | AY9: =INDEX(Assumptions!$B$33:$B$37,MATCH(IF($D9="","Queen",$D9),Assumptions!$A$33:$A$37,0)) -> 79.99 | AZ9: =INDEX(Assumptions!$K$33:$K$37,MATCH(IF($D9="","Queen",$D9),Assumptions!$A$33:$A$37,0)) -> 0.55866046 | BA9: =INDEX(Assumptions!$H$33:$H$37,MATCH(IF($D9="","Queen",$D9),Assumptions!$A$33:$A$37,0)) -> 0.37244031 | BB9: =AY9*AZ9*AD9 -> 4.5849119 | BC9: =ROUND(MIN(AW9*Assumptions!$B$11,BB9),2) -> 2.38 | BD9: Yes | BE9: =IF(AO9="Ranking — Full Push",MAX(0,MIN(IF(BD9="Yes",Assumptions!$B$12,Assumptions!$B$13),FLOOR(MAX(0,BB9/BC9-1),Assumptions!$B$14))),0) -> 0.75 | BF9: =IF(AO9="Ranking — Full Push",IF(BE9>=1,"YES — +100% Top of Search. Effective CPC $"&TEXT(BG9,"0.00")&" (= $"&TEXT(BC9,"0.00")&" × 2) stays within the $"&TEXT(BB9,"0.00")&" max ranking CPC"&" (= $"&TEXT(AY9,"0.00")&" price × "&TEXT(AZ9,"0.0%")&" ranking ceiling × "&TEXT(AD9,"0.0%")&" CVR)"&". Sleephoria CVR is proven on this term, so the full push is justified.",IF(AND(BD9="No",BE9>=Assumptions!$B$13),"PARTIAL — +"&TEXT(BE9,"0%")&" Top of Search (limit for terms without proven CVR). Effective CPC $"&TEXT(BG9,"0.00")&" vs $"&TEXT(BB9,"0.00")&" max ranking CPC"&" (= $"&TEXT(AY9,"0.00")&" price × "&TEXT(AZ9,"0.0%")&" ranking ceiling × "&TEXT(AD9,"0.0%")&" CVR)"&". Raise to +100% only after CooLinens converts at ≥ "&TEXT(AD9,"0.0%")&" on 50+ clicks and $"&TEXT(BC9*2,"0.00")&" ≤ the max.",IF(BE9>0,"PARTIAL — +"&TEXT(BE9,"0%")&" Top of Search. Effective CPC $"&TEXT(BG9,"0.00")&" stays within the $"&TEXT(BB9,"0.00")&" max ranking CPC"&" (= $"&TEXT(AY9,"0.00")&" price × "&TEXT(AZ9,"0.0%")&" ranking ceiling × "&TEXT(AD9,"0.0%")&" CVR)"&". +100% would cost $"&TEXT(BC9*2,"0.00")&" per click and push ACoS to "&TEXT(BC9*2/(AY9*AD9),"0.0%")&", above the "&TEXT(AZ9,"0.0%")&" ceiling.","NO — 0%. Base bid $"&TEXT(BC9,"0.00")&" already equals the $"&TEXT(BB9,"0.00")&" max ranking CPC"&" (= $"&TEXT(AY9,"0.00")&" price × "&TEXT(AZ9,"0.0%")&" ranking ceiling × "&TEXT(AD9,"0.0%")&" CVR)"&"; any modifier would push ACoS above the "&TEXT(AZ9,"0.0%")&" ceiling."))),IF(OR(AO9="Ranking — Head Term (Capped)",AO9="Ranking — Capped Entry",AO9="Ranking — Capped Long-Tail"),"NO — 0% (capped ranking entry). Bid $"&TEXT(BC9,"0.00")&" vs $"&TEXT(BB9,"0.00")&" max ranking CPC"&" (= $"&TEXT(AY9,"0.00")&" price × "&TEXT(AZ9,"0.0%")&" ranking ceiling × "&TEXT(AD9,"0.0%")&" CVR)"&". While spend is capped at "&TEXT(AS9,"0.00")&" clicks/day, a placement premium would only raise CPC without buying more rank; the modifier is set when this term moves to a full push.","NO — 0% (support / brand term). Bid $"&TEXT(BC9,"0.00")&" vs $"&TEXT(BB9,"0.00")&" max ranking CPC"&" (= $"&TEXT(AY9,"0.00")&" price × "&TEXT(AZ9,"0.0%")&" ranking ceiling × "&TEXT(AD9,"0.0%")&" CVR)"&"; expected ACoS "&TEXT(BI9,"0.0%")&" vs the "&TEXT(AZ9,"0.0%")&" ceiling.")) -> PARTIAL — +75% Top of Search. Effective CPC $4.17 stays within the $4.58 max ranking CPC (= $79.99 price × 55.9% ranking ceiling × 10.3% CVR). +100% would cost $4.76 per click and push ACoS to 58.0%, above the 55.9% ceiling. | BG9: =BC9*(1+BE9) -> 4.165 | BH9: =AS9*BG9 -> 7.0751628 | BI9: =IFERROR(BG9/(AY9*AD9),"") -> 0.50749521 | BJ9: =IF(BI9="","",IF(BI9<=BA9,"Profitable (≤ break-even)",IF(BI9<=AZ9,"Ranking investment (≤ ceiling)","Above ceiling — reduce bid"))) -> Ranking investment (≤ ceiling) | BK9: ="Base $"&TEXT(BC9,"0.00")&" × (1 + "&TEXT(BE9,"0%")&" TOS) = $"&TEXT(BG9,"0.00")&" effective CPC [max $"&TEXT(BB9,"0.00")&"]. "&TEXT(AG9,"0.0")&" market clicks/day × "&TEXT(AH9,"0.00%")&" click share × "&TEXT(AI9,"0%")&" paid = "&TEXT(AJ9,"0.00")&" clicks/day needed; "&"planned "&TEXT(AS9,"0.00")&" clicks/day × "&TEXT(AD9,"0.0%")&" CVR = "&TEXT(AU9,"0.00")&" orders/day. "&"Spend $"&TEXT(BH9,"0.00")&"/day, ACoS "&TEXT(BI9,"0.0%")&" (ceiling "&TEXT(AZ9,"0.0%")&", break-even "&TEXT(BA9,"0.0%")&"). "&"Target organic rank #"&S9&" by week 8 ("&T9&")." -> Base $2.38 × (1 + 75% TOS) = $4.17 effective CPC [max $4.58]. 91.9 market clicks/day × 2.80% click share × 66% paid = 1.70 clicks/day needed; planned 1.70 clicks/day × 10.3% CVR = 0.17 orders/day. Spend $7.08/day, ACoS 50.7% (ceiling 55.9%, break-even 37.2%). Target organic rank #10 by week 8 (#40 → #20 → #10). | BL9: cooling sheets|Queen | BM9: Hero (single-keyword campaign) | BN9: CLCS4-SP-queen cooling sheets-HSV-Exact-Rank-Fix-Q-GRAPHITE | BO9: queen cooling sheets | BP9: CL-COOLING-SHEET-QUEEN-GRAPHITE | BQ9: B0H6K1MKQW | BR9: =IFERROR(INDEX(Campaigns!$L:$L,MATCH(BN9,Campaigns!$A:$A,0)),"") -> 10 | BS9: =IFERROR(INDEX(Inventory!$O:$O,MATCH(BP9,Inventory!$A:$A,0)),"") -> OK | BT9: =IFERROR(INDEX(Inventory!$N:$N,MATCH(BP9,Inventory!$A:$A,0)),"") -> 91.53226 | BU9: "queen cooling sheets" asks for a Queen cooling sheet product that CooLinens sells (BreezeWeave nylon/spandex knit, 16″ pocket, 4-piece set). Relevance 100%: product type ✓, use case ✓, material ✓, intent ✓. | BV9: Decolure ($38 microfiber — adjacent, lower weight): small sample (88 clicks); organic best #4 (2025-06-18), 103 days in top 10, median #20. | BW9: Sleephoria (same product and price — strongest evidence): proven on the same product (78 clicks, CVR 12.8%, ACoS 23%); organic best #3 (2025-11-08), first top-10 2025-10-12, now #45. | BX9: SV 4,728/mo (MKL (DataDive)); launch window ≈ 5,605/mo; SQP 12-mo 86,358 searches, peak 2026-07, Oct at 0.91× its avg; Mar-24→Mar-26 ×2.19; market CVR 5.0% (head term 1.5%). | BY9: Organic top 20: Love's cabin #1, Bedsure PW #4. Advertising: OMERAI SP#4, Bambaw SP#5, BEDELITE SP#8, Breescape SP#9. Rival ad share 52%. | BZ9: Top-20 is held by bamboo/viscose sets (Love's cabin, Bedsure PW); no synthetic cooling-knit rival ranks here. CooLinens is the only nylon/spandex cooling option on the page at $79.99 — Sleephoria proved the knit ranks here. | CA9: Launch-window demand is ~35% of the June peak but these are the terms where evidence is strongest; ranking now means CooLinens holds position before the March ramp (SQP March ≈ 2× January). Queen roots belong to CooLinens, so this can be pushed at ranking spend from day 1. | CB9: Batch 1 Hero: relevance 100% ≥ 90%, clean wording, launch-window demand 5,605 searches/mo > 300 (own campaign), and evidence score 9.0/12 ≥ 6.0 (Sleephoria PPC +4 · Sleephoria rank +2 · market CVR +2 · competitors +0.5 · Decolure +0.5). Sleephoria did not overpay on it beyond the ranking ceiling. | CC9: ≤10 (≤40 by wk 2, ≤20 by wk 4, ≤10 by wk 8): Sleephoria, the same product, reached #3 here; 2 tracked rival(s) in the top 20.
A10: cooling queen sheets | B10: 1 | C10: 15 Oct 2026 | D10: Queen | E10: LAUNCH 15 Oct — rank push | F10: 1 | G10: Type ✓ · Use ✓ · Material ✓ · Intent ✓ | H10: High | I10: 8.5 | J10: Sleephoria PPC +4 · Sleephoria rank +2 · market CVR +1.5 · competitors +1 · Decolure +0 | K10: 2635 | L10: 2787 | M10: =L10/30 -> 92.9 | N10: 0.037781212 | O10: now #124 | P10: best #4 (2025-10-15) · PPC-period median #20 · now #24 | Q10: #4 Love's cabin | R10: 3 | S10: 10 | T10: #40 → #20 → #10 | U10: Love's cabin #4, Bedsure PW #5, Bambaw #11; Ads: KARISSA MAE SP#4, BEDELITE SP#5, Bambaw SP#6, REST SP#11 | V10: =IFERROR(INDEX(Sleephoria_History!$F$454:$F$2115,MATCH($A10,Sleephoria_History!$A$454:$A$2115,0)),"") -> 234 | W10: =IFERROR(INDEX(Sleephoria_History!$J$454:$J$2115,MATCH($A10,Sleephoria_History!$A$454:$A$2115,0)),"") -> 0.1111 | X10: =IFERROR(INDEX(Sleephoria_History!$H$454:$H$2115,MATCH($A10,Sleephoria_History!$A$454:$A$2115,0)),"") -> 2.95 | Y10: =IFERROR(INDEX(Sleephoria_History!$M$454:$M$2115,MATCH($A10,Sleephoria_History!$A$454:$A$2115,0)),"") -> 0.38 | Z10: =IFERROR(INDEX(Sleephoria_History!$L$454:$L$2115,MATCH($A10,Sleephoria_History!$A$454:$A$2115,0)),"") -> 1814.7 | AA10: =IFERROR(INDEX(Decolure_History!$F$397:$F$709,MATCH($A10,Decolure_History!$A$397:$A$709,0)),"") | AB10: =IFERROR(INDEX(Decolure_History!$J$397:$J$709,MATCH($A10,Decolure_History!$A$397:$A$709,0)),"") | AC10: =IFERROR(INDEX(Decolure_History!$M$397:$M$709,MATCH($A10,Decolure_History!$A$397:$A$709,0)),"") | AD10: 0.0889 | AE10: Sleephoria term CVR 11.1% on 234 clicks ×0.8 launch | AF10: 0.475 | AG10: =M10*AF10 -> 44.1275 | AH10: =IF(AO10="Brand Defense",0,IFERROR(VLOOKUP(S10,Assumptions!$A$24:$B$28,2,FALSE()),0)) -> 0.028 | AI10: =Assumptions!$B$6 -> 0.66 | AJ10: =AG10*AH10*AI10 -> 0.8154762 | AK10: =AJ10*AD10 -> 0.072495834 | AL10: =AJ10*56 -> 45.666667 | AM10: =AK10*56 -> 4.0597667 | AN10: =M10*Assumptions!$B$8 -> 9.29 | AO10: Ranking — Full Push | AP10: Full ranking push: Queen is CooLinens' own size (its keywords are not shared with Sleephoria) and the evidence is High (8.5/12). Every click the target rank requires is funded, with a Top-of-Search modifier where the ceiling allows. | AQ10: Exact | AR10: Exact: organic rank is earned per exact query, so sales must land on this wording; one keyword per campaign gives full control of bid, TOS modifier and budget, and clean attribution. Phrase / broad / auto open from week 4 for harvesting only. | AS10: =IF(AO10="Ranking — Full Push",MIN(MAX(AJ10,Assumptions!$B$9),AN10),IF(AO10="Brand Defense",MIN(Assumptions!$B$7,AN10),IF(OR(AO10="Ranking — Head Term (Capped)",AO10="Ranking — Capped Entry"),MIN(MAX(AJ10,Assumptions!$B$9),Assumptions!$B$7,AN10),IF(AO10="Ranking — Capped Long-Tail",MIN(AJ10,Assumptions!$B$10,AN10),MIN(AJ10,AN10))))) -> 1 | AT10: =IF(AJ10<=0,"",IF(AS10>=AJ10,IF(AS10>AJ10*1.05,"Floor of "&TEXT(AS10,"0.0")&" click/day to read CVR (rank needs "&TEXT(AJ10,"0.00")&")","Fully funded (100%)"),"Capped at "&TEXT(AS10/AJ10,"0%")&" of required")) -> Floor of 1.0 click/day to read CVR (rank needs 0.82) | AU10: =AS10*AD10 -> 0.0889 | AV10: =AU10*AY10 -> 7.111111 | AW10: 2.95 | AX10: Sleephoria CPC on this exact term (234 clicks) | AY10: =INDEX(Assumptions!$B$33:$B$37,MATCH(IF($D10="","Queen",$D10),Assumptions!$A$33:$A$37,0)) -> 79.99 | AZ10: =INDEX(Assumptions!$K$33:$K$37,MATCH(IF($D10="","Queen",$D10),Assumptions!$A$33:$A$37,0)) -> 0.55866046 | BA10: =INDEX(Assumptions!$H$33:$H$37,MATCH(IF($D10="","Queen",$D10),Assumptions!$A$33:$A$37,0)) -> 0.37244031 | BB10: =AY10*AZ10*AD10 -> 3.9726965 | BC10: =ROUND(MIN(AW10*Assumptions!$B$11,BB10),2) -> 2.95 | BD10: Yes | BE10: =IF(AO10="Ranking — Full Push",MAX(0,MIN(IF(BD10="Yes",Assumptions!$B$12,Assumptions!$B$13),FLOOR(MAX(0,BB10/BC10-1),Assumptions!$B$14))),0) -> 0.25 | BF10: =IF(AO10="Ranking — Full Push",IF(BE10>=1,"YES — +100% Top of Search. Effective CPC $"&TEXT(BG10,"0.00")&" (= $"&TEXT(BC10,"0.00")&" × 2) stays within the $"&TEXT(BB10,"0.00")&" max ranking CPC"&" (= $"&TEXT(AY10,"0.00")&" price × "&TEXT(AZ10,"0.0%")&" ranking ceiling × "&TEXT(AD10,"0.0%")&" CVR)"&". Sleephoria CVR is proven on this term, so the full push is justified.",IF(AND(BD10="No",BE10>=Assumptions!$B$13),"PARTIAL — +"&TEXT(BE10,"0%")&" Top of Search (limit for terms without proven CVR). Effective CPC $"&TEXT(BG10,"0.00")&" vs $"&TEXT(BB10,"0.00")&" max ranking CPC"&" (= $"&TEXT(AY10,"0.00")&" price × "&TEXT(AZ10,"0.0%")&" ranking ceiling × "&TEXT(AD10,"0.0%")&" CVR)"&". Raise to +100% only after CooLinens converts at ≥ "&TEXT(AD10,"0.0%")&" on 50+ clicks and $"&TEXT(BC10*2,"0.00")&" ≤ the max.",IF(BE10>0,"PARTIAL — +"&TEXT(BE10,"0%")&" Top of Search. Effective CPC $"&TEXT(BG10,"0.00")&" stays within the $"&TEXT(BB10,"0.00")&" max ranking CPC"&" (= $"&TEXT(AY10,"0.00")&" price × "&TEXT(AZ10,"0.0%")&" ranking ceiling × "&TEXT(AD10,"0.0%")&" CVR)"&". +100% would cost $"&TEXT(BC10*2,"0.00")&" per click and push ACoS to "&TEXT(BC10*2/(AY10*AD10),"0.0%")&", above the "&TEXT(AZ10,"0.0%")&" ceiling.","NO — 0%. Base bid $"&TEXT(BC10,"0.00")&" already equals the $"&TEXT(BB10,"0.00")&" max ranking CPC"&" (= $"&TEXT(AY10,"0.00")&" price × "&TEXT(AZ10,"0.0%")&" ranking ceiling × "&TEXT(AD10,"0.0%")&" CVR)"&"; any modifier would push ACoS above the "&TEXT(AZ10,"0.0%")&" ceiling."))),IF(OR(AO10="Ranking — Head Term (Capped)",AO10="Ranking — Capped Entry",AO10="Ranking — Capped Long-Tail"),"NO — 0% (capped ranking entry). Bid $"&TEXT(BC10,"0.00")&" vs $"&TEXT(BB10,"0.00")&" max ranking CPC"&" (= $"&TEXT(AY10,"0.00")&" price × "&TEXT(AZ10,"0.0%")&" ranking ceiling × "&TEXT(AD10,"0.0%")&" CVR)"&". While spend is capped at "&TEXT(AS10,"0.00")&" clicks/day, a placement premium would only raise CPC without buying more rank; the modifier is set when this term moves to a full push.","NO — 0% (support / brand term). Bid $"&TEXT(BC10,"0.00")&" vs $"&TEXT(BB10,"0.00")&" max ranking CPC"&" (= $"&TEXT(AY10,"0.00")&" price × "&TEXT(AZ10,"0.0%")&" ranking ceiling × "&TEXT(AD10,"0.0%")&" CVR)"&"; expected ACoS "&TEXT(BI10,"0.0%")&" vs the "&TEXT(AZ10,"0.0%")&" ceiling.")) -> PARTIAL — +25% Top of Search. Effective CPC $3.69 stays within the $3.97 max ranking CPC (= $79.99 price × 55.9% ranking ceiling × 8.9% CVR). +100% would cost $5.90 per click and push ACoS to 83.0%, above the 55.9% ceiling. | BG10: =BC10*(1+BE10) -> 3.6875 | BH10: =AS10*BG10 -> 3.6875 | BI10: =IFERROR(BG10/(AY10*AD10),"") -> 0.5185547 | BJ10: =IF(BI10="","",IF(BI10<=BA10,"Profitable (≤ break-even)",IF(BI10<=AZ10,"Ranking investment (≤ ceiling)","Above ceiling — reduce bid"))) -> Ranking investment (≤ ceiling) | BK10: ="Base $"&TEXT(BC10,"0.00")&" × (1 + "&TEXT(BE10,"0%")&" TOS) = $"&TEXT(BG10,"0.00")&" effective CPC [max $"&TEXT(BB10,"0.00")&"]. "&TEXT(AG10,"0.0")&" market clicks/day × "&TEXT(AH10,"0.00%")&" click share × "&TEXT(AI10,"0%")&" paid = "&TEXT(AJ10,"0.00")&" clicks/day needed; "&"planned "&TEXT(AS10,"0.00")&" clicks/day × "&TEXT(AD10,"0.0%")&" CVR = "&TEXT(AU10,"0.00")&" orders/day. "&"Spend $"&TEXT(BH10,"0.00")&"/day, ACoS "&TEXT(BI10,"0.0%")&" (ceiling "&TEXT(AZ10,"0.0%")&", break-even "&TEXT(BA10,"0.0%")&"). "&"Target organic rank #"&S10&" by week 8 ("&T10&")." -> Base $2.95 × (1 + 25% TOS) = $3.69 effective CPC [max $3.97]. 44.1 market clicks/day × 2.80% click share × 66% paid = 0.82 clicks/day needed; planned 1.00 clicks/day × 8.9% CVR = 0.09 orders/day. Spend $3.69/day, ACoS 51.9% (ceiling 55.9%, break-even 37.2%). Target organic rank #10 by week 8 (#40 → #20 → #10). | BL10: cooling sheets|Queen | BM10: Hero (single-keyword campaign) | BN10: CLCS4-SP-cooling queen sheets-HSV-Exact-Rank-Fix-Q-GRAPHITE | BO10: cooling queen sheets | BP10: CL-COOLING-SHEET-QUEEN-GRAPHITE | BQ10: B0H6K1MKQW | BR10: =IFERROR(INDEX(Campaigns!$L:$L,MATCH(BN10,Campaigns!$A:$A,0)),"") -> 10 | BS10: =IFERROR(INDEX(Inventory!$O:$O,MATCH(BP10,Inventory!$A:$A,0)),"") -> OK | BT10: =IFERROR(INDEX(Inventory!$N:$N,MATCH(BP10,Inventory!$A:$A,0)),"") -> 91.53226 | BU10: "cooling queen sheets" asks for a Queen cooling sheet product that CooLinens sells (BreezeWeave nylon/spandex knit, 16″ pocket, 4-piece set). Relevance 100%: product type ✓, use case ✓, material ✓, intent ✓. | BV10: Decolure ($38 microfiber — adjacent, lower weight): no search-term history. | BW10: Sleephoria (same product and price — strongest evidence): proven on the same product (234 clicks, CVR 11.1%, ACoS 38%); organic best #4 (2025-10-15), first top-10 2025-10-13, now #24. Launch entry Oct-25: 1.2 clicks/day, 0.28 orders/day, $7/day → top 10 in 10 days. | BX10: SV 2,635/mo (MKL (DataDive)); launch window ≈ 2,787/mo; SQP 12-mo 28,627 searches, peak 2026-06, Oct at 0.67× its avg; Mar-24→Mar-26 ×1.06; market CVR 3.8% (head term 1.5%). | BY10: Organic top 20: Love's cabin #4, Bedsure PW #5, Bambaw #11. Advertising: KARISSA MAE SP#4, BEDELITE SP#5, Bambaw SP#6, REST SP#11. Rival ad share 49%. | BZ10: Top-20 is held by bamboo/viscose sets (Love's cabin, Bedsure PW, Bambaw); no synthetic cooling-knit rival ranks here. CooLinens is the only nylon/spandex cooling option on the page at $79.99 — Sleephoria proved the knit ranks here. | CA10: Launch-window demand is ~35% of the June peak but these are the terms where evidence is strongest; ranking now means CooLinens holds position before the March ramp (SQP March ≈ 2× January). Queen roots belong to CooLinens, so this can be pushed at ranking spend from day 1. | CB10: Batch 1 Hero: relevance 100% ≥ 90%, clean wording, launch-window demand 2,787 searches/mo > 300 (own campaign), and evidence score 8.5/12 ≥ 6.0 (Sleephoria PPC +4 · Sleephoria rank +2 · market CVR +1.5 · competitors +1 · Decolure +0). Sleephoria did not overpay on it beyond the ranking ceiling. | CC10: ≤10 (≤40 by wk 2, ≤20 by wk 4, ≤10 by wk 8): Sleephoria, the same product, reached #4 here and entered the top 10 within 10 days; 3 tracked rival(s) in the top 20.
A11: queen bed sheets cooling | B11: 1 | C11: 15 Oct 2026 | D11: Queen | E11: LAUNCH 15 Oct — rank push | F11: 1 | G11: Type ✓ · Use ✓ · Material ✓ · Intent ✓ | H11: High | I11: 7.5 | J11: Sleephoria PPC +2 · Sleephoria rank +2 · market CVR +2 · competitors +1 · Decolure +0.5 | K11: 2630 | L11: 2485 | M11: =L11/30 -> 82.833333 | N11: 0.061472715 | O11: best #9 (2025-04-25) · median #22 · now #105 | P11: best #4 (2026-04-05) · PPC-period median #26 · now #14 | Q11: #3 Bedsure PW | R11: 3 | S11: 10 | T11: #40 → #20 → #10 | U11: Bedsure PW #3, Love's cabin #4, Bambaw #9; Ads: Bambaw SP#7, BEDELITE SP#9, Love's cabin SP#12, Hotel Sheets Direct SP#12 | V11: =IFERROR(INDEX(Sleephoria_History!$F$454:$F$2115,MATCH($A11,Sleephoria_History!$A$454:$A$2115,0)),"") -> 35 | W11: =IFERROR(INDEX(Sleephoria_History!$J$454:$J$2115,MATCH($A11,Sleephoria_History!$A$454:$A$2115,0)),"") -> 0.1143 | X11: =IFERROR(INDEX(Sleephoria_History!$H$454:$H$2115,MATCH($A11,Sleephoria_History!$A$454:$A$2115,0)),"") -> 3.14 | Y11: =IFERROR(INDEX(Sleephoria_History!$M$454:$M$2115,MATCH($A11,Sleephoria_History!$A$454:$A$2115,0)),"") -> 0.355 | Z11: =IFERROR(INDEX(Sleephoria_History!$L$454:$L$2115,MATCH($A11,Sleephoria_History!$A$454:$A$2115,0)),"") -> 309.96 | AA11: =IFERROR(INDEX(Decolure_History!$F$397:$F$709,MATCH($A11,Decolure_History!$A$397:$A$709,0)),"") -> 204 | AB11: =IFERROR(INDEX(Decolure_History!$J$397:$J$709,MATCH($A11,Decolure_History!$A$397:$A$709,0)),"") -> 0.049 | AC11: =IFERROR(INDEX(Decolure_History!$M$397:$M$709,MATCH($A11,Decolure_History!$A$397:$A$709,0)),"") -> 0.742 | AD11: 0.064 | AE11: bucket default (no history) ×0.8 launch | AF11: 0.409 | AG11: =M11*AF11 -> 33.878833 | AH11: =IF(AO11="Brand Defense",0,IFERROR(VLOOKUP(S11,Assumptions!$A$24:$B$28,2,FALSE()),0)) -> 0.028 | AI11: =Assumptions!$B$6 -> 0.66 | AJ11: =AG11*AH11*AI11 -> 0.62608084 | AK11: =AJ11*AD11 -> 0.040069174 | AL11: =AJ11*56 -> 35.060527 | AM11: =AK11*56 -> 2.2438737 | AN11: =M11*Assumptions!$B$8 -> 8.2833333 | AO11: Ranking — Full Push | AP11: Full ranking push: Queen is CooLinens' own size (its keywords are not shared with Sleephoria) and the evidence is High (7.5/12). Every click the target rank requires is funded, with a Top-of-Search modifier where the ceiling allows. | AQ11: Exact | AR11: Exact: organic rank is earned per exact query, so sales must land on this wording; one keyword per campaign gives full control of bid, TOS modifier and budget, and clean attribution. Phrase / broad / auto open from week 4 for harvesting only. | AS11: =IF(AO11="Ranking — Full Push",MIN(MAX(AJ11,Assumptions!$B$9),AN11),IF(AO11="Brand Defense",MIN(Assumptions!$B$7,AN11),IF(OR(AO11="Ranking — Head Term (Capped)",AO11="Ranking — Capped Entry"),MIN(MAX(AJ11,Assumptions!$B$9),Assumptions!$B$7,AN11),IF(AO11="Ranking — Capped Long-Tail",MIN(AJ11,Assumptions!$B$10,AN11),MIN(AJ11,AN11))))) -> 1 | AT11: =IF(AJ11<=0,"",IF(AS11>=AJ11,IF(AS11>AJ11*1.05,"Floor of "&TEXT(AS11,"0.0")&" click/day to read CVR (rank needs "&TEXT(AJ11,"0.00")&")","Fully funded (100%)"),"Capped at "&TEXT(AS11/AJ11,"0%")&" of required")) -> Floor of 1.0 click/day to read CVR (rank needs 0.63) | AU11: =AS11*AD11 -> 0.064 | AV11: =AU11*AY11 -> 5.11936 | AW11: 3.14 | AX11: Sleephoria CPC on this exact term (35 clicks) | AY11: =INDEX(Assumptions!$B$33:$B$37,MATCH(IF($D11="","Queen",$D11),Assumptions!$A$33:$A$37,0)) -> 79.99 | AZ11: =INDEX(Assumptions!$K$33:$K$37,MATCH(IF($D11="","Queen",$D11),Assumptions!$A$33:$A$37,0)) -> 0.55866046 | BA11: =INDEX(Assumptions!$H$33:$H$37,MATCH(IF($D11="","Queen",$D11),Assumptions!$A$33:$A$37,0)) -> 0.37244031 | BB11: =AY11*AZ11*AD11 -> 2.859984 | BC11: =ROUND(MIN(AW11*Assumptions!$B$11,BB11),2) -> 2.86 | BD11: No | BE11: =IF(AO11="Ranking — Full Push",MAX(0,MIN(IF(BD11="Yes",Assumptions!$B$12,Assumptions!$B$13),FLOOR(MAX(0,BB11/BC11-1),Assumptions!$B$14))),0) -> 0 | BF11: =IF(AO11="Ranking — Full Push",IF(BE11>=1,"YES — +100% Top of Search. Effective CPC $"&TEXT(BG11,"0.00")&" (= $"&TEXT(BC11,"0.00")&" × 2) stays within the $"&TEXT(BB11,"0.00")&" max ranking CPC"&" (= $"&TEXT(AY11,"0.00")&" price × "&TEXT(AZ11,"0.0%")&" ranking ceiling × "&TEXT(AD11,"0.0%")&" CVR)"&". Sleephoria CVR is proven on this term, so the full push is justified.",IF(AND(BD11="No",BE11>=Assumptions!$B$13),"PARTIAL — +"&TEXT(BE11,"0%")&" Top of Search (limit for terms without proven CVR). Effective CPC $"&TEXT(BG11,"0.00")&" vs $"&TEXT(BB11,"0.00")&" max ranking CPC"&" (= $"&TEXT(AY11,"0.00")&" price × "&TEXT(AZ11,"0.0%")&" ranking ceiling × "&TEXT(AD11,"0.0%")&" CVR)"&". Raise to +100% only after CooLinens converts at ≥ "&TEXT(AD11,"0.0%")&" on 50+ clicks and $"&TEXT(BC11*2,"0.00")&" ≤ the max.",IF(BE11>0,"PARTIAL — +"&TEXT(BE11,"0%")&" Top of Search. Effective CPC $"&TEXT(BG11,"0.00")&" stays within the $"&TEXT(BB11,"0.00")&" max ranking CPC"&" (= $"&TEXT(AY11,"0.00")&" price × "&TEXT(AZ11,"0.0%")&" ranking ceiling × "&TEXT(AD11,"0.0%")&" CVR)"&". +100% would cost $"&TEXT(BC11*2,"0.00")&" per click and push ACoS to "&TEXT(BC11*2/(AY11*AD11),"0.0%")&", above the "&TEXT(AZ11,"0.0%")&" ceiling.","NO — 0%. Base bid $"&TEXT(BC11,"0.00")&" already equals the $"&TEXT(BB11,"0.00")&" max ranking CPC"&" (= $"&TEXT(AY11,"0.00")&" price × "&TEXT(AZ11,"0.0%")&" ranking ceiling × "&TEXT(AD11,"0.0%")&" CVR)"&"; any modifier would push ACoS above the "&TEXT(AZ11,"0.0%")&" ceiling."))),IF(OR(AO11="Ranking — Head Term (Capped)",AO11="Ranking — Capped Entry",AO11="Ranking — Capped Long-Tail"),"NO — 0% (capped ranking entry). Bid $"&TEXT(BC11,"0.00")&" vs $"&TEXT(BB11,"0.00")&" max ranking CPC"&" (= $"&TEXT(AY11,"0.00")&" price × "&TEXT(AZ11,"0.0%")&" ranking ceiling × "&TEXT(AD11,"0.0%")&" CVR)"&". While spend is capped at "&TEXT(AS11,"0.00")&" clicks/day, a placement premium would only raise CPC without buying more rank; the modifier is set when this term moves to a full push.","NO — 0% (support / brand term). Bid $"&TEXT(BC11,"0.00")&" vs $"&TEXT(BB11,"0.00")&" max ranking CPC"&" (= $"&TEXT(AY11,"0.00")&" price × "&TEXT(AZ11,"0.0%")&" ranking ceiling × "&TEXT(AD11,"0.0%")&" CVR)"&"; expected ACoS "&TEXT(BI11,"0.0%")&" vs the "&TEXT(AZ11,"0.0%")&" ceiling.")) -> NO — 0%. Base bid $2.86 already equals the $2.86 max ranking CPC (= $79.99 price × 55.9% ranking ceiling × 6.4% CVR); any modifier would push ACoS above the 55.9% ceiling. | BG11: =BC11*(1+BE11) -> 2.86 | BH11: =AS11*BG11 -> 2.86 | BI11: =IFERROR(BG11/(AY11*AD11),"") -> 0.55866358 | BJ11: =IF(BI11="","",IF(BI11<=BA11,"Profitable (≤ break-even)",IF(BI11<=AZ11,"Ranking investment (≤ ceiling)","Above ceiling — reduce bid"))) -> Above ceiling — reduce bid | BK11: ="Base $"&TEXT(BC11,"0.00")&" × (1 + "&TEXT(BE11,"0%")&" TOS) = $"&TEXT(BG11,"0.00")&" effective CPC [max $"&TEXT(BB11,"0.00")&"]. "&TEXT(AG11,"0.0")&" market clicks/day × "&TEXT(AH11,"0.00%")&" click share × "&TEXT(AI11,"0%")&" paid = "&TEXT(AJ11,"0.00")&" clicks/day needed; "&"planned "&TEXT(AS11,"0.00")&" clicks/day × "&TEXT(AD11,"0.0%")&" CVR = "&TEXT(AU11,"0.00")&" orders/day. "&"Spend $"&TEXT(BH11,"0.00")&"/day, ACoS "&TEXT(BI11,"0.0%")&" (ceiling "&TEXT(AZ11,"0.0%")&", break-even "&TEXT(BA11,"0.0%")&"). "&"Target organic rank #"&S11&" by week 8 ("&T11&")." -> Base $2.86 × (1 + 0% TOS) = $2.86 effective CPC [max $2.86]. 33.9 market clicks/day × 2.80% click share × 66% paid = 0.63 clicks/day needed; planned 1.00 clicks/day × 6.4% CVR = 0.06 orders/day. Spend $2.86/day, ACoS 55.9% (ceiling 55.9%, break-even 37.2%). Target organic rank #10 by week 8 (#40 → #20 → #10). | BL11: cooling bed sheets|Queen | BM11: Hero (single-keyword campaign) | BN11: CLCS4-SP-queen bed sheets cooling-HSV-Exact-Rank-Fix-Q-GRAPHITE | BO11: queen bed sheets cooling | BP11: CL-COOLING-SHEET-QUEEN-GRAPHITE | BQ11: B0H6K1MKQW | BR11: =IFERROR(INDEX(Campaigns!$L:$L,MATCH(BN11,Campaigns!$A:$A,0)),"") -> 10 | BS11: =IFERROR(INDEX(Inventory!$O:$O,MATCH(BP11,Inventory!$A:$A,0)),"") -> OK | BT11: =IFERROR(INDEX(Inventory!$N:$N,MATCH(BP11,Inventory!$A:$A,0)),"") -> 91.53226 | BU11: "queen bed sheets cooling" asks for a Queen cooling sheet product that CooLinens sells (BreezeWeave nylon/spandex knit, 16″ pocket, 4-piece set). Relevance 100%: product type ✓, use case ✓, material ✓, intent ✓. | BV11: Decolure ($38 microfiber — adjacent, lower weight): small sample (204 clicks); organic best #9 (2025-04-25), 7 days in top 10, median #22. | BW11: Sleephoria (same product and price — strongest evidence): positive but small sample (35 clicks, CVR 11.4%); organic best #4 (2026-04-05), first top-10 2025-10-15, now #14. | BX11: SV 2,630/mo (MKL (DataDive)); launch window ≈ 2,485/mo; SQP 12-mo 51,598 searches, peak 2026-07, Oct at 0.86× its avg; Mar-24→Mar-26 ×1.75; market CVR 6.1% (head term 1.5%). | BY11: Organic top 20: Bedsure PW #3, Love's cabin #4, Bambaw #9. Advertising: Bambaw SP#7, BEDELITE SP#9, Love's cabin SP#12, Hotel Sheets Direct SP#12. Rival ad share 56%. | BZ11: Top-20 is held by bamboo/viscose sets (Bedsure PW, Love's cabin, Bambaw); no synthetic cooling-knit rival ranks here. CooLinens is the only nylon/spandex cooling option on the page at $79.99 — Sleephoria proved the knit ranks here. | CA11: Launch-window demand is ~35% of the June peak but these are the terms where evidence is strongest; ranking now means CooLinens holds position before the March ramp (SQP March ≈ 2× January). Queen roots belong to CooLinens, so this can be pushed at ranking spend from day 1. | CB11: Batch 1 Hero: relevance 100% ≥ 90%, clean wording, launch-window demand 2,485 searches/mo > 300 (own campaign), and evidence score 7.5/12 ≥ 6.0 (Sleephoria PPC +2 · Sleephoria rank +2 · market CVR +2 · competitors +1 · Decolure +0.5). Sleephoria did not overpay on it beyond the ranking ceiling. | CC11: ≤10 (≤40 by wk 2, ≤20 by wk 4, ≤10 by wk 8): Sleephoria, the same product, reached #4 here; 3 tracked rival(s) in the top 20.
