Workbook

Sheet Summary
A1: CooLinens Cooling Sheets 4PC — Data-Backed PPC Launch Strategy (DRAFT v2)
A2: Go-live 15 Oct 2026 · US · Parent B0H6K5RPX6 · Prepared 8 Oct 2026 for the 10 Oct review · v2 = v1 + full historical analysis (see CooLinens_Cooling_Sheets_4PC_Historical_Analysis_v1.xlsx) · MKL integration pending (see MKL_Intake)
A4: 1. Bottom line
A5: • Benchmark = Sleephoria Cooling Sheets 4PC (same COGS to within $0.30/size, same 12 colours, same sizes, same list price today: Queen $79.99 / King $84.99). Decolure is a $38 microfiber tier — use it for "what not to do", not for economics.
A6: • CooLinens is therefore a near-twin of Sleephoria, not a premium tier above it. Because the two are the same product at the same price, the main launch risk is the two listings bidding against each other on the same keywords. (v1 cited Decolure's session collapse after Sleephoria's launch; the historical analysis shows Decolure's decline started in Jul 2025, before Sleephoria's ads — that rationale is withdrawn.) SOP-33 requires a declared owner per shared keyword root before ranking-size spend.
A7: • Proposal: CooLinens leads the QUEEN cluster (biggest size: 41% of CooLinens stock, ~35–42% of category units) where Sleephoria is weak (organic 45–69) — and Sleephoria keeps the roots it already wins (head term #11–18, King #8–18, Twin #5, Cal King #3–9, "hot sleepers" #5–7). Two of our listings on page 1 > two listings bidding against each other.
A8: • Day 0 = 12 single-keyword SP Exact campaigns on the Queen Graphite child (B0H6K1MKQW, 373 FBA units; Graphite converted 13% vs 3.7% for other colours at Sleephoria). Fixed bids, all placement modifiers 0, no broad/phrase/auto/SB/SD/PAT on day 1 (SOP-22 P3.4).
A9: • Queen terms open as a SOP-33 P5 probe (50 → 100 clicks), are declared ~22 Oct, then scale to ranking size before the BFCM pre-event window (13 Nov). Day-0 budget ≈ $130/day (~$910/wk); post-declaration ≈ $175/day (~$1,220/wk) inside a declared $1,750/wk envelope, leaving ~$530/wk for Batch 2 / Phase 2. Projected blended ACoS ≈ 41% at 9% CVR. Queen ranking rows ≈ $113/day vs a Sleephoria-equivalent $135/day (cross-check). Every number is a live formula on editable inputs.
A10: 2. What the history says (numbers in the benchmark tabs)
A11: • Sleephoria launch curve (ad months 1→2→3): TACoS 24% → 15% → 10%, margin 3% → 11% → 17%; first ~20% margin in ad month 5. Spend $17.6k → $11.5k → $6.4k. CPC $4.87 → $4.24 → $2.49.
A12: • Top-10 on the head terms took ~12 days at ~$790/day, CPC ~$5, ACoS ~50% (with Prime Big Deal Days tailwind and some prior organic history). Rank decayed within 2–4 weeks whenever spend fell below ~$70/day or CVR collapsed (Dec–Jan and Jun–Jul).
A13: • Plan to NON-BRAND benchmarks: Sleephoria non-brand ACoS 31.5%, CVR 10.6%, CPC $2.24 (its blended figures lean on branded search at 14% ACoS, which CooLinens will not have).
... A28: Sources: Sellerboard (Ecotero account), Ecotero command center (ppc_* / traffic_* tools, products 45, 48, 69), DataDive niches & Rank Radar (read-only), team SOPs 06/12–19/22/23/28–30/32/33 + config/thresholds.yml in this repo. No live campaign was changed.

Sheet Economics
A1: CooLinens unit economics & bid ceilings (PROVISIONAL spine — SOP-22 P2.3 / rule M1)
A2: Blue = inputs. Price from Ali Muhammad's 6 Oct launch note; FBA fee & COGS from Sellerboard (Ecotero) 8 Oct 2026; referral 15%. Tag PROVISIONAL until per-variation margin lands (no fee data in command center yet).
A4: Input | B4: Value | C4: Source / rationale
A5: Launch CVR (base) | B5: 0.09 | C5: Sleephoria non-brand CVR 10.6% (Dec-25→Oct-26); Sep-26 at $77.58 ASP = 9.4%. New listing with 24 Vine reviews → 9% base.
A6: Launch CVR (downside) | B6: 0.06 | C6: Sleephoria Oct-26 with stockouts = 6.2%; market SQP CVR on cooling terms ≈ 3–4%.
A7: Refund + storage allowance ($/unit) | B7: 3.5 | C7: Sleephoria refund rate 5.4% lifetime; storage ~ $1/unit. Not in the per-unit fee estimate.
A8: Target ACoS factor (× BE) | B8: 0.5 | C8: SOP-22 rule M1: TargetACOS = 50% × BE_ACOS
A9: Max acceptable ACoS factor (× BE) | B9: 0.75 | C9: SOP-22 rule M1: MaxAccACOS = 75% × BE_ACOS
A10: Account reference Expected CPC | B10: 2.8 | C10: SOP-12/22: use $2.80 PROVISIONAL when no per-term Expected CPC exists
A11: Launch CPC premium (× Sleephoria hist CPC) | B11: 1.25 | C11: Sleephoria launch CPC was $4.87 vs $2.24 steady non-brand; new brand + TOS competition. Assumption.
A12: CPC floor | B12: 1.5 | C12: Assumption: below this, head-term exacts did not serve at Sleephoria/Decolure.
A13: Target purchase share at target rank | B13: 0.08 | C13: DSTR input. Market is fragmented (top-3 conversion share 4.2%); Sleephoria held 0.4–1.7% share at rank 11–45. 8% = launch headroom to out-sell the rank-10 incumbents (ad + organic). Assumption — calibrate after week 2.
A14: Default market purchase rate (purchases ÷ searches) | B14: 0.017 | C14: SQP Jul–Sep 2026 median across cooling terms (term-specific rates used where available).
A15: Capped-test / probe clicks (tranche 1) | B15: 50 | C15: SOP-33 P5 tranche 1 = 50 clicks (tranche 2 up to 100)
A16: Capped-test window (days) | B16: 14 | C16: SOP-22 WE-1 capped test over 14 days
... A18: Weekly envelope (declared) | B18: 1750 | C18: Declared envelope for the batch-1 plan; G7: budgets must sum ≤ 110% of envelope.
A20: Per-size economics
A21: Size | B21: Price | C21: Referral % | D21: Referral $ | E21: FBA fee | F21: COGS (landed) | G21: Allowance | H21: Margin / order | I21: BE ACoS | J21: Target ACoS | K21: Max acc. ACoS | L21: Max profitable CPC (base CVR) | M21: Max profitable CPC (downside CVR) | N21: Target CPC (base CVR) | O21: Margin class | P21: FBA stock 8 Oct | Q21: Stock share | R21: Sleephoria units share L90D | S21: Sleephoria NP/unit L90D
A22: Twin | B22: 62.99 | C22: 0.15 | D22: =B22*C22 -> 9.4485 | E22: 7.9 | F22: 19.94 | G22: =Economics!$B$7 -> 3.5 | H22: =B22-D22-E22-F22-G22 -> 22.2015 | I22: =IF(B22>0,H22/B22,0) -> 0.35246071 | J22: =I22*Economics!$B$8 -> 0.17623035 | K22: =I22*Economics!$B$9 -> 0.26434553 | L22: =H22*Economics!$B$5 -> 1.998135 | M22: =H22*Economics!$B$6 -> 1.33209 | N22: =B22*J22*Economics!$B$5 -> 0.9990675 | O22: =IF(H22<6,"THIN",IF(H22<=15,"STANDARD","RICH")) -> RICH | P22: 387 | Q22: =P22/SUM($P$22:$P$26) -> 0.10386473 | R22: 0.115 | S22: 15.69
A23: Full | B23: 67.99 | C23: 0.15 | D23: =B23*C23 -> 10.1985 | E23: 8.31 | F23: 24.61 | G23: =Economics!$B$7 -> 3.5 | H23: =B23-D23-E23-F23-G23 -> 21.3715 | I23: =IF(B23>0,H23/B23,0) -> 0.31433299 | J23: =I23*Economics!$B$8 -> 0.1571665 | K23: =I23*Economics!$B$9 -> 0.23574974 | L23: =H23*Economics!$B$5 -> 1.923435 | M23: =H23*Economics!$B$6 -> 1.28229 | N23: =B23*J23*Economics!$B$5 -> 0.9617175 | O23: =IF(H23<6,"THIN",IF(H23<=15,"STANDARD","RICH")) -> RICH | P23: 530 | Q23: =P23/SUM($P$22:$P$26) -> 0.14224369 | R23: 0.139 | S23: 10.38
A24: Queen | B24: 79.99 | C24: 0.15 | D24: =B24*C24 -> 11.9985 | E24: 8.5 | F24: 25.88 | G24: =Economics!$B$7 -> 3.5 | H24: =B24-D24-E24-F24-G24 -> 30.1115 | I24: =IF(B24>0,H24/B24,0) -> 0.37644081 | J24: =I24*Economics!$B$8 -> 0.1882204 | K24: =I24*Economics!$B$9 -> 0.2823306 | L24: =H24*Economics!$B$5 -> 2.710035 | M24: =H24*Economics!$B$6 -> 1.80669 | N24: =B24*J24*Economics!$B$5 -> 1.3550175 | O24: =IF(H24<6,"THIN",IF(H24<=15,"STANDARD","RICH")) -> RICH | P24: 1541 | Q24: =P24/SUM($P$22:$P$26) -> 0.41358025 | R24: 0.343 | S24: 11.68
A25: King | B25: 84.99 | C25: 0.15 | D25: =B25*C25 -> 12.7485 | E25: 8.9 | F25: 30.02 | G25: =Economics!$B$7 -> 3.5 | H25: =B25-D25-E25-F25-G25 -> 29.8215 | I25: =IF(B25>0,H25/B25,0) -> 0.35088246 | J25: =I25*Economics!$B$8 -> 0.17544123 | K25: =I25*Economics!$B$9 -> 0.26316184 | L25: =H25*Economics!$B$5 -> 2.683935 | M25: =H25*Economics!$B$6 -> 1.78929 | N25: =B25*J25*Economics!$B$5 -> 1.3419675 | O25: =IF(H25<6,"THIN",IF(H25<=15,"STANDARD","RICH")) -> RICH | P25: 873 | Q25: =P25/SUM($P$22:$P$26) -> 0.23429952 | R25: 0.29 | S25: 15.03
A26: Cal King | B26: 86.99 | C26: 0.15 | D26: =B26*C26 -> 13.0485 | E26: 8.73 | F26: 31.62 | G26: =Economics!$B$7 -> 3.5 | H26: =B26-D26-E26-F26-G26 -> 30.0915 | I26: =IF(B26>0,H26/B26,0) -> 0.34591907 | J26: =I26*Economics!$B$8 -> 0.17295954 | K26: =I26*Economics!$B$9 -> 0.2594393 | L26: =H26*Economics!$B$5 -> 2.708235 | M26: =H26*Economics!$B$6 -> 1.80549 | N26: =B26*J26*Economics!$B$5 -> 1.3541175 | O26: =IF(H26<6,"THIN",IF(H26<=15,"STANDARD","RICH")) -> RICH | P26: 395 | Q26: =P26/SUM($P$22:$P$26) -> 0.10601181 | R26: 0.114 | S26: 19.59
A28: Notes
A29: BE ACoS here (≈31–38%) is higher than Sleephoria's command-center figure (~31%) only because it uses today's list prices; Sleephoria at the same $79.99/$84.99 has the same math.
A30: Margin class RICH (> $15/order) on every size → THIN-margin CPC cap (margin ÷ 3) does not apply.
A31: Ceiling read (SOP-23): Expected CPC ÷ max profitable CPC ≤0.8 SAFE · 0.8–1.0 AT-CEILING · 1.0–1.5 PUSH-ONLY · >1.5 UNJUSTIFIABLE outside a sized push.
A32: Full has the thinnest margin and the lowest Sleephoria NP/unit → do not lead with Full; King is the best Sleephoria profit engine but its keywords are the most expensive (CPC $3.3–4.9).

Sheet Batch1_Plan
A1: Batch 1 — Day-0 single-keyword SP Exact plan (go-live 15 Oct 2026)
A2: SOP-22 P3: one campaign / one keyword / one ad group · fixed bids · TOS/ROS/PP modifiers 0 · advertised SKU = D2 preferred variation. Blue = inputs; black = formulas (edit Economics inputs to re-size).
A4: # | B4: Keyword | C4: Type | D4: Sibling status (SOP-33) | E4: Objective | F4: Campaign name (SOP-12 App. A) | G4: Advertised SKU (D2) | H4: ASIN | I4: Size | J4: Wk SV (6 Oct) | K4: DD monthly SV | L4: SV tier | M4: Rivals organic top-10 | N4: Ad share of traffic | O4: Sleephoria org rank | P4: Decolure org rank | Q4: Sleephoria hist clicks | R4: Sleephoria hist CPC | S4: Sleephoria hist CVR | T4: Sleephoria hist ACoS | U4: Expected CPC = start bid | V4: Market purchase rate | W4: DSTR (orders/day) | X4: CVR used | Y4: Clicks/day — Day 0 (probe/cap) | Z4: Daily budget — Day 0 | AA4: Clicks/day — post-declaration | AB4: Daily budget — post-declaration | AC4: Price | AD4: Projected ACoS | AE4: BE ACoS | AF4: Weekly loss ceiling (post-decl.) | AG4: Max profitable CPC | AH4: Ceiling read | AI4: Target organic rank | AJ4: Rationale / evidence
A5: 1 | B5: cooling sheets queen | C5: Ranking | D5: Shared root — Sleephoria live, organic 35–45 (not owner-grade) | E5: Ranking | F5: CLCS4-SP-cooling sheets queen-VHSV-Exact-Rank-Fix-Q-GRAPHITE | G5: CL-COOLING-SHEET-QUEEN-GRAPHITE | H5: B0H6K1MKQW | I5: Queen | J5: 7904 | K5: 41329 | L5: VHSV | M5: 4 | N5: 0.451 | O5: 45 | P5: 110 | Q5: 2552 | R5: 2.24 | S5: 0.1187 | T5: 0.289 | U5: =IF(R5="",Economics!$B$10,MAX(Economics!$B$12,R5*Economics!$B$11)) -> 2.8 | V5: 0.0175 | W5: =IF(C5="Ranking",J5/7*V5*Economics!$B$13,0) -> 1.5808 | X5: =Economics!$B$5 -> 0.09 | Y5: =Economics!$B$15/Economics!$B$16 -> 3.5714286 | Z5: =MAX(Economics!$B$17,Y5*U5) -> 10 | AA5: =IF(C5="Ranking",MAX(W5/X5,Economics!$B$15/Economics!$B$16),Economics!$B$15/Economics!$B$16) -> 17.564444 | AB5: =MAX(Economics!$B$17,AA5*U5) -> 49.180444 | AC5: =INDEX(Economics!$B$22:$B$26,MATCH(I5,Economics!$A$22:$A$26,0)) -> 79.99 | AD5: =U5/(AC5*X5) -> 0.38893751 | AE5: =INDEX(Economics!$I$22:$I$26,MATCH(I5,Economics!$A$22:$A$26,0)) -> 0.37644081 | AF5: =MAX(0,(AD5-AE5)*AA5*7*X5*AC5) -> 11.061297 | AG5: =INDEX(Economics!$L$22:$L$26,MATCH(I5,Economics!$A$22:$A$26,0)) -> 2.710035 | AH5: =IF(U5/AG5<=0.8,"SAFE",IF(U5/AG5<=1,"AT-CEILING",IF(U5/AG5<=1.5,"PUSH-ONLY","UNJUSTIFIABLE"))) -> PUSH-ONLY | AI5: 10 | AJ5: Largest size term (DD 41.3k/mo). Sleephoria 28.9% ACoS / 11.9% CVR here — proven converter. Sleephoria fell from #5 to 35–45 → open gap.
A6: 2 | B6: queen sheets cooling | C6: Ranking | D6: Shared root — Sleephoria organic 69 | E6: Ranking | F6: CLCS4-SP-queen sheets cooling-HSV-Exact-Rank-Fix-Q-GRAPHITE | G6: CL-COOLING-SHEET-QUEEN-GRAPHITE | H6: B0H6K1MKQW | I6: Queen | J6: 1212 | K6: 7935 | L6: HSV | M6: 2 | N6: 0.365 | O6: 69 | P6: 127 | Q6: 55 | R6: 2.42 | S6: 0.0909 | T6: 0.37 | U6: =IF(R6="",Economics!$B$10,MAX(Economics!$B$12,R6*Economics!$B$11)) -> 3.025 | V6: 0.0307 | W6: =IF(C6="Ranking",J6/7*V6*Economics!$B$13,0) -> 0.42523886 | X6: =Economics!$B$5 -> 0.09 | Y6: =Economics!$B$15/Economics!$B$16 -> 3.5714286 | Z6: =MAX(Economics!$B$17,Y6*U6) -> 10.803571 | AA6: =IF(C6="Ranking",MAX(W6/X6,Economics!$B$15/Economics!$B$16),Economics!$B$15/Economics!$B$16) -> 4.7248762 | AB6: =MAX(Economics!$B$17,AA6*U6) -> 14.29275 | AC6: =INDEX(Economics!$B$22:$B$26,MATCH(I6,Economics!$A$22:$A$26,0)) -> 79.99 | AD6: =U6/(AC6*X6) -> 0.42019141 | AE6: =INDEX(Economics!$I$22:$I$26,MATCH(I6,Economics!$A$22:$A$26,0)) -> 0.37644081 | AF6: =MAX(0,(AD6-AE6)*AA6*7*X6*AC6) -> 10.417194 | AG6: =INDEX(Economics!$L$22:$L$26,MATCH(I6,Economics!$A$22:$A$26,0)) -> 2.710035 | AH6: =IF(U6/AG6<=0.8,"SAFE",IF(U6/AG6<=1,"AT-CEILING",IF(U6/AG6<=1.5,"PUSH-ONLY","UNJUSTIFIABLE"))) -> PUSH-ONLY | AI6: 10 | AJ6: DD ~7.9k/mo; SQP purchase rate 3.1% (highest of queen terms). No sibling in top 30.
A7: 3 | B7: queen cooling sheets | C7: Ranking | D7: Shared root — Sleephoria organic 45, Decolure 130 | E7: Ranking | F7: CLCS4-SP-queen cooling sheets-HSV-Exact-Rank-Fix-Q-GRAPHITE | G7: CL-COOLING-SHEET-QUEEN-GRAPHITE | H7: B0H6K1MKQW | I7: Queen | J7: 1127 | K7: 6994 | L7: HSV | M7: 2 | N7: 0.367 | O7: 45 | P7: 130 | Q7: 78 | R7: 2.38 | S7: 0.1282 | T7: 0.23 | U7: =IF(R7="",Economics!$B$10,MAX(Economics!$B$12,R7*Economics!$B$11)) -> 2.975 | V7: 0.0288 | W7: =IF(C7="Ranking",J7/7*V7*Economics!$B$13,0) -> 0.370944 | X7: =Economics!$B$5 -> 0.09 | Y7: =Economics!$B$15/Economics!$B$16 -> 3.5714286 | Z7: =MAX(Economics!$B$17,Y7*U7) -> 10.625 | AA7: =IF(C7="Ranking",MAX(W7/X7,Economics!$B$15/Economics!$B$16),Economics!$B$15/Economics!$B$16) -> 4.1216 | AB7: =MAX(Economics!$B$17,AA7*U7) -> 12.26176 | AC7: =INDEX(Economics!$B$22:$B$26,MATCH(I7,Economics!$A$22:$A$26,0)) -> 79.99 | AD7: =U7/(AC7*X7) -> 0.4132461 | AE7: =INDEX(Economics!$I$22:$I$26,MATCH(I7,Economics!$A$22:$A$26,0)) -> 0.37644081 | AF7: =MAX(0,(AD7-AE7)*AA7*7*X7*AC7) -> 7.6445582 | AG7: =INDEX(Economics!$L$22:$L$26,MATCH(I7,Economics!$A$22:$A$26,0)) -> 2.710035 | AH7: =IF(U7/AG7<=0.8,"SAFE",IF(U7/AG7<=1,"AT-CEILING",IF(U7/AG7<=1.5,"PUSH-ONLY","UNJUSTIFIABLE"))) -> PUSH-ONLY | AI7: 10 | AJ7: DD 7.0k/mo; Sleephoria 23% ACoS / 12.8% CVR when served.
A8: 4 | B8: cooling bed sheets queen | C8: Ranking | D8: Shared root — Sleephoria organic 18 (borderline) | E8: Ranking | F8: CLCS4-SP-cooling bed sheets queen-HSV-Exact-Rank-Fix-Q-GRAPHITE | G8: CL-COOLING-SHEET-QUEEN-GRAPHITE | H8: B0H6K1MKQW | I8: Queen | J8: 598 | K8: 4766 | L8: HSV | M8: 4 | N8: 0.305 | O8: 18 | P8: 140 | Q8: 86 | R8: 1.96 | S8: 0.0465 | T8: 0.569 | U8: =IF(R8="",Economics!$B$10,MAX(Economics!$B$12,R8*Economics!$B$11)) -> 2.45 | V8: 0.0156 | W8: =IF(C8="Ranking",J8/7*V8*Economics!$B$13,0) -> 0.10661486 | X8: =Economics!$B$5 -> 0.09 | Y8: =Economics!$B$15/Economics!$B$16 -> 3.5714286 | Z8: =MAX(Economics!$B$17,Y8*U8) -> 10 | AA8: =IF(C8="Ranking",MAX(W8/X8,Economics!$B$15/Economics!$B$16),Economics!$B$15/Economics!$B$16) -> 3.5714286 | AB8: =MAX(Economics!$B$17,AA8*U8) -> 10 | AC8: =INDEX(Economics!$B$22:$B$26,MATCH(I8,Economics!$A$22:$A$26,0)) -> 79.99 | AD8: =U8/(AC8*X8) -> 0.34032032 | AE8: =INDEX(Economics!$I$22:$I$26,MATCH(I8,Economics!$A$22:$A$26,0)) -> 0.37644081 | AF8: =MAX(0,(AD8-AE8)*AA8*7*X8*AC8) -> 0 | AG8: =INDEX(Economics!$L$22:$L$26,MATCH(I8,Economics!$A$22:$A$26,0)) -> 2.710035 | AH8: =IF(U8/AG8<=0.8,"SAFE",IF(U8/AG8<=1,"AT-CEILING",IF(U8/AG8<=1.5,"PUSH-ONLY","UNJUSTIFIABLE"))) -> AT-CEILING | AI8: 15 | AJ8: DD 4.8k/mo; Decolure ranked top-10 here in 2025 on a $38 product. Watch CVR (Sleephoria 4.7% on 86 clicks).
A9: 5 | B9: queen size cooling sheets | C9: Ranking | D9: Shared root — Sleephoria organic 48 | E9: Ranking | F9: CLCS4-SP-queen size cooling sheets-HSV-Exact-Rank-Fix-Q-GRAPHITE | G9: CL-COOLING-SHEET-QUEEN-GRAPHITE | H9: B0H6K1MKQW | I9: Queen | J9: 572 | K9: 3107 | L9: HSV | M9: 2 | N9: 0.349 | O9: 48 | P9: 142 | Q9: 37 | R9: 3.05 | S9: 0.027 | T9: 1.413 | U9: =IF(R9="",Economics!$B$10,MAX(Economics!$B$12,R9*Economics!$B$11)) -> 3.8125 | V9: 0.0275 | W9: =IF(C9="Ranking",J9/7*V9*Economics!$B$13,0) -> 0.17977143 | X9: =Economics!$B$5 -> 0.09 | Y9: =Economics!$B$15/Economics!$B$16 -> 3.5714286 | Z9: =MAX(Economics!$B$17,Y9*U9) -> 13.616071 | AA9: =IF(C9="Ranking",MAX(W9/X9,Economics!$B$15/Economics!$B$16),Economics!$B$15/Economics!$B$16) -> 3.5714286 | AB9: =MAX(Economics!$B$17,AA9*U9) -> 13.616071 | AC9: =INDEX(Economics!$B$22:$B$26,MATCH(I9,Economics!$A$22:$A$26,0)) -> 79.99 | AD9: =U9/(AC9*X9) -> 0.52958009 | AE9: =INDEX(Economics!$I$22:$I$26,MATCH(I9,Economics!$A$22:$A$26,0)) -> 0.37644081 | AF9: =MAX(0,(AD9-AE9)*AA9*7*X9*AC9) -> 27.561625 | AG9: =INDEX(Economics!$L$22:$L$26,MATCH(I9,Economics!$A$22:$A$26,0)) -> 2.710035 | AH9: =IF(U9/AG9<=0.8,"SAFE",IF(U9/AG9<=1,"AT-CEILING",IF(U9/AG9<=1.5,"PUSH-ONLY","UNJUSTIFIABLE"))) -> PUSH-ONLY | AI9: 15 | AJ9: Gap term; Sleephoria wasted $113 here (1 order / 37 clicks) — start at Expected CPC, no TOS modifier.
A10: 6 | B10: cooling queen sheets | C10: Ranking | D10: Shared root — Sleephoria organic 24 | E10: Ranking | F10: CLCS4-SP-cooling queen sheets-HSV-Exact-Rank-Fix-Q-GRAPHITE | G10: CL-COOLING-SHEET-QUEEN-GRAPHITE | H10: B0H6K1MKQW | I10: Queen | J10: 592 | K10: 3027 | L10: HSV | M10: 2 | N10: 0.311 | O10: 24 | P10: 124 | Q10: 234 | R10: 2.95 | S10: 0.1111 | T10: 0.38 | U10: =IF(R10="",Economics!$B$10,MAX(Economics!$B$12,R10*Economics!$B$11)) -> 3.6875 | V10: 0.0186 | W10: =IF(C10="Ranking",J10/7*V10*Economics!$B$13,0) -> 0.12584229 | X10: =Economics!$B$5 -> 0.09 | Y10: =Economics!$B$15/Economics!$B$16 -> 3.5714286 | Z10: =MAX(Economics!$B$17,Y10*U10) -> 13.169643 | AA10: =IF(C10="Ranking",MAX(W10/X10,Economics!$B$15/Economics!$B$16),Economics!$B$15/Economics!$B$16) -> 3.5714286 | AB10: =MAX(Economics!$B$17,AA10*U10) -> 13.169643 | AC10: =INDEX(Economics!$B$22:$B$26,MATCH(I10,Economics!$A$22:$A$26,0)) -> 79.99 | AD10: =U10/(AC10*X10) -> 0.5122168 | AE10: =INDEX(Economics!$I$22:$I$26,MATCH(I10,Economics!$A$22:$A$26,0)) -> 0.37644081 | AF10: =MAX(0,(AD10-AE10)*AA10*7*X10*AC10) -> 24.436625 | AG10: =INDEX(Economics!$L$22:$L$26,MATCH(I10,Economics!$A$22:$A$26,0)) -> 2.710035 | AH10: =IF(U10/AG10<=0.8,"SAFE",IF(U10/AG10<=1,"AT-CEILING",IF(U10/AG10<=1.5,"PUSH-ONLY","UNJUSTIFIABLE"))) -> PUSH-ONLY | AI10: 15 | AJ10: Sleephoria 38% ACoS / 11.1% CVR (234 clicks) — growth-acceptable.
A11: 7 | B11: cooling sheet set | C11: Discovery (capped) | D11: Weakly held — Sleephoria organic 38 | E11: Discovery | F11: CLCS4-SP-cooling sheet set-HSV-Exact-Disc-Fix-Q-GRAPHITE | G11: CL-COOLING-SHEET-QUEEN-GRAPHITE | H11: B0H6K1MKQW | I11: Queen | J11: 337 | K11: 3289 | L11: HSV | M11: 3 | N11: 0.415 | O11: 38 | P11: 135 | Q11: 61 | R11: 2.35 | S11: 0.0984 | T11: 0.302 | U11: =IF(R11="",Economics!$B$10,MAX(Economics!$B$12,R11*Economics!$B$11)) -> 2.9375 | V11: 0.0066 | W11: =IF(C11="Ranking",J11/7*V11*Economics!$B$13,0) -> 0 | X11: =Economics!$B$5 -> 0.09 | Y11: =Economics!$B$15/Economics!$B$16 -> 3.5714286 | Z11: =MAX(Economics!$B$17,Y11*U11) -> 10.491071 | AA11: =IF(C11="Ranking",MAX(W11/X11,Economics!$B$15/Economics!$B$16),Economics!$B$15/Economics!$B$16) -> 3.5714286 | AB11: =MAX(Economics!$B$17,AA11*U11) -> 10.491071 | AC11: =INDEX(Economics!$B$22:$B$26,MATCH(I11,Economics!$A$22:$A$26,0)) -> 79.99 | AD11: =U11/(AC11*X11) -> 0.40803712 | AE11: =INDEX(Economics!$I$22:$I$26,MATCH(I11,Economics!$A$22:$A$26,0)) -> 0.37644081 | AF11: =MAX(0,(AD11-AE11)*AA11*7*X11*AC11) -> 5.686625 | AG11: =INDEX(Economics!$L$22:$L$26,MATCH(I11,Economics!$A$22:$A$26,0)) -> 2.710035 | AH11: =IF(U11/AG11<=0.8,"SAFE",IF(U11/AG11<=1,"AT-CEILING",IF(U11/AG11<=1.5,"PUSH-ONLY","UNJUSTIFIABLE"))) -> PUSH-ONLY | AI11: 20 | AJ11: Set-intent term matches 4-piece; Sleephoria 30.2% ACoS. Premium rival Breescape #10.
A12: 8 | B12: best cooling sheets | C12: Discovery (capped) | D12: Weakly held — Sleephoria organic 34 | E12: Discovery | F12: CLCS4-SP-best cooling sheets-HSV-Exact-Disc-Fix-Q-GRAPHITE | G12: CL-COOLING-SHEET-QUEEN-GRAPHITE | H12: B0H6K1MKQW | I12: Queen | J12: 259 | K12: 2716 | L12: HSV | M12: 4 | N12: 0.253 | O12: 34 | P12: 140 | Q12: 211 | R12: 1.32 | S12: 0.0521 | T12: 0.373 | U12: =IF(R12="",Economics!$B$10,MAX(Economics!$B$12,R12*Economics!$B$11)) -> 1.65 | V12: 0.0056 | W12: =IF(C12="Ranking",J12/7*V12*Economics!$B$13,0) -> 0 | X12: =Economics!$B$5 -> 0.09 | Y12: =Economics!$B$15/Economics!$B$16 -> 3.5714286 | Z12: =MAX(Economics!$B$17,Y12*U12) -> 10 | AA12: =IF(C12="Ranking",MAX(W12/X12,Economics!$B$15/Economics!$B$16),Economics!$B$15/Economics!$B$16) -> 3.5714286 | AB12: =MAX(Economics!$B$17,AA12*U12) -> 10 | AC12: =INDEX(Economics!$B$22:$B$26,MATCH(I12,Economics!$A$22:$A$26,0)) -> 79.99 | AD12: =U12/(AC12*X12) -> 0.22919532 | AE12: =INDEX(Economics!$I$22:$I$26,MATCH(I12,Economics!$A$22:$A$26,0)) -> 0.37644081 | AF12: =MAX(0,(AD12-AE12)*AA12*7*X12*AC12) -> 0 | AG12: =INDEX(Economics!$L$22:$L$26,MATCH(I12,Economics!$A$22:$A$26,0)) -> 2.710035 | AH12: =IF(U12/AG12<=0.8,"SAFE",IF(U12/AG12<=1,"AT-CEILING",IF(U12/AG12<=1.5,"PUSH-ONLY","UNJUSTIFIABLE"))) -> SAFE | AI12: 20 | AJ12: Comparison shoppers; REST #17. Sleephoria 37% ACoS / 5.2% CVR → keep capped.
A13: 9 | B13: cooling bedding | C13: Discovery (capped) | D13: Unowned — neither sibling ranks | E13: Discovery | F13: CLCS4-SP-cooling bedding-HSV-Exact-Disc-Fix-Q-GRAPHITE | G13: CL-COOLING-SHEET-QUEEN-GRAPHITE | H13: B0H6K1MKQW | I13: Queen | J13: 494 | K13: 4862 | L13: HSV | M13: 0 | N13: 0.406 | O13: NR | P13: NR | Q13: 2 | U13: =IF(R13="",Economics!$B$10,MAX(Economics!$B$12,R13*Economics!$B$11)) -> 2.8 | V13: =Economics!$B$14 -> 0.017 | W13: =IF(C13="Ranking",J13/7*V13*Economics!$B$13,0) -> 0 | X13: =Economics!$B$5 -> 0.09 | Y13: =Economics!$B$15/Economics!$B$16 -> 3.5714286 | Z13: =MAX(Economics!$B$17,Y13*U13) -> 10 | AA13: =IF(C13="Ranking",MAX(W13/X13,Economics!$B$15/Economics!$B$16),Economics!$B$15/Economics!$B$16) -> 3.5714286 | AB13: =MAX(Economics!$B$17,AA13*U13) -> 10 | AC13: =INDEX(Economics!$B$22:$B$26,MATCH(I13,Economics!$A$22:$A$26,0)) -> 79.99 | AD13: =U13/(AC13*X13) -> 0.38893751 | AE13: =INDEX(Economics!$I$22:$I$26,MATCH(I13,Economics!$A$22:$A$26,0)) -> 0.37644081 | AF13: =MAX(0,(AD13-AE13)*AA13*7*X13*AC13) -> 2.249125 | AG13: =INDEX(Economics!$L$22:$L$26,MATCH(I13,Economics!$A$22:$A$26,0)) -> 2.710035 | AH13: =IF(U13/AG13<=0.8,"SAFE",IF(U13/AG13<=1,"AT-CEILING",IF(U13/AG13<=1.5,"PUSH-ONLY","UNJUSTIFIABLE"))) -> PUSH-ONLY | AI13: 20 | AJ13: DD 4.9k/mo; 0 rivals in organic top 10. Uncontested.
A14: 10 | B14: hot sleepers must haves | C14: Discovery (capped) | D14: Unowned — Sleephoria organic 130 | E14: Discovery | F14: CLCS4-SP-hot sleepers must haves-HSV-Exact-Disc-Fix-Q-GRAPHITE | G14: CL-COOLING-SHEET-QUEEN-GRAPHITE | H14: B0H6K1MKQW | I14: Queen | J14: 463 | K14: 3837 | L14: HSV | M14: 0 | N14: 0.718 | O14: 130 | P14: NR | Q14: 2 | U14: =IF(R14="",Economics!$B$10,MAX(Economics!$B$12,R14*Economics!$B$11)) -> 2.8 | V14: 0.0056 | W14: =IF(C14="Ranking",J14/7*V14*Economics!$B$13,0) -> 0 | X14: =Economics!$B$5 -> 0.09 | Y14: =Economics!$B$15/Economics!$B$16 -> 3.5714286 | Z14: =MAX(Economics!$B$17,Y14*U14) -> 10 | AA14: =IF(C14="Ranking",MAX(W14/X14,Economics!$B$15/Economics!$B$16),Economics!$B$15/Economics!$B$16) -> 3.5714286 | AB14: =MAX(Economics!$B$17,AA14*U14) -> 10 | AC14: =INDEX(Economics!$B$22:$B$26,MATCH(I14,Economics!$A$22:$A$26,0)) -> 79.99 | AD14: =U14/(AC14*X14) -> 0.38893751 | AE14: =INDEX(Economics!$I$22:$I$26,MATCH(I14,Economics!$A$22:$A$26,0)) -> 0.37644081 | AF14: =MAX(0,(AD14-AE14)*AA14*7*X14*AC14) -> 2.249125 | AG14: =INDEX(Economics!$L$22:$L$26,MATCH(I14,Economics!$A$22:$A$26,0)) -> 2.710035 | AH14: =IF(U14/AG14<=0.8,"SAFE",IF(U14/AG14<=1,"AT-CEILING",IF(U14/AG14<=1.5,"PUSH-ONLY","UNJUSTIFIABLE"))) -> PUSH-ONLY | AI14: 20 | AJ14: DD 3.8k/mo; 0 rivals organic top 10, 72% ad traffic. Gift/listicle intent — test only.
A15: 11 | B15: cooling sheets | C15: Probe (sibling-owned) | D15: Sleephoria-owned — organic 11–18 | E15: Discovery | F15: CLCS4-SP-cooling sheets-VHSV-Exact-Disc-Fix-Q-GRAPHITE | G15: CL-COOLING-SHEET-QUEEN-GRAPHITE | H15: B0H6K1MKQW | I15: Queen | J15: 16968 | K15: 129480 | L15: VHSV | M15: 3 | N15: 0.509 | O15: 13 | P15: 132 | Q15: 485 | R15: 2.01 | S15: 0.0948 | T15: 0.295 | U15: =IF(R15="",Economics!$B$10,MAX(Economics!$B$12,R15*Economics!$B$11)) -> 2.5125 | V15: 0.0073 | W15: =IF(C15="Ranking",J15/7*V15*Economics!$B$13,0) -> 0 | X15: =Economics!$B$5 -> 0.09 | Y15: =Economics!$B$15/Economics!$B$16 -> 3.5714286 | Z15: =MAX(Economics!$B$17,Y15*U15) -> 10 | AA15: =IF(C15="Ranking",MAX(W15/X15,Economics!$B$15/Economics!$B$16),Economics!$B$15/Economics!$B$16) -> 3.5714286 | AB15: =MAX(Economics!$B$17,AA15*U15) -> 10 | AC15: =INDEX(Economics!$B$22:$B$26,MATCH(I15,Economics!$A$22:$A$26,0)) -> 79.99 | AD15: =U15/(AC15*X15) -> 0.34900196 | AE15: =INDEX(Economics!$I$22:$I$26,MATCH(I15,Economics!$A$22:$A$26,0)) -> 0.37644081 | AF15: =MAX(0,(AD15-AE15)*AA15*7*X15*AC15) -> 0 | AG15: =INDEX(Economics!$L$22:$L$26,MATCH(I15,Economics!$A$22:$A$26,0)) -> 2.710035 | AH15: =IF(U15/AG15<=0.8,"SAFE",IF(U15/AG15<=1,"AT-CEILING",IF(U15/AG15<=1.5,"PUSH-ONLY","UNJUSTIFIABLE"))) -> AT-CEILING | AJ15: Head term (DD 129k/mo). Capped probe only: collect CooLinens CVR for SOP-33 ceiling test; no ranking spend.
A16: 12 | B16: cooling bed sheets | C16: Probe (sibling-owned) | D16: Sleephoria-owned — organic 15–18 | E16: Discovery | F16: CLCS4-SP-cooling bed sheets-VHSV-Exact-Disc-Fix-Q-GRAPHITE | G16: CL-COOLING-SHEET-QUEEN-GRAPHITE | H16: B0H6K1MKQW | I16: Queen | J16: 3632 | K16: 21134 | L16: VHSV | M16: 4 | N16: 0.425 | O16: 18 | P16: 92 | Q16: 259 | R16: 2.45 | S16: 0.0772 | T16: 0.421 | U16: =IF(R16="",Economics!$B$10,MAX(Economics!$B$12,R16*Economics!$B$11)) -> 3.0625 | V16: 0.0074 | W16: =IF(C16="Ranking",J16/7*V16*Economics!$B$13,0) -> 0 | X16: =Economics!$B$5 -> 0.09 | Y16: =Economics!$B$15/Economics!$B$16 -> 3.5714286 | Z16: =MAX(Economics!$B$17,Y16*U16) -> 10.9375 | AA16: =IF(C16="Ranking",MAX(W16/X16,Economics!$B$15/Economics!$B$16),Economics!$B$15/Economics!$B$16) -> 3.5714286 | AB16: =MAX(Economics!$B$17,AA16*U16) -> 10.9375 | AC16: =INDEX(Economics!$B$22:$B$26,MATCH(I16,Economics!$A$22:$A$26,0)) -> 79.99 | AD16: =U16/(AC16*X16) -> 0.4254004 | AE16: =INDEX(Economics!$I$22:$I$26,MATCH(I16,Economics!$A$22:$A$26,0)) -> 0.37644081 | AF16: =MAX(0,(AD16-AE16)*AA16*7*X16*AC16) -> 8.811625 | AG16: =INDEX(Economics!$L$22:$L$26,MATCH(I16,Economics!$A$22:$A$26,0)) -> 2.710035 | AH16: =IF(U16/AG16<=0.8,"SAFE",IF(U16/AG16<=1,"AT-CEILING",IF(U16/AG16<=1.5,"PUSH-ONLY","UNJUSTIFIABLE"))) -> PUSH-ONLY | AJ16: DD 21k/mo. Capped probe only.
B17: TOTAL | Y17: =SUM(Y5:Y16) -> 42.857143 | Z17: =SUM(Z5:Z16) -> 129.64286 | AA17: =SUM(AA5:AA16) -> 58.553778 | AB17: =SUM(AB5:AB16) -> 173.94924 | AF17: =SUM(AF5:AF16) -> 100.1178
B19: Weekly budget — Day 0 | C19: =Z17*7 -> 907.5
B20: Weekly budget — post-declaration | C20: =AB17*7 -> 1217.6447
B21: Declared weekly envelope | C21: =Economics!$B$18 -> 1750
B22: G7 check: post-declaration budgets ≤ 110% of envelope | C22: =IF(C20<=1.1*C21,"PASS","FAIL — raise envelope or drop terms") -> PASS
B23: Projected weekly ad sales — post-declaration (clicks × CVR × price) | C23: =SUMPRODUCT(AA5:AA16,X5:X16,AC5:AC16)*7 -> 2950.7415
B24: Projected blended ACoS — post-declaration | C24: =IF(C23>0,C20/C23,0) -> 0.41265718
B25: Cross-check: Sleephoria launch-month spend/day (Oct-25) | C25: =608 -> 608
B26: Cross-check: Queen share of Sleephoria cooling spend (Cooling+Queen $8,873 ÷ Cooling $40,089) | C26: =8873/40089 -> 0.22133254
B27: Cross-check: Sleephoria-equivalent Queen spend/day | C27: =C25*C26 -> 134.57018
B28: Queen ranking rows — post-declaration $/day (this plan) | C28: =SUMIF(C5:C16,"Ranking",AB5:AB16) -> 112.52067
B31: Day 0: Ranking rows run at probe level (tranche 1 = 50 clicks over 14 days, bid = Expected CPC) until the SOP-33 owner declaration (target ~22 Oct). Post-declaration = DSTR ÷ CVR clicks/day (SOP-23 M2), floored at the probe rate.
B32: DSTR = weekly SV ÷ 7 × market purchase rate (SQP Jul–Sep 2026 where available) × target purchase share. Sleephoria empirical cross-check: top-10 in ~12 days at ~$790/day across ~100 campaigns, CPC ~$5, ACoS ~50% (with PBDD tailwind). If ranks have not moved by week 3, the SOP-23 sizing is too light — escalate, do not silently add spend.
B33: Placements: TOS / ROS / PP modifiers start at 0 (SOP-22 P3.9). First TOS raise only after ≥15 clicks/7d with TOS CVR > ROS CVR and CPA ≤ ceiling, ≤ +20 pts per move, one move per 14 days (thresholds.yml W6). Off-Amazon: exclude (Sleephoria $661, 0 orders).
B34: Budgets: Sleephoria's branded and King ranking campaigns ran out of budget before noon — check D6 (ranking campaigns must not cap before 20:00) daily during week 1; budget relief ≤ +25% once/week is pre-authorised.
B35: Halo: none on day 0. Sleephoria colour test: Graphite 13% CVR vs 3.7% for all other colours → hero-only. Re-point to Queen Cool Grey (B0H6JWNCK3, 280 FBA) only if Queen Graphite DOH < 21.
B36: Not on day 0 (SOP-22 P3.4/F1): broad, phrase, auto, SB/SBV/SD, PAT/conquest, own-brand defence (no branded search yet).

Sheet Preferred_Backup
A1: Preferred (D2) and backup advertised variation per size
A2: Evidence: Sleephoria & Decolure colour demand by unit share (hero-only ads distort per-SKU CVR/NP), CooLinens FBA 8 Oct 2026. Switch to backup when preferred cover < 21 days (trailing-7d velocity) or below the unit floor with nothing receivable in 10 days; switch back at ≥ 45 days cover.
A4: size | B4: preferred_sku | C4: preferred_asin | D4: preferred_fba_2026-10-08 | E4: preferred_inbound | F4: proj_vel_u_day (SL analogue, hero) | G4: preferred_DOH_base | H4: preferred_DOH_hero_x1.5 | I4: backup_sku | J4: backup_asin | K4: backup_fba_2026-10-08 | L4: backup_inbound | M4: backup_DOH_if_it_inherits_hero_velocity | N4: SL_share_in_size_pref_pct | O4: SL_share_in_size_backup_pct | P4: BM_share_in_size_pref_pct | Q4: BM_share_in_size_backup_pct | R4: switch_to_backup_when | S4: switch_back_when | T4: rationale
A5: Queen | B5: CL-COOLING-SHEET-QUEEN-GRAPHITE | C5: B0H6K1MKQW | D5: 373 | E5: 0 | F5: 3.62 | G5: 103 | H5: 69 | I5: CL-COOLING-SHEET-QUEEN-COOL-GREY | J5: B0H6JWNCK3 | K5: 280 | L5: 0 | M5: 77 | N5: 20 | O5: 14 | P5: 25.6 | Q5: 14.8 | R5: preferred available FBA DOH < 21 at trailing-7d velocity OR preferred FBA < 76 units, with no inbound receivable within 10 days | S5: preferred available FBA >= 45 DOH (received, not just shipped) | T5: Graphite = #1 Queen colour in SL (20% of Queen units, 1,021 u) and BM (BM-QUEEN-GRAPHITE-GREY #1 SKU, 25.6% of BM Queen); deepest CL stock. Cool Grey = #2 in both brands (SL 14%, BM 14.8%) and 2nd-deepest CL stock. Both colours carry ad-landing traffic so their unit-session % (2.4-2.8%) understates true preference.
A6: King | B6: CL-COOLING-SHEET-KING-GRAPHITE | C6: B0H6JXBD3K | D6: 174 | E6: 0 | F6: 2.31 | G6: 75 | H6: 50 | I6: CL-COOLING-SHEET-KING-COOL-GREY | J6: B0H6K77BRL | K6: 146 | L6: 0 | M6: 63 | N6: 19.9 | O6: 12.1 | P6: 17.5 | Q6: 19.5 | R6: preferred available FBA DOH < 21 at trailing-7d velocity OR preferred FBA < 49 units, with no inbound receivable within 10 days | S6: preferred available FBA >= 45 DOH (received, not just shipped) | T6: Graphite #1 King colour SL (19.9%, 26.5% in Jul-Oct 2026) and in BM (17.5%); Cool Grey #2 in SL (12.1%) and #1 in BM (19.5%). CL King Light Grey (#3 SL, best King CVR 6.6%) has only 42 units, too thin for a backup.
A7: CalKing | B7: CL-COOLING-SHEET-CAL-KING-GRAPHITE | C7: B0H6JV73R5 | D7: 66 | E7: 0 | F7: 0.53 | G7: 124 | H7: 82 | I7: CL-COOLING-SHEET-CAL-KING-MIDNIGHT-BLACK | J7: B0H6JZG4W5 | K7: 42 | L7: 0 | M7: 79 | N7: 20.8 | O7: 9.2 | P7: 14.6 | Q7: 11.9 | R7: preferred available FBA DOH < 21 at trailing-7d velocity OR preferred FBA < 15 units, with no inbound receivable within 10 days | S7: preferred available FBA >= 45 DOH (received, not just shipped) | T7: Graphite #1 Cal King in SL (20.8%) and BM (14.6%). Cool Grey is #2 by demand (SL 13.3%, BM 16.2%) but CL holds only 24 units; Midnight Black (SL 9.2%, BM 11.9%, CVR 5.1%) has 42 units, so it is the stock-feasible backup; Cool Grey is tertiary.
A8: Full | B8: CL-COOLING-SHEET-FULL-COOL-GREY | C8: B0H6K4KPGJ | D8: 90 | E8: 0 | F8: 0.77 | G8: 117 | H8: 78 | I8: CL-COOLING-SHEET-FULL-GRAPHITE | J8: B0H6K1C7N1 | K8: 54 | L8: 0 | M8: 70 | N8: 16.5 | O8: 10.9 | P8: 12.5 | Q8: 14.2 | R8: preferred available FBA DOH < 21 at trailing-7d velocity OR preferred FBA < 16 units, with no inbound receivable within 10 days | S8: preferred available FBA >= 45 DOH (received, not just shipped) | T8: SL Full Cool Grey #1 (16.5%) but it was the advertised Full child; Graphite #2 SL (10.9%) and #1 BM Full (14.2%). In Jul-Oct 2026 Full colours are near-even (Midnight Black 13.2%, Cool Grey 10.1%, Graphite 9.6%). Preferred = Cool Grey on CL stock depth (90 vs 54); Graphite backup keeps the dark-grey hero family; Midnight Black (66 u) tertiary.
A9: Twin | B9: CL-COOLING-SHEET-TWIN-GRAPHITE | C9: B0H6K1TJWV | D9: 41 | E9: 0 | F9: 0.73 | G9: 56 | H9: 37 | I9: CL-COOLING-SHEET-TWIN-NAVY-BLUE | J9: B0H6K777C2 | K9: 35 | L9: 1 | M9: 48 | N9: 21.9 | O9: 16.3 | P9: 14.3 | Q9: 9.2 | R9: preferred available FBA DOH < 21 at trailing-7d velocity OR preferred FBA < 15 units, with no inbound receivable within 10 days | S9: preferred available FBA >= 45 DOH (received, not just shipped) | T9: Graphite #1 Twin in SL (21.9%) and BM (14.3%). Navy Blue #2 SL (16.3%, 19.6% in Jul-Oct 2026, best Twin CVR 7.4%). White (48 u) is a stock-deeper tertiary. Both Twin preferred and backup are thin (41/35 u).

Sheet Roadmap
A1: Phase roadmap & dated checkpoints
A2: Dates follow SOP-22 phases, SOP-33 arbitration and the SOP-32 BFCM window (Black Friday 27 Nov 2026, Cyber Monday 30 Nov 2026).
A4: Date | B4: Phase / gate | C4: Actions | D4: Owner | E4: Artifact (SOP)
A5: 8–10 Oct | B5: Pre-launch (P1, day −5) | C5: Strategy review (this file); MKL intake → G12 hygiene; G5 indexing check of all 12 terms on B0H6K1MKQW; G6 inventory; G11 sibling scan; event-window row; envelope G7. | D5: PPC Lead, launch operator | E5: Countersigned P1 checklist; blocker list
A6: 10 Oct | B6: Pre-launch | C6: PPC Lead rulings on Open_Items 1–4. SOP-33 finding opened on shared Queen/head roots; ceiling test (CooLinens margin × best family CVR × depth). | D6: PPC Lead, Brand owner | E6: S-series finding + composite card
A7: 13 Oct | B7: Pre-launch (P2) | C7: Clone Command Workbook; T0 cells AOV/Margin/BE/Target/MaxAcc/ExpectedCPC/Envelope = PROVISIONAL. Build day-0 bulk (12 campaigns). Pre-load walls: "coolinens" negative phrase in Sleephoria/Decolure discovery; sibling ASINs as negative ASIN in all CooLinens auto later. | D7: PPC Specialist | E7: Bulk file + T3 registry + T6 predictions (one per term)
A8: 15 Oct (Day 0) | B8: Phase 1 — Batch 1 | C8: 12 single-keyword exacts live on Queen Graphite; fixed bids = Expected CPC; modifiers 0; Queen ranking terms at probe tranche 1; daily D1–D7 checks start. | D8: PPC Specialist | E8: P3 standup record
A9: 20–22 Oct | B9: Phase 1 — Probe read | C9: Tranche 1 (50 clicks) read; extend to 100 clicks if CVR verdict needed. Six-step structural inspection (SOP-33 P7). Declaration: Queen roots → CooLinens (proposed); Sleephoria Queen terms → DEFEND AT FLOOR; walls confirmed same day. | D9: PPC Lead + Brand owner | E9: Declaration record (6 fields, 3 numeric re-arbitration triggers)
A10: 23 Oct | B10: Phase 1 — Ranking push | C10: Scale Queen exacts to post-declaration size (Batch1_Plan col AB). Sizing worksheet per push (SOP-23), 3-week horizon, stop-loss S-R5. | D10: PPC Specialist | E10: SOP-23 sizing worksheet
A11: 28 Oct | B11: BFCM T-30 | C11: BFCM event plan due (SOP-32): must NAME the CooLinens push, any Phase 2 standup, caps (baseline × lift), deal (recommend coupon / Prime-exclusive discount). | D11: PPC Lead | E11: Event plan v1
A12: 29 Oct | B12: Phase 1 — Batch 2 | C12: 14-day pass: Queen tail Class-2 consolidated exact (see Batch2_Candidates) funded from released budget + unspent envelope (envelope-neutral). MKL-driven additions. | D12: PPC Specialist | E12: P5 progression log
A13: 5 Nov | B13: Honeymoon exit (illustrative 21 days) | C13: No efficiency tightening before this date (SOP-22 P4.3). After: weekly steering per README cadence. | D13: PPC Lead | E13: T5 row
A14: 5–12 Nov | B14: Phase 2 entry (if P7 passes AND named in event plan) | C14: Auto close-match (low bid) + family broad (Queen root, down-only) + harvest register. If not named in the event plan → defer to ≥15 Dec. | D14: PPC Specialist | E14: P7 phase-advance record
A15: 9 Nov | B15: Sibling conflict | C15: Sleephoria Queen "wave 1" push was scheduled — must be cancelled or redirected per the declaration (cannot open on an undeclared/non-owned root, SOP-33 P3). | D15: PPC Lead | E15: Sleephoria plan amendment
... A22: Jan 2027+ | B22: Phase 3–4 (post handoff) | C22: PAT/conquest (PAT_Shortlist), SB brand defence (once branded search exists), SBV if SP CPC ≥ 1.5× ceiling. P10 11-field handoff packet → KDR weekly system. | D22: PPC Lead | E22: P10 packet, P12 co-sign

Sheet Launch_Targets
A1: Launch targets & stop rules
A2: Calibrated on Sleephoria's Oct-25 → Feb-26 curve, discounted for an off-season, new-brand start. SOP-22 §3 launch TACoS band 15–25% (F2).
A4: When | B4: Metric | C4: Target / rule | D4: Basis
A5: Wk 1–2 (15–28 Oct) | B5: Delivery | C5: Every batch-1 exact ≥ 15 clicks / 7 days; no ranking campaign out of budget before 20:00 (D6) | D5: SOP-22 G2; thresholds D6
A6: Wk 1–2 | B6: Conversion | C6: Queen Graphite CVR ≥ 8% on ≥ 50 probe clicks (verdict at 100) | D6: Sleephoria non-brand 10.6%; Sep-26 at $77.58 = 9.4%
A7: Wk 1–2 | B7: Efficiency | C7: Ranking terms ACoS ≤ 80% (ranking envelope 50–80%); blended ≤ 60% | D7: SOP-23 F1; Sleephoria launch 48.8%
A8: Wk 1–2 | B8: Rank | C8: "cooling sheets queen" organic ≤ 50 | D8: Sleephoria went 34–101 → 4 in ~10 days with ~$790/day
A9: Wk 3–4 (to 11 Nov) | B9: Rank | C9: Queen ranking cluster organic top 20 on ≥ 3 of 6 terms | D9: Batch1_Plan target ranks
A10: Wk 3–4 | B10: Volume / TACoS | C10: ≥ 10 units/day total; TACoS ≤ 30% | D10: Sleephoria month-1 TACoS 24.5%; off-season discount
A11: Wk 6 (26 Nov, pre-BFCM) | B11: Rank | C11: "cooling sheets queen" top 15; cluster top 20 on ≥ 5 of 6 | D11: —
A12: Wk 6 | B12: TACoS | C12: ≤ 25% (top of launch band) | D12: SOP-22 F2
A13: Wk 8–10 (Dec) | B13: Rank → taper | C13: Top 10 on target terms 2 consecutive weeks → TAPER ~10%/week | D13: SOP-23 S-R6 / M3
A14: Wk 8–10 | B14: Efficiency | C14: ACoS ≤ 40%; TACoS ≤ 15%; NP/unit ≥ $7 | D14: Sleephoria ad month 2–3: TACoS 15% → 10%, NP/unit $7.25 → $10.51
A15: Wk 12–16 (Jan–Feb) | B15: Seasonal context | C15: Jan is the demand trough (SQP index 0.55; purchases 0.48). Judge Jan on rank held + TACoS, not on unit growth. | D15: Historical_Analysis: Seasonality
... A20: Continuous | B20: Inventory | C20: Re-point the advertised child to the BACKUP when preferred cover < 21 days or below the unit floor (Preferred_Backup); G6 RED at ≤ 14 days | D20: Median cover 14 days before observed stockouts = 17.5 days; Sleephoria never re-pointed and lost peak season

Sheet Open_Items
A1: Open items & rulings required before go-live
A2: Owner decides; this file proposes.
A4: # | B4: Item | C4: Proposal | D4: Decision owner | E4: Impact
A5: 1 | B5: Sibling ownership of Queen roots (SOP-33) | C5: CooLinens = owner of Queen roots; Sleephoria keeps head/King/Twin/Cal King/hot-sleeper roots; Sleephoria Queen terms → DEFEND AT FLOOR | D5: PPC Lead + Brand owner | E5: Blocks ranking-size spend on Queen terms
A6: 2 | B6: Sleephoria Queen "wave 1" push scheduled 9 Nov | C6: Cancel or redirect to King cluster (Sleephoria King CVR 12–16%) | D6: PPC Lead | E6: Two pushes on one root = self-bidding
A7: 3 | B7: O3 FAR-BEHIND review gate (24 Vine reviews vs top-5 median far higher) | C7: Waive for launch: Sleephoria ranked top-10 with ~39 Vine reviews in Oct-25 | D7: PPC Lead | E7: SOP-23 bars ranking pushes otherwise
A8: 4 | B8: Mechanical CODE RED (launch TACoS) vs BFCM Recovery Mode precedence (AM-16) | C8: Record CODE RED; Event Mode governs the launch exacts named in the BFCM plan | D8: PPC Lead | E8: Needed before 28 Oct event plan
A9: 5 | B9: SOP-33 P3.5 "no new exact instance" on undeclared roots vs P5 probe / SOP-22 I-11 capped test | C9: Treat day-0 Queen exacts as the P5 probe (capped) | D9: PPC Lead | E9: Otherwise Queen terms cannot go live on 15 Oct
A10: 6 | B10: thresholds.yml vs v4.0 conflicts (G2 clicks 15 vs 10; harvest 3 vs 2 orders; TOS share floor 30% vs 20%; objective mix) | C10: Use SOP/v4.0 values for launch; thresholds.yml after handoff | D10: PPC Lead | E10: —
A11: 7 | B11: G5 indexing of all 12 batch-1 terms on B0H6K1MKQW | C11: Check this week (listing was made live 7 Oct for creator outreach) | D11: Launch operator | E11: Unindexed terms cannot enter batch 1
A12: 8 | B12: Fabric & claims (bamboo / Tencel / Coolmax / Q-Max?) | C12: Confirm; drives material keywords and negatives | D12: Brand owner | E12: Decolure "bamboo" terms failed (60–118% ACoS)
A13: 9 | B13: BFCM deal | C13: Coupon or Prime-exclusive discount on Queen/King Graphite | D13: Brand owner | E13: PBDD 2026: TACoS 7.7% with deal vs 17% without
A14: 10 | B14: CooLinens fee data missing in command center | C14: Load fees so BE ACoS can be computed natively (spine is PROVISIONAL) | D14: Data owner | E14: —
A15: 11 | B15: Creatives final by 15 Oct (Nat) | C15: Launch exacts only once main/secondary/A+ are final — price/image changes reset CVR reads (G9) | D15: Creative | E15: Sleephoria Aug–Sep price + image changes preceded CVR slide
A16: 12 | B16: Re-order for the Mar–Jul peak (no CooLinens inbound) | C16: Place PO sized to land by early March; prioritise Queen/King Graphite + Cool Grey and thin Twin/Cal King SKUs | D16: Brand owner / Ops | E16: Stockout at peak was the costliest event in Sleephoria history
A17: 13 | B17: MKL | C17: Merge on arrival (MKL_Intake); re-score relevancy against live listing; finalise Batch 2 + negatives | D17: PPC team | E17: G12 requires MKL refreshed within 30 days

Sheet Batch2_Candidates
A1: Batch 2 / Phase 2 candidates (from history + market data; finalise after MKL)
A2: Funded only from released budget + unspent envelope (SOP-22 P5). Graduation bar into exact = 3 orders (S-H1).
A4: Term / surface | B4: Bucket | C4: Historical evidence | D4: Proposed owner
A5: queen sheet set cooling | B5: Queen tail (Class-2 consolidated exact) | C5: Sleephoria 8.5% ACoS on 8 clicks / 3 orders; Decolure 52% | D5: CooLinens (if Queen declared)
A6: cooling queen sheet set | B6: Queen tail | C6: Low data at Sleephoria | D6: CooLinens
A7: queen cooling sheet set | B7: Queen tail | C7: Low data | D7: CooLinens
A8: cooling sheets queen size | B8: Queen tail | C8: Sleephoria 38.6% ACoS, 5.8% CVR (504 clicks) — bid conservatively | D8: CooLinens
A9: sheets queen cooling | B9: Queen tail | C9: Sleephoria org 35–41 | D9: CooLinens
A10: queen size sheets cooling | B10: Queen tail | C10: Sleephoria 36% ACoS | D10: CooLinens
A11: cool sheets queen | B11: Queen tail | C11: Sleephoria 22.8% ACoS, 15% CVR; Decolure 17.8% | D11: CooLinens
A12: queen bed sheets cooling | B12: Queen tail | C12: Sleephoria org 14, 35.5% ACoS → shared; probe only | D12: Sleephoria-held — probe
A13: cooling sheets queen deep pockets | B13: Queen tail | C13: Low data; Decolure 0 orders / 32 clicks | D13: CooLinens — capped
A14: cooling bedding set | B14: Discovery | C14: DD 1.3k/mo; 1 rival top 10 | D14: Unowned
A15: deep pocket cooling sheets | B15: Discovery | C15: Sleephoria 53.6% ACoS (23 clicks) | D15: Unowned — capped
... A22: <MKL additions> | B22: Pending MKL | C22: Insert MKL-scored terms here (relevancy + syntax tag required, G12) | D22: —

Sheet Negatives_Day1
A1: Negative & wall architecture (SOP-29) — pre-load at each structure event
A2: Exact campaigns get NO keyword pre-load. These apply to every broad / phrase / auto surface when Phase 2 opens, plus the sibling walls which go in on day 0.
A4: Term / ASIN set | B4: Match | C4: Scope | D4: Evidence / reason
A5: sleephoria | B5: Negative phrase | C5: All CooLinens discovery surfaces | D5: Sibling brand wall (SOP-29 P7)
A6: decolure | B6: Negative phrase | C6: All CooLinens discovery surfaces | D6: Sibling brand wall
A7: coolinens | B7: Negative phrase | C7: All Sleephoria + Decolure non-branded discovery (day 0) | D7: Reverse wall — stop siblings buying CooLinens brand traffic
A8: Sleephoria & Decolure child ASINs | B8: Negative ASIN | C8: CooLinens auto / PAT (when opened) | D8: Self-cannibalisation wall
A9: CooLinens child ASINs | B9: Negative ASIN | C9: Sleephoria + Decolure auto / PAT | D9: Reverse wall
A10: Declared CooLinens Queen roots (e.g. "cooling sheets queen") | B10: Negative exact (then phrase on root) | C10: Sleephoria discovery, same day as declaration | D10: SOP-33 wall; Sleephoria keeps model-specific variants at DEFEND AT FLOOR
A11: Graduated exacts | B11: Negative exact | C11: Every broad/phrase/auto that could serve them | D11: Isolation (SOP-12 P1.9)
A12: fan | B12: Negative phrase | C12: Discovery | D12: Sleephoria: "under the sheets cooling fan", "bed cooling fan under sheets" — 0 orders
A13: bed jet / bed cooling system | B13: Negative phrase | C13: Discovery | D13: Sleephoria 0–1 orders; device intent
A14: comforter | B14: Negative phrase | C14: Discovery | D14: Sleephoria + Decolure 0-order spend; separate Sleephoria product
A15: blanket | B15: Negative phrase | C15: Discovery | D15: Decolure $22, 0 orders
... A28: Watch, not negate: king cooling sheets, cold sheets, cold bed sheets, black cooling sheets, cooling bed set | B28: Bid down / TOS-only | C28: — | D28: Relevant but uneconomic at Sleephoria (60–78% ACoS); not CooLinens roots at launch
A30: Reactive negation (after launch): ≥ 2× target CPA spend, 0 orders, ≥ 10 clicks, 60-day window (thresholds.yml W4a; SOP-29 AM-1 — v4.0 value not specified). Never negate an in-window converter.

Sheet PAT_Shortlist
A1: PAT / conquest shortlist — Phase 3–4 only (NOT at launch, SOP-22 §5)
A2: SOP-16 S-C1: we must win ≥ 2 of price / rating / review count (or rival OOS). Enter CooLinens rating once Vine reviews settle (yellow cell).
A4: CooLinens Queen price | B4: 79.99
A5: CooLinens rating (enter) | B5: 4.4
A6: CooLinens review count (enter) | B6: 24
A8: Rival | B8: ASINs | C8: Rival price | D8: Rival rating | E8: Rival reviews | F8: We win price? | G8: We win rating? | H8: We win reviews? | I8: Wins (of 3) | J8: S-C1 gate | K8: Recommendation
A9: Breescape | B9: B0DSPZJKTB / B0DSPZ9151 / B0DSPZSVFL | C9: 149.99 | D9: 4.2 | E9: 593 | F9: =IF(C9="","",IF($B$4<C9,1,0)) -> 1 | G9: =IF(D9="","",IF($B$5>D9,1,0)) -> 1 | H9: =IF(E9="","",IF($B$6>E9,1,0)) -> 0 | I9: =SUM(F9:H9) -> 2 | J9: =IF(I9>=2,"PASS","FAIL") -> PASS | K9: Target
A10: Breescape (old parents) | B10: B0DSPYXPSP / B0DSQ26RH3 | C10: 139.99 | D10: 3.8 | E10: 72 | F10: =IF(C10="","",IF($B$4<C10,1,0)) -> 1 | G10: =IF(D10="","",IF($B$5>D10,1,0)) -> 1 | H10: =IF(E10="","",IF($B$6>E10,1,0)) -> 0 | I10: =SUM(F10:H10) -> 2 | J10: =IF(I10>=2,"PASS","FAIL") -> PASS | K10: Target
A11: REST Evercool+ | B11: B0BLYSGFRW / B0C56ZNQVQ / B0D9JJSNC5 / B0D25LDRPS | C11: 164.25 | D11: 4.3 | E11: 1133 | F11: =IF(C11="","",IF($B$4<C11,1,0)) -> 1 | G11: =IF(D11="","",IF($B$5>D11,1,0)) -> 1 | H11: =IF(E11="","",IF($B$6>E11,1,0)) -> 0 | I11: =SUM(F11:H11) -> 2 | J11: =IF(I11>=2,"PASS","FAIL") -> PASS | K11: Target
A12: SHEEX | B12: B00EWJS3PO | C12: 149 | D12: 4.5 | E12: 3254 | F12: =IF(C12="","",IF($B$4<C12,1,0)) -> 1 | G12: =IF(D12="","",IF($B$5>D12,1,0)) -> 0 | H12: =IF(E12="","",IF($B$6>E12,1,0)) -> 0 | I12: =SUM(F12:H12) -> 1 | J12: =IF(I12>=2,"PASS","FAIL") -> FAIL | K12: Target (price only — needs rating win)
A13: Cozy Bliss Premium (3pc, no flat) | B13: B0DMNQDZNB / B0DMNP5BC8 | C13: 89.99 | D13: 4.5 | E13: 436 | F13: =IF(C13="","",IF($B$4<C13,1,0)) -> 1 | G13: =IF(D13="","",IF($B$5>D13,1,0)) -> 0 | H13: =IF(E13="","",IF($B$6>E13,1,0)) -> 0 | I13: =SUM(F13:H13) -> 1 | J13: =IF(I13>=2,"PASS","FAIL") -> FAIL | K13: Target (3pc vs our 4pc)
A14: Dream Valley (3pc King) | B14: B0D3WMGX6P | C14: 99 | F14: =IF(C14="","",IF($B$4<C14,1,0)) -> 1 | G14: =IF(D14="","",IF($B$5>D14,1,0)) | H14: =IF(E14="","",IF($B$6>E14,1,0)) | I14: =SUM(F14:H14) -> 1 | J14: =IF(I14>=2,"PASS","FAIL") -> FAIL | K14: Target
A15: Degrees of Comfort PolarEdge Pro | B15: B0DYS4HVM3 | C15: 148.99 | D15: 4.3 | E15: 59 | F15: =IF(C15="","",IF($B$4<C15,1,0)) -> 1 | G15: =IF(D15="","",IF($B$5>D15,1,0)) -> 1 | H15: =IF(E15="","",IF($B$6>E15,1,0)) -> 0 | I15: =SUM(F15:H15) -> 2 | J15: =IF(I15>=2,"PASS","FAIL") -> PASS | K15: Target
A16: DOWNCOOL | B16: B0F93XMMQY | C16: 79.99 | D16: 4.1 | E16: 24 | F16: =IF(C16="","",IF($B$4<C16,1,0)) -> 0 | G16: =IF(D16="","",IF($B$5>D16,1,0)) -> 1 | H16: =IF(E16="","",IF($B$6>E16,1,0)) -> 0 | I16: =SUM(F16:H16) -> 1 | J16: =IF(I16>=2,"PASS","FAIL") -> FAIL | K16: Target
A17: Elegear | B17: B0GCHG6VG6 / B0GCHRGYZZ | C17: 89.99 | D17: 4.4 | E17: 129 | F17: =IF(C17="","",IF($B$4<C17,1,0)) -> 1 | G17: =IF(D17="","",IF($B$5>D17,1,0)) -> 0 | H17: =IF(E17="","",IF($B$6>E17,1,0)) -> 0 | I17: =SUM(F17:H17) -> 1 | J17: =IF(I17>=2,"PASS","FAIL") -> FAIL | K17: Target
A18: KARISSA MAE | B18: B0G1CSCQTB | C18: 119.99 | D18: 4.3 | E18: 472 | F18: =IF(C18="","",IF($B$4<C18,1,0)) -> 1 | G18: =IF(D18="","",IF($B$5>D18,1,0)) -> 1 | H18: =IF(E18="","",IF($B$6>E18,1,0)) -> 0 | I18: =SUM(F18:H18) -> 2 | J18: =IF(I18>=2,"PASS","FAIL") -> PASS | K18: Target
A19: Pillcase legacy listings | B19: B0FLDYD61P / B0GZ243WW5 | C19: 79 | D19: 2.5 | E19: 250 | F19: =IF(C19="","",IF($B$4<C19,1,0)) -> 0 | G19: =IF(D19="","",IF($B$5>D19,1,0)) -> 1 | H19: =IF(E19="","",IF($B$6>E19,1,0)) -> 0 | I19: =SUM(F19:H19) -> 1 | J19: =IF(I19>=2,"PASS","FAIL") -> FAIL | K19: Target
A20: TWK | B20: B0DYT2QWLC | C20: 62.1 | D20: 3.6 | E20: 131 | F20: =IF(C20="","",IF($B$4<C20,1,0)) -> 0 | G20: =IF(D20="","",IF($B$5>D20,1,0)) -> 1 | H20: =IF(E20="","",IF($B$6>E20,1,0)) -> 0 | I20: =SUM(F20:H20) -> 1 | J20: =IF(I20>=2,"PASS","FAIL") -> FAIL | K20: Test
A21: Brookstone fitted only | B21: B0CTKL3YJ2 | C21: 69.99 | D21: 4.1 | E21: 183 | F21: =IF(C21="","",IF($B$4<C21,1,0)) -> 0 | G21: =IF(D21="","",IF($B$5>D21,1,0)) -> 1 | H21: =IF(E21="","",IF($B$6>E21,1,0)) -> 0 | I21: =SUM(F21:H21) -> 1 | J21: =IF(I21>=2,"PASS","FAIL") -> FAIL | K21: Test (fitted-only shopper)
A22: Degrees of Comfort Coolmax | B22: B08YS6WZRR | C22: 28.49 | D22: 4.1 | E22: 7324 | F22: =IF(C22="","",IF($B$4<C22,1,0)) -> 0 | G22: =IF(D22="","",IF($B$5>D22,1,0)) -> 1 | H22: =IF(E22="","",IF($B$6>E22,1,0)) -> 0 | I22: =SUM(F22:H22) -> 1 | J22: =IF(I22>=2,"PASS","FAIL") -> FAIL | K22: AVOID
A23: Comfort Spaces | B23: B08R6MTY36 | C23: 28.49 | D23: 4.1 | E23: 23009 | F23: =IF(C23="","",IF($B$4<C23,1,0)) -> 0 | G23: =IF(D23="","",IF($B$5>D23,1,0)) -> 1 | H23: =IF(E23="","",IF($B$6>E23,1,0)) -> 0 | I23: =SUM(F23:H23) -> 1 | J23: =IF(I23>=2,"PASS","FAIL") -> FAIL | K23: AVOID
A24: Love's cabin | B24: B0DN1DVKH5 | C24: 37.99 | D24: 4.4 | E24: 1856 | F24: =IF(C24="","",IF($B$4<C24,1,0)) -> 0 | G24: =IF(D24="","",IF($B$5>D24,1,0)) -> 0 | H24: =IF(E24="","",IF($B$6>E24,1,0)) -> 0 | I24: =SUM(F24:H24) -> 0 | J24: =IF(I24>=2,"PASS","FAIL") -> FAIL | K24: AVOID
A25: Bedsure PureWoven | B25: B07YKCZHGK | C25: 64.59 | D25: 4.4 | E25: 64995 | F25: =IF(C25="","",IF($B$4<C25,1,0)) -> 0 | G25: =IF(D25="","",IF($B$5>D25,1,0)) -> 0 | H25: =IF(E25="","",IF($B$6>E25,1,0)) -> 0 | I25: =SUM(F25:H25) -> 0 | J25: =IF(I25>=2,"PASS","FAIL") -> FAIL | K25: AVOID
A26: CGK microfiber | B26: B01M16WBW1 | C26: 24.99 | D26: 4.5 | E26: 461815 | F26: =IF(C26="","",IF($B$4<C26,1,0)) -> 0 | G26: =IF(D26="","",IF($B$5>D26,1,0)) -> 0 | H26: =IF(E26="","",IF($B$6>E26,1,0)) -> 0 | I26: =SUM(F26:H26) -> 0 | J26: =IF(I26>=2,"PASS","FAIL") -> FAIL | K26: AVOID
A27: Pure Bamboo | B27: B07DZTQ4JC | C27: 109.99 | D27: 4.5 | E27: 21857 | F27: =IF(C27="","",IF($B$4<C27,1,0)) -> 1 | G27: =IF(D27="","",IF($B$5>D27,1,0)) -> 0 | H27: =IF(E27="","",IF($B$6>E27,1,0)) -> 0 | I27: =SUM(F27:H27) -> 1 | J27: =IF(I27>=2,"PASS","FAIL") -> FAIL | K27: Test only

Sheet Brand_Compare
A1: Sleephoria vs Decolure — what is repeatable
A2: Sellerboard (Ecotero account) + Ecotero command center. Sleephoria PPC data from 3 Oct 2025; Decolure PPC detail from Sep 2025 (launch Oct 2023 not in PPC data).
A4: Dimension | B4: Sleephoria 4PC | C4: Decolure 4PC | D4: Carry-over to CooLinens
A5: Price tier (Queen) | B5: $64.99 → $79.99 now | C5: ~$38 | D5: Sleephoria
A6: COGS / unit | B6: $26.31 | C6: $15.81 | D6: CooLinens = Sleephoria
A7: Amazon fees / unit | B7: $19.19 | C7: $19.13 | D7: Fees same $ → price drives profit
A8: NP / unit (L12M) | B8: $11.24 | C8: −$4.68 | D8: —
A9: TACoS (L12M) | B9: 9.6% | C9: 16.2% | D9: —
A10: Ad months 1–3 TACoS | B10: 24% → 15% → 10% | C10: 30% → 21% → 22% | D10: Sleephoria curve = template
A11: Ad months 1–3 margin | B11: 3% → 11% → 17% | C11: −12% → −4% → −21% | D11: —
A12: Non-brand ACoS / CVR / CPC | B12: 31.5% / 10.6% / $2.24 | C12: 51.6% / 6.6% / $1.36 | D12: Plan to Sleephoria non-brand
A13: Branded share of keyword ad sales | B13: ~40% at 14% ACoS | C13: small | D13: Not available to CooLinens at launch
A14: Best structure | B14: Single-kw exact per size on hero child + low-bid auto/broad harvest + branded defence | C14: Own-ASIN defence + LTSF autos (multi-product, blurs reads) | D14: Single-kw exact on hero child
A15: Worst structure | B15: Single-kw exact on "king cooling sheets" (57.9% ACoS, $4.86 CPC) | C15: Exact ranking pushes off-season (59.5% ACoS); broad 209% | D15: Gate King; no off-season rank buying
... A22: Size mix (units) | B22: Queen 42%, King 26%, Full 15%, Twin 9%, Cal King 8% | C22: Queen 48%, King 27%, Full 12%, Cal King 8%, Twin 6% | D22: Queen lead; CooLinens stock 41/23/14/11/10 matches

Sheet Sleephoria_Monthly
A1: Sleephoria Monthly
A2: Sellerboard (total business) + command-center PPC (7-day attribution, includes sibling-variation halo). PPC data starts 3 Oct 2025.
A4: Month | B4: Sales $ | C4: Units | D4: Orders | E4: Refund % | F4: Ad spend $ | G4: TACoS % | H4: COGS $ | I4: Amazon fees $ | J4: Net profit $ | K4: Margin % | L4: NP / unit | M4: ASP | N4: Sessions | O4: Unit session % | P4: LTSF $
A5: 2025-07 | B5: 1919.68 | C5: 32 | D5: 32 | E5: 0 | F5: 0 | G5: 0 | H5: -766.4 | I5: -276.46 | J5: -982.87 | K5: -51.2 | L5: -30.71 | M5: 59.99 | N5: 99 | O5: 32.32 | P5: 0
A6: 2025-08 | B6: 2849.53 | C6: 47 | D6: 44 | E6: 0 | F6: 0 | G6: 0 | H6: -1163.85 | I6: -876.2 | J6: 329.56 | K6: 11.57 | L6: 7.01 | M6: 60.63 | N6: 3834 | O6: 1.23 | P6: 0
A7: 2025-09 | B7: 4529.18 | C7: 82 | D7: 76 | E7: 4.9 | F7: 0 | G7: 0 | H7: -1887.11 | I7: -1576.26 | J7: 908.06 | K7: 20.05 | L7: 11.07 | M7: 55.23 | N7: 2887 | O7: 2.84 | P7: 0
A8: 2025-10 | B8: 72449.24 | C8: 1187 | D8: 1162 | E8: 2.8 | F8: 17635.66 | G8: 24.3 | H8: -29594.06 | I8: -21172.85 | J8: 2031.89 | K8: 2.8 | L8: 1.71 | M8: 61.04 | N8: 19407 | O8: 6.12 | P8: 0
A9: 2025-11 | B9: 76508.15 | C9: 1186 | D9: 1167 | E9: 5 | F9: 11480.77 | G9: 15 | H9: -29318.28 | I9: -24562.41 | J9: 8601.15 | K9: 11.24 | L9: 7.25 | M9: 64.51 | N9: 20061 | O9: 5.91 | P9: 0
A10: 2025-12 | B10: 63859.59 | C10: 1003 | D10: 988 | E10: 4.9 | F10: 6361.05 | G10: 10 | H10: -24581.8 | I10: -19960.92 | J10: 10539.7 | K10: 16.5 | L10: 10.51 | M10: 63.67 | N10: 15284 | O10: 6.56 | P10: 0
A11: 2026-01 | B11: 24375.16 | C11: 372 | D11: 358 | E11: 12.4 | F11: 1634.34 | G11: 6.7 | H11: -9915.07 | I11: -6942.95 | J11: 4013 | K11: 16.46 | L11: 10.79 | M11: 65.52 | N11: 9518 | O11: 3.91 | P11: -0.73
A12: 2026-02 | B12: 57344.39 | C12: 866 | D12: 855 | E12: 4.5 | F12: 3290.88 | G12: 5.7 | H12: -23646.14 | I12: -15919.36 | J12: 12784.12 | K12: 22.29 | L12: 14.76 | M12: 66.22 | N12: 16412 | O12: 5.28 | P12: -38.23
A13: 2026-03 | B13: 122501.4 | C13: 1873 | D13: 1845 | E13: 3.3 | F13: 5376.24 | G13: 4.4 | H13: -51381.79 | I13: -33656.62 | J13: 29172.14 | K13: 23.81 | L13: 15.58 | M13: 65.4 | N13: 59708 | O13: 3.14 | P13: -22.36
A14: 2026-04 | B14: 103299.26 | C14: 1586 | D14: 1568 | E14: 7.4 | F14: 4159.69 | G14: 4 | H14: -42411.57 | I14: -29396.96 | J14: 21419.36 | K14: 20.74 | L14: 13.51 | M14: 65.13 | N14: 63352 | O14: 2.5 | P14: -1.93
A15: 2026-05 | B15: 57946.17 | C15: 888 | D15: 871 | E15: 7.3 | F15: 4408.76 | G15: 7.6 | H15: -23704.74 | I15: -16611.15 | J15: 9986.32 | K15: 17.23 | L15: 11.25 | M15: 65.25 | N15: 22122 | O15: 4.01 | P15: 0
A16: 2026-06 | B16: 34284.34 | C16: 560 | D16: 548 | E16: 7.7 | F16: 4912.76 | G16: 14.3 | H16: -14280.92 | I16: -9543.07 | J16: 3494.75 | K16: 10.19 | L16: 6.24 | M16: 61.22 | N16: 21322 | O16: 2.63 | P16: 0
... A20: 2026-10-MTD | B20: 10268.7 | C20: 131 | D20: 131 | E20: 5.3 | F20: 1482.05 | G20: 14.4 | H20: -3738.64 | I20: -2653.33 | J20: 2012.62 | K20: 19.6 | L20: 15.36 | M20: 78.39 | N20: 2750 | O20: 4.76 | P20: 0
A22: PPC trajectory (Ecotero command center)
A23: Month | B23: PPC spend | C23: Ad sales | D23: ACoS % | E23: TACoS % | F23: Impressions | G23: Clicks | H23: CTR % | I23: CPC | J23: CVR % | K23: Orders | L23: Spend/day
A24: 2025-10 | B24: 17636 | C24: 36174 | D24: 48.8 | E24: 24.5 | F24: 255511 | G24: 3621 | H24: 1.42 | I24: 4.87 | J24: 16.2 | K24: 587 | L24: 608
A25: 2025-11 | B25: 11481 | C25: 25610 | D25: 44.8 | E25: 15 | F25: 197132 | G25: 2709 | H25: 1.37 | I25: 4.24 | J25: 14.9 | K25: 403 | L25: 383
A26: 2025-12 | B26: 6361 | C26: 23684 | D26: 26.9 | E26: 10 | F26: 256525 | G26: 2554 | H26: 1 | I26: 2.49 | J26: 15.1 | K26: 386 | L26: 205
A27: 2026-01 | B27: 1634 | C27: 5355 | D27: 30.5 | E27: 6.7 | F27: 88155 | G27: 820 | H27: 0.93 | I27: 1.99 | J27: 11.1 | K27: 91 | L27: 53
A28: 2026-02 | B28: 3291 | C28: 13909 | D28: 23.7 | E28: 5.7 | F28: 119532 | G28: 1435 | H28: 1.2 | I28: 2.29 | J28: 15.4 | K28: 221 | L28: 118
A29: 2026-03 | B29: 5382 | C29: 24656 | D29: 21.8 | E29: 4.4 | F29: 158510 | G29: 2353 | H29: 1.48 | I29: 2.29 | J29: 16.5 | K29: 389 | L29: 174
A30: 2026-04 | B30: 4165 | C30: 15644 | D30: 26.6 | E30: 4 | F30: 158678 | G30: 2094 | H30: 1.32 | I30: 1.99 | J30: 12.2 | K30: 256 | L30: 139
A31: 2026-05 | B31: 4411 | C31: 16069 | D31: 27.5 | E31: 7.6 | F31: 306571 | G31: 2137 | H31: 0.7 | I31: 2.06 | J31: 12.1 | K31: 259 | L31: 142
A32: 2026-06 | B32: 4916 | C32: 13512 | D32: 36.4 | E32: 14.2 | F32: 230687 | G32: 2383 | H32: 1.03 | I32: 2.06 | J32: 9.9 | K32: 235 | L32: 164
A33: 2026-07 | B33: 2025 | C33: 8791 | D33: 23 | E33: 6.8 | F33: 131201 | G33: 1350 | H33: 1.03 | I33: 1.5 | J33: 11.2 | K33: 151 | L33: 65
A34: 2026-08 | B34: 6578 | C34: 28302 | D34: 23.2 | E34: 8.8 | F34: 477465 | G34: 3407 | H34: 0.71 | I34: 1.93 | J34: 11.7 | K34: 397 | L34: 212
A35: 2026-09 | B35: 7423 | C35: 26676 | D35: 27.8 | E35: 11.7 | F35: 509129 | G35: 3656 | H35: 0.72 | I35: 2.03 | J35: 9.4 | K35: 344 | L35: 247
A36: 2026-10 | B36: 1482 | C36: 3744 | D36: 39.6 | E36: 15.8 | F36: 170207 | G36: 793 | H36: 0.47 | I36: 1.87 | J36: 6.2 | K36: 49 | L36: 212

Sheet Decolure_Monthly
A1: Decolure Monthly
A2: Sellerboard (total business), Oct 2023 → Oct 2026 MTD. PPC detail per month in Decolure PPC section below.
A4: Month | B4: Sales $ | C4: Units | D4: Orders | E4: Refund % | F4: Ad spend $ | G4: TACoS % | H4: COGS $ | I4: Amazon fees $ | J4: Net profit $ | K4: Margin % | L4: NP / unit | M4: ASP | N4: Sessions | O4: Unit session % | P4: LTSF $
A5: 2023-10 | B5: 1481.4 | C5: 255 | D5: 253 | E5: 0.4 | F5: 0 | G5: 0 | H5: -2969.85 | I5: 299.19 | J5: -1206.92 | K5: -81.47 | L5: -4.73 | M5: 5.81 | N5: 2781 | O5: 9.17 | P5: 0
A6: 2023-11 | B6: 31955.95 | C6: 1001 | D6: 990 | E6: 2 | F6: 9507.3 | G6: 29.8 | H6: -11564.56 | I6: -14096.53 | J6: -3782.07 | K6: -11.84 | L6: -3.78 | M6: 31.92 | N6: 19164 | O6: 5.22 | P6: 0
